File: Fig6C/211130_Instron/211130/PureCompression_TTball_4.is_comp_Exports/PureCompression_TTball_4_1.csv
Results Table 1


Results Table 2


Time,Displacement,Force,Compressive displacement,Compressive strain (Displacement),Compressive stress,PIP count
(s),(mm),(kN),(mm),(%),(MPa),
"0.0000","0.0000","0.0000","0.0000","0.0000","0.0049","0.0000"
"0.0600","0.0323","0.0001","0.0323","0.0809","0.0054","0.0000"
"0.1200","0.0975","0.0000","0.0975","0.2438","-0.0025","0.0000"
"0.1800","0.1504","0.0000","0.1504","0.3760","-0.0029","0.0000"
"0.2400","0.2010","0.0000","0.2010","0.5026","-0.0006","0.0000"
"0.3000","0.2511","0.0006","0.2511","0.6278","0.0618","0.0000"
"0.3600","0.3015","0.0028","0.3015","0.7538","0.2769","0.0000"
"0.4200","0.3518","0.0050","0.3518","0.8795","0.4993","0.0000"
"0.4800","0.4016","0.0072","0.4016","1.0041","0.7177","0.0000"
"0.5400","0.4517","0.0093","0.4517","1.1292","0.9323","0.0000"
"0.6000","0.5011","0.0115","0.5011","1.2529","1.1493","0.0000"
"0.6600","0.5513","0.0136","0.5513","1.3783","1.3573","0.0000"
"0.7200","0.6017","0.0157","0.6017","1.5043","1.5714","0.0000"
"0.7800","0.6518","0.0177","0.6518","1.6295","1.7672","0.0000"
"0.8400","0.7016","0.0197","0.7016","1.7540","1.9656","0.0000"
"0.9000","0.7514","0.0217","0.7514","1.8786","2.1653","0.0000"
"0.9600","0.8017","0.0237","0.8017","2.0043","2.3672","0.0000"
"1.0200","0.8513","0.0257","0.8513","2.1282","2.5698","0.0000"
"1.0800","0.9016","0.0277","0.9016","2.2540","2.7668","0.0000"
"1.1400","0.9515","0.0298","0.9515","2.3788","2.9800","0.0000"
"1.2000","1.0016","0.0319","1.0016","2.5040","3.1897","0.0000"
"1.2600","1.0518","0.0341","1.0518","2.6294","3.4066","0.0000"
"1.3200","1.1013","0.0361","1.1013","2.7534","3.6132","0.0000"
"1.3800","1.1517","0.0383","1.1517","2.8794","3.8306","0.0000"
"1.4400","1.2013","0.0405","1.2013","3.0033","4.0473","0.0000"
"1.5000","1.2515","0.0426","1.2515","3.1288","4.2620","0.0000"
"1.5600","1.3014","0.0448","1.3014","3.2536","4.4754","0.0000"
"1.6200","1.3515","0.0468","1.3515","3.3788","4.6793","0.0000"
"1.6800","1.4014","0.0489","1.4014","3.5036","4.8896","0.0000"
"1.7400","1.4514","0.0511","1.4514","3.6284","5.1097","0.0000"
"1.8000","1.5018","0.0535","1.5018","3.7545","5.3483","0.0000"
"1.8600","1.5511","0.0560","1.5511","3.8778","5.5952","0.0000"
"1.9200","1.6017","0.0584","1.6017","4.0041","5.8383","0.0000"
"1.9800","1.6516","0.0608","1.6516","4.1290","6.0813","0.0000"
"2.0400","1.7013","0.0632","1.7013","4.2532","6.3220","0.0000"
"2.1000","1.7517","0.0656","1.7517","4.3793","6.5619","0.0000"
"2.1600","1.8013","0.0681","1.8013","4.5032","6.8109","0.0000"
"2.2200","1.8512","0.0705","1.8512","4.6281","7.0502","0.0000"
"2.2800","1.9019","0.0730","1.9019","4.7547","7.2986","0.0000"
"2.3400","1.9517","0.0755","1.9517","4.8792","7.5464","0.0000"
"2.4000","2.0015","0.0779","2.0015","5.0038","7.7942","0.0000"
"2.4600","2.0515","0.0805","2.0515","5.1286","8.0452","0.0000"
"2.5200","2.1017","0.0830","2.1017","5.2544","8.3010","0.0000"
"2.5800","2.1514","0.0855","2.1514","5.3786","8.5508","0.0000"
"2.6400","2.2016","0.0881","2.2016","5.5040","8.8101","0.0000"
"2.7000","2.2513","0.0905","2.2513","5.6283","9.0514","0.0000"
"2.7600","2.3013","0.0929","2.3013","5.7531","9.2899","0.0000"
"2.8200","2.3520","0.0952","2.3520","5.8801","9.5233","0.0000"
"2.8800","2.4014","0.0972","2.4014","6.0034","9.7218","0.0000"
"2.9400","2.4517","0.0977","2.4517","6.1291","9.7743","0.0000"
"3.0000","2.5014","0.0970","2.5014","6.2534","9.7007","0.0000"
"3.0600","2.5514","0.0978","2.5514","6.3785","9.7762","0.0000"
"3.1200","2.6016","0.0991","2.6016","6.5040","9.9126","0.0000"
"3.1800","2.6515","0.1006","2.6515","6.6288","10.0560","0.0000"
"3.2400","2.7015","0.1021","2.7015","6.7537","10.2138","0.0000"
"3.3000","2.7518","0.1038","2.7518","6.8794","10.3752","0.0000"
"3.3600","2.8019","0.1054","2.8019","7.0048","10.5427","0.0000"
"3.4200","2.8514","0.1071","2.8514","7.1285","10.7084","0.0000"
"3.4800","2.9017","0.1087","2.9017","7.2542","10.8675","0.0000"
"3.5400","2.9516","0.1105","2.9516","7.3791","11.0484","0.0000"
"3.6000","3.0014","0.1124","3.0014","7.5036","11.2409","0.0000"
"3.6600","3.0517","0.1142","3.0517","7.6293","11.4165","0.0000"
"3.7200","3.1016","0.1156","3.1016","7.7539","11.5616","0.0000"
"3.7800","3.1513","0.1169","3.1513","7.8781","11.6926","0.0000"
"3.8400","3.2014","0.1184","3.2014","8.0036","11.8390","0.0000"
"3.9000","3.2517","0.1199","3.2517","8.1293","11.9936","0.0000"
"3.9600","3.3018","0.1216","3.3018","8.2544","12.1595","0.0000"
"4.0200","3.3514","0.1230","3.3514","8.3784","12.3003","0.0000"
"4.0800","3.4017","0.1244","3.4017","8.5041","12.4392","0.0000"
"4.1400","3.4514","0.1254","3.4514","8.6284","12.5426","0.0000"
"4.2000","3.5014","0.1265","3.5014","8.7535","12.6515","0.0000"
"4.2600","3.5515","0.1277","3.5515","8.8787","12.7687","0.0000"
"4.3200","3.6016","0.1288","3.6016","9.0041","12.8770","0.0000"
"4.3800","3.6517","0.1297","3.6517","9.1292","12.9726","0.0000"
"4.4400","3.7014","0.1305","3.7014","9.2535","13.0473","0.0000"
"4.5000","3.7517","0.1312","3.7517","9.3792","13.1249","0.0000"
"4.5600","3.8016","0.1319","3.8016","9.5041","13.1883","0.0000"
"4.6200","3.8517","0.1325","3.8517","9.6292","13.2451","0.0000"
"4.6800","3.9016","0.1331","3.9016","9.7540","13.3053","0.0000"
"4.7400","3.9514","0.1336","3.9514","9.8786","13.3634","0.0000"
"4.8000","4.0015","0.1342","4.0015","10.0037","13.4243","0.0000"
"4.8600","4.0512","0.1349","4.0512","10.1280","13.4919","0.0000"
"4.9200","4.1018","0.1356","4.1018","10.2546","13.5617","0.0000"
"4.9800","4.1514","0.1362","4.1514","10.3786","13.6240","0.0000"
"5.0400","4.2017","0.1369","4.2017","10.5043","13.6917","0.0000"
"5.1000","4.2515","0.1376","4.2515","10.6288","13.7645","0.0000"
"5.1600","4.3015","0.1384","4.3015","10.7537","13.8448","0.0000"
"5.2200","4.3519","0.1394","4.3519","10.8797","13.9362","0.0000"
"5.2800","4.4013","0.1403","4.4013","11.0034","14.0340","0.0000"
"5.3400","4.4516","0.1415","4.4516","11.1291","14.1478","0.0000"
"5.4000","4.5013","0.1425","4.5013","11.2534","14.2500","0.0000"
"5.4600","4.5516","0.1436","4.5516","11.3791","14.3606","0.0000"
"5.5200","4.6016","0.1446","4.6016","11.5039","14.4560","0.0000"
"5.5800","4.6514","0.1457","4.6514","11.6285","14.5650","0.0000"
"5.6400","4.7017","0.1467","4.7017","11.7542","14.6663","0.0000"
"5.7000","4.7513","0.1477","4.7513","11.8782","14.7667","0.0000"
"5.7600","4.8018","0.1489","4.8018","12.0045","14.8884","0.0000"
"5.8200","4.8516","0.1501","4.8516","12.1290","15.0096","0.0000"
"5.8800","4.9012","0.1512","4.9012","12.2530","15.1249","0.0000"
"5.9400","4.9516","0.1525","4.9516","12.3790","15.2527","0.0000"
"6.0000","5.0015","0.1537","5.0015","12.5039","15.3747","0.0000"
"6.0600","5.0517","0.1550","5.0517","12.6293","15.4969","0.0000"
"6.1200","5.1013","0.1560","5.1013","12.7532","15.6049","0.0000"
"6.1800","5.1514","0.1572","5.1514","12.8784","15.7236","0.0000"
"6.2400","5.2013","0.1583","5.2013","13.0032","15.8323","0.0000"
"6.3000","5.2517","0.1594","5.2517","13.1293","15.9402","0.0000"
"6.3600","5.3019","0.1607","5.3019","13.2547","16.0696","0.0000"
"6.4200","5.3516","0.1620","5.3516","13.3789","16.1951","0.0000"
"6.4800","5.4016","0.1632","5.4016","13.5041","16.3215","0.0000"
"6.5400","5.4512","0.1644","5.4512","13.6280","16.4356","0.0000"
"6.6000","5.5014","0.1657","5.5014","13.7535","16.5740","0.0000"
"6.6600","5.5516","0.1669","5.5516","13.8789","16.6939","0.0000"
"6.7200","5.6015","0.1679","5.6015","14.0038","16.7919","0.0000"
"6.7800","5.6517","0.1690","5.6517","14.1292","16.9012","0.0000"
"6.8400","5.7014","0.1700","5.7014","14.2534","16.9955","0.0000"
"6.9000","5.7518","0.1710","5.7518","14.3795","17.0956","0.0000"
"6.9600","5.8015","0.1720","5.8015","14.5037","17.1957","0.0000"
"7.0200","5.8515","0.1729","5.8515","14.6289","17.2922","0.0000"
"7.0800","5.9015","0.1740","5.9015","14.7537","17.3993","0.0000"
"7.1400","5.9514","0.1750","5.9514","14.8785","17.5018","0.0000"
"7.2000","6.0017","0.1760","6.0017","15.0043","17.5999","0.0000"
"7.2600","6.0515","0.1768","6.0515","15.1288","17.6799","0.0000"
"7.3200","6.1018","0.1774","6.1018","15.2545","17.7415","0.0000"
"7.3800","6.1513","0.1779","6.1513","15.3782","17.7904","0.0000"
"7.4400","6.2016","0.1785","6.2016","15.5039","17.8537","0.0000"
"7.5000","6.2519","0.1792","6.2519","15.6297","17.9225","0.0000"
"7.5600","6.3016","0.1800","6.3016","15.7539","17.9963","0.0000"
"7.6200","6.3516","0.1809","6.3516","15.8791","18.0863","0.0000"
"7.6800","6.4012","0.1818","6.4012","16.0030","18.1824","0.0000"
"7.7400","6.4515","0.1828","6.4515","16.1288","18.2819","0.0000"
"7.8000","6.5016","0.1838","6.5016","16.2539","18.3808","0.0000"
"7.8600","6.5517","0.1847","6.5517","16.3793","18.4733","0.0000"
"7.9200","6.6019","0.1858","6.6019","16.5048","18.5767","0.0000"
"7.9800","6.6511","0.1869","6.6511","16.6278","18.6860","0.0000"
"8.0400","6.7012","0.1879","6.7012","16.7530","18.7925","0.0000"
"8.1000","6.7514","0.1889","6.7514","16.8784","18.8909","0.0000"
"8.1600","6.8019","0.1899","6.8019","17.0047","18.9922","0.0000"
"8.2200","6.8517","0.1910","6.8517","17.1293","19.0979","0.0000"
"8.2800","6.9015","0.1921","6.9015","17.2538","19.2075","0.0000"
"8.3400","6.9516","0.1933","6.9516","17.3790","19.3310","0.0000"
"8.4000","7.0016","0.1945","7.0016","17.5041","19.4497","0.0000"
"8.4600","7.0518","0.1958","7.0518","17.6295","19.5811","0.0000"
"8.5200","7.1015","0.1970","7.1015","17.7538","19.7037","0.0000"
"8.5800","7.1515","0.1981","7.1515","17.8786","19.8143","0.0000"
"8.6400","7.2013","0.1992","7.2013","18.0032","19.9240","0.0000"
"8.7000","7.2514","0.2003","7.2514","18.1286","20.0279","0.0000"
"8.7600","7.3019","0.2017","7.3019","18.2546","20.1711","0.0000"
"8.8200","7.3513","0.2029","7.3513","18.3783","20.2925","0.0000"
"8.8800","7.4015","0.2041","7.4015","18.5037","20.4129","0.0000"
"8.9400","7.4512","0.2052","7.4512","18.6280","20.5236","0.0000"
"9.0000","7.5017","0.2063","7.5017","18.7543","20.6312","0.0000"
"9.0600","7.5517","0.2076","7.5517","18.8791","20.7552","0.0000"
"9.1200","7.6015","0.2087","7.6015","19.0037","20.8666","0.0000"
"9.1800","7.6517","0.2098","7.6517","19.1291","20.9815","0.0000"
"9.2400","7.7012","0.2108","7.7012","19.2531","21.0783","0.0000"
"9.3000","7.7516","0.2118","7.7516","19.3791","21.1832","0.0000"
"9.3600","7.8016","0.2130","7.8016","19.5040","21.3012","0.0000"
"9.4200","7.8518","0.2142","7.8518","19.6294","21.4212","0.0000"
"9.4800","7.9015","0.2154","7.9015","19.7536","21.5378","0.0000"
"9.5400","7.9513","0.2164","7.9513","19.8782","21.6444","0.0000"
"9.6000","8.0018","0.2177","8.0018","20.0045","21.7727","0.0000"
"9.6600","8.0513","0.2188","8.0513","20.1282","21.8814","0.0000"
"9.7200","8.1018","0.2200","8.1018","20.2545","21.9960","0.0000"
"9.7800","8.1517","0.2211","8.1517","20.3793","22.1131","0.0000"
"9.8400","8.2016","0.2222","8.2016","20.5039","22.2168","0.0000"
"9.9000","8.2516","0.2233","8.2516","20.6290","22.3341","0.0000"
"9.9600","8.3013","0.2244","8.3013","20.7533","22.4374","0.0000"
"10.0200","8.3516","0.2255","8.3516","20.8790","22.5527","0.0000"
"10.0800","8.4015","0.2268","8.4015","21.0039","22.6799","0.0000"
"10.1400","8.4516","0.2280","8.4516","21.1290","22.8029","0.0000"
"10.2000","8.5014","0.2294","8.5014","21.2535","22.9408","0.0000"
"10.2600","8.5515","0.2305","8.5515","21.3787","23.0549","0.0000"
"10.3200","8.6019","0.2319","8.6019","21.5047","23.1855","0.0000"
"10.3800","8.6512","0.2328","8.6512","21.6281","23.2789","0.0000"
"10.4400","8.7014","0.2339","8.7014","21.7535","23.3872","0.0000"
"10.5000","8.7513","0.2351","8.7513","21.8783","23.5063","0.0000"
"10.5600","8.8014","0.2363","8.8014","22.0035","23.6295","0.0000"
"10.6200","8.8516","0.2378","8.8516","22.1289","23.7781","0.0000"
"10.6800","8.9016","0.2391","8.9016","22.2541","23.9052","0.0000"
"10.7400","8.9517","0.2402","8.9517","22.3792","24.0246","0.0000"
"10.8000","9.0013","0.2412","9.0013","22.5032","24.1241","0.0000"
"10.8600","9.0513","0.2424","9.0513","22.6283","24.2435","0.0000"
"10.9200","9.1017","0.2437","9.1017","22.7543","24.3730","0.0000"
"10.9800","9.1518","0.2450","9.1518","22.8795","24.4969","0.0000"
"11.0400","9.2018","0.2462","9.2018","23.0046","24.6213","0.0000"
"11.1000","9.2514","0.2473","9.2514","23.1286","24.7251","0.0000"
"11.1600","9.3015","0.2484","9.3015","23.2537","24.8413","0.0000"
"11.2200","9.3513","0.2496","9.3513","23.3782","24.9586","0.0000"
"11.2800","9.4017","0.2506","9.4017","23.5043","25.0616","0.0000"
"11.3400","9.4515","0.2517","9.4515","23.6288","25.1735","0.0000"
"11.4000","9.5016","0.2527","9.5016","23.7540","25.2664","0.0000"
"11.4600","9.5515","0.2536","9.5515","23.8788","25.3639","0.0000"
"11.5200","9.6013","0.2546","9.6013","24.0034","25.4605","0.0000"
"11.5800","9.6516","0.2556","9.6516","24.1291","25.5645","0.0000"
"11.6400","9.7016","0.2568","9.7016","24.2539","25.6778","0.0000"
"11.7000","9.7517","0.2580","9.7517","24.3794","25.8024","0.0000"
"11.7600","9.8014","0.2593","9.8014","24.5036","25.9320","0.0000"
"11.8200","9.8515","0.2605","9.8515","24.6288","26.0495","0.0000"
"11.8800","9.9016","0.2616","9.9016","24.7539","26.1630","0.0000"
"11.9400","9.9514","0.2627","9.9514","24.8784","26.2731","0.0000"
"12.0000","10.0018","0.2640","10.0018","25.0045","26.3955","0.0000"
"12.0600","10.0516","0.2652","10.0516","25.1290","26.5209","0.0000"
"12.1200","10.1017","0.2664","10.1017","25.2541","26.6413","0.0000"
"12.1800","10.1515","0.2675","10.1515","25.3787","26.7533","0.0000"
"12.2400","10.2013","0.2685","10.2013","25.5032","26.8489","0.0000"
"12.3000","10.2517","0.2696","10.2517","25.6293","26.9617","0.0000"
"12.3600","10.3014","0.2707","10.3014","25.7535","27.0718","0.0000"
"12.4200","10.3517","0.2718","10.3517","25.8793","27.1843","0.0000"
"12.4800","10.4013","0.2729","10.4013","26.0032","27.2930","0.0000"
"12.5400","10.4515","0.2740","10.4515","26.1286","27.3996","0.0000"
"12.6000","10.5017","0.2752","10.5017","26.2544","27.5207","0.0000"
"12.6600","10.5516","0.2764","10.5516","26.3789","27.6375","0.0000"
"12.7200","10.6019","0.2774","10.6019","26.5047","27.7420","0.0000"
"12.7800","10.6514","0.2785","10.6514","26.6286","27.8492","0.0000"
"12.8400","10.7015","0.2796","10.7015","26.7538","27.9559","0.0000"
"12.9000","10.7514","0.2806","10.7514","26.8786","28.0614","0.0000"
"12.9600","10.8015","0.2816","10.8015","27.0037","28.1628","0.0000"
"13.0200","10.8517","0.2826","10.8517","27.1292","28.2631","0.0000"
"13.0800","10.9014","0.2836","10.9014","27.2534","28.3591","0.0000"
"13.1400","10.9517","0.2847","10.9517","27.3791","28.4666","0.0000"
"13.2000","11.0015","0.2857","11.0015","27.5037","28.5706","0.0000"
"13.2600","11.0515","0.2868","11.0515","27.6288","28.6819","0.0000"
"13.3200","11.1015","0.2880","11.1015","27.7537","28.8008","0.0000"
"13.3800","11.1513","0.2890","11.1513","27.8782","28.9010","0.0000"
"13.4400","11.2016","0.2903","11.2016","28.0040","29.0279","0.0000"
"13.5000","11.2515","0.2913","11.2515","28.1288","29.1328","0.0000"
"13.5600","11.3019","0.2926","11.3019","28.2548","29.2615","0.0000"
"13.6200","11.3515","0.2939","11.3515","28.3788","29.3934","0.0000"
"13.6800","11.4015","0.2951","11.4015","28.5036","29.5134","0.0000"
"13.7400","11.4515","0.2964","11.4515","28.6288","29.6361","0.0000"
"13.8000","11.5014","0.2974","11.5014","28.7536","29.7398","0.0000"
"13.8600","11.5517","0.2987","11.5517","28.8793","29.8676","0.0000"
"13.9200","11.6016","0.2998","11.6016","29.0039","29.9820","0.0000"
"13.9800","11.6516","0.3011","11.6516","29.1290","30.1113","0.0000"
"14.0400","11.7014","0.3024","11.7014","29.2536","30.2366","0.0000"
"14.1000","11.7517","0.3038","11.7517","29.3793","30.3758","0.0000"
"14.1600","11.8015","0.3052","11.8015","29.5039","30.5163","0.0000"
"14.2200","11.8515","0.3063","11.8515","29.6287","30.6288","0.0000"
"14.2800","11.9017","0.3075","11.9017","29.7541","30.7534","0.0000"
"14.3400","11.9514","0.3086","11.9514","29.8784","30.8636","0.0000"
"14.4000","12.0016","0.3101","12.0016","30.0041","31.0060","0.0000"
"14.4600","12.0513","0.3115","12.0513","30.1284","31.1517","0.0000"
"14.5200","12.1015","0.3129","12.1015","30.2538","31.2869","0.0000"
"14.5800","12.1515","0.3144","12.1515","30.3786","31.4396","0.0000"
"14.6400","12.2014","0.3156","12.2014","30.5035","31.5631","0.0000"
"14.7000","12.2519","0.3171","12.2519","30.6298","31.7113","0.0000"
"14.7600","12.3016","0.3183","12.3016","30.7541","31.8326","0.0000"
"14.8200","12.3517","0.3196","12.3517","30.8792","31.9557","0.0000"
"14.8800","12.4014","0.3208","12.4014","31.0035","32.0783","0.0000"
"14.9400","12.4513","0.3219","12.4513","31.1283","32.1900","0.0000"
"15.0000","12.5017","0.3232","12.5017","31.2543","32.3162","0.0000"
"15.0600","12.5515","0.3243","12.5515","31.3789","32.4322","0.0000"
"15.1200","12.6014","0.3256","12.6014","31.5034","32.5607","0.0000"
"15.1800","12.6514","0.3268","12.6514","31.6286","32.6808","0.0000"
"15.2400","12.7016","0.3281","12.7016","31.7540","32.8115","0.0000"
"15.3000","12.7514","0.3294","12.7514","31.8785","32.9388","0.0000"
"15.3600","12.8014","0.3304","12.8014","32.0034","33.0396","0.0000"
"15.4200","12.8519","0.3318","12.8519","32.1297","33.1777","0.0000"
"15.4800","12.9016","0.3329","12.9016","32.2540","33.2950","0.0000"
"15.5400","12.9519","0.3341","12.9519","32.3797","33.4137","0.0000"
"15.6000","13.0012","0.3353","13.0012","32.5031","33.5256","0.0000"
"15.6600","13.0515","0.3364","13.0515","32.6288","33.6380","0.0000"
"15.7200","13.1017","0.3375","13.1017","32.7542","33.7482","0.0000"
"15.7800","13.1515","0.3386","13.1515","32.8788","33.8609","0.0000"
"15.8400","13.2017","0.3398","13.2017","33.0042","33.9786","0.0000"
"15.9000","13.2515","0.3411","13.2515","33.1288","34.1087","0.0000"
"15.9600","13.3019","0.3425","13.3019","33.2548","34.2489","0.0000"
"16.0200","13.3516","0.3438","13.3516","33.3790","34.3795","0.0000"
"16.0800","13.4015","0.3450","13.4015","33.5039","34.4987","0.0000"
"16.1400","13.4516","0.3463","13.4516","33.6290","34.6348","0.0000"
"16.2000","13.5012","0.3476","13.5012","33.7530","34.7571","0.0000"
"16.2600","13.5521","0.3492","13.5521","33.8802","34.9150","0.0000"
"16.3200","13.6015","0.3507","13.6015","34.0038","35.0661","0.0000"
"16.3800","13.6515","0.3522","13.6515","34.1287","35.2243","0.0000"
"16.4400","13.7014","0.3538","13.7014","34.2535","35.3845","0.0000"
"16.5000","13.7515","0.3555","13.7515","34.3787","35.5466","0.0000"
"16.5600","13.8015","0.3572","13.8015","34.5038","35.7196","0.0000"
"16.6200","13.8513","0.3586","13.8513","34.6284","35.8648","0.0000"
"16.6800","13.9018","0.3602","13.9018","34.7544","36.0208","0.0000"
"16.7400","13.9515","0.3614","13.9515","34.8786","36.1423","0.0000"
"16.8000","14.0015","0.3626","14.0015","35.0038","36.2648","0.0000"
"16.8600","14.0516","0.3639","14.0516","35.1289","36.3950","0.0000"
"16.9200","14.1015","0.3651","14.1015","35.2537","36.5136","0.0000"
"16.9800","14.1517","0.3666","14.1517","35.3792","36.6562","0.0000"
"17.0400","14.2013","0.3676","14.2013","35.5031","36.7650","0.0000"
"17.1000","14.2518","0.3690","14.2518","35.6295","36.8960","0.0000"
"17.1600","14.3016","0.3703","14.3016","35.7540","37.0264","0.0000"
"17.2200","14.3515","0.3716","14.3515","35.8789","37.1616","0.0000"
"17.2800","14.4016","0.3731","14.4016","36.0040","37.3090","0.0000"
"17.3400","14.4514","0.3744","14.4514","36.1285","37.4393","0.0000"
"17.4000","14.5018","0.3758","14.5018","36.2546","37.5786","0.0000"
"17.4600","14.5514","0.3769","14.5514","36.3785","37.6896","0.0000"
"17.5200","14.6017","0.3782","14.6017","36.5043","37.8226","0.0000"
"17.5800","14.6513","0.3794","14.6513","36.6282","37.9444","0.0000"
"17.6400","14.7016","0.3805","14.7016","36.7539","38.0524","0.0000"
"17.7000","14.7516","0.3818","14.7516","36.8791","38.1753","0.0000"
"17.7600","14.8016","0.3827","14.8016","37.0039","38.2667","0.0000"
"17.8200","14.8517","0.3838","14.8517","37.1294","38.3825","0.0000"
"17.8800","14.9011","0.3847","14.9011","37.2527","38.4729","0.0000"
"17.9400","14.9516","0.3859","14.9516","37.3790","38.5944","0.0000"
"18.0000","15.0013","0.3871","15.0013","37.5033","38.7129","0.0000"
"18.0600","15.0515","0.3884","15.0515","37.6287","38.8416","0.0000"
"18.1200","15.1017","0.3897","15.1017","37.7542","38.9739","0.0000"
"18.1800","15.1509","0.3909","15.1509","37.8772","39.0858","0.0000"
"18.2400","15.2017","0.3923","15.2017","38.0042","39.2263","0.0000"
"18.3000","15.2517","0.3938","15.2517","38.1293","39.3830","0.0000"
"18.3600","15.3020","0.3954","15.3020","38.2550","39.5398","0.0000"
"18.4200","15.3515","0.3968","15.3515","38.3787","39.6799","0.0000"
"18.4800","15.4014","0.3980","15.4014","38.5035","39.7954","0.0000"
"18.5400","15.4517","0.3994","15.4517","38.6293","39.9450","0.0000"
"18.6000","15.5013","0.4006","15.5013","38.7532","40.0556","0.0000"
"18.6600","15.5518","0.4018","15.5518","38.8795","40.1768","0.0000"
"18.7200","15.6015","0.4029","15.6015","39.0038","40.2906","0.0000"
"18.7800","15.6515","0.4043","15.6515","39.1286","40.4342","0.0000"
"18.8400","15.7014","0.4058","15.7014","39.2535","40.5823","0.0000"
"18.9000","15.7514","0.4070","15.7514","39.3786","40.7044","0.0000"
"18.9600","15.8020","0.4087","15.8020","39.5049","40.8708","0.0000"
"19.0200","15.8513","0.4099","15.8513","39.6283","40.9903","0.0000"
"19.0800","15.9016","0.4115","15.9016","39.7540","41.1479","0.0000"
"19.1400","15.9515","0.4127","15.9515","39.8789","41.2732","0.0000"
"19.2000","16.0018","0.4140","16.0018","40.0046","41.4024","0.0000"
"19.2600","16.0517","0.4152","16.0517","40.1291","41.5218","0.0000"
"19.3200","16.1016","0.4162","16.1016","40.2540","41.6155","0.0000"
"19.3800","16.1515","0.4175","16.1515","40.3788","41.7467","0.0000"
"19.4400","16.2012","0.4187","16.2012","40.5031","41.8674","0.0000"
"19.5000","16.2518","0.4201","16.2518","40.6294","42.0078","0.0000"
"19.5600","16.3015","0.4215","16.3015","40.7537","42.1494","0.0000"
"19.6200","16.3515","0.4229","16.3515","40.8788","42.2930","0.0000"
"19.6800","16.4015","0.4242","16.4015","41.0036","42.4249","0.0000"
"19.7400","16.4512","0.4253","16.4512","41.1279","42.5348","0.0000"
"19.8000","16.5018","0.4267","16.5018","41.2545","42.6694","0.0000"
"19.8600","16.5516","0.4279","16.5516","41.3791","42.7861","0.0000"
"19.9200","16.6018","0.4291","16.6018","41.5045","42.9101","0.0000"
"19.9800","16.6515","0.4303","16.6515","41.6288","43.0266","0.0000"
"20.0400","16.7017","0.4315","16.7017","41.7542","43.1537","0.0000"
"20.1000","16.7517","0.4328","16.7517","41.8793","43.2820","0.0000"
"20.1600","16.8015","0.4340","16.8015","42.0039","43.4016","0.0000"
"20.2200","16.8517","0.4357","16.8517","42.1293","43.5716","0.0000"
"20.2800","16.9014","0.4373","16.9014","42.2536","43.7308","0.0000"
"20.3400","16.9516","0.4387","16.9516","42.3790","43.8653","0.0000"
"20.4000","17.0014","0.4401","17.0014","42.5035","44.0093","0.0000"
"20.4600","17.0516","0.4412","17.0516","42.6290","44.1249","0.0000"
"20.5200","17.1019","0.4427","17.1019","42.7547","44.2658","0.0000"
"20.5800","17.1513","0.4440","17.1513","42.8784","44.3978","0.0000"
"20.6400","17.2014","0.4458","17.2014","43.0035","44.5839","0.0000"
"20.7000","17.2511","0.4475","17.2511","43.1278","44.7453","0.0000"
"20.7600","17.3019","0.4490","17.3019","43.2547","44.9018","0.0000"
"20.8200","17.3516","0.4506","17.3516","43.3789","45.0585","0.0000"
"20.8800","17.4014","0.4518","17.4014","43.5035","45.1836","0.0000"
"20.9400","17.4516","0.4533","17.4516","43.6289","45.3349","0.0000"
"21.0000","17.5010","0.4545","17.5010","43.7526","45.4460","0.0000"
"21.0600","17.5518","0.4562","17.5518","43.8795","45.6228","0.0000"
"21.1200","17.6018","0.4578","17.6018","44.0046","45.7837","0.0000"
"21.1800","17.6519","0.4595","17.6519","44.1298","45.9455","0.0000"
"21.2400","17.7016","0.4610","17.7016","44.2540","46.1025","0.0000"
"21.3000","17.7514","0.4623","17.7514","44.3786","46.2339","0.0000"
"21.3600","17.8018","0.4638","17.8018","44.5046","46.3771","0.0000"
"21.4200","17.8514","0.4649","17.8514","44.6285","46.4923","0.0000"
"21.4800","17.9016","0.4666","17.9016","44.7540","46.6612","0.0000"
"21.5400","17.9513","0.4682","17.9513","44.8782","46.8229","0.0000"
"21.6000","18.0016","0.4697","18.0016","45.0040","46.9709","0.0000"
"21.6600","18.0516","0.4715","18.0516","45.1291","47.1465","0.0000"
"21.7200","18.1015","0.4731","18.1015","45.2536","47.3099","0.0000"
"21.7800","18.1518","0.4751","18.1518","45.3794","47.5134","0.0000"
"21.8400","18.2012","0.4768","18.2012","45.5030","47.6795","0.0000"
"21.9000","18.2517","0.4785","18.2517","45.6294","47.8549","0.0000"
"21.9600","18.3014","0.4803","18.3014","45.7536","48.0319","0.0000"
"22.0200","18.3515","0.4821","18.3515","45.8788","48.2071","0.0000"
"22.0800","18.4019","0.4843","18.4019","46.0048","48.4332","0.0000"
"22.1400","18.4515","0.4862","18.4515","46.1287","48.6239","0.0000"
"22.2000","18.5018","0.4883","18.5018","46.2545","48.8316","0.0000"
"22.2600","18.5513","0.4898","18.5513","46.3781","48.9794","0.0000"
"22.3200","18.6015","0.4916","18.6015","46.5039","49.1552","0.0000"
"22.3800","18.6515","0.4933","18.6515","46.6287","49.3330","0.0000"
"22.4400","18.7017","0.4949","18.7017","46.7541","49.4867","0.0000"
"22.5000","18.7521","0.4967","18.7521","46.8802","49.6698","0.0000"
"22.5600","18.8013","0.4979","18.8013","47.0032","49.7914","0.0000"
"22.6200","18.8516","0.4995","18.8516","47.1290","49.9549","0.0000"
"22.6800","18.9013","0.5013","18.9013","47.2532","50.1294","0.0000"
"22.7400","18.9516","0.5029","18.9516","47.3789","50.2891","0.0000"
"22.8000","19.0014","0.5046","19.0014","47.5035","50.4643","0.0000"
"22.8600","19.0516","0.5064","19.0516","47.6289","50.6406","0.0000"
"22.9200","19.1017","0.5082","19.1017","47.7544","50.8234","0.0000"
"22.9800","19.1512","0.5098","19.1512","47.8780","50.9794","0.0000"
"23.0400","19.2017","0.5116","19.2017","48.0043","51.1620","0.0000"
"23.1000","19.2514","0.5135","19.2514","48.1286","51.3450","0.0000"
"23.1600","19.3015","0.5152","19.3015","48.2537","51.5182","0.0000"
"23.2200","19.3517","0.5171","19.3517","48.3792","51.7125","0.0000"
"23.2800","19.4013","0.5189","19.4013","48.5031","51.8933","0.0000"
"23.3400","19.4517","0.5210","19.4517","48.6291","52.1044","0.0000"
"23.4000","19.5014","0.5231","19.5014","48.7534","52.3119","0.0000"
"23.4600","19.5518","0.5253","19.5518","48.8794","52.5274","0.0000"
"23.5200","19.6015","0.5273","19.6015","49.0037","52.7252","0.0000"
"23.5800","19.6515","0.5294","19.6515","49.1288","52.9410","0.0000"
"23.6400","19.7017","0.5319","19.7017","49.2543","53.1867","0.0000"
"23.7000","19.7513","0.5340","19.7513","49.3782","53.3963","0.0000"
"23.7600","19.8018","0.5366","19.8018","49.5045","53.6583","0.0000"
"23.8200","19.8512","0.5387","19.8512","49.6279","53.8683","0.0000"
"23.8800","19.9013","0.5409","19.9013","49.7533","54.0871","0.0000"
"23.9400","19.9513","0.5432","19.9513","49.8782","54.3192","0.0000"
"24.0000","20.0019","0.5460","20.0019","50.0048","54.6007","0.0000"
"24.0600","20.0520","0.5577","20.0520","50.1299","55.7722","0.0000"
"24.1200","20.1013","0.5706","20.1013","50.2533","57.0556","0.0000"
"24.1800","20.1515","0.5832","20.1515","50.3787","58.3199","0.0000"
"24.2400","20.2013","0.5951","20.2013","50.5033","59.5050","0.0000"
"24.3000","20.2516","0.6060","20.2516","50.6290","60.5960","0.0000"
"24.3600","20.3017","0.6168","20.3017","50.7542","61.6759","0.0000"
"24.4200","20.3515","0.6267","20.3515","50.8787","62.6742","0.0000"
"24.4800","20.4017","0.6379","20.4017","51.0041","63.7944","0.0000"
"24.5400","20.4514","0.6492","20.4514","51.1284","64.9225","0.0000"
"24.6000","20.5015","0.6604","20.5015","51.2538","66.0407","0.0000"
"24.6600","20.5513","0.6711","20.5513","51.3784","67.1063","0.0000"
"24.7200","20.6014","0.6810","20.6014","51.5035","68.0982","0.0000"
"24.7800","20.6515","0.6912","20.6515","51.6286","69.1247","0.0000"
"24.8400","20.7014","0.7011","20.7014","51.7535","70.1054","0.0000"
"24.9000","20.7518","0.7113","20.7518","51.8795","71.1258","0.0000"
"24.9600","20.8015","0.7209","20.8015","52.0038","72.0936","0.0000"
"25.0200","20.8514","0.7302","20.8514","52.1286","73.0215","0.0000"
"25.0800","20.9016","0.7393","20.9016","52.2540","73.9285","0.0000"
"25.1400","20.9516","0.7475","20.9516","52.3789","74.7541","0.0000"
"25.2000","21.0015","0.7555","21.0015","52.5037","75.5491","0.0000"
"25.2600","21.0512","0.7628","21.0512","52.6280","76.2811","0.0000"
"25.3200","21.1016","0.7705","21.1016","52.7540","77.0461","0.0000"
"25.3800","21.1514","0.7773","21.1514","52.8786","77.7312","0.0000"
"25.4400","21.2015","0.7839","21.2015","53.0037","78.3909","0.0000"
"25.5000","21.2515","0.7908","21.2515","53.1288","79.0768","0.0000"
"25.5600","21.3016","0.7969","21.3016","53.2540","79.6943","0.0000"
"25.6200","21.3518","0.8033","21.3518","53.3794","80.3256","0.0000"
"25.6800","21.4013","0.8093","21.4013","53.5034","80.9342","0.0000"
"25.7400","21.4514","0.8155","21.4514","53.6285","81.5484","0.0000"
"25.8000","21.5013","0.8216","21.5013","53.7534","82.1630","0.0000"
"25.8600","21.5514","0.8275","21.5514","53.8785","82.7486","0.0000"
"25.9200","21.6017","0.8336","21.6017","54.0042","83.3618","0.0000"
"25.9800","21.6516","0.8392","21.6516","54.1291","83.9210","0.0000"
"26.0400","21.7018","0.8452","21.7018","54.2545","84.5184","0.0000"
"26.1000","21.7511","0.8508","21.7511","54.3779","85.0755","0.0000"
"26.1600","21.8016","0.8565","21.8016","54.5039","85.6513","0.0000"
"26.2200","21.8515","0.8625","21.8515","54.6287","86.2469","0.0000"
"26.2800","21.9016","0.8682","21.9016","54.7539","86.8174","0.0000"
"26.3400","21.9518","0.8747","21.9518","54.8796","87.4678","0.0000"
"26.4000","22.0014","0.8803","22.0014","55.0036","88.0340","0.0000"
"26.4600","22.0516","0.8865","22.0516","55.1290","88.6497","0.0000"
"26.5200","22.1012","0.8923","22.1012","55.2530","89.2325","0.0000"
"26.5800","22.1515","0.8984","22.1515","55.3787","89.8350","0.0000"
"26.6400","22.2014","0.9049","22.2014","55.5035","90.4945","0.0000"
"26.7000","22.2515","0.9104","22.2515","55.6287","91.0420","0.0000"
"26.7600","22.3016","0.9172","22.3016","55.7541","91.7194","0.0000"
"26.8200","22.3516","0.9237","22.3516","55.8789","92.3685","0.0000"
"26.8800","22.4019","0.9310","22.4019","56.0047","93.0979","0.0000"
"26.9400","22.4513","0.9373","22.4513","56.1283","93.7274","0.0000"
"27.0000","22.5015","0.9442","22.5015","56.2538","94.4220","0.0000"
"27.0600","22.5514","0.9511","22.5514","56.3786","95.1113","0.0000"
"27.1200","22.6015","0.9576","22.6015","56.5037","95.7589","0.0000"
"27.1800","22.6517","0.9646","22.6517","56.6292","96.4631","0.0000"
"27.2400","22.7014","0.9710","22.7014","56.7534","97.0989","0.0000"
"27.3000","22.7517","0.9780","22.7517","56.8792","97.7981","0.0000"
"27.3600","22.8014","0.9846","22.8014","57.0034","98.4615","0.0000"
"27.4200","22.8517","0.9910","22.8517","57.1292","99.1021","0.0000"
"27.4800","22.9017","0.9978","22.9017","57.2543","99.7757","0.0000"
"27.5400","22.9514","1.0030","22.9514","57.3785","100.3045","0.0000"
"27.6000","23.0017","1.0092","23.0017","57.5043","100.9240","0.0000"
"27.6600","23.0513","1.0146","23.0513","57.6282","101.4597","0.0000"
"27.7200","23.1018","1.0202","23.1018","57.7546","102.0151","0.0000"
"27.7800","23.1518","1.0254","23.1518","57.8794","102.5434","0.0000"
"27.8400","23.2016","1.0295","23.2016","58.0039","102.9528","0.0000"
"27.9000","23.2515","1.0340","23.2515","58.1288","103.3999","0.0000"
"27.9600","23.3013","1.0373","23.3013","58.2533","103.7287","0.0000"
"28.0200","23.3516","1.0406","23.3516","58.3791","104.0632","0.0000"
"28.0800","23.4012","1.0424","23.4012","58.5030","104.2404","0.0000"
"28.1400","23.4516","1.0425","23.4516","58.6290","104.2547","0.0000"
"28.2000","23.5013","1.0379","23.5013","58.7533","103.7865","0.0000"
"28.2600","23.5517","1.0302","23.5517","58.8793","103.0240","0.0000"
"28.3200","23.6018","1.0254","23.6018","59.0045","102.5370","0.0000"
"28.3800","23.6512","1.0221","23.6512","59.1281","102.2101","0.0000"
"28.4400","23.7015","1.0206","23.7015","59.2539","102.0599","0.0000"
"28.5000","23.7515","1.0195","23.7515","59.3787","101.9456","0.0000"
"28.5600","23.8018","1.0186","23.8018","59.5044","101.8648","0.0000"
"28.6200","23.8516","1.0175","23.8516","59.6290","101.7534","0.0000"
"28.6800","23.9015","1.0161","23.9015","59.7538","101.6138","0.0000"
"28.7400","23.9517","1.0153","23.9517","59.8792","101.5295","0.0000"
"28.8000","24.0014","1.0136","24.0014","60.0035","101.3632","0.0000"
"28.8600","24.0520","1.0124","24.0520","60.1301","101.2424","0.0000"
"28.9200","24.1015","1.0109","24.1015","60.2538","101.0910","0.0000"
"28.9800","24.1516","1.0092","24.1516","60.3789","100.9195","0.0000"
"29.0400","24.2013","1.0079","24.2013","60.5032","100.7915","0.0000"
"29.1000","24.2514","1.0061","24.2514","60.6286","100.6082","0.0000"
"29.1600","24.3019","1.0050","24.3019","60.7546","100.5050","0.0000"
"29.2200","24.3513","1.0033","24.3513","60.8783","100.3307","0.0000"
"29.2800","24.4017","1.0021","24.4017","61.0043","100.2114","0.0000"
"29.3400","24.4513","1.0008","24.4513","61.1283","100.0784","0.0000"
"29.4000","24.5016","0.9992","24.5016","61.2540","99.9170","0.0000"
"29.4600","24.5515","0.9985","24.5515","61.3789","99.8464","0.0000"
"29.5200","24.6014","0.9973","24.6014","61.5034","99.7261","0.0000"
"29.5800","24.6517","0.9972","24.6517","61.6291","99.7196","0.0000"
"29.6400","24.7015","0.9969","24.7015","61.7537","99.6872","0.0000"
"29.7000","24.7518","0.9968","24.7518","61.8794","99.6820","0.0000"
"29.7600","24.8016","0.9968","24.8016","62.0040","99.6843","0.0000"
"29.8200","24.8515","0.9968","24.8515","62.1288","99.6796","0.0000"
"29.8800","24.9016","0.9989","24.9016","62.2539","99.8887","0.0000"
"29.9400","24.9513","1.0003","24.9513","62.3782","100.0257","0.0000"
"30.0000","25.0017","1.0023","25.0017","62.5042","100.2293","0.0000"
"30.0600","25.0515","1.0038","25.0515","62.6288","100.3766","0.0000"
"30.1200","25.1016","1.0054","25.1016","62.7539","100.5363","0.0000"
"30.1800","25.1516","1.0072","25.1516","62.8790","100.7235","0.0000"
"30.2400","25.2014","1.0086","25.2014","63.0036","100.8601","0.0000"
"30.3000","25.2516","1.0103","25.2516","63.1290","101.0345","0.0000"
"30.3600","25.3013","1.0116","25.3013","63.2533","101.1575","0.0000"
"30.4200","25.3516","1.0130","25.3516","63.3790","101.2969","0.0000"
"30.4800","25.4015","1.0144","25.4015","63.5039","101.4448","0.0000"
"30.5400","25.4516","1.0155","25.4516","63.6290","101.5540","0.0000"
"30.6000","25.5017","1.0167","25.5017","63.7541","101.6687","0.0000"
"30.6600","25.5516","1.0177","25.5516","63.8790","101.7739","0.0000"
"30.7200","25.6018","1.0192","25.6018","64.0044","101.9184","0.0000"
"30.7800","25.6512","1.0198","25.6512","64.1281","101.9827","0.0000"
"30.8400","25.7016","1.0208","25.7016","64.2541","102.0794","0.0000"
"30.9000","25.7513","1.0218","25.7513","64.3784","102.1842","0.0000"
"30.9600","25.8016","1.0223","25.8016","64.5041","102.2319","0.0000"
"31.0200","25.8514","1.0245","25.8514","64.6286","102.4532","0.0000"
"31.0800","25.9015","1.0273","25.9015","64.7538","102.7270","0.0000"
"31.1400","25.9517","1.0303","25.9517","64.8792","103.0349","0.0000"
"31.2000","26.0010","1.0327","26.0010","65.0026","103.2689","0.0000"
"31.2600","26.0518","1.0351","26.0518","65.1295","103.5068","0.0000"
"31.3200","26.1017","1.0373","26.1017","65.2543","103.7282","0.0000"
"31.3800","26.1517","1.0383","26.1517","65.3792","103.8268","0.0000"
"31.4400","26.2017","1.0394","26.2017","65.5043","103.9368","0.0000"
"31.5000","26.2515","1.0389","26.2515","65.6289","103.8912","0.0000"
"31.5600","26.3017","1.0385","26.3017","65.7543","103.8540","0.0000"
"31.6200","26.3514","1.0377","26.3514","65.8785","103.7734","0.0000"
"31.6800","26.4016","1.0377","26.4016","66.0040","103.7727","0.0000"
"31.7400","26.4513","1.0369","26.4513","66.1282","103.6856","0.0000"
"31.8000","26.5017","1.0345","26.5017","66.2542","103.4454","0.0000"
"31.8600","26.5519","1.0325","26.5519","66.3797","103.2546","0.0000"
"31.9200","26.6015","1.0296","26.6015","66.5036","102.9603","0.0000"
"31.9800","26.6518","1.0274","26.6517","66.6294","102.7408","0.0000"
"32.0400","26.7013","1.0249","26.7013","66.7533","102.4881","0.0000"
"32.1000","26.7515","1.0227","26.7515","66.8788","102.2741","0.0000"
"32.1600","26.8014","1.0210","26.8014","67.0036","102.1034","0.0000"
"32.2200","26.8514","1.0187","26.8514","67.1285","101.8735","0.0000"
"32.2800","26.9016","1.0176","26.9016","67.2539","101.7644","0.0000"
"32.3400","26.9513","1.0156","26.9513","67.3781","101.5593","0.0000"
"32.4000","27.0017","1.0144","27.0017","67.5042","101.4373","0.0000"
"32.4600","27.0515","1.0127","27.0515","67.6287","101.2688","0.0000"
"32.5200","27.1019","1.0116","27.1019","67.7547","101.1630","0.0000"
"32.5800","27.1516","1.0111","27.1516","67.8790","101.1084","0.0000"
"32.6400","27.2015","1.0101","27.2015","68.0038","101.0065","0.0000"
"32.7000","27.2518","1.0100","27.2518","68.1296","100.9976","0.0000"
"32.7600","27.3018","1.0107","27.3018","68.2544","101.0678","0.0000"
"32.8200","27.3518","1.0124","27.3518","68.3795","101.2411","0.0000"
"32.8800","27.4013","1.0138","27.4013","68.5032","101.3799","0.0000"
"32.9400","27.4515","1.0148","27.4515","68.6287","101.4821","0.0000"
"33.0000","27.5015","1.0162","27.5015","68.7538","101.6207","0.0000"
"33.0600","27.5517","1.0173","27.5517","68.8792","101.7300","0.0000"
"33.1200","27.6016","1.0191","27.6016","69.0041","101.9083","0.0000"
"33.1800","27.6511","1.0202","27.6511","69.1277","102.0246","0.0000"
"33.2400","27.7014","1.0218","27.7014","69.2535","102.1762","0.0000"
"33.3000","27.7512","1.0228","27.7512","69.3780","102.2756","0.0000"
"33.3600","27.8020","1.0231","27.8020","69.5049","102.3123","0.0000"
"33.4200","27.8518","1.0230","27.8518","69.6295","102.2997","0.0000"
"33.4800","27.9016","1.0227","27.9016","69.7540","102.2742","0.0000"
"33.5400","27.9514","1.0228","27.9514","69.8786","102.2810","0.0000"
"33.6000","28.0014","1.0222","28.0014","70.0034","102.2159","0.0000"
"33.6600","28.0518","1.0217","28.0518","70.1294","102.1666","0.0000"
"33.7200","28.1016","1.0213","28.1016","70.2540","102.1316","0.0000"
"33.7800","28.1514","1.0215","28.1514","70.3785","102.1506","0.0000"
"33.8400","28.2015","1.0223","28.2015","70.5037","102.2331","0.0000"
"33.9000","28.2516","1.0230","28.2516","70.6291","102.3048","0.0000"
"33.9600","28.3019","1.0240","28.3019","70.7548","102.3979","0.0000"
"34.0200","28.3515","1.0245","28.3515","70.8788","102.4514","0.0000"
"34.0800","28.4012","1.0249","28.4012","71.0030","102.4895","0.0000"
"34.1400","28.4513","1.0260","28.4513","71.1282","102.6049","0.0000"
"34.2000","28.5018","1.0266","28.5018","71.2545","102.6629","0.0000"
"34.2600","28.5520","1.0273","28.5520","71.3799","102.7293","0.0000"
"34.3200","28.6014","1.0276","28.6014","71.5036","102.7554","0.0000"
"34.3800","28.6516","1.0286","28.6516","71.6290","102.8644","0.0000"
"34.4400","28.7012","1.0295","28.7012","71.7530","102.9478","0.0000"
"34.5000","28.7517","1.0304","28.7517","71.8793","103.0443","0.0000"
"34.5600","28.8018","1.0315","28.8018","72.0044","103.1529","0.0000"
"34.6200","28.8515","1.0319","28.8515","72.1287","103.1915","0.0000"
"34.6800","28.9017","1.0332","28.9017","72.2541","103.3152","0.0000"
"34.7400","28.9512","1.0339","28.9512","72.3781","103.3925","0.0000"
"34.8000","29.0016","1.0349","29.0016","72.5041","103.4888","0.0000"
"34.8600","29.0516","1.0359","29.0516","72.6290","103.5877","0.0000"
"34.9200","29.1018","1.0362","29.1018","72.7544","103.6238","0.0000"
"34.9800","29.1515","1.0372","29.1515","72.8786","103.7237","0.0000"
"35.0400","29.2014","1.0378","29.2014","73.0035","103.7845","0.0000"
"35.1000","29.2518","1.0389","29.2518","73.1295","103.8896","0.0000"
"35.1600","29.3014","1.0392","29.3014","73.2535","103.9213","0.0000"
"35.2200","29.3516","1.0398","29.3516","73.3789","103.9818","0.0000"
"35.2800","29.4016","1.0406","29.4016","73.5040","104.0573","0.0000"
"35.3400","29.4517","1.0405","29.4517","73.6292","104.0483","0.0000"
"35.4000","29.5017","1.0408","29.5017","73.7543","104.0825","0.0000"
"35.4600","29.5513","1.0406","29.5513","73.8783","104.0611","0.0000"
"35.5200","29.6015","1.0410","29.6015","74.0037","104.0990","0.0000"
"35.5800","29.6515","1.0412","29.6515","74.1289","104.1220","0.0000"
"35.6400","29.7017","1.0412","29.7017","74.2543","104.1243","0.0000"
"35.7000","29.7515","1.0414","29.7515","74.3788","104.1415","0.0000"
"35.7600","29.8015","1.0412","29.8015","74.5037","104.1181","0.0000"
"35.8200","29.8518","1.0417","29.8518","74.6294","104.1666","0.0000"
"35.8800","29.9013","1.0414","29.9013","74.7534","104.1408","0.0000"
"35.9400","29.9515","1.0412","29.9515","74.8788","104.1214","0.0000"
"36.0000","30.0012","1.0413","30.0012","75.0031","104.1299","0.0000"
"36.0600","30.0514","1.0410","30.0514","75.1285","104.0990","0.0000"
"36.1200","30.1016","1.0409","30.1016","75.2539","104.0870","0.0000"
"36.1800","30.1515","1.0404","30.1515","75.3788","104.0426","0.0000"
"36.2400","30.2017","1.0403","30.2017","75.5042","104.0340","0.0000"
"36.3000","30.2514","1.0398","30.2514","75.6285","103.9752","0.0000"
"36.3600","30.3017","1.0401","30.3017","75.7542","104.0131","0.0000"
"36.4200","30.3515","1.0401","30.3515","75.8787","104.0083","0.0000"
"36.4800","30.4017","1.0397","30.4017","76.0042","103.9657","0.0000"
"36.5400","30.4515","1.0395","30.4515","76.1287","103.9505","0.0000"
"36.6000","30.5014","1.0384","30.5014","76.2536","103.8429","0.0000"
"36.6600","30.5516","1.0381","30.5516","76.3790","103.8083","0.0000"
"36.7200","30.6014","1.0373","30.6014","76.5035","103.7317","0.0000"
"36.7800","30.6516","1.0367","30.6516","76.6290","103.6747","0.0000"
"36.8400","30.7015","1.0360","30.7015","76.7538","103.6015","0.0000"
"36.9000","30.7512","1.0346","30.7512","76.8781","103.4609","0.0000"
"36.9600","30.8019","1.0343","30.8019","77.0047","103.4275","0.0000"
"37.0200","30.8516","1.0333","30.8516","77.1289","103.3307","0.0000"
"37.0800","30.9019","1.0326","30.9019","77.2547","103.2603","0.0000"
"37.1400","30.9515","1.0314","30.9515","77.3786","103.1446","0.0000"
"37.2000","31.0017","1.0305","31.0017","77.5044","103.0513","0.0000"
"37.2600","31.0514","1.0300","31.0514","77.6286","103.0049","0.0000"
"37.3200","31.1015","1.0296","31.1015","77.7538","102.9606","0.0000"
"37.3800","31.1516","1.0295","31.1516","77.8789","102.9511","0.0000"
"37.4400","31.2014","1.0292","31.2014","78.0034","102.9243","0.0000"
"37.5000","31.2518","1.0301","31.2518","78.1295","103.0071","0.0000"
"37.5600","31.3016","1.0307","31.3016","78.2540","103.0747","0.0000"
"37.6200","31.3515","1.0316","31.3515","78.3789","103.1600","0.0000"
"37.6800","31.4017","1.0329","31.4017","78.5043","103.2867","0.0000"
"37.7400","31.4514","1.0334","31.4514","78.6286","103.3403","0.0000"
"37.8000","31.5018","1.0342","31.5018","78.7546","103.4155","0.0000"
"37.8600","31.5513","1.0348","31.5513","78.8782","103.4799","0.0000"
"37.9200","31.6016","1.0355","31.6016","79.0040","103.5484","0.0000"
"37.9800","31.6515","1.0365","31.6515","79.1288","103.6530","0.0000"
"38.0400","31.7016","1.0368","31.7016","79.2539","103.6848","0.0000"
"38.1000","31.7515","1.0389","31.7515","79.3788","103.8927","0.0000"
"38.1600","31.8015","1.0411","31.8015","79.5036","104.1091","0.0000"
"38.2200","31.8519","1.0438","31.8519","79.6297","104.3752","0.0000"
"38.2800","31.9014","1.0461","31.9014","79.7536","104.6067","0.0000"
"38.3400","31.9517","1.0486","31.9517","79.8793","104.8559","0.0000"
"38.4000","32.0013","1.0514","32.0013","80.0033","105.1415","0.0000"
"38.4600","32.0514","1.0536","32.0514","80.1284","105.3642","0.0000"
"38.5200","32.1017","1.0566","32.1017","80.2542","105.6630","0.0000"
"38.5800","32.1514","1.0594","32.1514","80.3784","105.9431","0.0000"
"38.6400","32.2015","1.0624","32.2015","80.5039","106.2395","0.0000"
"38.7000","32.2515","1.0657","32.2515","80.6287","106.5671","0.0000"
"38.7600","32.3018","1.0689","32.3018","80.7544","106.8905","0.0000"
"38.8200","32.3514","1.0726","32.3514","80.8784","107.2602","0.0000"
"38.8800","32.4013","1.0787","32.4013","81.0032","107.8667","0.0000"
"38.9400","32.4515","1.0859","32.4515","81.1287","108.5863","0.0000"
"39.0000","32.5013","1.0934","32.5013","81.2532","109.3352","0.0000"
"39.0600","32.5517","1.1040","32.5517","81.3792","110.3989","0.0000"
"39.1200","32.6016","1.1157","32.6016","81.5041","111.5685","0.0000"
"39.1800","32.6517","1.1281","32.6517","81.6292","112.8137","0.0000"
"39.2400","32.7015","1.1408","32.7015","81.7538","114.0829","0.0000"
"39.3000","32.7511","1.1534","32.7511","81.8777","115.3403","0.0000"
"39.3600","32.8020","1.1680","32.8020","82.0049","116.7990","0.0000"
"39.4200","32.8514","1.1813","32.8514","82.1286","118.1349","0.0000"
"39.4800","32.9014","1.1946","32.9014","82.2534","119.4579","0.0000"
"39.5400","32.9511","1.2077","32.9511","82.3777","120.7677","0.0000"
"39.6000","33.0016","1.2209","33.0016","82.5040","122.0900","0.0000"
"39.6600","33.0514","1.2341","33.0514","82.6286","123.4056","0.0000"
"39.7200","33.1012","1.2463","33.1012","82.7531","124.6288","0.0000"
"39.7800","33.1517","1.2608","33.1517","82.8791","126.0828","0.0000"
"39.8400","33.2014","1.2750","33.2014","83.0034","127.4952","0.0000"
"39.9000","33.2520","1.2900","33.2520","83.1300","128.9977","0.0000"
"39.9600","33.3015","1.3042","33.3015","83.2537","130.4151","0.0000"
"40.0200","33.3515","1.3183","33.3515","83.3788","131.8306","0.0000"
"40.0800","33.4015","1.3342","33.4015","83.5036","133.4214","0.0000"
"40.1400","33.4514","1.3497","33.4514","83.6285","134.9709","0.0000"
"40.2000","33.5018","1.3673","33.5018","83.7545","136.7292","0.0000"
"40.2600","33.5515","1.3853","33.5515","83.8788","138.5348","0.0000"
"40.3200","33.6016","1.4040","33.6016","84.0039","140.4000","0.0000"
"40.3800","33.6513","1.4235","33.6513","84.1282","142.3524","0.0000"
"40.4400","33.7013","1.4420","33.7013","84.2533","144.1951","0.0000"
"40.5000","33.7517","1.4622","33.7517","84.3793","146.2155","0.0000"
"40.5600","33.8013","1.4819","33.8013","84.5033","148.1873","0.0000"
"40.6200","33.8516","1.5029","33.8516","84.6290","150.2859","0.0000"
"40.6800","33.9012","1.5235","33.9012","84.7530","152.3507","0.0000"
"40.7400","33.9515","1.5434","33.9515","84.8787","154.3362","0.0000"
"40.8000","34.0014","1.5637","34.0014","85.0035","156.3687","0.0000"
"40.8600","34.0516","1.5831","34.0516","85.1290","158.3124","0.0000"
"40.9200","34.1016","1.6043","34.1016","85.2541","160.4335","0.0000"
"40.9800","34.1511","1.6237","34.1511","85.3778","162.3675","0.0000"
"41.0400","34.2016","1.6451","34.2016","85.5041","164.5124","0.0000"
"41.1000","34.2511","1.6650","34.2511","85.6278","166.4998","0.0000"
"41.1600","34.3016","1.6847","34.3016","85.7541","168.4682","0.0000"
"41.2200","34.3513","1.7048","34.3513","85.8783","170.4814","0.0000"
"41.2800","34.4014","1.7238","34.4014","86.0035","172.3809","0.0000"
"41.3400","34.4517","1.7446","34.4517","86.1292","174.4583","0.0000"
"41.4000","34.5013","1.7662","34.5013","86.2532","176.6196","0.0000"
"41.4600","34.5517","1.7893","34.5517","86.3792","178.9349","0.0000"
"41.5200","34.6015","1.8138","34.6015","86.5037","181.3786","0.0000"
"41.5800","34.6514","1.8398","34.6514","86.6286","183.9760","0.0000"
"41.6400","34.7014","1.8672","34.7014","86.7534","186.7184","0.0000"
"41.7000","34.7512","1.8946","34.7512","86.8780","189.4612","0.0000"
"41.7600","34.8017","1.9265","34.8017","87.0043","192.6535","0.0000"
"41.8200","34.8511","1.9570","34.8511","87.1277","195.6952","0.0000"
"41.8800","34.9014","1.9897","34.9014","87.2534","198.9741","0.0000"
"41.9400","34.9512","2.0257","34.9512","87.3779","202.5713","0.0000"
"42.0000","35.0013","2.0621","35.0013","87.5034","206.2084","0.0000"