File: Fig6C/211130_Instron/211130/PureCompression_TTball_5.is_comp_Exports/PureCompression_TTball_5_1.csv
Results Table 1


Results Table 2


Time,Displacement,Force,Compressive displacement,Compressive strain (Displacement),Compressive stress,PIP count
(s),(mm),(kN),(mm),(%),(MPa),
"0.0000","0.0001","0.0001","0.0001","0.0003","0.0050","0.0000"
"0.0600","0.0323","0.0002","0.0323","0.0809","0.0169","0.0000"
"0.1200","0.0975","0.0001","0.0975","0.2438","0.0066","0.0000"
"0.1800","0.1504","0.0000","0.1504","0.3760","0.0038","0.0000"
"0.2400","0.2013","0.0001","0.2013","0.5032","0.0065","0.0000"
"0.3000","0.2512","0.0009","0.2512","0.6281","0.0924","0.0000"
"0.3600","0.3018","0.0026","0.3018","0.7544","0.2586","0.0000"
"0.4200","0.3518","0.0042","0.3518","0.8795","0.4222","0.0000"
"0.4800","0.4017","0.0058","0.4017","1.0044","0.5849","0.0000"
"0.5400","0.4519","0.0074","0.4519","1.1298","0.7439","0.0000"
"0.6000","0.5013","0.0091","0.5013","1.2532","0.9090","0.0000"
"0.6600","0.5517","0.0108","0.5517","1.3792","1.0758","0.0000"
"0.7200","0.6018","0.0124","0.6018","1.5046","1.2442","0.0000"
"0.7800","0.6518","0.0141","0.6518","1.6295","1.4123","0.0000"
"0.8400","0.7017","0.0159","0.7017","1.7543","1.5944","0.0000"
"0.9000","0.7514","0.0177","0.7514","1.8786","1.7731","0.0000"
"0.9600","0.8016","0.0197","0.8016","2.0040","1.9675","0.0000"
"1.0200","0.8518","0.0216","0.8518","2.1294","2.1551","0.0000"
"1.0800","0.9018","0.0235","0.9018","2.2546","2.3488","0.0000"
"1.1400","0.9516","0.0255","0.9516","2.3791","2.5517","0.0000"
"1.2000","1.0018","0.0276","1.0018","2.5045","2.7552","0.0000"
"1.2600","1.0518","0.0297","1.0518","2.6294","2.9663","0.0000"
"1.3200","1.1016","0.0319","1.1016","2.7539","3.1851","0.0000"
"1.3800","1.1519","0.0340","1.1519","2.8797","3.3997","0.0000"
"1.4400","1.2015","0.0361","1.2015","3.0036","3.6146","0.0000"
"1.5000","1.2516","0.0383","1.2516","3.1291","3.8314","0.0000"
"1.5600","1.3016","0.0405","1.3016","3.2539","4.0473","0.0000"
"1.6200","1.3516","0.0428","1.3516","3.3790","4.2796","0.0000"
"1.6800","1.4018","0.0453","1.4018","3.5045","4.5340","0.0000"
"1.7400","1.4515","0.0478","1.4515","3.6287","4.7828","0.0000"
"1.8000","1.5018","0.0503","1.5018","3.7545","5.0305","0.0000"
"1.8600","1.5512","0.0528","1.5512","3.8781","5.2830","0.0000"
"1.9200","1.6017","0.0554","1.6017","4.0041","5.5384","0.0000"
"1.9800","1.6516","0.0580","1.6516","4.1290","5.8038","0.0000"
"2.0400","1.7015","0.0605","1.7015","4.2538","6.0531","0.0000"
"2.1000","1.7521","0.0632","1.7521","4.3802","6.3188","0.0000"
"2.1600","1.8015","0.0658","1.8015","4.5038","6.5758","0.0000"
"2.2200","1.8518","0.0684","1.8518","4.6295","6.8377","0.0000"
"2.2800","1.9018","0.0710","1.9018","4.7544","7.1020","0.0000"
"2.3400","1.9516","0.0736","1.9516","4.8789","7.3600","0.0000"
"2.4000","2.0016","0.0763","2.0016","5.0041","7.6298","0.0000"
"2.4600","2.0516","0.0790","2.0516","5.1289","7.8980","0.0000"
"2.5200","2.1009","0.0817","2.1009","5.2523","8.1672","0.0000"
"2.5800","2.1520","0.0844","2.1520","5.3801","8.4403","0.0000"
"2.6400","2.2020","0.0872","2.2020","5.5049","8.7214","0.0000"
"2.7000","2.2516","0.0899","2.2516","5.6289","8.9926","0.0000"
"2.7600","2.3016","0.0926","2.3016","5.7540","9.2600","0.0000"
"2.8200","2.3518","0.0950","2.3518","5.8795","9.5028","0.0000"
"2.8800","2.4014","0.0959","2.4014","6.0034","9.5913","0.0000"
"2.9400","2.4517","0.0937","2.4517","6.1291","9.3692","0.0000"
"3.0000","2.5015","0.0940","2.5015","6.2537","9.4040","0.0000"
"3.0600","2.5509","0.0948","2.5509","6.3774","9.4836","0.0000"
"3.1200","2.6023","0.0957","2.6023","6.5057","9.5719","0.0000"
"3.1800","2.6519","0.0965","2.6519","6.6297","9.6534","0.0000"
"3.2400","2.7018","0.0974","2.7018","6.7545","9.7383","0.0000"
"3.3000","2.7518","0.0984","2.7518","6.8794","9.8415","0.0000"
"3.3600","2.8020","0.0995","2.8020","7.0051","9.9521","0.0000"
"3.4200","2.8516","0.1007","2.8516","7.1291","10.0660","0.0000"
"3.4800","2.9018","0.1017","2.9018","7.2545","10.1663","0.0000"
"3.5400","2.9516","0.1029","2.9516","7.3791","10.2898","0.0000"
"3.6000","3.0017","0.1041","3.0017","7.5042","10.4123","0.0000"
"3.6600","3.0520","0.1053","3.0520","7.6299","10.5317","0.0000"
"3.7200","3.1016","0.1065","3.1016","7.7539","10.6510","0.0000"
"3.7800","3.1516","0.1076","3.1516","7.8790","10.7607","0.0000"
"3.8400","3.2012","0.1089","3.2012","8.0030","10.8861","0.0000"
"3.9000","3.2516","0.1102","3.2516","8.1290","11.0152","0.0000"
"3.9600","3.3019","0.1115","3.3019","8.2547","11.1466","0.0000"
"4.0200","3.3515","0.1126","3.3515","8.3787","11.2646","0.0000"
"4.0800","3.4013","0.1138","3.4013","8.5032","11.3841","0.0000"
"4.1400","3.4517","0.1151","3.4517","8.6293","11.5108","0.0000"
"4.2000","3.5018","0.1165","3.5018","8.7544","11.6483","0.0000"
"4.2600","3.5516","0.1177","3.5516","8.8790","11.7713","0.0000"
"4.3200","3.6018","0.1188","3.6018","9.0044","11.8831","0.0000"
"4.3800","3.6517","0.1200","3.6517","9.1292","11.9980","0.0000"
"4.4400","3.7015","0.1210","3.7015","9.2538","12.1041","0.0000"
"4.5000","3.7519","0.1220","3.7519","9.3798","12.2027","0.0000"
"4.5600","3.8019","0.1230","3.8019","9.5047","12.3036","0.0000"
"4.6200","3.8519","0.1241","3.8519","9.6298","12.4061","0.0000"
"4.6800","3.9017","0.1252","3.9017","9.7543","12.5184","0.0000"
"4.7400","3.9516","0.1263","3.9516","9.8789","12.6319","0.0000"
"4.8000","4.0017","0.1275","4.0017","10.0043","12.7469","0.0000"
"4.8600","4.0513","0.1285","4.0513","10.1283","12.8496","0.0000"
"4.9200","4.1020","0.1296","4.1020","10.2549","12.9576","0.0000"
"4.9800","4.1515","0.1308","4.1515","10.3789","13.0807","0.0000"
"5.0400","4.2016","0.1320","4.2016","10.5040","13.2038","0.0000"
"5.1000","4.2514","0.1332","4.2514","10.6285","13.3232","0.0000"
"5.1600","4.3016","0.1344","4.3016","10.7540","13.4362","0.0000"
"5.2200","4.3521","0.1355","4.3521","10.8803","13.5499","0.0000"
"5.2800","4.4015","0.1366","4.4015","11.0037","13.6567","0.0000"
"5.3400","4.4518","0.1377","4.4518","11.1294","13.7670","0.0000"
"5.4000","4.5015","0.1387","4.5015","11.2536","13.8745","0.0000"
"5.4600","4.5516","0.1399","4.5516","11.3791","13.9917","0.0000"
"5.5200","4.6017","0.1410","4.6017","11.5042","14.0992","0.0000"
"5.5800","4.6515","0.1422","4.6515","11.6288","14.2213","0.0000"
"5.6400","4.7018","0.1435","4.7018","11.7545","14.3483","0.0000"
"5.7000","4.7515","0.1446","4.7515","11.8788","14.4563","0.0000"
"5.7600","4.8019","0.1459","4.8019","12.0048","14.5856","0.0000"
"5.8200","4.8516","0.1472","4.8516","12.1290","14.7224","0.0000"
"5.8800","4.9015","0.1484","4.9015","12.2539","14.8427","0.0000"
"5.9400","4.9517","0.1496","4.9517","12.3793","14.9576","0.0000"
"6.0000","5.0017","0.1507","5.0017","12.5041","15.0657","0.0000"
"6.0600","5.0518","0.1518","5.0518","12.6296","15.1822","0.0000"
"6.1200","5.1014","0.1532","5.1014","12.7535","15.3183","0.0000"
"6.1800","5.1515","0.1546","5.1515","12.8787","15.4597","0.0000"
"6.2400","5.2014","0.1560","5.2014","13.0035","15.6041","0.0000"
"6.3000","5.2518","0.1573","5.2518","13.1296","15.7350","0.0000"
"6.3600","5.3021","0.1586","5.3021","13.2553","15.8585","0.0000"
"6.4200","5.3516","0.1597","5.3516","13.3789","15.9651","0.0000"
"6.4800","5.4016","0.1608","5.4016","13.5041","16.0772","0.0000"
"6.5400","5.4512","0.1619","5.4512","13.6280","16.1908","0.0000"
"6.6000","5.5015","0.1632","5.5015","13.7538","16.3158","0.0000"
"6.6600","5.5517","0.1646","5.5517","13.8792","16.4596","0.0000"
"6.7200","5.6015","0.1659","5.6015","14.0038","16.5932","0.0000"
"6.7800","5.6520","0.1674","5.6520","14.1301","16.7412","0.0000"
"6.8400","5.7015","0.1689","5.7015","14.2537","16.8930","0.0000"
"6.9000","5.7518","0.1705","5.7518","14.3795","17.0492","0.0000"
"6.9600","5.8015","0.1719","5.8015","14.5037","17.1882","0.0000"
"7.0200","5.8517","0.1733","5.8517","14.6291","17.3256","0.0000"
"7.0800","5.9016","0.1746","5.9016","14.7540","17.4635","0.0000"
"7.1400","5.9515","0.1758","5.9515","14.8788","17.5751","0.0000"
"7.2000","6.0018","0.1770","6.0018","15.0046","17.6990","0.0000"
"7.2600","6.0515","0.1784","6.0515","15.1288","17.8428","0.0000"
"7.3200","6.1019","0.1798","6.1019","15.2548","17.9843","0.0000"
"7.3800","6.1514","0.1812","6.1514","15.3785","18.1168","0.0000"
"7.4400","6.2017","0.1825","6.2017","15.5042","18.2474","0.0000"
"7.5000","6.2519","0.1838","6.2519","15.6297","18.3784","0.0000"
"7.5600","6.3017","0.1851","6.3017","15.7542","18.5123","0.0000"
"7.6200","6.3517","0.1865","6.3517","15.8794","18.6534","0.0000"
"7.6800","6.4013","0.1880","6.4013","16.0033","18.7968","0.0000"
"7.7400","6.4516","0.1893","6.4516","16.1290","18.9334","0.0000"
"7.8000","6.5017","0.1908","6.5017","16.2542","19.0800","0.0000"
"7.8600","6.5520","0.1921","6.5520","16.3799","19.2113","0.0000"
"7.9200","6.6019","0.1936","6.6019","16.5048","19.3568","0.0000"
"7.9800","6.6513","0.1950","6.6512","16.6281","19.4973","0.0000"
"8.0400","6.7014","0.1966","6.7014","16.7536","19.6552","0.0000"
"8.1000","6.7516","0.1979","6.7516","16.8790","19.7882","0.0000"
"8.1600","6.8020","0.1992","6.8020","17.0050","19.9234","0.0000"
"8.2200","6.8517","0.2005","6.8517","17.1293","20.0537","0.0000"
"8.2800","6.9016","0.2017","6.9016","17.2541","20.1721","0.0000"
"8.3400","6.9518","0.2029","6.9518","17.3795","20.2919","0.0000"
"8.4000","7.0016","0.2041","7.0016","17.5041","20.4115","0.0000"
"8.4600","7.0520","0.2054","7.0520","17.6301","20.5383","0.0000"
"8.5200","7.1016","0.2066","7.1016","17.7541","20.6558","0.0000"
"8.5800","7.1516","0.2078","7.1516","17.8789","20.7808","0.0000"
"8.6400","7.2014","0.2091","7.2014","18.0035","20.9074","0.0000"
"8.7000","7.2516","0.2104","7.2516","18.1289","21.0433","0.0000"
"8.7600","7.3021","0.2117","7.3021","18.2552","21.1743","0.0000"
"8.8200","7.3514","0.2128","7.3514","18.3786","21.2815","0.0000"
"8.8800","7.4015","0.2138","7.4015","18.5037","21.3836","0.0000"
"8.9400","7.4513","0.2149","7.4513","18.6283","21.4872","0.0000"
"9.0000","7.5017","0.2159","7.5017","18.7543","21.5875","0.0000"
"9.0600","7.5518","0.2169","7.5518","18.8794","21.6888","0.0000"
"9.1200","7.6016","0.2178","7.6016","19.0040","21.7756","0.0000"
"9.1800","7.6519","0.2188","7.6519","19.1297","21.8842","0.0000"
"9.2400","7.7015","0.2199","7.7015","19.2537","21.9903","0.0000"
"9.3000","7.7518","0.2209","7.7518","19.3794","22.0896","0.0000"
"9.3600","7.8017","0.2220","7.8017","19.5043","22.2033","0.0000"
"9.4200","7.8519","0.2232","7.8519","19.6297","22.3180","0.0000"
"9.4800","7.9018","0.2245","7.9018","19.7545","22.4495","0.0000"
"9.5400","7.9514","0.2256","7.9514","19.8785","22.5574","0.0000"
"9.6000","8.0019","0.2267","8.0019","20.0048","22.6699","0.0000"
"9.6600","8.0516","0.2277","8.0516","20.1291","22.7737","0.0000"
"9.7200","8.1018","0.2290","8.1018","20.2545","22.8962","0.0000"
"9.7800","8.1517","0.2303","8.1517","20.3793","23.0307","0.0000"
"9.8400","8.2017","0.2315","8.2017","20.5042","23.1548","0.0000"
"9.9000","8.2518","0.2328","8.2518","20.6296","23.2751","0.0000"
"9.9600","8.3014","0.2339","8.3014","20.7536","23.3860","0.0000"
"10.0200","8.3517","0.2349","8.3517","20.8793","23.4896","0.0000"
"10.0800","8.4017","0.2360","8.4017","21.0041","23.6033","0.0000"
"10.1400","8.4517","0.2371","8.4517","21.1293","23.7142","0.0000"
"10.2000","8.5017","0.2383","8.5017","21.2541","23.8315","0.0000"
"10.2600","8.5516","0.2394","8.5516","21.3790","23.9351","0.0000"
"10.3200","8.6020","0.2405","8.6020","21.5050","24.0452","0.0000"
"10.3800","8.6513","0.2413","8.6513","21.6284","24.1334","0.0000"
"10.4400","8.7015","0.2423","8.7015","21.7538","24.2261","0.0000"
"10.5000","8.7513","0.2431","8.7513","21.8783","24.3130","0.0000"
"10.5600","8.8016","0.2439","8.8016","22.0041","24.3880","0.0000"
"10.6200","8.8518","0.2448","8.8518","22.1295","24.4776","0.0000"
"10.6800","8.9019","0.2457","8.9019","22.2547","24.5716","0.0000"
"10.7400","8.9517","0.2467","8.9517","22.3792","24.6713","0.0000"
"10.8000","9.0011","0.2476","9.0011","22.5029","24.7637","0.0000"
"10.8600","9.0516","0.2487","9.0516","22.6289","24.8709","0.0000"
"10.9200","9.1020","0.2497","9.1020","22.7549","24.9663","0.0000"
"10.9800","9.1521","0.2505","9.1521","22.8803","25.0538","0.0000"
"11.0400","9.2018","0.2514","9.2018","23.0046","25.1382","0.0000"
"11.1000","9.2515","0.2524","9.2515","23.1289","25.2380","0.0000"
"11.1600","9.3017","0.2536","9.3017","23.2543","25.3572","0.0000"
"11.2200","9.3515","0.2547","9.3515","23.3788","25.4709","0.0000"
"11.2800","9.4018","0.2559","9.4018","23.5046","25.5899","0.0000"
"11.3400","9.4516","0.2571","9.4516","23.6291","25.7064","0.0000"
"11.4000","9.5017","0.2583","9.5017","23.7543","25.8331","0.0000"
"11.4600","9.5518","0.2595","9.5518","23.8794","25.9536","0.0000"
"11.5200","9.6013","0.2606","9.6013","24.0034","26.0626","0.0000"
"11.5800","9.6518","0.2618","9.6518","24.1294","26.1833","0.0000"
"11.6400","9.7017","0.2631","9.7017","24.2542","26.3053","0.0000"
"11.7000","9.7520","0.2644","9.7520","24.3799","26.4424","0.0000"
"11.7600","9.8014","0.2657","9.8014","24.5036","26.5734","0.0000"
"11.8200","9.8516","0.2670","9.8516","24.6290","26.7000","0.0000"
"11.8800","9.9016","0.2682","9.9016","24.7539","26.8157","0.0000"
"11.9400","9.9515","0.2692","9.9515","24.8787","26.9155","0.0000"
"12.0000","10.0018","0.2702","10.0018","25.0045","27.0191","0.0000"
"12.0600","10.0517","0.2711","10.0517","25.1293","27.1115","0.0000"
"12.1200","10.1018","0.2722","10.1018","25.2544","27.2165","0.0000"
"12.1800","10.1515","0.2733","10.1515","25.3787","27.3255","0.0000"
"12.2400","10.2015","0.2743","10.2015","25.5038","27.4288","0.0000"
"12.3000","10.2518","0.2753","10.2518","25.6296","27.5314","0.0000"
"12.3600","10.3014","0.2761","10.3014","25.7535","27.6120","0.0000"
"12.4200","10.3519","0.2772","10.3519","25.8798","27.7182","0.0000"
"12.4800","10.4015","0.2780","10.4015","26.0038","27.8003","0.0000"
"12.5400","10.4516","0.2790","10.4516","26.1289","27.9037","0.0000"
"12.6000","10.5017","0.2801","10.5017","26.2544","28.0121","0.0000"
"12.6600","10.5516","0.2812","10.5516","26.3789","28.1185","0.0000"
"12.7200","10.6021","0.2824","10.6021","26.5052","28.2395","0.0000"
"12.7800","10.6516","0.2835","10.6516","26.6289","28.3466","0.0000"
"12.8400","10.7016","0.2845","10.7016","26.7540","28.4503","0.0000"
"12.9000","10.7514","0.2857","10.7514","26.8786","28.5682","0.0000"
"12.9600","10.8015","0.2868","10.8015","27.0037","28.6756","0.0000"
"13.0200","10.8518","0.2879","10.8518","27.1295","28.7940","0.0000"
"13.0800","10.9016","0.2890","10.9016","27.2540","28.8986","0.0000"
"13.1400","10.9519","0.2901","10.9519","27.3797","29.0143","0.0000"
"13.2000","11.0015","0.2914","11.0015","27.5037","29.1380","0.0000"
"13.2600","11.0517","0.2927","11.0517","27.6291","29.2680","0.0000"
"13.3200","11.1015","0.2941","11.1015","27.7537","29.4131","0.0000"
"13.3800","11.1515","0.2952","11.1515","27.8788","29.5241","0.0000"
"13.4400","11.2017","0.2965","11.2017","28.0043","29.6503","0.0000"
"13.5000","11.2516","0.2977","11.2516","28.1291","29.7725","0.0000"
"13.5600","11.3019","0.2989","11.3019","28.2548","29.8864","0.0000"
"13.6200","11.3515","0.2999","11.3515","28.3788","29.9935","0.0000"
"13.6800","11.4017","0.3010","11.4017","28.5042","30.1025","0.0000"
"13.7400","11.4517","0.3022","11.4517","28.6294","30.2168","0.0000"
"13.8000","11.5016","0.3031","11.5016","28.7539","30.3114","0.0000"
"13.8600","11.5520","0.3041","11.5520","28.8799","30.4149","0.0000"
"13.9200","11.6013","0.3051","11.6013","29.0033","30.5105","0.0000"
"13.9800","11.6518","0.3062","11.6518","29.1296","30.6202","0.0000"
"14.0400","11.7014","0.3077","11.7014","29.2536","30.7704","0.0000"
"14.1000","11.7518","0.3092","11.7518","29.3796","30.9171","0.0000"
"14.1600","11.8018","0.3108","11.8018","29.5044","31.0756","0.0000"
"14.2200","11.8517","0.3120","11.8517","29.6293","31.1959","0.0000"
"14.2800","11.9019","0.3133","11.9019","29.7547","31.3324","0.0000"
"14.3400","11.9514","0.3145","11.9514","29.8784","31.4471","0.0000"
"14.4000","12.0019","0.3157","12.0019","30.0047","31.5679","0.0000"
"14.4600","12.0516","0.3168","12.0516","30.1290","31.6819","0.0000"
"14.5200","12.1016","0.3180","12.1016","30.2541","31.8037","0.0000"
"14.5800","12.1517","0.3195","12.1517","30.3792","31.9471","0.0000"
"14.6400","12.2015","0.3209","12.2015","30.5038","32.0852","0.0000"
"14.7000","12.2519","0.3224","12.2519","30.6298","32.2393","0.0000"
"14.7600","12.3016","0.3237","12.3016","30.7541","32.3707","0.0000"
"14.8200","12.3518","0.3248","12.3518","30.8795","32.4774","0.0000"
"14.8800","12.4015","0.3259","12.4015","31.0037","32.5852","0.0000"
"14.9400","12.4516","0.3269","12.4516","31.1289","32.6914","0.0000"
"15.0000","12.5018","0.3283","12.5018","31.2546","32.8252","0.0000"
"15.0600","12.5515","0.3295","12.5515","31.3789","32.9482","0.0000"
"15.1200","12.6017","0.3308","12.6017","31.5043","33.0791","0.0000"
"15.1800","12.6514","0.3321","12.6514","31.6286","33.2058","0.0000"
"15.2400","12.7018","0.3334","12.7018","31.7546","33.3448","0.0000"
"15.3000","12.7515","0.3349","12.7515","31.8788","33.4850","0.0000"
"15.3600","12.8016","0.3362","12.8016","32.0040","33.6189","0.0000"
"15.4200","12.8518","0.3375","12.8518","32.1294","33.7508","0.0000"
"15.4800","12.9017","0.3385","12.9017","32.2543","33.8539","0.0000"
"15.5400","12.9519","0.3396","12.9519","32.3797","33.9635","0.0000"
"15.6000","13.0015","0.3407","13.0015","32.5036","34.0739","0.0000"
"15.6600","13.0518","0.3421","13.0518","32.6294","34.2147","0.0000"
"15.7200","13.1017","0.3435","13.1017","32.7542","34.3506","0.0000"
"15.7800","13.1515","0.3450","13.1515","32.8788","34.5007","0.0000"
"15.8400","13.2018","0.3465","13.2018","33.0045","34.6544","0.0000"
"15.9000","13.2517","0.3480","13.2517","33.1293","34.8001","0.0000"
"15.9600","13.3020","0.3496","13.3020","33.2551","34.9601","0.0000"
"16.0200","13.3516","0.3511","13.3516","33.3790","35.1059","0.0000"
"16.0800","13.4018","0.3524","13.4018","33.5045","35.2450","0.0000"
"16.1400","13.4516","0.3540","13.4516","33.6290","35.3957","0.0000"
"16.2000","13.5014","0.3553","13.5014","33.7536","35.5321","0.0000"
"16.2600","13.5521","0.3569","13.5521","33.8802","35.6873","0.0000"
"16.3200","13.6015","0.3582","13.6015","34.0038","35.8165","0.0000"
"16.3800","13.6516","0.3597","13.6516","34.1290","35.9655","0.0000"
"16.4400","13.7013","0.3612","13.7013","34.2532","36.1214","0.0000"
"16.5000","13.7513","0.3626","13.7513","34.3784","36.2553","0.0000"
"16.5600","13.8018","0.3641","13.8018","34.5044","36.4118","0.0000"
"16.6200","13.8516","0.3654","13.8516","34.6289","36.5392","0.0000"
"16.6800","13.9020","0.3668","13.9020","34.7550","36.6823","0.0000"
"16.7400","13.9517","0.3680","13.9517","34.8792","36.7965","0.0000"
"16.8000","14.0015","0.3691","14.0015","35.0038","36.9110","0.0000"
"16.8600","14.0517","0.3706","14.0517","35.1292","37.0585","0.0000"
"16.9200","14.1017","0.3719","14.1017","35.2543","37.1912","0.0000"
"16.9800","14.1519","0.3735","14.1519","35.3798","37.3498","0.0000"
"17.0400","14.2014","0.3750","14.2014","35.5034","37.5020","0.0000"
"17.1000","14.2519","0.3769","14.2519","35.6298","37.6936","0.0000"
"17.1600","14.3016","0.3786","14.3016","35.7540","37.8612","0.0000"
"17.2200","14.3517","0.3802","14.3517","35.8791","38.0168","0.0000"
"17.2800","14.4017","0.3818","14.4017","36.0043","38.1810","0.0000"
"17.3400","14.4518","0.3833","14.4518","36.1294","38.3280","0.0000"
"17.4000","14.5018","0.3851","14.5018","36.2546","38.5073","0.0000"
"17.4600","14.5515","0.3869","14.5515","36.3788","38.6929","0.0000"
"17.5200","14.6017","0.3890","14.6017","36.5043","38.8966","0.0000"
"17.5800","14.6514","0.3909","14.6514","36.6285","39.0935","0.0000"
"17.6400","14.7016","0.3928","14.7016","36.7539","39.2760","0.0000"
"17.7000","14.7517","0.3948","14.7517","36.8794","39.4763","0.0000"
"17.7600","14.8017","0.3966","14.8017","37.0042","39.6553","0.0000"
"17.8200","14.8519","0.3986","14.8519","37.1297","39.8630","0.0000"
"17.8800","14.9012","0.4005","14.9012","37.2530","40.0495","0.0000"
"17.9400","14.9516","0.4025","14.9516","37.3790","40.2455","0.0000"
"18.0000","15.0014","0.4042","15.0014","37.5036","40.4154","0.0000"
"18.0600","15.0517","0.4057","15.0517","37.6293","40.5728","0.0000"
"18.1200","15.1018","0.4075","15.1018","37.7545","40.7535","0.0000"
"18.1800","15.1510","0.4088","15.1510","37.8775","40.8838","0.0000"
"18.2400","15.2015","0.4105","15.2015","38.0039","41.0481","0.0000"
"18.3000","15.2517","0.4121","15.2517","38.1293","41.2146","0.0000"
"18.3600","15.3022","0.4138","15.3022","38.2556","41.3808","0.0000"
"18.4200","15.3516","0.4149","15.3516","38.3790","41.4941","0.0000"
"18.4800","15.4015","0.4162","15.4015","38.5038","41.6174","0.0000"
"18.5400","15.4517","0.4177","15.4517","38.6293","41.7679","0.0000"
"18.6000","15.5015","0.4186","15.5015","38.7538","41.8620","0.0000"
"18.6600","15.5519","0.4197","15.5519","38.8798","41.9750","0.0000"
"18.7200","15.6017","0.4209","15.6017","39.0044","42.0859","0.0000"
"18.7800","15.6517","0.4221","15.6517","39.1292","42.2134","0.0000"
"18.8400","15.7015","0.4236","15.7015","39.2538","42.3593","0.0000"
"18.9000","15.7516","0.4248","15.7516","39.3789","42.4829","0.0000"
"18.9600","15.8020","0.4264","15.8020","39.5049","42.6400","0.0000"
"19.0200","15.8513","0.4275","15.8513","39.6283","42.7550","0.0000"
"19.0800","15.9017","0.4291","15.9017","39.7543","42.9143","0.0000"
"19.1400","15.9515","0.4305","15.9515","39.8789","43.0524","0.0000"
"19.2000","16.0020","0.4319","16.0020","40.0049","43.1901","0.0000"
"19.2600","16.0518","0.4336","16.0518","40.1294","43.3565","0.0000"
"19.3200","16.1015","0.4350","16.1015","40.2537","43.4987","0.0000"
"19.3800","16.1515","0.4367","16.1515","40.3788","43.6654","0.0000"
"19.4400","16.2015","0.4381","16.2015","40.5037","43.8124","0.0000"
"19.5000","16.2519","0.4396","16.2519","40.6297","43.9647","0.0000"
"19.5600","16.3016","0.4409","16.3016","40.7540","44.0905","0.0000"
"19.6200","16.3518","0.4421","16.3518","40.8794","44.2086","0.0000"
"19.6800","16.4013","0.4436","16.4013","41.0033","44.3555","0.0000"
"19.7400","16.4514","0.4450","16.4514","41.1285","44.5017","0.0000"
"19.8000","16.5019","0.4468","16.5019","41.2548","44.6772","0.0000"
"19.8600","16.5516","0.4480","16.5516","41.3791","44.7976","0.0000"
"19.9200","16.6019","0.4491","16.6019","41.5048","44.9109","0.0000"
"19.9800","16.6516","0.4502","16.6516","41.6290","45.0229","0.0000"
"20.0400","16.7018","0.4514","16.7018","41.7545","45.1360","0.0000"
"20.1000","16.7518","0.4529","16.7518","41.8796","45.2936","0.0000"
"20.1600","16.8017","0.4543","16.8017","42.0042","45.4310","0.0000"
"20.2200","16.8520","0.4561","16.8520","42.1299","45.6101","0.0000"
"20.2800","16.9014","0.4578","16.9014","42.2536","45.7840","0.0000"
"20.3400","16.9516","0.4594","16.9516","42.3790","45.9433","0.0000"
"20.4000","17.0015","0.4611","17.0015","42.5038","46.1063","0.0000"
"20.4600","17.0518","0.4626","17.0518","42.6296","46.2625","0.0000"
"20.5200","17.1020","0.4644","17.1020","42.7550","46.4395","0.0000"
"20.5800","17.1515","0.4660","17.1515","42.8787","46.5988","0.0000"
"20.6400","17.2016","0.4679","17.2016","43.0041","46.7901","0.0000"
"20.7000","17.2511","0.4696","17.2511","43.1278","46.9566","0.0000"
"20.7600","17.3019","0.4714","17.3019","43.2547","47.1367","0.0000"
"20.8200","17.3517","0.4730","17.3517","43.3792","47.3008","0.0000"
"20.8800","17.4016","0.4745","17.4016","43.5041","47.4462","0.0000"
"20.9400","17.4518","0.4763","17.4518","43.6295","47.6296","0.0000"
"21.0000","17.5011","0.4778","17.5011","43.7529","47.7829","0.0000"
"21.0600","17.5519","0.4799","17.5519","43.8798","47.9938","0.0000"
"21.1200","17.6018","0.4820","17.6018","44.0046","48.2029","0.0000"
"21.1800","17.6520","0.4839","17.6520","44.1301","48.3908","0.0000"
"21.2400","17.7016","0.4856","17.7016","44.2540","48.5566","0.0000"
"21.3000","17.7515","0.4870","17.7515","44.3789","48.7015","0.0000"
"21.3600","17.8020","0.4886","17.8020","44.5049","48.8631","0.0000"
"21.4200","17.8517","0.4900","17.8517","44.6291","48.9995","0.0000"
"21.4800","17.9017","0.4917","17.9017","44.7543","49.1728","0.0000"
"21.5400","17.9514","0.4934","17.9514","44.8785","49.3377","0.0000"
"21.6000","18.0017","0.4950","18.0017","45.0043","49.4953","0.0000"
"21.6600","18.0518","0.4969","18.0518","45.1294","49.6897","0.0000"
"21.7200","18.1016","0.4985","18.1016","45.2539","49.8529","0.0000"
"21.7800","18.1519","0.5003","18.1519","45.3797","50.0257","0.0000"
"21.8400","18.2012","0.5015","18.2012","45.5030","50.1544","0.0000"
"21.9000","18.2519","0.5028","18.2519","45.6297","50.2849","0.0000"
"21.9600","18.3017","0.5043","18.3017","45.7542","50.4336","0.0000"
"22.0200","18.3517","0.5055","18.3517","45.8793","50.5543","0.0000"
"22.0800","18.4019","0.5071","18.4019","46.0048","50.7065","0.0000"
"22.1400","18.4515","0.5082","18.4515","46.1287","50.8228","0.0000"
"22.2000","18.5018","0.5099","18.5018","46.2545","50.9883","0.0000"
"22.2600","18.5515","0.5115","18.5515","46.3787","51.1466","0.0000"
"22.3200","18.6018","0.5131","18.6018","46.5044","51.3066","0.0000"
"22.3800","18.6517","0.5149","18.6517","46.6293","51.4854","0.0000"
"22.4400","18.7017","0.5165","18.7017","46.7541","51.6505","0.0000"
"22.5000","18.7521","0.5189","18.7521","46.8802","51.8909","0.0000"
"22.5600","18.8015","0.5210","18.8015","47.0038","52.1010","0.0000"
"22.6200","18.8518","0.5233","18.8518","47.1296","52.3329","0.0000"
"22.6800","18.9014","0.5253","18.9014","47.2535","52.5328","0.0000"
"22.7400","18.9516","0.5272","18.9516","47.3789","52.7176","0.0000"
"22.8000","19.0016","0.5293","19.0016","47.5041","52.9321","0.0000"
"22.8600","19.0516","0.5309","19.0516","47.6289","53.0897","0.0000"
"22.9200","19.1019","0.5326","19.1019","47.7547","53.2641","0.0000"
"22.9800","19.1514","0.5338","19.1514","47.8786","53.3801","0.0000"
"23.0400","19.2019","0.5354","19.2019","48.0046","53.5420","0.0000"
"23.1000","19.2517","0.5371","19.2517","48.1292","53.7052","0.0000"
"23.1600","19.3016","0.5386","19.3016","48.2540","53.8649","0.0000"
"23.2200","19.3517","0.5404","19.3517","48.3792","54.0396","0.0000"
"23.2800","19.4014","0.5417","19.4014","48.5034","54.1710","0.0000"
"23.3400","19.4518","0.5434","19.4518","48.6294","54.3356","0.0000"
"23.4000","19.5015","0.5452","19.5015","48.7537","54.5159","0.0000"
"23.4600","19.5519","0.5474","19.5519","48.8797","54.7366","0.0000"
"23.5200","19.6015","0.5495","19.6015","49.0037","54.9548","0.0000"
"23.5800","19.6515","0.5517","19.6515","49.1288","55.1679","0.0000"
"23.6400","19.7017","0.5541","19.7017","49.2543","55.4143","0.0000"
"23.7000","19.7515","0.5561","19.7515","49.3788","55.6103","0.0000"
"23.7600","19.8019","0.5584","19.8019","49.5048","55.8442","0.0000"
"23.8200","19.8512","0.5603","19.8512","49.6279","56.0321","0.0000"
"23.8800","19.9016","0.5624","19.9016","49.7539","56.2443","0.0000"
"23.9400","19.9514","0.5646","19.9514","49.8785","56.4551","0.0000"
"24.0000","20.0019","0.5664","20.0019","50.0048","56.6359","0.0000"
"24.0600","20.0521","0.5684","20.0521","50.1302","56.8381","0.0000"
"24.1200","20.1013","0.5699","20.1013","50.2533","56.9920","0.0000"
"24.1800","20.1516","0.5721","20.1516","50.3790","57.2133","0.0000"
"24.2400","20.2014","0.5743","20.2014","50.5036","57.4288","0.0000"
"24.3000","20.2517","0.5765","20.2517","50.6293","57.6530","0.0000"
"24.3600","20.3018","0.5828","20.3018","50.7544","58.2789","0.0000"
"24.4200","20.3516","0.5910","20.3516","50.8790","59.1018","0.0000"
"24.4800","20.4019","0.5994","20.4019","51.0047","59.9385","0.0000"
"24.5400","20.4514","0.6068","20.4514","51.1284","60.6810","0.0000"
"24.6000","20.5015","0.6145","20.5015","51.2538","61.4475","0.0000"
"24.6600","20.5516","0.6215","20.5516","51.3790","62.1478","0.0000"
"24.7200","20.6015","0.6281","20.6015","51.5038","62.8092","0.0000"
"24.7800","20.6517","0.6345","20.6517","51.6292","63.4521","0.0000"
"24.8400","20.7016","0.6403","20.7016","51.7541","64.0305","0.0000"
"24.9000","20.7519","0.6460","20.7519","51.8798","64.6005","0.0000"
"24.9600","20.8015","0.6510","20.8015","52.0038","65.1037","0.0000"
"25.0200","20.8514","0.6557","20.8514","52.1286","65.5680","0.0000"
"25.0800","20.9019","0.6603","20.9019","52.2546","66.0335","0.0000"
"25.1400","20.9518","0.6643","20.9518","52.3795","66.4326","0.0000"
"25.2000","21.0018","0.6684","21.0019","52.5046","66.8371","0.0000"
"25.2600","21.0512","0.6720","21.0512","52.6280","67.2027","0.0000"
"25.3200","21.1017","0.6763","21.1017","52.7543","67.6333","0.0000"
"25.3800","21.1515","0.6810","21.1515","52.8789","68.0986","0.0000"
"25.4400","21.2016","0.6860","21.2016","53.0040","68.5978","0.0000"
"25.5000","21.2517","0.6918","21.2517","53.1291","69.1831","0.0000"
"25.5600","21.3017","0.6975","21.3017","53.2543","69.7455","0.0000"
"25.6200","21.3519","0.7041","21.3519","53.3797","70.4094","0.0000"
"25.6800","21.4013","0.7106","21.4013","53.5034","71.0597","0.0000"
"25.7400","21.4516","0.7177","21.4516","53.6291","71.7699","0.0000"
"25.8000","21.5012","0.7250","21.5012","53.7531","72.4988","0.0000"
"25.8600","21.5518","0.7320","21.5518","53.8794","73.1966","0.0000"
"25.9200","21.6018","0.7396","21.6018","54.0045","73.9650","0.0000"
"25.9800","21.6516","0.7467","21.6516","54.1291","74.6657","0.0000"
"26.0400","21.7017","0.7546","21.7017","54.2542","75.4597","0.0000"
"26.1000","21.7513","0.7620","21.7513","54.3782","76.1974","0.0000"
"26.1600","21.8018","0.7699","21.8018","54.5045","76.9903","0.0000"
"26.2200","21.8517","0.7774","21.8517","54.6293","77.7435","0.0000"
"26.2800","21.9017","0.7847","21.9017","54.7542","78.4729","0.0000"
"26.3400","21.9517","0.7921","21.9517","54.8793","79.2076","0.0000"
"26.4000","22.0015","0.7990","22.0015","55.0039","79.8968","0.0000"
"26.4600","22.0518","0.8060","22.0518","55.1296","80.5952","0.0000"
"26.5200","22.1013","0.8122","22.1013","55.2532","81.2191","0.0000"
"26.5800","22.1516","0.8188","22.1516","55.3790","81.8826","0.0000"
"26.6400","22.2015","0.8258","22.2015","55.5038","82.5826","0.0000"
"26.7000","22.2513","0.8321","22.2513","55.6284","83.2140","0.0000"
"26.7600","22.3019","0.8395","22.3019","55.7547","83.9491","0.0000"
"26.8200","22.3518","0.8462","22.3518","55.8795","84.6181","0.0000"
"26.8800","22.4021","0.8534","22.4021","56.0053","85.3372","0.0000"
"26.9400","22.4515","0.8593","22.4515","56.1286","85.9340","0.0000"
"27.0000","22.5017","0.8657","22.5017","56.2544","86.5714","0.0000"
"27.0600","22.5517","0.8721","22.5517","56.3792","87.2122","0.0000"
"27.1200","22.6015","0.8776","22.6015","56.5037","87.7632","0.0000"
"27.1800","22.6518","0.8842","22.6518","56.6295","88.4225","0.0000"
"27.2400","22.7014","0.8896","22.7014","56.7534","88.9623","0.0000"
"27.3000","22.7517","0.8956","22.7517","56.8792","89.5599","0.0000"
"27.3600","22.8015","0.9014","22.8015","57.0037","90.1419","0.0000"
"27.4200","22.8518","0.9068","22.8518","57.1294","90.6761","0.0000"
"27.4800","22.9017","0.9128","22.9017","57.2543","91.2845","0.0000"
"27.5400","22.9515","0.9175","22.9515","57.3788","91.7493","0.0000"
"27.6000","23.0018","0.9232","23.0018","57.5046","92.3166","0.0000"
"27.6600","23.0514","0.9280","23.0514","57.6285","92.8047","0.0000"
"27.7200","23.1019","0.9336","23.1019","57.7548","93.3557","0.0000"
"27.7800","23.1519","0.9392","23.1519","57.8797","93.9242","0.0000"
"27.8400","23.2017","0.9441","23.2017","58.0042","94.4113","0.0000"
"27.9000","23.2516","0.9495","23.2516","58.1291","94.9545","0.0000"
"27.9600","23.3016","0.9542","23.3016","58.2539","95.4219","0.0000"
"28.0200","23.3517","0.9596","23.3517","58.3794","95.9566","0.0000"
"28.0800","23.4013","0.9642","23.4013","58.5033","96.4166","0.0000"
"28.1400","23.4517","0.9693","23.4517","58.6293","96.9269","0.0000"
"28.2000","23.5014","0.9742","23.5014","58.7536","97.4228","0.0000"
"28.2600","23.5516","0.9788","23.5516","58.8790","97.8818","0.0000"
"28.3200","23.6019","0.9839","23.6019","59.0048","98.3876","0.0000"
"28.3800","23.6514","0.9882","23.6514","59.1284","98.8185","0.0000"
"28.4400","23.7015","0.9930","23.7015","59.2539","99.3027","0.0000"
"28.5000","23.7516","0.9982","23.7516","59.3790","99.8238","0.0000"
"28.5600","23.8019","1.0031","23.8019","59.5047","100.3076","0.0000"
"28.6200","23.8518","1.0078","23.8518","59.6296","100.7847","0.0000"
"28.6800","23.9016","1.0119","23.9016","59.7541","101.1894","0.0000"
"28.7400","23.9518","1.0168","23.9518","59.8795","101.6813","0.0000"
"28.8000","24.0015","1.0206","24.0015","60.0038","102.0620","0.0000"
"28.8600","24.0520","1.0252","24.0520","60.1301","102.5165","0.0000"
"28.9200","24.1016","1.0292","24.1016","60.2541","102.9181","0.0000"
"28.9800","24.1517","1.0329","24.1517","60.3792","103.2886","0.0000"
"29.0400","24.2015","1.0373","24.2015","60.5038","103.7252","0.0000"
"29.1000","24.2516","1.0408","24.2516","60.6289","104.0790","0.0000"
"29.1600","24.3019","1.0449","24.3019","60.7546","104.4947","0.0000"
"29.2200","24.3514","1.0481","24.3514","60.8786","104.8108","0.0000"
"29.2800","24.4018","1.0515","24.4018","61.0046","105.1543","0.0000"
"29.3400","24.4513","1.0545","24.4513","61.1283","105.4479","0.0000"
"29.4000","24.5017","1.0572","24.5017","61.2543","105.7198","0.0000"
"29.4600","24.5517","1.0601","24.5517","61.3791","106.0073","0.0000"
"29.5200","24.6014","1.0619","24.6014","61.5034","106.1912","0.0000"
"29.5800","24.6517","1.0647","24.6517","61.6291","106.4713","0.0000"
"29.6400","24.7016","1.0673","24.7016","61.7540","106.7330","0.0000"
"29.7000","24.7519","1.0696","24.7519","61.8797","106.9607","0.0000"
"29.7600","24.8017","1.0713","24.8017","62.0042","107.1288","0.0000"
"29.8200","24.8518","1.0722","24.8518","62.1294","107.2244","0.0000"
"29.8800","24.9017","1.0735","24.9017","62.2542","107.3508","0.0000"
"29.9400","24.9513","1.0738","24.9513","62.3782","107.3830","0.0000"
"30.0000","25.0018","1.0742","25.0018","62.5045","107.4250","0.0000"
"30.0600","25.0517","1.0738","25.0517","62.6294","107.3800","0.0000"
"30.1200","25.1017","1.0728","25.1017","62.7542","107.2820","0.0000"
"30.1800","25.1517","1.0715","25.1517","62.8793","107.1452","0.0000"
"30.2400","25.2016","1.0685","25.2016","63.0039","106.8495","0.0000"
"30.3000","25.2517","1.0652","25.2517","63.1293","106.5201","0.0000"
"30.3600","25.3014","1.0593","25.3014","63.2536","105.9314","0.0000"
"30.4200","25.3518","1.0512","25.3518","63.3796","105.1211","0.0000"
"30.4800","25.4017","1.0402","25.4017","63.5041","104.0205","0.0000"
"30.5400","25.4518","1.0276","25.4518","63.6296","102.7561","0.0000"
"30.6000","25.5018","1.0156","25.5018","63.7544","101.5570","0.0000"
"30.6600","25.5517","1.0050","25.5517","63.8793","100.4988","0.0000"
"30.7200","25.6019","0.9973","25.6019","64.0047","99.7258","0.0000"
"30.7800","25.6515","0.9905","25.6515","64.1287","99.0491","0.0000"
"30.8400","25.7018","0.9853","25.7018","64.2544","98.5313","0.0000"
"30.9000","25.7515","0.9807","25.7515","64.3786","98.0705","0.0000"
"30.9600","25.8018","0.9764","25.8018","64.5044","97.6354","0.0000"
"31.0200","25.8517","0.9728","25.8517","64.6292","97.2829","0.0000"
"31.0800","25.9016","0.9694","25.9016","64.7541","96.9431","0.0000"
"31.1400","25.9519","0.9668","25.9519","64.8798","96.6820","0.0000"
"31.2000","26.0013","0.9637","26.0013","65.0032","96.3735","0.0000"
"31.2600","26.0519","0.9610","26.0519","65.1298","96.1017","0.0000"
"31.3200","26.1018","0.9586","26.1018","65.2546","95.8556","0.0000"
"31.3800","26.1517","0.9557","26.1517","65.3792","95.5743","0.0000"
"31.4400","26.2018","0.9533","26.2018","65.5046","95.3275","0.0000"
"31.5000","26.2518","0.9504","26.2518","65.6294","95.0448","0.0000"
"31.5600","26.3021","0.9480","26.3021","65.7552","94.8046","0.0000"
"31.6200","26.3515","0.9455","26.3515","65.8788","94.5483","0.0000"
"31.6800","26.4016","0.9432","26.4016","66.0040","94.3191","0.0000"
"31.7400","26.4514","0.9412","26.4514","66.1285","94.1191","0.0000"
"31.8000","26.5018","0.9387","26.5018","66.2546","93.8739","0.0000"
"31.8600","26.5520","0.9369","26.5520","66.3800","93.6882","0.0000"
"31.9200","26.6016","0.9346","26.6016","66.5039","93.4561","0.0000"
"31.9800","26.6519","0.9329","26.6519","66.6297","93.2919","0.0000"
"32.0400","26.7013","0.9309","26.7013","66.7533","93.0913","0.0000"
"32.1000","26.7515","0.9291","26.7515","66.8788","92.9139","0.0000"
"32.1600","26.8017","0.9277","26.8017","67.0042","92.7743","0.0000"
"32.2200","26.8516","0.9260","26.8516","67.1290","92.5977","0.0000"
"32.2800","26.9017","0.9248","26.9017","67.2542","92.4832","0.0000"
"32.3400","26.9513","0.9234","26.9513","67.3781","92.3418","0.0000"
"32.4000","27.0017","0.9239","27.0017","67.5042","92.3881","0.0000"
"32.4600","27.0518","0.9249","27.0518","67.6296","92.4896","0.0000"
"32.5200","27.1020","0.9261","27.1020","67.7550","92.6107","0.0000"
"32.5800","27.1517","0.9283","27.1517","67.8793","92.8325","0.0000"
"32.6400","27.2018","0.9300","27.2018","68.0044","93.0029","0.0000"
"32.7000","27.2518","0.9321","27.2518","68.1296","93.2116","0.0000"
"32.7600","27.3016","0.9337","27.3016","68.2541","93.3657","0.0000"
"32.8200","27.3519","0.9352","27.3519","68.3798","93.5226","0.0000"
"32.8800","27.4014","0.9365","27.4014","68.5035","93.6527","0.0000"
"32.9400","27.4517","0.9375","27.4517","68.6292","93.7479","0.0000"
"33.0000","27.5018","0.9395","27.5018","68.7544","93.9477","0.0000"
"33.0600","27.5518","0.9417","27.5518","68.8795","94.1737","0.0000"
"33.1200","27.6017","0.9442","27.6017","69.0044","94.4219","0.0000"
"33.1800","27.6513","0.9459","27.6513","69.1283","94.5887","0.0000"
"33.2400","27.7015","0.9477","27.7015","69.2537","94.7666","0.0000"
"33.3000","27.7514","0.9495","27.7514","69.3786","94.9478","0.0000"
"33.3600","27.8022","0.9515","27.8022","69.5055","95.1494","0.0000"
"33.4200","27.8518","0.9533","27.8518","69.6295","95.3316","0.0000"
"33.4800","27.9015","0.9547","27.9015","69.7537","95.4713","0.0000"
"33.5400","27.9517","0.9561","27.9517","69.8791","95.6121","0.0000"
"33.6000","28.0015","0.9569","28.0015","70.0037","95.6933","0.0000"
"33.6600","28.0519","0.9576","28.0519","70.1297","95.7591","0.0000"
"33.7200","28.1017","0.9580","28.1017","70.2543","95.7968","0.0000"
"33.7800","28.1515","0.9576","28.1515","70.3788","95.7616","0.0000"
"33.8400","28.2016","0.9577","28.2016","70.5040","95.7729","0.0000"
"33.9000","28.2518","0.9573","28.2518","70.6294","95.7333","0.0000"
"33.9600","28.3022","0.9570","28.3022","70.7554","95.6955","0.0000"
"34.0200","28.3516","0.9563","28.3516","70.8791","95.6319","0.0000"
"34.0800","28.4014","0.9564","28.4014","71.0036","95.6421","0.0000"
"34.1400","28.4514","0.9573","28.4514","71.1285","95.7269","0.0000"
"34.2000","28.5018","0.9579","28.5018","71.2545","95.7879","0.0000"
"34.2600","28.5521","0.9585","28.5521","71.3802","95.8521","0.0000"
"34.3200","28.6016","0.9585","28.6016","71.5039","95.8532","0.0000"
"34.3800","28.6517","0.9590","28.6517","71.6293","95.9050","0.0000"
"34.4400","28.7014","0.9590","28.7014","71.7536","95.8986","0.0000"
"34.5000","28.7520","0.9592","28.7520","71.8799","95.9229","0.0000"
"34.5600","28.8018","0.9592","28.8018","72.0044","95.9243","0.0000"
"34.6200","28.8516","0.9590","28.8516","72.1290","95.9010","0.0000"
"34.6800","28.9017","0.9593","28.9017","72.2541","95.9276","0.0000"
"34.7400","28.9515","0.9592","28.9515","72.3787","95.9173","0.0000"
"34.8000","29.0018","0.9590","29.0018","72.5044","95.9041","0.0000"
"34.8600","29.0518","0.9590","29.0518","72.6295","95.8981","0.0000"
"34.9200","29.1018","0.9587","29.1018","72.7544","95.8659","0.0000"
"34.9800","29.1516","0.9585","29.1516","72.8789","95.8508","0.0000"
"35.0400","29.2016","0.9582","29.2016","73.0041","95.8153","0.0000"
"35.1000","29.2520","0.9581","29.2520","73.1301","95.8132","0.0000"
"35.1600","29.3015","0.9577","29.3015","73.2538","95.7729","0.0000"
"35.2200","29.3516","0.9574","29.3516","73.3789","95.7425","0.0000"
"35.2800","29.4017","0.9576","29.4017","73.5043","95.7571","0.0000"
"35.3400","29.4518","0.9572","29.4518","73.6295","95.7202","0.0000"
"35.4000","29.5018","0.9583","29.5018","73.7546","95.8281","0.0000"
"35.4600","29.5514","0.9593","29.5514","73.8786","95.9285","0.0000"
"35.5200","29.6017","0.9610","29.6017","74.0043","96.1009","0.0000"
"35.5800","29.6515","0.9624","29.6515","74.1289","96.2375","0.0000"
"35.6400","29.7017","0.9636","29.7017","74.2543","96.3618","0.0000"
"35.7000","29.7518","0.9648","29.7518","74.3794","96.4810","0.0000"
"35.7600","29.8016","0.9657","29.8016","74.5040","96.5677","0.0000"
"35.8200","29.8519","0.9672","29.8519","74.6297","96.7196","0.0000"
"35.8800","29.9015","0.9681","29.9015","74.7537","96.8132","0.0000"
"35.9400","29.9515","0.9692","29.9515","74.8788","96.9216","0.0000"
"36.0000","30.0013","0.9707","30.0013","75.0033","97.0706","0.0000"
"36.0600","30.0516","0.9721","30.0516","75.1291","97.2095","0.0000"
"36.1200","30.1017","0.9735","30.1017","75.2542","97.3484","0.0000"
"36.1800","30.1517","0.9754","30.1517","75.3794","97.5356","0.0000"
"36.2400","30.2018","0.9778","30.2018","75.5045","97.7787","0.0000"
"36.3000","30.2514","0.9799","30.2514","75.6285","97.9853","0.0000"
"36.3600","30.3018","0.9826","30.3018","75.7545","98.2565","0.0000"
"36.4200","30.3516","0.9848","30.3516","75.8790","98.4849","0.0000"
"36.4800","30.4017","0.9872","30.4017","76.0042","98.7226","0.0000"
"36.5400","30.4516","0.9895","30.4516","76.1290","98.9525","0.0000"
"36.6000","30.5014","0.9916","30.5014","76.2536","99.1627","0.0000"
"36.6600","30.5517","0.9936","30.5517","76.3793","99.3587","0.0000"
"36.7200","30.6017","0.9958","30.6017","76.5041","99.5838","0.0000"
"36.7800","30.6518","0.9981","30.6518","76.6296","99.8106","0.0000"
"36.8400","30.7018","1.0005","30.7018","76.7544","100.0498","0.0000"
"36.9000","30.7513","1.0020","30.7513","76.8784","100.2039","0.0000"
"36.9600","30.8019","1.0057","30.8019","77.0047","100.5712","0.0000"
"37.0200","30.8516","1.0085","30.8516","77.1289","100.8540","0.0000"
"37.0800","30.9018","1.0116","30.9018","77.2544","101.1592","0.0000"
"37.1400","30.9516","1.0142","30.9516","77.3789","101.4207","0.0000"
"37.2000","31.0019","1.0169","31.0019","77.5047","101.6932","0.0000"
"37.2600","31.0516","1.0200","31.0516","77.6289","101.9966","0.0000"
"37.3200","31.1016","1.0224","31.1016","77.7540","102.2380","0.0000"
"37.3800","31.1517","1.0251","31.1517","77.8792","102.5145","0.0000"
"37.4400","31.2013","1.0296","31.2013","78.0031","102.9589","0.0000"
"37.5000","31.2518","1.0359","31.2518","78.1295","103.5852","0.0000"
"37.5600","31.3017","1.0414","31.3017","78.2543","104.1362","0.0000"
"37.6200","31.3517","1.0469","31.3517","78.3791","104.6879","0.0000"
"37.6800","31.4017","1.0516","31.4017","78.5043","105.1560","0.0000"
"37.7400","31.4517","1.0553","31.4517","78.6291","105.5298","0.0000"
"37.8000","31.5019","1.0596","31.5019","78.7549","105.9581","0.0000"
"37.8600","31.5515","1.0637","31.5515","78.8788","106.3716","0.0000"
"37.9200","31.6019","1.0677","31.6019","79.0048","106.7701","0.0000"
"37.9800","31.6515","1.0719","31.6515","79.1288","107.1935","0.0000"
"38.0400","31.7017","1.0755","31.7017","79.2542","107.5512","0.0000"
"38.1000","31.7515","1.0797","31.7515","79.3788","107.9719","0.0000"
"38.1600","31.8016","1.0838","31.8016","79.5039","108.3785","0.0000"
"38.2200","31.8519","1.0878","31.8519","79.6297","108.7831","0.0000"
"38.2800","31.9017","1.0923","31.9017","79.7542","109.2291","0.0000"
"38.3400","31.9519","1.0965","31.9519","79.8796","109.6506","0.0000"
"38.4000","32.0014","1.1007","32.0014","80.0036","110.0705","0.0000"
"38.4600","32.0515","1.1046","32.0515","80.1287","110.4603","0.0000"
"38.5200","32.1018","1.1091","32.1018","80.2545","110.9070","0.0000"
"38.5800","32.1516","1.1134","32.1516","80.3790","111.3361","0.0000"
"38.6400","32.2018","1.1178","32.2018","80.5044","111.7768","0.0000"
"38.7000","32.2516","1.1219","32.2516","80.6290","112.1947","0.0000"
"38.7600","32.3018","1.1260","32.3018","80.7544","112.6050","0.0000"
"38.8200","32.3515","1.1306","32.3515","80.8787","113.0569","0.0000"
"38.8800","32.4015","1.1348","32.4015","81.0038","113.4832","0.0000"
"38.9400","32.4517","1.1403","32.4517","81.1293","114.0342","0.0000"
"39.0000","32.5014","1.1465","32.5014","81.2535","114.6472","0.0000"
"39.0600","32.5518","1.1528","32.5518","81.3795","115.2766","0.0000"
"39.1200","32.6019","1.1593","32.6019","81.5047","115.9251","0.0000"
"39.1800","32.6518","1.1653","32.6518","81.6295","116.5338","0.0000"
"39.2400","32.7016","1.1717","32.7016","81.7541","117.1666","0.0000"
"39.3000","32.7512","1.1777","32.7512","81.8780","117.7688","0.0000"
"39.3600","32.8021","1.1851","32.8021","82.0052","118.5099","0.0000"
"39.4200","32.8516","1.1917","32.8516","82.1289","119.1687","0.0000"
"39.4800","32.9015","1.1984","32.9015","82.2537","119.8439","0.0000"
"39.5400","32.9512","1.2055","32.9512","82.3780","120.5457","0.0000"
"39.6000","33.0017","1.2127","33.0017","82.5043","121.2712","0.0000"
"39.6600","33.0518","1.2202","33.0518","82.6294","122.0188","0.0000"
"39.7200","33.1012","1.2266","33.1012","82.7531","122.6611","0.0000"
"39.7800","33.1515","1.2350","33.1515","82.8788","123.4989","0.0000"
"39.8400","33.2016","1.2442","33.2016","83.0040","124.4187","0.0000"
"39.9000","33.2520","1.2541","33.2520","83.1300","125.4095","0.0000"
"39.9600","33.3016","1.2640","33.3016","83.2540","126.3966","0.0000"
"40.0200","33.3516","1.2742","33.3516","83.3791","127.4233","0.0000"
"40.0800","33.4017","1.2856","33.4017","83.5042","128.5596","0.0000"
"40.1400","33.4514","1.2977","33.4514","83.6285","129.7739","0.0000"
"40.2000","33.5020","1.3125","33.5020","83.7551","131.2471","0.0000"
"40.2600","33.5515","1.3260","33.5515","83.8788","132.5973","0.0000"
"40.3200","33.6014","1.3404","33.6014","84.0036","134.0434","0.0000"
"40.3800","33.6515","1.3578","33.6515","84.1287","135.7817","0.0000"
"40.4400","33.7014","1.3749","33.7014","84.2536","137.4894","0.0000"
"40.5000","33.7518","1.3943","33.7518","84.3796","139.4283","0.0000"
"40.5600","33.8015","1.4125","33.8015","84.5039","141.2500","0.0000"
"40.6200","33.8516","1.4319","33.8516","84.6290","143.1883","0.0000"
"40.6800","33.9013","1.4523","33.9013","84.7533","145.2256","0.0000"
"40.7400","33.9516","1.4731","33.9516","84.8790","147.3066","0.0000"
"40.8000","34.0014","1.4939","34.0014","85.0035","149.3885","0.0000"
"40.8600","34.0516","1.5141","34.0516","85.1290","151.4065","0.0000"
"40.9200","34.1018","1.5366","34.1018","85.2544","153.6583","0.0000"
"40.9800","34.1512","1.5572","34.1512","85.3781","155.7213","0.0000"
"41.0400","34.2019","1.5801","34.2019","85.5047","158.0123","0.0000"
"41.1000","34.2513","1.6020","34.2513","85.6283","160.1954","0.0000"
"41.1600","34.3018","1.6235","34.3018","85.7544","162.3453","0.0000"
"41.2200","34.3515","1.6453","34.3515","85.8786","164.5278","0.0000"
"41.2800","34.4015","1.6664","34.4015","86.0038","166.6357","0.0000"
"41.3400","34.4517","1.6890","34.4517","86.1292","168.9022","0.0000"
"41.4000","34.5014","1.7107","34.5014","86.2535","171.0708","0.0000"
"41.4600","34.5519","1.7336","34.5519","86.3798","173.3632","0.0000"
"41.5200","34.6016","1.7575","34.6016","86.5040","175.7488","0.0000"
"41.5800","34.6516","1.7811","34.6516","86.6289","178.1054","0.0000"
"41.6400","34.7015","1.8069","34.7015","86.7537","180.6946","0.0000"
"41.7000","34.7513","1.8318","34.7513","86.8783","183.1813","0.0000"
"41.7600","34.8020","1.8593","34.8020","87.0049","185.9314","0.0000"
"41.8200","34.8513","1.8853","34.8513","87.1283","188.5323","0.0000"
"41.8800","34.9015","1.9118","34.9015","87.2537","191.1786","0.0000"
"41.9400","34.9513","1.9386","34.9513","87.3782","193.8634","0.0000"
"42.0000","35.0016","1.9645","35.0016","87.5040","196.4458","0.0000"