File: Fig6C/211130_Instron/211130/entangled/PureCompression_TTball_7_1.csv
Results Table 1


Results Table 2


1,Time,Displacement,Force,Compressive displacement,Compressive strain (Displacement),Compressive stress,PIP count
,(s),(mm),(kN),(mm),(%),(MPa),
"","0.0000","0.0000","0.0000","0.0000","0.0000","-0.0026","0.0000"
"","0.2000","0.1678","0.0001","0.1678","0.1118","0.0054","0.0000"
"","0.4000","0.3349","0.0002","0.3349","0.2233","0.0163","0.0000"
"","0.6000","0.5016","0.0003","0.5016","0.3344","0.0258","0.0000"
"","0.8000","0.6684","0.0003","0.6684","0.4456","0.0342","0.0000"
"","1.0000","0.8348","0.0004","0.8348","0.5565","0.0399","0.0000"
"","1.2000","1.0017","0.0005","1.0017","0.6678","0.0487","0.0000"
"","1.4000","1.1682","0.0005","1.1682","0.7788","0.0501","0.0000"
"","1.6000","1.3349","0.0006","1.3349","0.8899","0.0609","0.0000"
"","1.8000","1.5017","0.0006","1.5017","1.0011","0.0612","0.0000"
"","2.0000","1.6680","0.0007","1.6680","1.1120","0.0712","0.0000"
"","2.2000","1.8347","0.0008","1.8347","1.2231","0.0763","0.0000"
"","2.4000","2.0015","0.0008","2.0015","1.3343","0.0841","0.0000"
"","2.6000","2.1682","0.0009","2.1682","1.4455","0.0903","0.0000"
"","2.8000","2.3350","0.0010","2.3350","1.5567","0.1008","0.0000"
"","3.0000","2.5014","0.0011","2.5014","1.6676","0.1079","0.0000"
"","3.2000","2.6683","0.0012","2.6683","1.7789","0.1170","0.0000"
"","3.4000","2.8349","0.0012","2.8349","1.8899","0.1228","0.0000"
"","3.6000","3.0017","0.0013","3.0017","2.0011","0.1297","0.0000"
"","3.8000","3.1684","0.0014","3.1684","2.1122","0.1428","0.0000"
"","4.0000","3.3348","0.0014","3.3348","2.2232","0.1420","0.0000"
"","4.2000","3.5018","0.0016","3.5018","2.3345","0.1559","0.0000"
"","4.4000","3.6680","0.0017","3.6680","2.4453","0.1664","0.0000"
"","4.6000","3.8350","0.0018","3.8350","2.5567","0.1758","0.0000"
"","4.8000","4.0015","0.0018","4.0015","2.6677","0.1800","0.0000"
"","5.0000","4.1682","0.0019","4.1682","2.7788","0.1908","0.0000"
"","5.2000","4.3351","0.0019","4.3351","2.8901","0.1949","0.0000"
"","5.4000","4.5015","0.0020","4.5015","3.0010","0.2039","0.0000"
"","5.6000","4.6683","0.0022","4.6683","3.1122","0.2163","0.0000"
"","5.8000","4.8345","0.0023","4.8345","3.2230","0.2252","0.0000"
"","6.0000","5.0015","0.0023","5.0015","3.3344","0.2325","0.0000"
"","6.2000","5.1685","0.0024","5.1685","3.4456","0.2445","0.0000"
"","6.4000","5.3346","0.0025","5.3346","3.5564","0.2522","0.0000"
"","6.6000","5.5019","0.0027","5.5019","3.6679","0.2667","0.0000"
"","6.8000","5.6680","0.0028","5.6680","3.7786","0.2811","0.0000"
"","7.0000","5.8349","0.0028","5.8349","3.8899","0.2752","0.0000"
"","7.2000","6.0016","0.0028","6.0016","4.0011","0.2841","0.0000"
"","7.4000","6.1682","0.0029","6.1682","4.1121","0.2944","0.0000"
"","7.6000","6.3350","0.0029","6.3350","4.2233","0.2911","0.0000"
"","7.8000","6.5013","0.0030","6.5013","4.3342","0.3001","0.0000"
"","8.0000","6.6684","0.0031","6.6684","4.4456","0.3059","0.0000"
"","8.2000","6.8346","0.0031","6.8346","4.5564","0.3097","0.0000"
"","8.4000","7.0015","0.0032","7.0015","4.6677","0.3174","0.0000"
"","8.6000","7.1682","0.0032","7.1682","4.7788","0.3237","0.0000"
"","8.8000","7.3348","0.0033","7.3348","4.8899","0.3278","0.0000"
"","9.0000","7.5017","0.0033","7.5017","5.0011","0.3323","0.0000"
"","9.2000","7.6682","0.0034","7.6682","5.1121","0.3370","0.0000"
"","9.4000","7.8349","0.0035","7.8349","5.2232","0.3481","0.0000"
"","9.6000","8.0017","0.0035","8.0017","5.3345","0.3512","0.0000"
"","9.8000","8.1680","0.0036","8.1680","5.4454","0.3617","0.0000"
"","10.0000","8.3352","0.0038","8.3352","5.5568","0.3808","0.0000"
"","10.2000","8.5012","0.0040","8.5012","5.6675","0.3979","0.0000"
"","10.4000","8.6685","0.0040","8.6685","5.7790","0.4017","0.0000"
"","10.6000","8.8350","0.0041","8.8350","5.8900","0.4117","0.0000"
"","10.8000","9.0014","0.0041","9.0014","6.0009","0.4143","0.0000"
"","11.0000","9.1684","0.0042","9.1684","6.1123","0.4185","0.0000"
"","11.2000","9.3347","0.0043","9.3347","6.2231","0.4250","0.0000"
"","11.4000","9.5017","0.0042","9.5017","6.3345","0.4196","0.0000"
"","11.6000","9.6682","0.0043","9.6682","6.4454","0.4303","0.0000"
"","11.8000","9.8349","0.0043","9.8349","6.5566","0.4349","0.0000"
"","12.0000","10.0017","0.0043","10.0017","6.6678","0.4293","0.0000"
"","12.2000","10.1681","0.0045","10.1681","6.7787","0.4481","0.0000"
"","12.4000","10.3349","0.0045","10.3349","6.8900","0.4483","0.0000"
"","12.6000","10.5013","0.0046","10.5013","7.0009","0.4571","0.0000"
"","12.8000","10.6681","0.0047","10.6681","7.1121","0.4714","0.0000"
"","13.0000","10.8350","0.0047","10.8350","7.2233","0.4675","0.0000"
"","13.2000","11.0015","0.0047","11.0015","7.3343","0.4690","0.0000"
"","13.4000","11.1685","0.0048","11.1685","7.4457","0.4816","0.0000"
"","13.6000","11.3345","0.0049","11.3345","7.5563","0.4921","0.0000"
"","13.8000","11.5016","0.0048","11.5016","7.6677","0.4775","0.0000"
"","14.0000","11.6681","0.0048","11.6681","7.7788","0.4848","0.0000"
"","14.2000","11.8347","0.0048","11.8347","7.8898","0.4802","0.0000"
"","14.4000","12.0018","0.0048","12.0018","8.0012","0.4797","0.0000"
"","14.6000","12.1681","0.0048","12.1681","8.1121","0.4794","0.0000"
"","14.8000","12.3349","0.0048","12.3349","8.2233","0.4788","0.0000"
"","15.0000","12.5015","0.0047","12.5015","8.3343","0.4737","0.0000"
"","15.2000","12.6683","0.0048","12.6683","8.4455","0.4824","0.0000"
"","15.4000","12.8349","0.0050","12.8349","8.5566","0.5021","0.0000"
"","15.6000","13.0016","0.0050","13.0016","8.6677","0.4984","0.0000"
"","15.8000","13.1683","0.0050","13.1683","8.7788","0.5013","0.0000"
"","16.0000","13.3347","0.0050","13.3347","8.8898","0.5023","0.0000"
"","16.2000","13.5019","0.0051","13.5019","9.0013","0.5063","0.0000"
"","16.4000","13.6684","0.0052","13.6684","9.1122","0.5173","0.0000"
"","16.6000","13.8346","0.0052","13.8346","9.2231","0.5224","0.0000"
"","16.8000","14.0017","0.0051","14.0017","9.3345","0.5125","0.0000"
"","17.0000","14.1680","0.0052","14.1680","9.4453","0.5209","0.0000"
"","17.2000","14.3349","0.0053","14.3349","9.5566","0.5259","0.0000"
"","17.4000","14.5017","0.0053","14.5017","9.6678","0.5265","0.0000"
"","17.6000","14.6680","0.0052","14.6680","9.7787","0.5212","0.0000"
"","17.8000","14.8350","0.0053","14.8350","9.8900","0.5300","0.0000"
"","18.0000","15.0016","0.0052","15.0016","10.0010","0.5245","0.0000"
"","18.2000","15.1684","0.0053","15.1684","10.1122","0.5312","0.0000"
"","18.4000","15.3348","0.0053","15.3348","10.2232","0.5261","0.0000"
"","18.6000","15.5013","0.0053","15.5013","10.3342","0.5274","0.0000"
"","18.8000","15.6686","0.0053","15.6686","10.4457","0.5314","0.0000"
"","19.0000","15.8348","0.0055","15.8348","10.5565","0.5481","0.0000"
"","19.2000","16.0017","0.0056","16.0017","10.6678","0.5551","0.0000"
"","19.4000","16.1682","0.0055","16.1682","10.7788","0.5531","0.0000"
"","19.6000","16.3351","0.0057","16.3351","10.8901","0.5684","0.0000"
"","19.8000","16.5016","0.0056","16.5016","11.0010","0.5570","0.0000"
"","20.0000","16.6679","0.0056","16.6679","11.1119","0.5608","0.0000"
"","20.2000","16.8351","0.0056","16.8351","11.2234","0.5587","0.0000"
"","20.4000","17.0015","0.0057","17.0015","11.3344","0.5660","0.0000"
"","20.6000","17.1682","0.0057","17.1682","11.4455","0.5735","0.0000"
"","20.8000","17.3348","0.0059","17.3348","11.5565","0.5867","0.0000"
"","21.0000","17.5014","0.0060","17.5014","11.6676","0.5981","0.0000"
"","21.2000","17.6684","0.0061","17.6684","11.7790","0.6117","0.0000"
"","21.4000","17.8343","0.0063","17.8343","11.8895","0.6310","0.0000"
"","21.6000","18.0019","0.0065","18.0019","12.0013","0.6474","0.0000"
"","21.8000","18.1680","0.0067","18.1680","12.1120","0.6702","0.0000"
"","22.0000","18.3351","0.0070","18.3351","12.2234","0.7012","0.0000"
"","22.2000","18.5017","0.0074","18.5017","12.3344","0.7380","0.0000"
"","22.4000","18.6681","0.0080","18.6681","12.4454","0.7955","0.0000"
"","22.6000","18.8351","0.0085","18.8351","12.5567","0.8451","0.0000"
"","22.8000","19.0013","0.0090","19.0013","12.6675","0.9038","0.0000"
"","23.0000","19.1686","0.0097","19.1686","12.7790","0.9702","0.0000"
"","23.2000","19.3349","0.0099","19.3349","12.8899","0.9908","0.0000"
"","23.4000","19.5016","0.0100","19.5016","13.0011","1.0023","0.0000"
"","23.6000","19.6684","0.0103","19.6684","13.1123","1.0315","0.0000"
"","23.8000","19.8345","0.0104","19.8345","13.2230","1.0450","0.0000"
"","24.0000","20.0016","0.0106","20.0016","13.3344","1.0557","0.0000"
"","24.2000","20.1683","0.0106","20.1683","13.4455","1.0621","0.0000"
"","24.4000","20.3350","0.0107","20.3350","13.5566","1.0660","0.0000"
"","24.6000","20.5018","0.0105","20.5018","13.6678","1.0548","0.0000"
"","24.8000","20.6681","0.0107","20.6681","13.7787","1.0718","0.0000"
"","25.0000","20.8350","0.0107","20.8350","13.8900","1.0723","0.0000"
"","25.2000","21.0016","0.0108","21.0016","14.0011","1.0831","0.0000"
"","25.4000","21.1683","0.0108","21.1683","14.1122","1.0761","0.0000"
"","25.6000","21.3350","0.0109","21.3350","14.2233","1.0855","0.0000"
"","25.8000","21.5015","0.0111","21.5015","14.3343","1.1108","0.0000"
"","26.0000","21.6679","0.0113","21.6679","14.4453","1.1290","0.0000"
"","26.2000","21.8347","0.0114","21.8347","14.5565","1.1396","0.0000"
"","26.4000","22.0015","0.0115","22.0015","14.6677","1.1473","0.0000"
"","26.6000","22.1682","0.0117","22.1682","14.7788","1.1744","0.0000"
"","26.8000","22.3345","0.0111","22.3345","14.8896","1.1144","0.0000"
"","27.0000","22.5019","0.0111","22.5019","15.0012","1.1083","0.0000"
"","27.2000","22.6680","0.0109","22.6680","15.1120","1.0912","0.0000"
"","27.4000","22.8348","0.0113","22.8348","15.2232","1.1314","0.0000"
"","27.6000","23.0017","0.0114","23.0017","15.3345","1.1353","0.0000"
"","27.8000","23.1679","0.0114","23.1679","15.4453","1.1391","0.0000"
"","28.0000","23.3350","0.0116","23.3350","15.5567","1.1628","0.0000"
"","28.2000","23.5016","0.0116","23.5016","15.6677","1.1637","0.0000"
"","28.4000","23.6685","0.0113","23.6685","15.7790","1.1299","0.0000"
"","28.6000","23.8346","0.0117","23.8346","15.8897","1.1655","0.0000"
"","28.8000","24.0012","0.0119","24.0012","16.0008","1.1909","0.0000"
"","29.0000","24.1686","0.0123","24.1686","16.1124","1.2271","0.0000"
"","29.2000","24.3346","0.0122","24.3346","16.2230","1.2162","0.0000"
"","29.4000","24.5017","0.0122","24.5017","16.3345","1.2240","0.0000"
"","29.6000","24.6681","0.0124","24.6681","16.4454","1.2366","0.0000"
"","29.8000","24.8350","0.0123","24.8350","16.5567","1.2333","0.0000"
"","30.0000","25.0016","0.0127","25.0016","16.6677","1.2716","0.0000"
"","30.2000","25.1681","0.0132","25.1681","16.7788","1.3209","0.0000"
"","30.4000","25.3351","0.0133","25.3351","16.8901","1.3285","0.0000"
"","30.6000","25.5013","0.0132","25.5013","17.0009","1.3160","0.0000"
"","30.8000","25.6683","0.0134","25.6683","17.1122","1.3367","0.0000"
"","31.0000","25.8349","0.0136","25.8349","17.2233","1.3559","0.0000"
"","31.2000","26.0016","0.0138","26.0016","17.3344","1.3759","0.0000"
"","31.4000","26.1685","0.0142","26.1685","17.4457","1.4160","0.0000"
"","31.6000","26.3342","0.0137","26.3342","17.5561","1.3741","0.0000"
"","31.8000","26.5019","0.0137","26.5019","17.6680","1.3679","0.0000"
"","32.0000","26.6683","0.0135","26.6683","17.7789","1.3511","0.0000"
"","32.2000","26.8349","0.0134","26.8349","17.8899","1.3388","0.0000"
"","32.4000","27.0017","0.0132","27.0017","18.0011","1.3156","0.0000"
"","32.6000","27.1680","0.0133","27.1680","18.1120","1.3259","0.0000"
"","32.8000","27.3352","0.0132","27.3352","18.2234","1.3231","0.0000"
"","33.0000","27.5013","0.0136","27.5013","18.3342","1.3617","0.0000"
"","33.2000","27.6683","0.0143","27.6683","18.4456","1.4251","0.0000"
"","33.4000","27.8348","0.0148","27.8348","18.5565","1.4764","0.0000"
"","33.6000","28.0011","0.0158","28.0011","18.6674","1.5806","0.0000"
"","33.8000","28.1685","0.0162","28.1685","18.7790","1.6152","0.0000"
"","34.0000","28.3349","0.0164","28.3349","18.8899","1.6361","0.0000"
"","34.2000","28.5016","0.0168","28.5016","19.0010","1.6808","0.0000"
"","34.4000","28.6680","0.0170","28.6680","19.1120","1.6999","0.0000"
"","34.6000","28.8352","0.0173","28.8352","19.2235","1.7284","0.0000"
"","34.8000","29.0018","0.0175","29.0018","19.3345","1.7474","0.0000"
"","35.0000","29.1681","0.0174","29.1681","19.4454","1.7387","0.0000"
"","35.2000","29.3350","0.0173","29.3350","19.5567","1.7329","0.0000"
"","35.4000","29.5013","0.0174","29.5013","19.6675","1.7382","0.0000"
"","35.6000","29.6683","0.0173","29.6683","19.7789","1.7278","0.0000"
"","35.8000","29.8351","0.0174","29.8351","19.8901","1.7416","0.0000"
"","36.0000","30.0012","0.0178","30.0012","20.0008","1.7801","0.0000"
"","36.2000","30.1684","0.0183","30.1684","20.1123","1.8297","0.0000"
"","36.4000","30.3346","0.0181","30.3346","20.2231","1.8101","0.0000"
"","36.6000","30.5015","0.0186","30.5015","20.3344","1.8562","0.0000"
"","36.8000","30.6682","0.0186","30.6682","20.4455","1.8585","0.0000"
"","37.0000","30.8348","0.0187","30.8348","20.5565","1.8668","0.0000"
"","37.2000","31.0017","0.0186","31.0017","20.6678","1.8612","0.0000"
"","37.4000","31.1681","0.0184","31.1681","20.7787","1.8448","0.0000"
"","37.6000","31.3349","0.0183","31.3349","20.8899","1.8291","0.0000"
"","37.8000","31.5016","0.0177","31.5016","21.0011","1.7697","0.0000"
"","38.0000","31.6679","0.0173","31.6679","21.1120","1.7332","0.0000"
"","38.2000","31.8351","0.0168","31.8351","21.2234","1.6816","0.0000"
"","38.4000","32.0017","0.0165","32.0017","21.3344","1.6483","0.0000"
"","38.6000","32.1681","0.0163","32.1681","21.4454","1.6338","0.0000"
"","38.8000","32.3348","0.0163","32.3348","21.5566","1.6313","0.0000"
"","39.0000","32.5016","0.0161","32.5016","21.6678","1.6140","0.0000"
"","39.2000","32.6685","0.0165","32.6685","21.7790","1.6486","0.0000"
"","39.4000","32.8347","0.0149","32.8347","21.8898","1.4903","0.0000"
"","39.6000","33.0020","0.0149","33.0020","22.0013","1.4937","0.0000"
"","39.8000","33.1683","0.0154","33.1683","22.1122","1.5357","0.0000"
"","40.0000","33.3349","0.0150","33.3349","22.2232","1.4996","0.0000"
"","40.2000","33.5017","0.0152","33.5017","22.3345","1.5215","0.0000"
"","40.4000","33.6680","0.0157","33.6680","22.4454","1.5656","0.0000"
"","40.6000","33.8350","0.0158","33.8350","22.5566","1.5757","0.0000"
"","40.8000","34.0014","0.0162","34.0014","22.6676","1.6222","0.0000"
"","41.0000","34.1683","0.0161","34.1683","22.7789","1.6131","0.0000"
"","41.2000","34.3349","0.0164","34.3349","22.8899","1.6381","0.0000"
"","41.4000","34.5014","0.0165","34.5014","23.0009","1.6547","0.0000"
"","41.6000","34.6683","0.0169","34.6683","23.1122","1.6912","0.0000"
"","41.8000","34.8343","0.0172","34.8343","23.2229","1.7203","0.0000"
"","42.0000","35.0018","0.0173","35.0018","23.3345","1.7306","0.0000"
"","42.2000","35.1683","0.0170","35.1683","23.4455","1.6964","0.0000"
"","42.4000","35.3346","0.0168","35.3346","23.5564","1.6841","0.0000"
"","42.6000","35.5018","0.0172","35.5018","23.6679","1.7229","0.0000"
"","42.8000","35.6679","0.0174","35.6679","23.7786","1.7403","0.0000"
"","43.0000","35.8349","0.0167","35.8349","23.8900","1.6724","0.0000"
"","43.2000","36.0015","0.0163","36.0015","24.0010","1.6268","0.0000"
"","43.4000","36.1682","0.0167","36.1682","24.1121","1.6677","0.0000"
"","43.6000","36.3349","0.0167","36.3349","24.2233","1.6674","0.0000"
"","43.8000","36.5014","0.0168","36.5014","24.3342","1.6798","0.0000"
"","44.0000","36.6685","0.0166","36.6685","24.4457","1.6619","0.0000"
"","44.2000","36.8347","0.0169","36.8347","24.5565","1.6927","0.0000"
"","44.4000","37.0014","0.0172","37.0014","24.6676","1.7223","0.0000"
"","44.6000","37.1681","0.0174","37.1681","24.7788","1.7353","0.0000"
"","44.8000","37.3351","0.0173","37.3351","24.8900","1.7320","0.0000"
"","45.0000","37.5018","0.0175","37.5018","25.0012","1.7500","0.0000"
"","45.2000","37.6681","0.0176","37.6681","25.1121","1.7582","0.0000"
"","45.4000","37.8349","0.0180","37.8349","25.2233","1.7969","0.0000"
"","45.6000","38.0014","0.0181","38.0014","25.3343","1.8089","0.0000"
"","45.8000","38.1682","0.0183","38.1682","25.4455","1.8253","0.0000"
"","46.0000","38.3351","0.0186","38.3351","25.5567","1.8552","0.0000"
"","46.2000","38.5013","0.0188","38.5013","25.6676","1.8813","0.0000"
"","46.4000","38.6684","0.0192","38.6684","25.7789","1.9151","0.0000"
"","46.6000","38.8348","0.0195","38.8348","25.8899","1.9485","0.0000"
"","46.8000","39.0014","0.0193","39.0014","26.0009","1.9285","0.0000"
"","47.0000","39.1682","0.0194","39.1682","26.1122","1.9370","0.0000"
"","47.2000","39.3345","0.0196","39.3345","26.2230","1.9595","0.0000"
"","47.4000","39.5016","0.0198","39.5016","26.3344","1.9815","0.0000"
"","47.6000","39.6683","0.0201","39.6683","26.4455","2.0051","0.0000"
"","47.8000","39.8350","0.0204","39.8350","26.5567","2.0408","0.0000"
"","48.0000","40.0016","0.0207","40.0016","26.6677","2.0725","0.0000"
"","48.2000","40.1682","0.0206","40.1682","26.7788","2.0581","0.0000"
"","48.4000","40.3350","0.0208","40.3350","26.8900","2.0780","0.0000"
"","48.6000","40.5014","0.0212","40.5014","27.0010","2.1183","0.0000"
"","48.8000","40.6683","0.0217","40.6683","27.1122","2.1673","0.0000"
"","49.0000","40.8348","0.0209","40.8348","27.2232","2.0867","0.0000"
"","49.2000","41.0015","0.0210","41.0015","27.3343","2.1033","0.0000"
"","49.4000","41.1684","0.0220","41.1684","27.4456","2.1984","0.0000"
"","49.6000","41.3347","0.0222","41.3347","27.5564","2.2153","0.0000"
"","49.8000","41.5017","0.0226","41.5017","27.6678","2.2613","0.0000"
"","50.0000","41.6681","0.0237","41.6681","27.7787","2.3750","0.0000"
"","50.2000","41.8348","0.0243","41.8348","27.8898","2.4320","0.0000"
"","50.4000","42.0017","0.0249","42.0017","28.0011","2.4908","0.0000"
"","50.6000","42.1679","0.0252","42.1679","28.1119","2.5236","0.0000"
"","50.8000","42.3351","0.0258","42.3351","28.2234","2.5774","0.0000"
"","51.0000","42.5013","0.0262","42.5013","28.3342","2.6164","0.0000"
"","51.2000","42.6682","0.0263","42.6682","28.4455","2.6341","0.0000"
"","51.4000","42.8349","0.0267","42.8349","28.5566","2.6718","0.0000"
"","51.6000","43.0015","0.0271","43.0015","28.6677","2.7084","0.0000"
"","51.8000","43.1683","0.0276","43.1683","28.7789","2.7617","0.0000"
"","52.0000","43.3348","0.0278","43.3348","28.8898","2.7823","0.0000"
"","52.2000","43.5017","0.0281","43.5017","29.0011","2.8114","0.0000"
"","52.4000","43.6682","0.0287","43.6682","29.1121","2.8655","0.0000"
"","52.6000","43.8349","0.0286","43.8349","29.2232","2.8604","0.0000"
"","52.8000","44.0018","0.0288","44.0018","29.3345","2.8758","0.0000"
"","53.0000","44.1680","0.0288","44.1680","29.4453","2.8787","0.0000"
"","53.2000","44.3348","0.0288","44.3348","29.5565","2.8819","0.0000"
"","53.4000","44.5013","0.0288","44.5013","29.6675","2.8759","0.0000"
"","53.6000","44.6683","0.0292","44.6683","29.7789","2.9226","0.0000"
"","53.8000","44.8349","0.0291","44.8349","29.8899","2.9124","0.0000"
"","54.0000","45.0015","0.0290","45.0015","30.0010","2.9046","0.0000"
"","54.2000","45.1684","0.0290","45.1684","30.1123","2.9006","0.0000"
"","54.4000","45.3344","0.0296","45.3344","30.2229","2.9597","0.0000"
"","54.6000","45.5017","0.0295","45.5017","30.3345","2.9459","0.0000"
"","54.8000","45.6684","0.0293","45.6684","30.4456","2.9298","0.0000"
"","55.0000","45.8351","0.0293","45.8351","30.5567","2.9275","0.0000"
"","55.2000","46.0016","0.0297","46.0016","30.6678","2.9704","0.0000"
"","55.4000","46.1680","0.0305","46.1680","30.7787","3.0481","0.0000"
"","55.6000","46.3349","0.0304","46.3349","30.8899","3.0385","0.0000"
"","55.8000","46.5014","0.0306","46.5014","31.0009","3.0624","0.0000"
"","56.0000","46.6679","0.0312","46.6679","31.1120","3.1197","0.0000"
"","56.2000","46.8352","0.0314","46.8352","31.2235","3.1410","0.0000"
"","56.4000","47.0013","0.0317","47.0013","31.3342","3.1719","0.0000"
"","56.6000","47.1683","0.0320","47.1683","31.4455","3.2044","0.0000"
"","56.8000","47.3347","0.0320","47.3347","31.5565","3.2048","0.0000"
"","57.0000","47.5015","0.0321","47.5015","31.6677","3.2096","0.0000"
"","57.2000","47.6684","0.0322","47.6684","31.7789","3.2199","0.0000"
"","57.4000","47.8346","0.0322","47.8346","31.8897","3.2230","0.0000"
"","57.6000","48.0017","0.0320","48.0017","32.0012","3.1959","0.0000"
"","57.8000","48.1682","0.0323","48.1682","32.1121","3.2341","0.0000"
"","58.0000","48.3349","0.0314","48.3349","32.2233","3.1362","0.0000"
"","58.2000","48.5014","0.0318","48.5014","32.3342","3.1827","0.0000"
"","58.4000","48.6680","0.0319","48.6680","32.4454","3.1938","0.0000"
"","58.6000","48.8351","0.0324","48.8351","32.5567","3.2378","0.0000"
"","58.8000","49.0011","0.0325","49.0011","32.6674","3.2516","0.0000"
"","59.0000","49.1687","0.0321","49.1687","32.7791","3.2134","0.0000"
"","59.2000","49.3348","0.0319","49.3348","32.8899","3.1892","0.0000"
"","59.4000","49.5015","0.0319","49.5015","33.0010","3.1854","0.0000"
"","59.6000","49.6681","0.0321","49.6681","33.1121","3.2105","0.0000"
"","59.8000","49.8347","0.0318","49.8347","33.2231","3.1831","0.0000"
"","60.0000","50.0016","0.0317","50.0016","33.3344","3.1728","0.0000"
"","60.2000","50.1681","0.0319","50.1681","33.4454","3.1857","0.0000"
"","60.4000","50.3348","0.0319","50.3348","33.5565","3.1929","0.0000"
"","60.6000","50.5017","0.0320","50.5017","33.6678","3.2030","0.0000"
"","60.8000","50.6680","0.0320","50.6680","33.7787","3.1951","0.0000"
"","61.0000","50.8352","0.0321","50.8352","33.8901","3.2076","0.0000"
"","61.2000","51.0011","0.0323","51.0011","34.0007","3.2272","0.0000"
"","61.4000","51.1685","0.0315","51.1685","34.1123","3.1473","0.0000"
"","61.6000","51.3349","0.0312","51.3349","34.2233","3.1232","0.0000"
"","61.8000","51.5016","0.0312","51.5016","34.3344","3.1185","0.0000"
"","62.0000","51.6684","0.0310","51.6684","34.4456","3.0957","0.0000"
"","62.2000","51.8345","0.0312","51.8345","34.5564","3.1172","0.0000"
"","62.4000","52.0015","0.0310","52.0015","34.6676","3.0960","0.0000"
"","62.6000","52.1682","0.0313","52.1682","34.7788","3.1314","0.0000"
"","62.8000","52.3349","0.0308","52.3349","34.8899","3.0772","0.0000"
"","63.0000","52.5015","0.0299","52.5015","35.0010","2.9939","0.0000"
"","63.2000","52.6680","0.0300","52.6680","35.1120","3.0030","0.0000"
"","63.4000","52.8348","0.0304","52.8348","35.2232","3.0377","0.0000"
"","63.6000","53.0015","0.0304","53.0015","35.3343","3.0408","0.0000"
"","63.8000","53.1680","0.0302","53.1680","35.4453","3.0157","0.0000"
"","64.0000","53.3350","0.0301","53.3350","35.5567","3.0130","0.0000"
"","64.2000","53.5014","0.0302","53.5014","35.6676","3.0175","0.0000"
"","64.4000","53.6683","0.0302","53.6683","35.7789","3.0194","0.0000"
"","64.6000","53.8346","0.0307","53.8346","35.8898","3.0748","0.0000"
"","64.8000","54.0016","0.0314","54.0016","36.0010","3.1438","0.0000"
"","65.0000","54.1681","0.0332","54.1681","36.1121","3.3170","0.0000"
"","65.2000","54.3347","0.0365","54.3347","36.2231","3.6531","0.0000"
"","65.4000","54.5016","0.0418","54.5016","36.3344","4.1811","0.0000"
"","65.6000","54.6681","0.0479","54.6681","36.4454","4.7923","0.0000"
"","65.8000","54.8350","0.0554","54.8350","36.5567","5.5355","0.0000"
"","66.0000","55.0015","0.0637","55.0015","36.6677","6.3693","0.0000"
"","66.2000","55.1676","0.0717","55.1676","36.7784","7.1706","0.0000"
"","66.4000","55.3349","0.0822","55.3349","36.8899","8.2243","0.0000"
"","66.6000","55.5016","0.0920","55.5016","37.0010","9.2010","0.0000"
"","66.8000","55.6684","0.1023","55.6684","37.1123","10.2266","0.0000"
"","67.0000","55.8344","0.1126","55.8344","37.2229","11.2575","0.0000"
"","67.2000","56.0017","0.1222","56.0017","37.3344","12.2156","0.0000"
"","67.4000","56.1682","0.1311","56.1682","37.4455","13.1148","0.0000"
"","67.6000","56.3347","0.1395","56.3347","37.5565","13.9484","0.0000"
"","67.8000","56.5020","0.1466","56.5020","37.6680","14.6640","0.0000"
"","68.0000","56.6677","0.1528","56.6677","37.7785","15.2777","0.0000"
"","68.2000","56.8349","0.1585","56.8349","37.8899","15.8483","0.0000"
"","68.4000","57.0017","0.1625","57.0017","38.0011","16.2513","0.0000"
"","68.6000","57.1678","0.1655","57.1678","38.1119","16.5536","0.0000"
"","68.8000","57.3350","0.1680","57.3350","38.2233","16.7966","0.0000"
"","69.0000","57.5008","0.1683","57.5008","38.3339","16.8324","0.0000"
"","69.2000","57.6685","0.1671","57.6685","38.4457","16.7098","0.0000"
"","69.4000","57.8348","0.1642","57.8348","38.5566","16.4200","0.0000"
"","69.6000","58.0015","0.1610","58.0015","38.6677","16.1006","0.0000"
"","69.8000","58.1685","0.1577","58.1685","38.7790","15.7703","0.0000"
"","70.0000","58.3349","0.1531","58.3349","38.8899","15.3126","0.0000"
"","70.2000","58.5016","0.1471","58.5016","39.0011","14.7110","0.0000"
"","70.4000","58.6679","0.1340","58.6679","39.1120","13.3999","0.0000"
"","70.6000","58.8351","0.1270","58.8351","39.2234","12.6952","0.0000"
"","70.8000","59.0016","0.1261","59.0016","39.3344","12.6100","0.0000"
"","71.0000","59.1681","0.1282","59.1681","39.4454","12.8230","0.0000"
"","71.2000","59.3350","0.1286","59.3350","39.5566","12.8631","0.0000"
"","71.4000","59.5014","0.1315","59.5014","39.6676","13.1511","0.0000"
"","71.6000","59.6683","0.1380","59.6683","39.7789","13.7984","0.0000"
"","71.8000","59.8347","0.1479","59.8347","39.8898","14.7891","0.0000"
"","72.0000","60.0017","0.1554","60.0017","40.0012","15.5447","0.0000"
"","72.2000","60.1683","0.1638","60.1683","40.1122","16.3828","0.0000"
"","72.4000","60.3345","0.1729","60.3345","40.2230","17.2948","0.0000"
"","72.6000","60.5016","0.1786","60.5016","40.3344","17.8615","0.0000"
"","72.8000","60.6682","0.1867","60.6682","40.4454","18.6729","0.0000"
"","73.0000","60.8350","0.1942","60.8350","40.5566","19.4165","0.0000"
"","73.2000","61.0015","0.1997","61.0015","40.6677","19.9736","0.0000"
"","73.4000","61.1680","0.2060","61.1680","40.7787","20.5968","0.0000"
"","73.6000","61.3349","0.2097","61.3349","40.8900","20.9707","0.0000"
"","73.8000","61.5013","0.2084","61.5013","41.0009","20.8363","0.0000"
"","74.0000","61.6683","0.2115","61.6683","41.1122","21.1480","0.0000"
"","74.2000","61.8349","0.2156","61.8349","41.2233","21.5614","0.0000"
"","74.4000","62.0014","0.2176","62.0014","41.3342","21.7606","0.0000"
"","74.6000","62.1684","0.2209","62.1684","41.4456","22.0929","0.0000"
"","74.8000","62.3349","0.2253","62.3349","41.5566","22.5308","0.0000"
"","75.0000","62.5016","0.2296","62.5016","41.6677","22.9583","0.0000"
"","75.2000","62.6683","0.2358","62.6683","41.7788","23.5804","0.0000"
"","75.4000","62.8348","0.2422","62.8348","41.8899","24.2164","0.0000"
"","75.6000","63.0019","0.2496","63.0019","42.0013","24.9567","0.0000"
"","75.8000","63.1681","0.2558","63.1681","42.1121","25.5828","0.0000"
"","76.0000","63.3350","0.2619","63.3350","42.2234","26.1883","0.0000"
"","76.2000","63.5014","0.2669","63.5014","42.3343","26.6887","0.0000"
"","76.4000","63.6680","0.2727","63.6680","42.4453","27.2748","0.0000"
"","76.6000","63.8349","0.2771","63.8349","42.5566","27.7081","0.0000"
"","76.8000","64.0015","0.2813","64.0015","42.6676","28.1283","0.0000"
"","77.0000","64.1683","0.2853","64.1683","42.7788","28.5348","0.0000"
"","77.2000","64.3346","0.2907","64.3346","42.8897","29.0733","0.0000"
"","77.4000","64.5015","0.2956","64.5015","43.0010","29.5586","0.0000"
"","77.6000","64.6682","0.3012","64.6682","43.1122","30.1187","0.0000"
"","77.8000","64.8347","0.3067","64.8347","43.2231","30.6705","0.0000"
"","78.0000","65.0019","0.3119","65.0019","43.3346","31.1891","0.0000"
"","78.2000","65.1679","0.3175","65.1679","43.4452","31.7525","0.0000"
"","78.4000","65.3349","0.3235","65.3349","43.5566","32.3505","0.0000"
"","78.6000","65.5016","0.3267","65.5016","43.6677","32.6712","0.0000"
"","78.8000","65.6681","0.3309","65.6681","43.7787","33.0880","0.0000"
"","79.0000","65.8349","0.3348","65.8349","43.8899","33.4823","0.0000"
"","79.2000","66.0016","0.3373","66.0016","44.0010","33.7281","0.0000"
"","79.4000","66.1686","0.3440","66.1686","44.1124","34.4050","0.0000"
"","79.6000","66.3347","0.3474","66.3347","44.2231","34.7406","0.0000"
"","79.8000","66.5018","0.3514","66.5018","44.3345","35.1392","0.0000"
"","80.0000","66.6682","0.3572","66.6682","44.4455","35.7159","0.0000"
"","80.2000","66.8347","0.3618","66.8347","44.5564","36.1827","0.0000"
"","80.4000","67.0017","0.3658","67.0017","44.6678","36.5799","0.0000"
"","80.6000","67.1678","0.3704","67.1678","44.7785","37.0408","0.0000"
"","80.8000","67.3350","0.3726","67.3350","44.8900","37.2639","0.0000"
"","81.0000","67.5017","0.3741","67.5017","45.0011","37.4070","0.0000"
"","81.2000","67.6680","0.3751","67.6680","45.1120","37.5117","0.0000"
"","81.4000","67.8348","0.3754","67.8348","45.2232","37.5446","0.0000"
"","81.6000","68.0013","0.3777","68.0013","45.3342","37.7735","0.0000"
"","81.8000","68.1685","0.3805","68.1685","45.4456","38.0515","0.0000"
"","82.0000","68.3349","0.3839","68.3349","45.5566","38.3869","0.0000"
"","82.2000","68.5015","0.3875","68.5015","45.6677","38.7525","0.0000"
"","82.4000","68.6685","0.3897","68.6685","45.7790","38.9667","0.0000"
"","82.6000","68.8347","0.3901","68.8347","45.8898","39.0103","0.0000"
"","82.8000","69.0016","0.3936","69.0016","46.0011","39.3646","0.0000"
"","83.0000","69.1683","0.3939","69.1683","46.1122","39.3873","0.0000"
"","83.2000","69.3345","0.3933","69.3345","46.2230","39.3293","0.0000"
"","83.4000","69.5019","0.3916","69.5019","46.3346","39.1641","0.0000"
"","83.6000","69.6680","0.3896","69.6680","46.4453","38.9604","0.0000"
"","83.8000","69.8353","0.3892","69.8353","46.5569","38.9188","0.0000"
"","84.0000","70.0013","0.3888","70.0013","46.6675","38.8752","0.0000"
"","84.2000","70.1684","0.3897","70.1684","46.7790","38.9721","0.0000"
"","84.4000","70.3350","0.3921","70.3350","46.8900","39.2108","0.0000"
"","84.6000","70.5012","0.3907","70.5012","47.0008","39.0675","0.0000"
"","84.8000","70.6684","0.3954","70.6684","47.1123","39.5379","0.0000"
"","85.0000","70.8347","0.3998","70.8347","47.2232","39.9750","0.0000"
"","85.2000","71.0017","0.4039","71.0017","47.3345","40.3930","0.0000"
"","85.4000","71.1681","0.4073","71.1681","47.4454","40.7320","0.0000"
"","85.6000","71.3347","0.4086","71.3347","47.5565","40.8634","0.0000"
"","85.8000","71.5018","0.4114","71.5018","47.6678","41.1418","0.0000"
"","86.0000","71.6680","0.4159","71.6680","47.7787","41.5909","0.0000"
"","86.2000","71.8350","0.4210","71.8350","47.8900","42.1005","0.0000"
"","86.4000","72.0014","0.4281","72.0014","48.0009","42.8074","0.0000"
"","86.6000","72.1682","0.4329","72.1682","48.1121","43.2943","0.0000"
"","86.8000","72.3351","0.4367","72.3351","48.2234","43.6706","0.0000"
"","87.0000","72.5013","0.4414","72.5013","48.3342","44.1397","0.0000"
"","87.2000","72.6683","0.4456","72.6683","48.4455","44.5642","0.0000"
"","87.4000","72.8346","0.4507","72.8346","48.5564","45.0742","0.0000"
"","87.6000","73.0017","0.4545","73.0017","48.6678","45.4509","0.0000"
"","87.8000","73.1682","0.4563","73.1682","48.7788","45.6339","0.0000"
"","88.0000","73.3348","0.4606","73.3348","48.8899","46.0580","0.0000"
"","88.2000","73.5017","0.4625","73.5017","49.0012","46.2466","0.0000"
"","88.4000","73.6681","0.4650","73.6681","49.1121","46.5036","0.0000"
"","88.6000","73.8349","0.4686","73.8349","49.2233","46.8596","0.0000"
"","88.8000","74.0017","0.4708","74.0017","49.3345","47.0836","0.0000"
"","89.0000","74.1680","0.4726","74.1680","49.4454","47.2564","0.0000"
"","89.2000","74.3349","0.4734","74.3349","49.5566","47.3415","0.0000"
"","89.4000","74.5016","0.4744","74.5016","49.6677","47.4383","0.0000"
"","89.6000","74.6682","0.4778","74.6682","49.7788","47.7752","0.0000"
"","89.8000","74.8348","0.4806","74.8348","49.8899","48.0648","0.0000"
"","90.0000","75.0015","0.4823","75.0015","50.0010","48.2252","0.0000"
"","90.2000","75.1683","0.4836","75.1683","50.1122","48.3551","0.0000"
"","90.4000","75.3345","0.4831","75.3345","50.2230","48.3063","0.0000"
"","90.6000","75.5020","0.4850","75.5020","50.3346","48.4987","0.0000"
"","90.8000","75.6685","0.4880","75.6685","50.4457","48.7953","0.0000"
"","91.0000","75.8348","0.4898","75.8348","50.5565","48.9767","0.0000"
"","91.2000","76.0018","0.4910","76.0018","50.6679","49.0968","0.0000"
"","91.4000","76.1678","0.4924","76.1678","50.7785","49.2350","0.0000"
"","91.6000","76.3351","0.4922","76.3351","50.8901","49.2236","0.0000"
"","91.8000","76.5014","0.4940","76.5014","51.0009","49.3969","0.0000"
"","92.0000","76.6682","0.4922","76.6682","51.1122","49.2238","0.0000"
"","92.2000","76.8348","0.4906","76.8348","51.2232","49.0646","0.0000"
"","92.4000","77.0016","0.4895","77.0016","51.3344","48.9539","0.0000"
"","92.6000","77.1686","0.4892","77.1686","51.4457","48.9242","0.0000"
"","92.8000","77.3344","0.4877","77.3344","51.5563","48.7737","0.0000"
"","93.0000","77.5018","0.4882","77.5018","51.6679","48.8195","0.0000"
"","93.2000","77.6680","0.4870","77.6680","51.7787","48.7020","0.0000"
"","93.4000","77.8344","0.4883","77.8344","51.8896","48.8295","0.0000"
"","93.6000","78.0021","0.4889","78.0021","52.0014","48.8919","0.0000"
"","93.8000","78.1680","0.4884","78.1680","52.1120","48.8378","0.0000"
"","94.0000","78.3349","0.4870","78.3349","52.2233","48.7043","0.0000"
"","94.2000","78.5013","0.4857","78.5013","52.3342","48.5710","0.0000"
"","94.4000","78.6682","0.4871","78.6682","52.4455","48.7138","0.0000"
"","94.6000","78.8350","0.4872","78.8350","52.5567","48.7179","0.0000"
"","94.8000","79.0014","0.4884","79.0013","52.6676","48.8383","0.0000"
"","95.0000","79.1684","0.4910","79.1684","52.7789","49.1019","0.0000"
"","95.2000","79.3347","0.4939","79.3347","52.8898","49.3854","0.0000"
"","95.4000","79.5016","0.4957","79.5016","53.0010","49.5674","0.0000"
"","95.6000","79.6683","0.4993","79.6683","53.1122","49.9259","0.0000"
"","95.8000","79.8350","0.4988","79.8350","53.2233","49.8842","0.0000"
"","96.0000","80.0018","0.4997","80.0018","53.3345","49.9723","0.0000"
"","96.2000","80.1679","0.5001","80.1679","53.4452","50.0073","0.0000"
"","96.4000","80.3352","0.5011","80.3352","53.5568","50.1083","0.0000"
"","96.6000","80.5014","0.5013","80.5014","53.6676","50.1317","0.0000"
"","96.8000","80.6684","0.5021","80.6684","53.7789","50.2122","0.0000"
"","97.0000","80.8350","0.5037","80.8350","53.8900","50.3715","0.0000"
"","97.2000","81.0015","0.5065","81.0015","54.0010","50.6478","0.0000"
"","97.4000","81.1683","0.5069","81.1683","54.1122","50.6864","0.0000"
"","97.6000","81.3347","0.5085","81.3347","54.2232","50.8540","0.0000"
"","97.8000","81.5014","0.5104","81.5014","54.3343","51.0374","0.0000"
"","98.0000","81.6681","0.5131","81.6681","54.4454","51.3128","0.0000"
"","98.2000","81.8345","0.5153","81.8345","54.5563","51.5298","0.0000"
"","98.4000","82.0015","0.5184","82.0015","54.6677","51.8421","0.0000"
"","98.6000","82.1681","0.5185","82.1681","54.7787","51.8515","0.0000"
"","98.8000","82.3349","0.5199","82.3349","54.8899","51.9941","0.0000"
"","99.0000","82.5014","0.5215","82.5014","55.0009","52.1476","0.0000"
"","99.2000","82.6683","0.5237","82.6683","55.1122","52.3731","0.0000"
"","99.4000","82.8351","0.5226","82.8351","55.2234","52.2561","0.0000"
"","99.6000","83.0016","0.5252","83.0016","55.3344","52.5184","0.0000"
"","99.8000","83.1683","0.5267","83.1683","55.4455","52.6724","0.0000"
"","100.0000","83.3347","0.5268","83.3347","55.5565","52.6808","0.0000"
"","100.2000","83.5016","0.5271","83.5016","55.6678","52.7116","0.0000"
"","100.4000","83.6685","0.5305","83.6685","55.7790","53.0504","0.0000"
"","100.6000","83.8346","0.5321","83.8345","55.8897","53.2095","0.0000"
"","100.8000","84.0016","0.5332","84.0016","56.0011","53.3201","0.0000"
"","101.0000","84.1682","0.5356","84.1682","56.1121","53.5561","0.0000"
"","101.2000","84.3349","0.5325","84.3349","56.2232","53.2480","0.0000"
"","101.4000","84.5016","0.5270","84.5016","56.3344","52.6992","0.0000"
"","101.6000","84.6680","0.5279","84.6680","56.4454","52.7896","0.0000"
"","101.8000","84.8351","0.5313","84.8351","56.5567","53.1257","0.0000"
"","102.0000","85.0015","0.5313","85.0015","56.6677","53.1311","0.0000"
"","102.2000","85.1685","0.5349","85.1685","56.7790","53.4945","0.0000"
"","102.4000","85.3348","0.5362","85.3348","56.8899","53.6157","0.0000"
"","102.6000","85.5015","0.5360","85.5015","57.0010","53.6027","0.0000"
"","102.8000","85.6685","0.5385","85.6685","57.1124","53.8507","0.0000"
"","103.0000","85.8348","0.5369","85.8348","57.2232","53.6886","0.0000"
"","103.2000","86.0017","0.5372","86.0017","57.3345","53.7249","0.0000"
"","103.4000","86.1683","0.5365","86.1683","57.4455","53.6453","0.0000"
"","103.6000","86.3346","0.5355","86.3346","57.5564","53.5502","0.0000"
"","103.8000","86.5018","0.5369","86.5018","57.6679","53.6871","0.0000"
"","104.0000","86.6681","0.5361","86.6681","57.7788","53.6077","0.0000"
"","104.2000","86.8349","0.5345","86.8349","57.8900","53.4466","0.0000"
"","104.4000","87.0015","0.5328","87.0015","58.0010","53.2771","0.0000"
"","104.6000","87.1682","0.5350","87.1682","58.1121","53.5000","0.0000"
"","104.8000","87.3348","0.5363","87.3348","58.2232","53.6309","0.0000"
"","105.0000","87.5012","0.5352","87.5012","58.3342","53.5222","0.0000"
"","105.2000","87.6684","0.5348","87.6684","58.4456","53.4836","0.0000"
"","105.4000","87.8346","0.5360","87.8346","58.5564","53.6001","0.0000"
"","105.6000","88.0018","0.5363","88.0018","58.6679","53.6295","0.0000"
"","105.8000","88.1681","0.5356","88.1681","58.7788","53.5566","0.0000"
"","106.0000","88.3348","0.5365","88.3348","58.8899","53.6500","0.0000"
"","106.2000","88.5016","0.5385","88.5016","59.0011","53.8462","0.0000"
"","106.4000","88.6677","0.5405","88.6677","59.1118","54.0464","0.0000"
"","106.6000","88.8353","0.5402","88.8353","59.2235","54.0196","0.0000"
"","106.8000","89.0014","0.5399","89.0014","59.3342","53.9850","0.0000"
"","107.0000","89.1684","0.5400","89.1684","59.4456","53.9994","0.0000"
"","107.2000","89.3349","0.5410","89.3349","59.5566","54.0960","0.0000"
"","107.4000","89.5014","0.5430","89.5014","59.6676","54.3024","0.0000"
"","107.6000","89.6683","0.5432","89.6683","59.7789","54.3163","0.0000"
"","107.8000","89.8347","0.5455","89.8347","59.8898","54.5518","0.0000"
"","108.0000","90.0014","0.5475","90.0014","60.0010","54.7514","0.0000"
"","108.2000","90.1684","0.5482","90.1684","60.1122","54.8185","0.0000"
"","108.4000","90.3346","0.5453","90.3346","60.2231","54.5315","0.0000"
"","108.6000","90.5020","0.5357","90.5020","60.3347","53.5711","0.0000"
"","108.8000","90.6682","0.5326","90.6682","60.4455","53.2595","0.0000"
"","109.0000","90.8348","0.5341","90.8348","60.5565","53.4095","0.0000"
"","109.2000","91.0014","0.5334","91.0014","60.6676","53.3391","0.0000"
"","109.4000","91.1685","0.5354","91.1685","60.7790","53.5395","0.0000"
"","109.6000","91.3351","0.5373","91.3351","60.8901","53.7338","0.0000"
"","109.8000","91.5012","0.5360","91.5012","61.0008","53.6028","0.0000"
"","110.0000","91.6683","0.5391","91.6683","61.1122","53.9120","0.0000"
"","110.2000","91.8346","0.5417","91.8346","61.2231","54.1718","0.0000"
"","110.4000","92.0018","0.5539","92.0018","61.3345","55.3915","0.0000"
"","110.6000","92.1682","0.5738","92.1682","61.4455","57.3787","0.0000"
"","110.8000","92.3347","0.6040","92.3347","61.5564","60.4038","0.0000"
"","111.0000","92.5016","0.6420","92.5016","61.6677","64.2022","0.0000"
"","111.2000","92.6681","0.6860","92.6681","61.7787","68.5981","0.0000"
"","111.4000","92.8348","0.7424","92.8348","61.8898","74.2357","0.0000"
"","111.6000","93.0016","0.8009","93.0016","62.0010","80.0932","0.0000"
"","111.8000","93.1680","0.8673","93.1680","62.1120","86.7348","0.0000"
"","112.0000","93.3350","0.9353","93.3350","62.2233","93.5269","0.0000"
"","112.2000","93.5012","0.9959","93.5012","62.3341","99.5907","0.0000"
"","112.4000","93.6682","1.0616","93.6682","62.4455","106.1618","0.0000"
"","112.6000","93.8349","1.1223","93.8349","62.5566","112.2332","0.0000"
"","112.8000","94.0014","1.1779","94.0014","62.6676","117.7851","0.0000"
"","113.0000","94.1684","1.2372","94.1684","62.7789","123.7241","0.0000"
"","113.2000","94.3346","1.2717","94.3346","62.8898","127.1682","0.0000"
"","113.4000","94.5015","1.3112","94.5015","63.0010","131.1160","0.0000"
"","113.6000","94.6683","1.3631","94.6683","63.1122","136.3118","0.0000"
"","113.8000","94.8347","1.4166","94.8347","63.2232","141.6580","0.0000"
"","114.0000","95.0017","1.4526","95.0017","63.3344","145.2607","0.0000"
"","114.2000","95.1679","1.4828","95.1679","63.4453","148.2811","0.0000"
"","114.4000","95.3348","1.5206","95.3348","63.5565","152.0607","0.0000"
"","114.6000","95.5013","1.5578","95.5013","63.6675","155.7759","0.0000"
"","114.8000","95.6680","1.5991","95.6680","63.7787","159.9066","0.0000"
"","115.0000","95.8349","1.6392","95.8349","63.8899","163.9185","0.0000"
"","115.2000","96.0012","1.6778","96.0012","64.0008","167.7813","0.0000"
"","115.4000","96.1684","1.7156","96.1684","64.1123","171.5627","0.0000"
"","115.6000","96.3346","1.7502","96.3346","64.2231","175.0241","0.0000"
"","115.8000","96.5014","1.7801","96.5014","64.3343","178.0139","0.0000"
"","116.0000","96.6681","1.8086","96.6681","64.4454","180.8557","0.0000"
"","116.2000","96.8344","1.8399","96.8344","64.5562","183.9917","0.0000"
"","116.4000","97.0016","1.8752","97.0016","64.6678","187.5234","0.0000"
"","116.6000","97.1678","1.9154","97.1677","64.7785","191.5391","0.0000"
"","116.8000","97.3350","1.9589","97.3350","64.8900","195.8850","0.0000"
"","117.0000","97.5015","1.9998","97.5015","65.0010","199.9816","0.0000"
"","117.2000","97.6681","2.0397","97.6681","65.1120","203.9696","0.0000"
"","117.4000","97.8349","2.0784","97.8349","65.2233","207.8359","0.0000"
"","117.6000","98.0014","2.1156","98.0014","65.3343","211.5631","0.0000"
"","117.8000","98.1683","2.1547","98.1683","65.4455","215.4741","0.0000"
"","118.0000","98.3345","2.1945","98.3345","65.5563","219.4459","0.0000"
"","118.2000","98.5019","2.2319","98.5019","65.6679","223.1923","0.0000"
"","118.4000","98.6681","2.2660","98.6681","65.7788","226.6038","0.0000"
"","118.6000","98.8345","2.2985","98.8345","65.8896","229.8455","0.0000"
"","118.8000","99.0017","2.3336","99.0017","66.0012","233.3584","0.0000"
"","119.0000","99.1677","2.3720","99.1677","66.1118","237.2049","0.0000"
"","119.2000","99.3348","2.4096","99.3348","66.2232","240.9568","0.0000"
"","119.4000","99.5016","2.4487","99.5016","66.3344","244.8730","0.0000"
"","119.6000","99.6682","2.4878","99.6682","66.4454","248.7765","0.0000"
"","119.8000","99.8351","2.5303","99.8351","66.5567","253.0300","0.0000"
"","120.0000","100.0013","2.5680","100.0013","66.6675","256.8046","0.0000"
"","120.2000","100.1683","2.6033","100.1683","66.7788","260.3277","0.0000"
"","120.4000","100.3348","2.6382","100.3348","66.8899","263.8203","0.0000"
"","120.6000","100.5013","2.6740","100.5013","67.0009","267.3974","0.0000"
"","120.8000","100.6683","2.7101","100.6683","67.1122","271.0136","0.0000"
"","121.0000","100.8349","2.7416","100.8349","67.2233","274.1621","0.0000"
"","121.2000","101.0017","2.7680","101.0017","67.3345","276.8043","0.0000"
"","121.4000","101.1679","2.7927","101.1679","67.4453","279.2744","0.0000"
"","121.6000","101.3350","2.8197","101.3350","67.5567","281.9743","0.0000"
"","121.8000","101.5014","2.8504","101.5014","67.6676","285.0362","0.0000"
"","122.0000","101.6682","2.8832","101.6682","67.7788","288.3228","0.0000"
"","122.2000","101.8348","2.9190","101.8348","67.8899","291.8968","0.0000"
"","122.4000","102.0018","2.9607","102.0018","68.0012","296.0750","0.0000"
"","122.6000","102.1682","3.0090","102.1682","68.1122","300.8975","0.0000"
"","122.8000","102.3348","3.0552","102.3348","68.2232","305.5195","0.0000"
"","123.0000","102.5013","3.1032","102.5013","68.3342","310.3205","0.0000"
"","123.2000","102.6683","3.1541","102.6683","68.4455","315.4091","0.0000"
"","123.4000","102.8347","3.2012","102.8347","68.5564","320.1229","0.0000"
"","123.6000","103.0016","3.2435","103.0016","68.6677","324.3465","0.0000"
"","123.8000","103.1680","3.2779","103.1680","68.7787","327.7901","0.0000"
"","124.0000","103.3352","3.3113","103.3352","68.8901","331.1255","0.0000"
"","124.2000","103.5017","3.3423","103.5017","69.0011","334.2318","0.0000"
"","124.4000","103.6680","3.3715","103.6680","69.1120","337.1470","0.0000"
"","124.6000","103.8349","3.4083","103.8349","69.2233","340.8252","0.0000"
"","124.8000","104.0013","3.4490","104.0013","69.3342","344.8978","0.0000"
"","125.0000","104.1683","3.4908","104.1683","69.4456","349.0789","0.0000"
"","125.2000","104.3348","3.5334","104.3348","69.5565","353.3409","0.0000"
"","125.4000","104.5016","3.5756","104.5016","69.6677","357.5580","0.0000"
"","125.6000","104.6683","3.6141","104.6683","69.7789","361.4106","0.0000"
"","125.8000","104.8345","3.6549","104.8345","69.8897","365.4858","0.0000"
"","126.0000","105.0016","3.6988","105.0016","70.0010","369.8761","0.0000"
"","126.2000","105.1683","3.7421","105.1683","70.1122","374.2127","0.0000"
"","126.4000","105.3348","3.7851","105.3348","70.2232","378.5122","0.0000"
"","126.6000","105.5020","3.8266","105.5020","70.3347","382.6637","0.0000"
"","126.8000","105.6679","3.8674","105.6679","70.4452","386.7438","0.0000"
"","127.0000","105.8352","3.9125","105.8352","70.5568","391.2535","0.0000"
"","127.2000","106.0015","3.9507","106.0015","70.6677","395.0721","0.0000"
"","127.4000","106.1682","3.9884","106.1682","70.7788","398.8384","0.0000"
"","127.6000","106.3346","4.0304","106.3346","70.8898","403.0408","0.0000"
"","127.8000","106.5013","4.0712","106.5014","71.0009","407.1197","0.0000"
"","128.0000","106.6679","4.1155","106.6679","71.1119","411.5524","0.0000"
"","128.2000","106.8347","4.1606","106.8347","71.2232","416.0552","0.0000"
"","128.4000","107.0015","4.2014","107.0015","71.3344","420.1434","0.0000"
"","128.6000","107.1681","4.2442","107.1681","71.4454","424.4242","0.0000"
"","128.8000","107.3346","4.2849","107.3346","71.5564","428.4908","0.0000"
"","129.0000","107.5017","4.3317","107.5017","71.6678","433.1673","0.0000"
"","129.2000","107.6677","4.3771","107.6677","71.7785","437.7147","0.0000"
"","129.4000","107.8349","4.4237","107.8349","71.8899","442.3669","0.0000"
"","129.6000","108.0015","4.4621","108.0015","72.0010","446.2069","0.0000"
"","129.8000","108.1679","4.5051","108.1679","72.1120","450.5081","0.0000"
"","130.0000","108.3347","4.5535","108.3347","72.2232","455.3520","0.0000"
"","130.2000","108.5015","4.6038","108.5015","72.3344","460.3798","0.0000"
"","130.4000","108.6684","4.6567","108.6684","72.4456","465.6662","0.0000"
"","130.6000","108.8347","4.7050","108.8347","72.5565","470.5000","0.0000"
"","130.8000","109.0016","4.7510","109.0016","72.6678","475.0995","0.0000"
"","131.0000","109.1684","4.7993","109.1684","72.7790","479.9273","0.0000"
"","131.2000","109.3348","4.8447","109.3348","72.8899","484.4726","0.0000"
"","131.4000","109.5018","4.8934","109.5018","73.0012","489.3402","0.0000"
"","131.5160","109.5989","4.8207","109.5989","73.0659","482.0683","0.0000"
"","131.6700","109.7266","4.7860","109.7266","73.1511","478.5980","0.0000"
"","131.8700","109.8930","4.8385","109.8930","73.2620","483.8482","0.0000"
"","132.0000","110.0016","4.8750","110.0016","73.3344","487.5005","0.0000"