File: Fig6C/211130_Instron/211130/tensile_curtain_2.is_tens_Exports/tensile_curtain_2_2.csv
Results Table 1


Results Table 2


Time,Displacement,Force,Tensile displacement,Tensile strain (Displacement),Tensile stress
(s),(mm),(kN),(mm),(%),(MPa)
"0.0000","0.0734","0.0004","0.0734","0.1499","0.1575"
"0.0200","0.0756","0.0004","0.0756","0.1542","0.1592"
"0.0400","0.0830","0.0004","0.0830","0.1694","0.1858"
"0.0600","0.0990","0.0005","0.0990","0.2021","0.2196"
"0.0800","0.1210","0.0006","0.1210","0.2470","0.2681"
"0.1000","0.1438","0.0008","0.1438","0.2935","0.3344"
"0.1200","0.1652","0.0010","0.1652","0.3371","0.4086"
"0.1400","0.1851","0.0012","0.1851","0.3778","0.4980"
"0.1600","0.2039","0.0013","0.2039","0.4161","0.5521"
"0.1800","0.2221","0.0015","0.2221","0.4532","0.6150"
"0.2000","0.2394","0.0017","0.2394","0.4886","0.6944"
"0.2200","0.2564","0.0018","0.2564","0.5233","0.7617"
"0.2400","0.2732","0.0019","0.2732","0.5575","0.8081"
"0.2600","0.2901","0.0020","0.2901","0.5920","0.8513"
"0.2800","0.3069","0.0022","0.3069","0.6264","0.9113"
"0.3000","0.3238","0.0023","0.3238","0.6609","0.9717"
"0.3200","0.3405","0.0024","0.3405","0.6948","1.0082"
"0.3400","0.3570","0.0025","0.3570","0.7286","1.0604"
"0.3600","0.3734","0.0027","0.3734","0.7621","1.1116"
"0.3800","0.3898","0.0028","0.3898","0.7955","1.1810"
"0.4000","0.4066","0.0030","0.4066","0.8298","1.2392"
"0.4200","0.4233","0.0031","0.4233","0.8640","1.2835"
"0.4400","0.4402","0.0032","0.4402","0.8984","1.3396"
"0.4600","0.4571","0.0033","0.4571","0.9329","1.3692"
"0.4800","0.4738","0.0034","0.4738","0.9669","1.4210"
"0.5000","0.4903","0.0035","0.4903","1.0006","1.4723"
"0.5200","0.5068","0.0037","0.5068","1.0343","1.5222"
"0.5400","0.5233","0.0038","0.5233","1.0680","1.5663"
"0.5600","0.5402","0.0039","0.5402","1.1025","1.6087"
"0.5800","0.5570","0.0040","0.5570","1.1367","1.6608"
"0.6000","0.5737","0.0041","0.5737","1.1709","1.7016"
"0.6200","0.5905","0.0042","0.5905","1.2051","1.7425"
"0.6400","0.6070","0.0043","0.6070","1.2389","1.7817"
"0.6600","0.6233","0.0044","0.6233","1.2721","1.8141"
"0.6800","0.6399","0.0045","0.6399","1.3058","1.8620"
"0.7000","0.6566","0.0046","0.6566","1.3401","1.9040"
"0.7200","0.6734","0.0046","0.6734","1.3743","1.9338"
"0.7400","0.6900","0.0047","0.6900","1.4082","1.9671"
"0.7600","0.7068","0.0049","0.7068","1.4424","2.0266"
"0.7800","0.7234","0.0050","0.7234","1.4764","2.0674"
"0.8000","0.7399","0.0050","0.7399","1.5099","2.0900"
"0.8200","0.7564","0.0051","0.7564","1.5436","2.1075"
"0.8400","0.7733","0.0051","0.7733","1.5781","2.1458"
"0.8600","0.7901","0.0052","0.7901","1.6125","2.1735"
"0.8800","0.8069","0.0053","0.8069","1.6468","2.2032"
"0.9000","0.8236","0.0054","0.8236","1.6807","2.2481"
"0.9200","0.8403","0.0055","0.8403","1.7149","2.2830"
"0.9400","0.8567","0.0055","0.8567","1.7484","2.3069"
"0.9600","0.8731","0.0056","0.8731","1.7819","2.3378"
"0.9800","0.8900","0.0057","0.8900","1.8164","2.3654"
"1.0000","0.9069","0.0058","0.9069","1.8508","2.3996"
"1.0200","0.9237","0.0058","0.9237","1.8850","2.4280"
"1.0400","0.9401","0.0059","0.9401","1.9185","2.4522"
"1.0600","0.9567","0.0059","0.9567","1.9525","2.4710"
"1.0800","0.9734","0.0060","0.9734","1.9865","2.5001"
"1.1000","0.9897","0.0061","0.9897","2.0197","2.5276"
"1.1200","1.0064","0.0061","1.0064","2.0539","2.5390"
"1.1400","1.0234","0.0061","1.0234","2.0886","2.5405"
"1.1600","1.0401","0.0062","1.0401","2.1226","2.5706"
"1.1800","1.0567","0.0063","1.0567","2.1566","2.6103"
"1.2000","1.0734","0.0063","1.0734","2.1905","2.6431"
"1.2200","1.0901","0.0064","1.0901","2.2247","2.6736"
"1.2400","1.1065","0.0065","1.1065","2.2582","2.7088"
"1.2600","1.1231","0.0065","1.1231","2.2920","2.7196"
"1.2800","1.1399","0.0066","1.1399","2.3264","2.7390"
"1.3000","1.1571","0.0066","1.1571","2.3614","2.7666"
"1.3200","1.1738","0.0067","1.1738","2.3956","2.7931"
"1.3400","1.1902","0.0068","1.1902","2.4291","2.8195"
"1.3600","1.2069","0.0068","1.2069","2.4630","2.8348"
"1.3800","1.2234","0.0069","1.2234","2.4968","2.8607"
"1.4000","1.2399","0.0069","1.2399","2.5305","2.8722"
"1.4200","1.2566","0.0069","1.2566","2.5645","2.8870"
"1.4400","1.2736","0.0070","1.2736","2.5991","2.9134"
"1.4600","1.2902","0.0070","1.2902","2.6331","2.9354"
"1.4800","1.3068","0.0071","1.3068","2.6669","2.9653"
"1.5000","1.3232","0.0071","1.3232","2.7003","2.9781"
"1.5200","1.3398","0.0072","1.3398","2.7343","2.9867"
"1.5400","1.3566","0.0073","1.3566","2.7685","3.0451"
"1.5600","1.3733","0.0074","1.3733","2.8027","3.0699"
"1.5800","1.3902","0.0073","1.3902","2.8372","3.0513"
"1.6000","1.4071","0.0074","1.4071","2.8716","3.0755"
"1.6200","1.4237","0.0075","1.4237","2.9056","3.1049"
"1.6400","1.4402","0.0075","1.4402","2.9391","3.1147"
"1.6600","1.4567","0.0075","1.4567","2.9728","3.1163"
"1.6800","1.4735","0.0075","1.4735","3.0070","3.1316"
"1.7000","1.4900","0.0075","1.4900","3.0408","3.1457"
"1.7200","1.5067","0.0076","1.5067","3.0750","3.1586"
"1.7400","1.5235","0.0076","1.5235","3.1092","3.1794"
"1.7600","1.5403","0.0076","1.5403","3.1434","3.1756"
"1.7800","1.5567","0.0077","1.5567","3.1769","3.2050"
"1.8000","1.5731","0.0078","1.5731","3.2104","3.2458"
"1.8200","1.5899","0.0078","1.5899","3.2446","3.2628"
"1.8400","1.6067","0.0079","1.6067","3.2791","3.2732"
"1.8600","1.6234","0.0079","1.6234","3.3130","3.2968"
"1.8800","1.6403","0.0080","1.6403","3.3475","3.3228"
"1.9000","1.6571","0.0080","1.6571","3.3819","3.3485"
"1.9200","1.6736","0.0081","1.6736","3.4154","3.3611"
"1.9400","1.6897","0.0081","1.6897","3.4484","3.3892"
"1.9600","1.7065","0.0082","1.7065","3.4826","3.4005"
"1.9800","1.7235","0.0082","1.7235","3.5173","3.4119"
"2.0000","1.7401","0.0082","1.7401","3.5513","3.4203"
"2.0200","1.7567","0.0083","1.7567","3.5850","3.4483"
"2.0400","1.7735","0.0083","1.7735","3.6195","3.4660"
"2.0600","1.7901","0.0083","1.7901","3.6532","3.4753"
"2.0800","1.8064","0.0084","1.8064","3.6865","3.4960"
"2.1000","1.8229","0.0085","1.8229","3.7202","3.5233"
"2.1200","1.8400","0.0085","1.8400","3.7551","3.5284"
"2.1400","1.8568","0.0085","1.8568","3.7893","3.5389"
"2.1600","1.8733","0.0085","1.8733","3.8231","3.5467"
"2.1800","1.8901","0.0085","1.8901","3.8573","3.5620"
"2.2000","1.9068","0.0086","1.9068","3.8915","3.5899"
"2.2200","1.9232","0.0087","1.9232","3.9250","3.6203"
"2.2400","1.9397","0.0087","1.9397","3.9585","3.6328"
"2.2600","1.9567","0.0087","1.9567","3.9932","3.6402"
"2.2800","1.9735","0.0088","1.9735","4.0276","3.6756"
"2.3000","1.9901","0.0089","1.9901","4.0614","3.6904"
"2.3200","2.0066","0.0089","2.0066","4.0951","3.6988"
"2.3400","2.0234","0.0089","2.0234","4.1293","3.7148"
"2.3600","2.0400","0.0089","2.0400","4.1633","3.7167"
"2.3800","2.0564","0.0090","2.0564","4.1968","3.7449"
"2.4000","2.0733","0.0090","2.0733","4.2312","3.7696"
"2.4200","2.0903","0.0091","2.0903","4.2659","3.7854"
"2.4400","2.1069","0.0091","2.1069","4.2999","3.7963"
"2.4600","2.1235","0.0091","2.1235","4.3336","3.8048"
"2.4800","2.1401","0.0092","2.1401","4.3676","3.8188"
"2.5000","2.1569","0.0092","2.1569","4.4018","3.8334"
"2.5200","2.1733","0.0092","2.1733","4.4353","3.8520"
"2.5400","2.1900","0.0093","2.1900","4.4695","3.8796"
"2.5600","2.2068","0.0094","2.2068","4.5037","3.9068"
"2.5800","2.2236","0.0094","2.2236","4.5379","3.9276"
"2.6000","2.2401","0.0095","2.2401","4.5716","3.9496"
"2.6200","2.2567","0.0095","2.2567","4.6056","3.9737"
"2.6400","2.2734","0.0096","2.2734","4.6396","3.9934"
"2.6600","2.2900","0.0096","2.2900","4.6736","4.0052"
"2.6800","2.3066","0.0097","2.3066","4.7073","4.0308"
"2.7000","2.3233","0.0097","2.3233","4.7415","4.0328"
"2.7200","2.3405","0.0097","2.3405","4.7764","4.0444"
"2.7400","2.3570","0.0097","2.3570","4.8102","4.0569"
"2.7600","2.3734","0.0098","2.3734","4.8437","4.0832"
"2.7800","2.3899","0.0099","2.3899","4.8774","4.1148"
"2.8000","2.4066","0.0099","2.4066","4.9114","4.1423"
"2.8200","2.4232","0.0100","2.4232","4.9453","4.1617"
"2.8400","2.4397","0.0100","2.4397","4.9791","4.1830"
"2.8600","2.4567","0.0101","2.4567","5.0137","4.1956"
"2.8800","2.4735","0.0101","2.4735","5.0480","4.2284"
"2.9000","2.4901","0.0102","2.4901","5.0819","4.2672"
"2.9200","2.5066","0.0103","2.5066","5.1154","4.2786"
"2.9400","2.5231","0.0103","2.5231","5.1491","4.2947"
"2.9600","2.5397","0.0103","2.5397","5.1831","4.3000"
"2.9800","2.5565","0.0104","2.5565","5.2173","4.3257"
"3.0000","2.5735","0.0104","2.5735","5.2520","4.3455"
"3.0200","2.5905","0.0105","2.5905","5.2867","4.3670"
"3.0400","2.6071","0.0106","2.6071","5.3207","4.4005"
"3.0600","2.6235","0.0106","2.6235","5.3542","4.4141"
"3.0800","2.6401","0.0106","2.6401","5.3879","4.4246"
"3.1000","2.6570","0.0106","2.6570","5.4224","4.4268"
"3.1200","2.6735","0.0106","2.6735","5.4561","4.4189"
"3.1400","2.6900","0.0107","2.6900","5.4898","4.4657"
"3.1600","2.7069","0.0108","2.7069","5.5243","4.5015"
"3.1800","2.7238","0.0109","2.7238","5.5587","4.5390"
"3.2000","2.7400","0.0109","2.7400","5.5917","4.5621"
"3.2200","2.7562","0.0110","2.7562","5.6250","4.5639"
"3.2400","2.7732","0.0110","2.7732","5.6597","4.5801"
"3.2600","2.7901","0.0110","2.7901","5.6941","4.6016"
"3.2800","2.8069","0.0111","2.8069","5.7283","4.6374"
"3.3000","2.8235","0.0112","2.8235","5.7623","4.6719"
"3.3200","2.8403","0.0113","2.8403","5.7965","4.6915"
"3.3400","2.8568","0.0113","2.8568","5.8303","4.7058"
"3.3600","2.8729","0.0113","2.8729","5.8630","4.7223"
"3.3800","2.8896","0.0114","2.8896","5.8972","4.7489"
"3.4000","2.9066","0.0114","2.9066","5.9319","4.7600"
"3.4200","2.9234","0.0115","2.9234","5.9661","4.7796"
"3.4400","2.9401","0.0115","2.9401","6.0001","4.8061"
"3.4600","2.9571","0.0116","2.9571","6.0348","4.8287"
"3.4800","2.9737","0.0117","2.9737","6.0688","4.8591"
"3.5000","2.9899","0.0117","2.9899","6.1018","4.8958"
"3.5200","3.0064","0.0118","3.0064","6.1355","4.9334"
"3.5400","3.0234","0.0119","3.0234","6.1702","4.9632"
"3.5600","3.0400","0.0119","3.0400","6.2042","4.9657"
"3.5800","3.0566","0.0119","3.0566","6.2379","4.9788"
"3.6000","3.0732","0.0120","3.0732","6.2719","4.9963"
"3.6200","3.0901","0.0120","3.0901","6.3063","5.0162"
"3.6400","3.1066","0.0121","3.1066","6.3401","5.0524"
"3.6600","3.1230","0.0122","3.1230","6.3736","5.0684"
"3.6800","3.1402","0.0122","3.1402","6.4085","5.0832"
"3.7000","3.1570","0.0123","3.1570","6.4429","5.1213"
"3.7200","3.1736","0.0123","3.1736","6.4767","5.1436"
"3.7400","3.1901","0.0124","3.1901","6.5104","5.1727"
"3.7600","3.2070","0.0125","3.2070","6.5449","5.1944"
"3.7800","3.2236","0.0125","3.2236","6.5788","5.2182"
"3.8000","3.2399","0.0126","3.2399","6.6121","5.2377"
"3.8200","3.2567","0.0126","3.2567","6.6463","5.2650"
"3.8400","3.2737","0.0127","3.2737","6.6810","5.2971"
"3.8600","3.2904","0.0128","3.2904","6.7152","5.3189"
"3.8800","3.3069","0.0128","3.3069","6.7487","5.3425"
"3.9000","3.3235","0.0129","3.3235","6.7827","5.3778"
"3.9200","3.3403","0.0130","3.3403","6.8169","5.4016"
"3.9400","3.3567","0.0130","3.3567","6.8504","5.4112"
"3.9600","3.3732","0.0130","3.3732","6.8841","5.4250"
"3.9800","3.3901","0.0131","3.3901","6.9185","5.4654"
"4.0000","3.4070","0.0132","3.4070","6.9530","5.5079"
"4.0200","3.4235","0.0133","3.4235","6.9867","5.5334"
"4.0400","3.4400","0.0133","3.4400","7.0204","5.5574"
"4.0600","3.4568","0.0134","3.4568","7.0547","5.5663"
"4.0800","3.4733","0.0134","3.4733","7.0884","5.6019"
"4.1000","3.4900","0.0135","3.4900","7.1224","5.6418"
"4.1200","3.5066","0.0136","3.5066","7.1563","5.6691"
"4.1400","3.5236","0.0137","3.5236","7.1910","5.7014"
"4.1600","3.5404","0.0137","3.5404","7.2252","5.7098"
"4.1800","3.5567","0.0138","3.5567","7.2585","5.7379"
"4.2000","3.5733","0.0138","3.5733","7.2925","5.7613"
"4.2200","3.5900","0.0139","3.5900","7.3264","5.7840"
"4.2400","3.6066","0.0140","3.6066","7.3604","5.8134"
"4.2600","3.6232","0.0140","3.6232","7.3944","5.8299"
"4.2800","3.6401","0.0140","3.6401","7.4288","5.8470"
"4.3000","3.6571","0.0141","3.6571","7.4635","5.8913"
"4.3200","3.6734","0.0142","3.6734","7.4968","5.9250"
"4.3400","3.6897","0.0143","3.6897","7.5300","5.9673"
"4.3600","3.7065","0.0144","3.7065","7.5642","5.9859"
"4.3800","3.7235","0.0144","3.7235","7.5989","6.0165"
"4.4000","3.7401","0.0145","3.7401","7.6329","6.0493"
"4.4200","3.7569","0.0146","3.7569","7.6671","6.0823"
"4.4400","3.7738","0.0146","3.7738","7.7016","6.0974"
"4.4600","3.7904","0.0147","3.7904","7.7355","6.1162"
"4.4800","3.8067","0.0147","3.8067","7.7688","6.1398"
"4.5000","3.8232","0.0148","3.8232","7.8025","6.1698"
"4.5200","3.8401","0.0148","3.8401","7.8370","6.1867"
"4.5400","3.8569","0.0150","3.8569","7.8712","6.2295"
"4.5600","3.8734","0.0150","3.8734","7.9049","6.2629"
"4.5800","3.8902","0.0151","3.8902","7.9391","6.2902"
"4.6000","3.9069","0.0152","3.9069","7.9733","6.3184"
"4.6200","3.9233","0.0152","3.9233","8.0068","6.3333"
"4.6400","3.9397","0.0153","3.9397","8.0403","6.3685"
"4.6600","3.9566","0.0154","3.9566","8.0748","6.4051"
"4.6800","3.9736","0.0155","3.9736","8.1095","6.4459"
"4.7000","3.9900","0.0155","3.9900","8.1429","6.4478"
"4.7200","4.0067","0.0155","4.0067","8.1769","6.4754"
"4.7400","4.0237","0.0156","4.0237","8.2116","6.4973"
"4.7600","4.0402","0.0157","4.0402","8.2453","6.5226"
"4.7800","4.0564","0.0158","4.0564","8.2783","6.5658"
"4.8000","4.0732","0.0159","4.0732","8.3126","6.6079"
"4.8200","4.0902","0.0159","4.0902","8.3472","6.6420"
"4.8400","4.1069","0.0160","4.1069","8.3815","6.6625"
"4.8600","4.1234","0.0160","4.1234","8.4152","6.6549"
"4.8800","4.1402","0.0160","4.1402","8.4494","6.6810"
"4.9000","4.1569","0.0161","4.1569","8.4834","6.7100"
"4.9200","4.1733","0.0162","4.1733","8.5169","6.7356"
"4.9400","4.1898","0.0161","4.1898","8.5506","6.7160"
"4.9600","4.2067","0.0158","4.2067","8.5850","6.5915"
"4.9800","4.2236","0.0157","4.2236","8.6195","6.5402"
"5.0000","4.2401","0.0157","4.2401","8.6532","6.5556"
"5.0200","4.2566","0.0158","4.2566","8.6870","6.5871"
"5.0400","4.2735","0.0159","4.2735","8.7214","6.6312"
"5.0600","4.2900","0.0160","4.2900","8.7551","6.6464"
"5.0800","4.3065","0.0160","4.3065","8.7889","6.6813"
"5.1000","4.3232","0.0161","4.3232","8.8228","6.7251"
"5.1200","4.3403","0.0161","4.3403","8.8578","6.7263"
"5.1400","4.3571","0.0162","4.3571","8.8920","6.7521"
"5.1600","4.3735","0.0163","4.3735","8.9255","6.7888"
"5.1800","4.3901","0.0164","4.3901","8.9595","6.8297"
"5.2000","4.4067","0.0165","4.4067","8.9932","6.8730"
"5.2200","4.4232","0.0166","4.4232","9.0269","6.9104"
"5.2400","4.4398","0.0166","4.4398","9.0609","6.9325"
"5.2600","4.4568","0.0167","4.4568","9.0956","6.9471"
"5.2800","4.4738","0.0167","4.4738","9.1303","6.9720"
"5.3000","4.4902","0.0168","4.4902","9.1638","7.0133"
"5.3200","4.5068","0.0170","4.5068","9.1975","7.0686"
"5.3400","4.5234","0.0171","4.5234","9.2315","7.1057"
"5.3600","4.5398","0.0171","4.5398","9.2649","7.1160"
"5.3800","4.5566","0.0171","4.5566","9.2992","7.1422"
"5.4000","4.5735","0.0172","4.5735","9.3336","7.1803"
"5.4200","4.5904","0.0173","4.5904","9.3681","7.2030"
"5.4400","4.6069","0.0174","4.6069","9.4018","7.2334"
"5.4600","4.6234","0.0174","4.6234","9.4355","7.2610"
"5.4800","4.6399","0.0175","4.6399","9.4693","7.3047"
"5.5000","4.6568","0.0176","4.6568","9.5037","7.3335"
"5.5200","4.6736","0.0177","4.6736","9.5379","7.3634"
"5.5400","4.6901","0.0178","4.6901","9.5717","7.4043"
"5.5600","4.7071","0.0178","4.7071","9.6063","7.4224"
"5.5800","4.7238","0.0179","4.7238","9.6403","7.4506"
"5.6000","4.7402","0.0180","4.7402","9.6738","7.4949"
"5.6200","4.7566","0.0181","4.7566","9.7073","7.5365"
"5.6400","4.7733","0.0182","4.7733","9.7415","7.5844"
"5.6600","4.7901","0.0182","4.7901","9.7757","7.5926"
"5.6800","4.8066","0.0183","4.8066","9.8095","7.6079"
"5.7000","4.8233","0.0183","4.8233","9.8434","7.6326"
"5.7200","4.8399","0.0184","4.8399","9.8774","7.6723"
"5.7400","4.8565","0.0185","4.8565","9.9111","7.7082"
"5.7600","4.8726","0.0186","4.8726","9.9441","7.7370"
"5.7800","4.8894","0.0186","4.8894","9.9783","7.7610"
"5.8000","4.9066","0.0187","4.9066","10.0135","7.7877"
"5.8200","4.9234","0.0188","4.9234","10.0477","7.8261"
"5.8400","4.9400","0.0189","4.9400","10.0817","7.8704"
"5.8600","4.9572","0.0190","4.9572","10.1166","7.9016"
"5.8800","4.9739","0.0190","4.9739","10.1508","7.9267"
"5.9000","4.9902","0.0190","4.9902","10.1841","7.9354"
"5.9200","5.0066","0.0191","5.0066","10.2176","7.9651"
"5.9400","5.0235","0.0192","5.0235","10.2520","8.0066"
"5.9600","5.0403","0.0193","5.0403","10.2863","8.0361"
"5.9800","5.0569","0.0194","5.0569","10.3202","8.0737"
"6.0000","5.0736","0.0195","5.0736","10.3542","8.1134"
"6.0200","5.0904","0.0196","5.0904","10.3886","8.1468"
"6.0400","5.1067","0.0197","5.1067","10.4219","8.1886"
"6.0600","5.1231","0.0197","5.1231","10.4554","8.2145"
"6.0800","5.1400","0.0198","5.1400","10.4898","8.2410"
"6.1000","5.1569","0.0198","5.1569","10.5243","8.2634"
"6.1200","5.1735","0.0199","5.1735","10.5583","8.2860"
"6.1400","5.1901","0.0199","5.1901","10.5920","8.2887"
"6.1600","5.2070","0.0199","5.2070","10.6264","8.2747"
"6.1800","5.2235","0.0199","5.2235","10.6602","8.2874"
"6.2000","5.2397","0.0200","5.2397","10.6932","8.3157"
"6.2200","5.2563","0.0200","5.2563","10.7272","8.3374"
"6.2400","5.2734","0.0201","5.2734","10.7621","8.3680"
"6.2600","5.2902","0.0202","5.2902","10.7963","8.4021"
"6.2800","5.3068","0.0202","5.3068","10.8303","8.4269"
"6.3000","5.3236","0.0203","5.3236","10.8645","8.4414"
"6.3200","5.3405","0.0203","5.3405","10.8989","8.4789"
"6.3400","5.3567","0.0205","5.3567","10.9319","8.5267"
"6.3600","5.3731","0.0205","5.3731","10.9654","8.5596"
"6.3800","5.3899","0.0206","5.3899","10.9999","8.6033"
"6.4000","5.4069","0.0207","5.4069","11.0346","8.6358"
"6.4200","5.4236","0.0208","5.4236","11.0686","8.6612"
"6.4400","5.4402","0.0209","5.4402","11.1025","8.7024"
"6.4600","5.4568","0.0210","5.4568","11.1363","8.7371"
"6.4800","5.4732","0.0211","5.4732","11.1697","8.7804"
"6.5000","5.4896","0.0212","5.4896","11.2032","8.8181"
"6.5200","5.5062","0.0212","5.5062","11.2372","8.8412"
"6.5400","5.5233","0.0213","5.5233","11.2721","8.8750"
"6.5600","5.5405","0.0214","5.5405","11.3071","8.9054"
"6.5800","5.5569","0.0215","5.5569","11.3406","8.9405"
"6.6000","5.5733","0.0216","5.5733","11.3740","8.9801"
"6.6200","5.5900","0.0216","5.5900","11.4083","9.0028"
"6.6400","5.6067","0.0217","5.6067","11.4422","9.0429"
"6.6600","5.6233","0.0218","5.6233","11.4762","9.0832"
"6.6800","5.6401","0.0218","5.6401","11.5104","9.1008"
"6.7000","5.6572","0.0219","5.6572","11.5453","9.1287"
"6.7200","5.6739","0.0220","5.6739","11.5793","9.1703"
"6.7400","5.6902","0.0221","5.6902","11.6126","9.2070"
"6.7600","5.7066","0.0222","5.7066","11.6461","9.2355"
"6.7800","5.7233","0.0222","5.7233","11.6803","9.2598"
"6.8000","5.7399","0.0223","5.7399","11.7140","9.2962"
"6.8200","5.7566","0.0224","5.7566","11.7482","9.3346"
"6.8400","5.7736","0.0225","5.7736","11.7829","9.3674"
"6.8600","5.7904","0.0225","5.7904","11.8171","9.3951"
"6.8800","5.8066","0.0226","5.8066","11.8501","9.4254"
"6.9000","5.8231","0.0227","5.8231","11.8839","9.4558"
"6.9200","5.8399","0.0227","5.8399","11.9181","9.4737"
"6.9400","5.8566","0.0228","5.8566","11.9523","9.4937"
"6.9600","5.8733","0.0228","5.8733","11.9862","9.5115"
"6.9800","5.8903","0.0229","5.8903","12.0209","9.5330"
"7.0000","5.9071","0.0230","5.9071","12.0554","9.5744"
"7.0200","5.9236","0.0231","5.9236","12.0889","9.6123"
"7.0400","5.9398","0.0231","5.9398","12.1221","9.6362"
"7.0600","5.9565","0.0232","5.9565","12.1561","9.6499"
"7.0800","5.9735","0.0232","5.9735","12.1908","9.6810"
"7.1000","5.9901","0.0233","5.9901","12.2248","9.7170"
"7.1200","6.0067","0.0234","6.0067","12.2585","9.7353"
"7.1400","6.0235","0.0235","6.0235","12.2930","9.7740"
"7.1600","6.0403","0.0235","6.0403","12.3272","9.8107"
"7.1800","6.0565","0.0236","6.0565","12.3602","9.8510"
"7.2000","6.0729","0.0237","6.0729","12.3937","9.8845"
"7.2200","6.0900","0.0238","6.0900","12.4286","9.9140"
"7.2400","6.1068","0.0239","6.1068","12.4628","9.9443"
"7.2600","6.1234","0.0239","6.1234","12.4968","9.9617"
"7.2800","6.1403","0.0240","6.1403","12.5312","9.9881"
"7.3000","6.1571","0.0240","6.1571","12.5654","10.0203"
"7.3200","6.1735","0.0241","6.1735","12.5989","10.0450"
"7.3400","6.1898","0.0242","6.1898","12.6322","10.0783"
"7.3600","6.2065","0.0243","6.2065","12.6664","10.1138"
"7.3800","6.2237","0.0244","6.2237","12.7013","10.1570"
"7.4000","6.2402","0.0245","6.2402","12.7351","10.2004"
"7.4200","6.2569","0.0246","6.2569","12.7693","10.2386"
"7.4400","6.2737","0.0247","6.2737","12.8035","10.2971"
"7.4600","6.2901","0.0248","6.2901","12.8370","10.3233"
"7.4800","6.3065","0.0249","6.3065","12.8705","10.3707"
"7.5000","6.3232","0.0249","6.3232","12.9044","10.3923"
"7.5200","6.3403","0.0250","6.3403","12.9394","10.4255"
"7.5400","6.3571","0.0251","6.3571","12.9736","10.4569"
"7.5600","6.3735","0.0252","6.3735","13.0071","10.4947"
"7.5800","6.3901","0.0253","6.3901","13.0410","10.5328"
"7.6000","6.4066","0.0254","6.4066","13.0748","10.5750"
"7.6200","6.4232","0.0255","6.4232","13.1085","10.6065"
"7.6400","6.4397","0.0255","6.4397","13.1422","10.6313"
"7.6600","6.4568","0.0255","6.4568","13.1772","10.6411"
"7.6800","6.4737","0.0256","6.4737","13.2116","10.6715"
"7.7000","6.4903","0.0257","6.4903","13.2456","10.7104"
"7.7200","6.5067","0.0258","6.5067","13.2791","10.7446"
"7.7400","6.5234","0.0259","6.5234","13.3131","10.7890"
"7.7600","6.5399","0.0259","6.5399","13.3468","10.8106"
"7.7800","6.5565","0.0260","6.5565","13.3805","10.8464"
"7.8000","6.5731","0.0261","6.5731","13.4145","10.8884"
"7.8200","6.5901","0.0261","6.5901","13.4492","10.8885"
"7.8400","6.6070","0.0262","6.6070","13.4836","10.9181"
"7.8600","6.6234","0.0262","6.6234","13.5171","10.9361"
"7.8800","6.6398","0.0263","6.6398","13.5506","10.9726"
"7.9000","6.6566","0.0263","6.6566","13.5848","10.9695"
"7.9200","6.6732","0.0264","6.6732","13.6188","10.9853"
"7.9400","6.6900","0.0265","6.6900","13.6530","11.0247"
"7.9600","6.7070","0.0265","6.7070","13.6877","11.0562"
"7.9800","6.7239","0.0266","6.7239","13.7221","11.0901"
"8.0000","6.7404","0.0267","6.7404","13.7559","11.1242"
"8.0200","6.7566","0.0267","6.7566","13.7889","11.1438"
"8.0400","6.7730","0.0268","6.7730","13.8224","11.1719"
"8.0600","6.7896","0.0269","6.7896","13.8563","11.2067"
"8.0800","6.8063","0.0270","6.8063","13.8903","11.2429"
"8.1000","6.8231","0.0270","6.8231","13.9248","11.2666"
"8.1200","6.8403","0.0271","6.8403","13.9597","11.2947"
"8.1400","6.8568","0.0272","6.8568","13.9934","11.3390"
"8.1600","6.8733","0.0273","6.8733","14.0272","11.3716"
"8.1800","6.8897","0.0274","6.8897","14.0607","11.4100"
"8.2000","6.9067","0.0275","6.9067","14.0953","11.4422"
"8.2200","6.9234","0.0275","6.9234","14.1293","11.4661"
"8.2400","6.9400","0.0277","6.9400","14.1633","11.5280"
"8.2600","6.9569","0.0277","6.9569","14.1977","11.5546"
"8.2800","6.9738","0.0278","6.9738","14.2322","11.5927"
"8.3000","6.9901","0.0278","6.9901","14.2654","11.5914"
"8.3200","7.0065","0.0279","7.0065","14.2989","11.6237"
"8.3400","7.0234","0.0280","7.0234","14.3334","11.6586"
"8.3600","7.0400","0.0281","7.0400","14.3674","11.6961"
"8.3800","7.0567","0.0282","7.0567","14.4013","11.7385"
"8.4000","7.0734","0.0283","7.0734","14.4355","11.7821"
"8.4200","7.0903","0.0284","7.0903","14.4700","11.8136"
"8.4400","7.1067","0.0284","7.1067","14.5035","11.8371"
"8.4600","7.1229","0.0284","7.1229","14.5365","11.8492"
"8.4800","7.1396","0.0285","7.1396","14.5707","11.8887"
"8.5000","7.1566","0.0286","7.1566","14.6054","11.9236"
"8.5200","7.1733","0.0287","7.1733","14.6394","11.9460"
"8.5400","7.1898","0.0288","7.1898","14.6731","11.9828"
"8.5600","7.2067","0.0288","7.2067","14.7076","12.0060"
"8.5800","7.2233","0.0289","7.2233","14.7415","12.0264"
"8.6000","7.2394","0.0289","7.2394","14.7743","12.0436"
"8.6200","7.2560","0.0289","7.2560","14.8083","12.0533"
"8.6400","7.2732","0.0289","7.2732","14.8432","12.0598"
"8.6600","7.2902","0.0289","7.2902","14.8779","12.0526"
"8.6800","7.3070","0.0290","7.3070","14.9123","12.0711"
"8.7000","7.3240","0.0290","7.3240","14.9470","12.0953"
"8.7200","7.3408","0.0291","7.3408","14.9812","12.1117"
"8.7400","7.3570","0.0292","7.3570","15.0143","12.1501"
"8.7600","7.3733","0.0292","7.3733","15.0475","12.1780"
"8.7800","7.3902","0.0293","7.3902","15.0820","12.2104"
"8.8000","7.4072","0.0294","7.4072","15.1167","12.2371"
"8.8200","7.4237","0.0294","7.4237","15.1504","12.2675"
"8.8400","7.4402","0.0295","7.4402","15.1841","12.2953"
"8.8600","7.4569","0.0295","7.4569","15.2181","12.3087"
"8.8800","7.4733","0.0296","7.4733","15.2516","12.3332"
"8.9000","7.4898","0.0297","7.4898","15.2853","12.3569"
"8.9200","7.5066","0.0297","7.5066","15.3195","12.3907"
"8.9400","7.5236","0.0298","7.5236","15.3542","12.4325"
"8.9600","7.5403","0.0299","7.5403","15.3884","12.4545"
"8.9800","7.5569","0.0300","7.5569","15.4221","12.4887"
"9.0000","7.5734","0.0301","7.5734","15.4559","12.5210"
"9.0200","7.5901","0.0301","7.5901","15.4901","12.5592"
"9.0400","7.6067","0.0302","7.6067","15.5238","12.6018"
"9.0600","7.6232","0.0303","7.6232","15.5576","12.6327"
"9.0800","7.6402","0.0304","7.6402","15.5922","12.6574"
"9.1000","7.6572","0.0304","7.6572","15.6269","12.6659"
"9.1200","7.6737","0.0305","7.6737","15.6607","12.6963"
"9.1400","7.6900","0.0306","7.6900","15.6939","12.7332"
"9.1600","7.7065","0.0306","7.7065","15.7276","12.7542"
"9.1800","7.7232","0.0307","7.7232","15.7616","12.7838"
"9.2000","7.7397","0.0307","7.7397","15.7954","12.8093"
"9.2200","7.7566","0.0308","7.7566","15.8298","12.8397"
"9.2400","7.7736","0.0309","7.7736","15.8645","12.8812"
"9.2600","7.7901","0.0310","7.7901","15.8982","12.9120"
"9.2800","7.8065","0.0311","7.8065","15.9317","12.9477"
"9.3000","7.8232","0.0311","7.8232","15.9657","12.9637"
"9.3200","7.8401","0.0311","7.8401","16.0001","12.9787"
"9.3400","7.8567","0.0312","7.8567","16.0341","12.9976"
"9.3600","7.8735","0.0313","7.8735","16.0683","13.0280"
"9.3800","7.8904","0.0314","7.8904","16.1028","13.0733"
"9.4000","7.9074","0.0315","7.9074","16.1375","13.1169"
"9.4200","7.9238","0.0315","7.9238","16.1710","13.1304"
"9.4400","7.9399","0.0316","7.9399","16.2040","13.1485"
"9.4600","7.9566","0.0316","7.9566","16.2379","13.1761"
"9.4800","7.9735","0.0317","7.9735","16.2724","13.1925"
"9.5000","7.9901","0.0317","7.9901","16.3064","13.2117"
"9.5200","8.0066","0.0318","8.0066","16.3401","13.2424"
"9.5400","8.0236","0.0319","8.0236","16.3748","13.2903"
"9.5600","8.0402","0.0319","8.0402","16.4085","13.3041"
"9.5800","8.0566","0.0320","8.0566","16.4420","13.3369"
"9.6000","8.0730","0.0321","8.0730","16.4755","13.3558"
"9.6200","8.0899","0.0321","8.0899","16.5099","13.3674"
"9.6400","8.1068","0.0321","8.1068","16.5444","13.3908"
"9.6600","8.1234","0.0322","8.1234","16.5784","13.4089"
"9.6800","8.1404","0.0323","8.1404","16.6131","13.4526"
"9.7000","8.1572","0.0324","8.1572","16.6473","13.4943"
"9.7200","8.1735","0.0325","8.1735","16.6805","13.5244"
"9.7400","8.1896","0.0325","8.1896","16.7135","13.5443"
"9.7600","8.2065","0.0325","8.2065","16.7480","13.5475"
"9.7800","8.2235","0.0326","8.2235","16.7827","13.5671"
"9.8000","8.2402","0.0327","8.2402","16.8166","13.6086"
"9.8200","8.2567","0.0327","8.2567","16.8504","13.6374"
"9.8400","8.2736","0.0328","8.2736","16.8848","13.6710"
"9.8600","8.2900","0.0329","8.2900","16.9183","13.6955"
"9.8800","8.3062","0.0329","8.3062","16.9513","13.7180"
"9.9000","8.3230","0.0330","8.3230","16.9858","13.7365"
"9.9200","8.3400","0.0330","8.3400","17.0205","13.7610"
"9.9400","8.3568","0.0331","8.3568","17.0547","13.7771"
"9.9600","8.3734","0.0331","8.3734","17.0887","13.7902"
"9.9800","8.3903","0.0332","8.3903","17.1231","13.8180"
"10.0000","8.4070","0.0332","8.4070","17.1571","13.8436"
"10.0200","8.4233","0.0333","8.4233","17.1903","13.8738"
"10.0400","8.4398","0.0334","8.4398","17.2241","13.9009"
"10.0600","8.4568","0.0334","8.4568","17.2588","13.9126"
"10.0800","8.4738","0.0335","8.4738","17.2934","13.9428"
"10.1000","8.4902","0.0336","8.4902","17.3269","13.9811"
"10.1200","8.5070","0.0336","8.5070","17.3612","14.0063"
"10.1400","8.5237","0.0336","8.5237","17.3954","14.0162"
"10.1600","8.5401","0.0336","8.5401","17.4289","14.0085"
"10.1800","8.5564","0.0336","8.5564","17.4621","14.0119"
"10.2000","8.5731","0.0337","8.5731","17.4961","14.0403"
"10.2200","8.5902","0.0337","8.5902","17.5310","14.0596"
"10.2400","8.6068","0.0338","8.6068","17.5650","14.0769"
"10.2600","8.6234","0.0339","8.6234","17.5987","14.1050"
"10.2800","8.6402","0.0339","8.6402","17.6332","14.1299"
"10.3000","8.6568","0.0340","8.6568","17.6669","14.1477"
"10.3200","8.6732","0.0340","8.6732","17.7004","14.1731"
"10.3400","8.6899","0.0341","8.6899","17.7346","14.2113"
"10.3600","8.7068","0.0342","8.7068","17.7690","14.2450"
"10.3800","8.7236","0.0343","8.7236","17.8033","14.2737"
"10.4000","8.7402","0.0343","8.7402","17.8372","14.2903"
"10.4200","8.7569","0.0344","8.7569","17.8712","14.3234"
"10.4400","8.7735","0.0344","8.7735","17.9052","14.3493"
"10.4600","8.7901","0.0345","8.7901","17.9389","14.3744"
"10.4800","8.8067","0.0346","8.8067","17.9729","14.4008"
"10.5000","8.8235","0.0346","8.8235","18.0071","14.4253"
"10.5200","8.8404","0.0347","8.8404","18.0415","14.4458"
"10.5400","8.8569","0.0348","8.8569","18.0753","14.4798"
"10.5600","8.8733","0.0348","8.8733","18.1088","14.4939"
"10.5800","8.8899","0.0348","8.8899","18.1427","14.4878"
"10.6000","8.9066","0.0348","8.9066","18.1767","14.4955"
"10.6200","8.9233","0.0349","8.9233","18.2109","14.5284"
"10.6400","8.9400","0.0349","8.9400","18.2449","14.5267"
"10.6600","8.9569","0.0349","8.9569","18.2793","14.5362"
"10.6800","8.9738","0.0350","8.9738","18.3138","14.5889"
"10.7000","8.9902","0.0351","8.9902","18.3473","14.6177"
"10.7200","9.0066","0.0351","9.0066","18.3808","14.6302"
"10.7400","9.0232","0.0351","9.0232","18.4147","14.6433"
"10.7600","9.0400","0.0352","9.0400","18.4489","14.6620"
"10.7800","9.0567","0.0353","9.0567","18.4832","14.6910"
"10.8000","9.0735","0.0353","9.0735","18.5174","14.7127"
"10.8200","9.0904","0.0354","9.0904","18.5518","14.7300"
"10.8400","9.1068","0.0354","9.1068","18.5853","14.7629"
"10.8600","9.1231","0.0355","9.1231","18.6186","14.7890"
"10.8800","9.1399","0.0355","9.1399","18.6528","14.8097"
"10.9000","9.1569","0.0356","9.1569","18.6875","14.8402"
"10.9200","9.1735","0.0357","9.1735","18.7214","14.8694"
"10.9400","9.1903","0.0357","9.1903","18.7557","14.8780"
"10.9600","9.2070","0.0357","9.2070","18.7899","14.8871"
"10.9800","9.2236","0.0358","9.2236","18.8236","14.9145"
"11.0000","9.2397","0.0358","9.2397","18.8566","14.9272"
"11.0200","9.2563","0.0359","9.2563","18.8903","14.9595"
"11.0400","9.2731","0.0360","9.2731","18.9248","15.0094"
"11.0600","9.2900","0.0360","9.2900","18.9592","15.0125"
"11.0800","9.3067","0.0360","9.3067","18.9932","15.0167"
"11.1000","9.3236","0.0361","9.3236","19.0277","15.0366"
"11.1200","9.3403","0.0361","9.3403","19.0619","15.0594"
"11.1400","9.3566","0.0362","9.3566","19.0951","15.0868"
"11.1600","9.3729","0.0363","9.3729","19.1284","15.1076"
"11.1800","9.3899","0.0363","9.3899","19.1631","15.1209"
"11.2000","9.4069","0.0363","9.4069","19.1978","15.1448"
"11.2200","9.4235","0.0364","9.4235","19.2317","15.1721"
"11.2400","9.4403","0.0365","9.4403","19.2659","15.2102"
"11.2600","9.4571","0.0365","9.4571","19.3002","15.2262"
"11.2800","9.4735","0.0366","9.4735","19.3336","15.2567"
"11.3000","9.4899","0.0367","9.4899","19.3671","15.2756"
"11.3200","9.5065","0.0367","9.5065","19.4011","15.2815"
"11.3400","9.5234","0.0367","9.5234","19.4356","15.3011"
"11.3600","9.5401","0.0368","9.5401","19.4695","15.3188"
"11.3800","9.5566","0.0368","9.5566","19.5033","15.3480"
"11.4000","9.5732","0.0369","9.5732","19.5372","15.3549"
"11.4200","9.5899","0.0369","9.5899","19.5712","15.3747"
"11.4400","9.6063","0.0369","9.6063","19.6047","15.3703"
"11.4600","9.6228","0.0370","9.6228","19.6384","15.4020"
"11.4800","9.6397","0.0370","9.6397","19.6729","15.4275"
"11.5000","9.6569","0.0371","9.6569","19.7080","15.4512"
"11.5200","9.6737","0.0372","9.6737","19.7423","15.4809"
"11.5400","9.6904","0.0372","9.6904","19.7762","15.4950"
"11.5600","9.7070","0.0372","9.7070","19.8102","15.4927"
"11.5800","9.7235","0.0372","9.7235","19.8439","15.5010"
"11.6000","9.7401","0.0373","9.7401","19.8777","15.5226"
"11.6200","9.7567","0.0373","9.7567","19.9116","15.5357"
"11.6400","9.7737","0.0370","9.7737","19.9463","15.4325"
"11.6600","9.7905","0.0367","9.7905","19.9805","15.2889"
"11.6800","9.8070","0.0365","9.8070","20.0143","15.2261"
"11.7000","9.8235","0.0366","9.8235","20.0480","15.2316"
"11.7200","9.8400","0.0366","9.8400","20.0817","15.2332"
"11.7400","9.8565","0.0366","9.8565","20.1152","15.2314"
"11.7600","9.8731","0.0366","9.8731","20.1492","15.2298"
"11.7800","9.8901","0.0366","9.8901","20.1839","15.2300"
"11.8000","9.9071","0.0366","9.9071","20.2186","15.2546"
"11.8200","9.9235","0.0367","9.9235","20.2521","15.2723"
"11.8400","9.9399","0.0367","9.9399","20.2856","15.3051"
"11.8600","9.9564","0.0368","9.9564","20.3193","15.3165"
"11.8800","9.9733","0.0368","9.9733","20.3537","15.3274"
"11.9000","9.9900","0.0368","9.9900","20.3877","15.3475"
"11.9200","10.0067","0.0369","10.0067","20.4219","15.3738"
"11.9400","10.0237","0.0369","10.0237","20.4566","15.3832"
"11.9600","10.0405","0.0369","10.0405","20.4908","15.3732"
"11.9800","10.0569","0.0369","10.0569","20.5243","15.3677"
"12.0000","10.0733","0.0369","10.0733","20.5578","15.3795"
"12.0200","10.0901","0.0370","10.0901","20.5920","15.4026"
"12.0400","10.1070","0.0370","10.1070","20.6265","15.4189"
"12.0600","10.1235","0.0370","10.1235","20.6602","15.4192"
"12.0800","10.1403","0.0371","10.1403","20.6944","15.4466"
"12.1000","10.1570","0.0371","10.1570","20.7286","15.4430"
"12.1200","10.1736","0.0370","10.1736","20.7624","15.4141"
"12.1400","10.1900","0.0370","10.1900","20.7958","15.4057"
"12.1600","10.2066","0.0370","10.2066","20.8298","15.4188"
"12.1800","10.2235","0.0371","10.2235","20.8643","15.4603"
"12.2000","10.2401","0.0372","10.2401","20.8982","15.5072"
"12.2200","10.2569","0.0372","10.2569","20.9325","15.5102"
"12.2400","10.2737","0.0373","10.2737","20.9667","15.5295"
"12.2600","10.2903","0.0373","10.2903","21.0006","15.5416"
"12.2800","10.3066","0.0373","10.3066","21.0339","15.5620"
"12.3000","10.3231","0.0374","10.3231","21.0676","15.5757"
"12.3200","10.3401","0.0375","10.3401","21.1023","15.6050"
"12.3400","10.3571","0.0375","10.3571","21.1370","15.6455"
"12.3600","10.3737","0.0376","10.3737","21.1707","15.6694"
"12.3800","10.3902","0.0377","10.3902","21.2045","15.6905"
"12.4000","10.4071","0.0377","10.4071","21.2389","15.7023"
"12.4200","10.4235","0.0377","10.4235","21.2724","15.7009"
"12.4400","10.4397","0.0377","10.4397","21.3054","15.7247"
"12.4600","10.4564","0.0378","10.4564","21.3396","15.7334"
"12.4800","10.4734","0.0378","10.4734","21.3743","15.7556"
"12.5000","10.4901","0.0378","10.4901","21.4083","15.7686"
"12.5200","10.5067","0.0378","10.5067","21.4423","15.7657"
"12.5400","10.5234","0.0378","10.5234","21.4762","15.7583"
"12.5600","10.5398","0.0378","10.5398","21.5097","15.7469"
"12.5800","10.5563","0.0378","10.5563","21.5434","15.7316"
"12.6000","10.5731","0.0378","10.5731","21.5777","15.7353"
"12.6200","10.5901","0.0379","10.5901","21.6124","15.7814"
"12.6400","10.6069","0.0379","10.6069","21.6468","15.7852"
"12.6600","10.6235","0.0379","10.6235","21.6805","15.7905"
"12.6800","10.6400","0.0380","10.6400","21.7143","15.8238"
"12.7000","10.6565","0.0380","10.6565","21.7480","15.8432"
"12.7200","10.6729","0.0380","10.6729","21.7815","15.8478"
"12.7400","10.6895","0.0381","10.6895","21.8152","15.8668"
"12.7600","10.7063","0.0381","10.7063","21.8497","15.8853"
"12.7800","10.7233","0.0382","10.7233","21.8844","15.9053"
"12.8000","10.7400","0.0382","10.7400","21.9183","15.9015"
"12.8200","10.7566","0.0382","10.7566","21.9523","15.9032"
"12.8400","10.7733","0.0382","10.7733","21.9863","15.9178"
"12.8600","10.7898","0.0382","10.7898","22.0200","15.9316"
"12.8800","10.8064","0.0383","10.8064","22.0540","15.9545"
"12.9000","10.8235","0.0383","10.8235","22.0887","15.9739"
"12.9200","10.8403","0.0384","10.8403","22.1231","15.9978"
"12.9400","10.8571","0.0384","10.8571","22.1573","16.0141"
"12.9600","10.8735","0.0385","10.8735","22.1908","16.0318"
"12.9800","10.8902","0.0385","10.8902","22.2248","16.0455"
"13.0000","10.9068","0.0386","10.9068","22.2588","16.0728"
"13.0200","10.9236","0.0386","10.9236","22.2930","16.0995"
"13.0400","10.9402","0.0386","10.9402","22.3270","16.0958"
"13.0600","10.9570","0.0386","10.9570","22.3612","16.1042"
"13.0800","10.9737","0.0385","10.9737","22.3954","16.0590"
"13.1000","10.9901","0.0380","10.9901","22.4289","15.8135"
"13.1200","11.0067","0.0376","11.0067","22.4626","15.6660"
"13.1400","11.0232","0.0375","11.0232","22.4963","15.6362"
"13.1600","11.0400","0.0375","11.0400","22.5305","15.6361"
"13.1800","11.0566","0.0376","11.0566","22.5645","15.6521"
"13.2000","11.0734","0.0376","11.0734","22.5987","15.6852"
"13.2200","11.0904","0.0377","11.0904","22.6334","15.7007"
"13.2400","11.1069","0.0377","11.1069","22.6671","15.6879"
"13.2600","11.1234","0.0376","11.1234","22.7009","15.6524"
"13.2800","11.1400","0.0376","11.1400","22.7346","15.6533"
"13.3000","11.1567","0.0376","11.1567","22.7688","15.6713"
"13.3200","11.1736","0.0376","11.1736","22.8033","15.6462"
"13.3400","11.1902","0.0375","11.1902","22.8372","15.6340"
"13.3600","11.2071","0.0375","11.2071","22.8717","15.6391"
"13.3800","11.2238","0.0376","11.2238","22.9057","15.6509"
"13.4000","11.2401","0.0376","11.2401","22.9389","15.6609"
"13.4200","11.2564","0.0376","11.2564","22.9722","15.6523"
"13.4400","11.2730","0.0376","11.2730","23.0061","15.6618"
"13.4600","11.2900","0.0376","11.2900","23.0408","15.6862"
"13.4800","11.3065","0.0377","11.3065","23.0746","15.7155"
"13.5000","11.3233","0.0378","11.3233","23.1088","15.7338"
"13.5200","11.3402","0.0378","11.3402","23.1432","15.7423"
"13.5400","11.3567","0.0378","11.3567","23.1770","15.7668"
"13.5600","11.3731","0.0378","11.3731","23.2104","15.7623"
"13.5800","11.3899","0.0379","11.3899","23.2447","15.7754"
"13.6000","11.4068","0.0379","11.4068","23.2791","15.7950"
"13.6200","11.4235","0.0379","11.4235","23.3133","15.8075"
"13.6400","11.4402","0.0380","11.4402","23.3473","15.8200"
"13.6600","11.4569","0.0380","11.4569","23.3815","15.8197"
"13.6800","11.4736","0.0380","11.4736","23.4155","15.8318"
"13.7000","11.4899","0.0380","11.4899","23.4487","15.8413"
"13.7200","11.5064","0.0374","11.5064","23.4825","15.5999"
"13.7400","11.5234","0.0370","11.5234","23.5171","15.4051"
"13.7600","11.5402","0.0369","11.5402","23.5514","15.3619"
"13.7800","11.5568","0.0369","11.5568","23.5853","15.3754"
"13.8000","11.5735","0.0370","11.5735","23.6193","15.4168"
"13.8200","11.5902","0.0370","11.5902","23.6535","15.4262"
"13.8400","11.6066","0.0370","11.6066","23.6870","15.4078"
"13.8600","11.6229","0.0370","11.6229","23.7202","15.3979"
"13.8800","11.6399","0.0370","11.6399","23.7549","15.4206"
"13.9000","11.6569","0.0371","11.6569","23.7896","15.4423"
"13.9200","11.6737","0.0371","11.6737","23.8238","15.4640"
"13.9400","11.6902","0.0372","11.6902","23.8576","15.4904"
"13.9600","11.7069","0.0372","11.7069","23.8916","15.5014"
"13.9800","11.7234","0.0372","11.7234","23.9253","15.5062"
"14.0000","11.7398","0.0373","11.7398","23.9588","15.5312"
"14.0200","11.7566","0.0373","11.7566","23.9930","15.5434"
"14.0400","11.7734","0.0374","11.7734","24.0274","15.5711"
"14.0600","11.7903","0.0374","11.7903","24.0619","15.5759"
"14.0800","11.8067","0.0374","11.8067","24.0954","15.5886"
"14.1000","11.8234","0.0374","11.8234","24.1293","15.5965"
"14.1200","11.8400","0.0375","11.8400","24.1633","15.6135"
"14.1400","11.8566","0.0375","11.8566","24.1970","15.6379"
"14.1600","11.8731","0.0375","11.8731","24.2308","15.6378"
"14.1800","11.8900","0.0375","11.8900","24.2652","15.6409"
"14.2000","11.9068","0.0376","11.9068","24.2997","15.6823"
"14.2200","11.9235","0.0376","11.9235","24.3337","15.6474"
"14.2400","11.9399","0.0375","11.9399","24.3671","15.6371"
"14.2600","11.9565","0.0376","11.9565","24.4011","15.6535"
"14.2800","11.9731","0.0376","11.9731","24.4348","15.6736"
"14.3000","11.9897","0.0376","11.9897","24.4688","15.6578"
"14.3200","12.0064","0.0375","12.0064","24.5028","15.6111"
"14.3400","12.0236","0.0374","12.0236","24.5380","15.5783"
"14.3600","12.0406","0.0374","12.0406","24.5727","15.5737"
"14.3800","12.0570","0.0369","12.0570","24.6061","15.3751"
"14.4000","12.0734","0.0364","12.0734","24.6396","15.1845"
"14.4200","12.0903","0.0363","12.0903","24.6741","15.1145"
"14.4400","12.1069","0.0363","12.1069","24.7081","15.1248"
"14.4600","12.1236","0.0363","12.1236","24.7420","15.1365"
"14.4800","12.1405","0.0363","12.1405","24.7765","15.1242"
"14.5000","12.1571","0.0357","12.1571","24.8105","14.8723"
"14.5200","12.1735","0.0347","12.1735","24.8439","14.4593"
"14.5400","12.1898","0.0342","12.1898","24.8772","14.2312"
"14.5600","12.2065","0.0340","12.2065","24.9112","14.1638"
"14.5800","12.2234","0.0341","12.2234","24.9456","14.1888"
"14.6000","12.2401","0.0342","12.2401","24.9798","14.2348"
"14.6200","12.2569","0.0342","12.2569","25.0140","14.2354"
"14.6400","12.2736","0.0342","12.2736","25.0483","14.2341"
"14.6600","12.2903","0.0341","12.2903","25.0822","14.2153"
"14.6800","12.3068","0.0341","12.3068","25.1160","14.2224"
"14.7000","12.3232","0.0342","12.3232","25.1494","14.2431"
"14.7200","12.3400","0.0342","12.3400","25.1837","14.2497"
"14.7400","12.3569","0.0336","12.3569","25.2181","14.0002"
"14.7600","12.3734","0.0330","12.3734","25.2518","13.7418"
"14.7800","12.3900","0.0328","12.3900","25.2858","13.6676"
"14.8000","12.4068","0.0328","12.4068","25.3200","13.6699"
"14.8200","12.4233","0.0328","12.4233","25.3538","13.6703"
"14.8400","12.4394","0.0329","12.4394","25.3865","13.6913"
"14.8600","12.4563","0.0329","12.4563","25.4210","13.6943"
"14.8800","12.4732","0.0329","12.4732","25.4554","13.7021"
"14.9000","12.4899","0.0329","12.4899","25.4896","13.7126"
"14.9200","12.5067","0.0329","12.5067","25.5238","13.7280"
"14.9400","12.5236","0.0320","12.5236","25.5583","13.3405"
"14.9600","12.5401","0.0301","12.5401","25.5920","12.5606"
"14.9800","12.5564","0.0288","12.5564","25.6253","11.9806"
"15.0000","12.5732","0.0279","12.5731","25.6595","11.6079"
"15.0200","12.5903","0.0269","12.5903","25.6944","11.1968"
"15.0400","12.6070","0.0261","12.6070","25.7286","10.8955"
"15.0600","12.6236","0.0253","12.6236","25.7624","10.5373"
"15.0800","12.6403","0.0249","12.6403","25.7966","10.3773"
"15.1000","12.6570","0.0248","12.6570","25.8306","10.3517"
"15.1200","12.6733","0.0249","12.6733","25.8638","10.3576"
"15.1400","12.6899","0.0249","12.6899","25.8978","10.3818"
"15.1600","12.7069","0.0249","12.7069","25.9325","10.3816"
"15.1800","12.7237","0.0249","12.7237","25.9667","10.3932"
"15.2000","12.7402","0.0250","12.7402","26.0004","10.4008"
"15.2200","12.7567","0.0249","12.7567","26.0341","10.3819"
"15.2400","12.7735","0.0242","12.7735","26.0683","10.1001"
"15.2600","12.7899","0.0236","12.7899","26.1018","9.8322"
"15.2660","12.7949","0.0231","12.7949","26.1120","9.6341"