File: Fig6C/211130_Instron/211130/PureCompression_TTball_2_1.csv
Results Table 1


Results Table 2


1,Time,Displacement,Force,Compressive displacement,Compressive strain (Displacement),Compressive stress,PIP count
,(s),(mm),(kN),(mm),(%),(MPa),
"","0.0000","0.0000","0.0000","0.0000","0.0000","-0.0007","0.0000"
"","0.0600","0.0270","0.0001","0.0270","0.0676","0.0067","0.0000"
"","0.1200","0.0940","0.0000","0.0940","0.2349","-0.0006","0.0000"
"","0.1800","0.1498","0.0000","0.1498","0.3745","-0.0009","0.0000"
"","0.2400","0.2014","0.0000","0.2014","0.5035","-0.0032","0.0000"
"","0.3000","0.2515","0.0004","0.2515","0.6286","0.0378","0.0000"
"","0.3600","0.3019","0.0020","0.3019","0.7547","0.2038","0.0000"
"","0.4200","0.3518","0.0038","0.3518","0.8795","0.3847","0.0000"
"","0.4800","0.4017","0.0057","0.4017","1.0044","0.5659","0.0000"
"","0.5400","0.4520","0.0074","0.4520","1.1301","0.7384","0.0000"
"","0.6000","0.5015","0.0091","0.5015","1.2537","0.9111","0.0000"
"","0.6600","0.5519","0.0109","0.5519","1.3798","1.0904","0.0000"
"","0.7200","0.6017","0.0127","0.6017","1.5043","1.2690","0.0000"
"","0.7800","0.6519","0.0146","0.6519","1.6298","1.4580","0.0000"
"","0.8400","0.7020","0.0166","0.7020","1.7549","1.6628","0.0000"
"","0.9000","0.7519","0.0186","0.7519","1.8797","1.8583","0.0000"
"","0.9600","0.8020","0.0208","0.8020","2.0049","2.0757","0.0000"
"","1.0200","0.8515","0.0229","0.8515","2.1288","2.2937","0.0000"
"","1.0800","0.9016","0.0252","0.9016","2.2540","2.5198","0.0000"
"","1.1400","0.9519","0.0275","0.9519","2.3797","2.7505","0.0000"
"","1.2000","1.0018","0.0297","1.0018","2.5045","2.9710","0.0000"
"","1.2600","1.0519","0.0321","1.0519","2.6297","3.2079","0.0000"
"","1.3200","1.1019","0.0344","1.1019","2.7548","3.4410","0.0000"
"","1.3800","1.1520","0.0368","1.1520","2.8800","3.6773","0.0000"
"","1.4400","1.2016","0.0391","1.2016","3.0039","3.9135","0.0000"
"","1.5000","1.2519","0.0415","1.2519","3.1297","4.1512","0.0000"
"","1.5600","1.3017","0.0438","1.3017","3.2542","4.3834","0.0000"
"","1.6200","1.3517","0.0462","1.3517","3.3793","4.6182","0.0000"
"","1.6800","1.4020","0.0486","1.4020","3.5051","4.8561","0.0000"
"","1.7400","1.4515","0.0509","1.4515","3.6287","5.0900","0.0000"
"","1.8000","1.5019","0.0533","1.5019","3.7548","5.3251","0.0000"
"","1.8600","1.5515","0.0556","1.5515","3.8787","5.5633","0.0000"
"","1.9200","1.6020","0.0579","1.6020","4.0050","5.7877","0.0000"
"","1.9800","1.6520","0.0602","1.6520","4.1299","6.0210","0.0000"
"","2.0400","1.7017","0.0624","1.7017","4.2541","6.2361","0.0000"
"","2.1000","1.7518","0.0645","1.7518","4.3796","6.4465","0.0000"
"","2.1600","1.8015","0.0666","1.8015","4.5038","6.6581","0.0000"
"","2.2200","1.8521","0.0691","1.8521","4.6301","6.9061","0.0000"
"","2.2800","1.9016","0.0716","1.9016","4.7541","7.1557","0.0000"
"","2.3400","1.9513","0.0741","1.9513","4.8784","7.4062","0.0000"
"","2.4000","2.0019","0.0768","2.0019","5.0047","7.6756","0.0000"
"","2.4600","2.0519","0.0795","2.0519","5.1298","7.9465","0.0000"
"","2.5200","2.1021","0.0823","2.1021","5.2552","8.2258","0.0000"
"","2.5800","2.1517","0.0850","2.1517","5.3792","8.4995","0.0000"
"","2.6400","2.2020","0.0877","2.2020","5.5049","8.7741","0.0000"
"","2.7000","2.2516","0.0906","2.2516","5.6289","9.0642","0.0000"
"","2.7600","2.3018","0.0934","2.3018","5.7546","9.3355","0.0000"
"","2.8200","2.3518","0.0962","2.3518","5.8795","9.6184","0.0000"
"","2.8800","2.4016","0.0988","2.4016","6.0040","9.8818","0.0000"
"","2.9400","2.4517","0.1012","2.4517","6.1291","10.1249","0.0000"
"","3.0000","2.5016","0.1027","2.5016","6.2540","10.2676","0.0000"
"","3.0600","2.5518","0.1020","2.5518","6.3794","10.2023","0.0000"
"","3.1200","2.6019","0.1019","2.6019","6.5049","10.1879","0.0000"
"","3.1800","2.6518","0.1021","2.6518","6.6294","10.2104","0.0000"
"","3.2400","2.7021","0.1021","2.7021","6.7551","10.2088","0.0000"
"","3.3000","2.7518","0.1021","2.7518","6.8794","10.2102","0.0000"
"","3.3600","2.8022","0.1025","2.8022","7.0054","10.2525","0.0000"
"","3.4200","2.8519","0.1034","2.8519","7.1297","10.3412","0.0000"
"","3.4800","2.9019","0.1043","2.9019","7.2548","10.4323","0.0000"
"","3.5400","2.9517","0.1055","2.9517","7.3794","10.5489","0.0000"
"","3.6000","3.0017","0.1066","3.0017","7.5042","10.6632","0.0000"
"","3.6600","3.0520","0.1077","3.0520","7.6299","10.7724","0.0000"
"","3.7200","3.1017","0.1088","3.1017","7.7542","10.8797","0.0000"
"","3.7800","3.1518","0.1099","3.1518","7.8796","10.9912","0.0000"
"","3.8400","3.2012","0.1111","3.2012","8.0030","11.1113","0.0000"
"","3.9000","3.2518","0.1124","3.2518","8.1296","11.2413","0.0000"
"","3.9600","3.3020","0.1139","3.3020","8.2550","11.3862","0.0000"
"","4.0200","3.3515","0.1151","3.3515","8.3787","11.5145","0.0000"
"","4.0800","3.4020","0.1164","3.4020","8.5050","11.6389","0.0000"
"","4.1400","3.4518","0.1176","3.4518","8.6296","11.7563","0.0000"
"","4.2000","3.5019","0.1188","3.5019","8.7547","11.8791","0.0000"
"","4.2600","3.5516","0.1202","3.5516","8.8790","12.0181","0.0000"
"","4.3200","3.6020","0.1216","3.6020","9.0050","12.1623","0.0000"
"","4.3800","3.6519","0.1228","3.6519","9.1298","12.2850","0.0000"
"","4.4400","3.7016","0.1240","3.7016","9.2541","12.4021","0.0000"
"","4.5000","3.7520","0.1251","3.7520","9.3801","12.5059","0.0000"
"","4.5600","3.8020","0.1261","3.8020","9.5049","12.6113","0.0000"
"","4.6200","3.8520","0.1271","3.8520","9.6301","12.7088","0.0000"
"","4.6800","3.9019","0.1281","3.9019","9.7546","12.8083","0.0000"
"","4.7400","3.9517","0.1292","3.9517","9.8792","12.9157","0.0000"
"","4.8000","4.0017","0.1304","4.0017","10.0043","13.0428","0.0000"
"","4.8600","4.0514","0.1317","4.0514","10.1286","13.1666","0.0000"
"","4.9200","4.1020","0.1327","4.1020","10.2549","13.2661","0.0000"
"","4.9800","4.1517","0.1336","4.1517","10.3791","13.3632","0.0000"
"","5.0400","4.2017","0.1346","4.2017","10.5043","13.4595","0.0000"
"","5.1000","4.2515","0.1356","4.2515","10.6288","13.5615","0.0000"
"","5.1600","4.3016","0.1366","4.3016","10.7540","13.6607","0.0000"
"","5.2200","4.3520","0.1378","4.3520","10.8800","13.7828","0.0000"
"","5.2800","4.4016","0.1388","4.4016","11.0040","13.8796","0.0000"
"","5.3400","4.4520","0.1398","4.4520","11.1300","13.9834","0.0000"
"","5.4000","4.5017","0.1409","4.5017","11.2542","14.0865","0.0000"
"","5.4600","4.5519","0.1420","4.5519","11.3797","14.2017","0.0000"
"","5.5200","4.6019","0.1433","4.6019","11.5048","14.3297","0.0000"
"","5.5800","4.6517","0.1446","4.6517","11.6294","14.4611","0.0000"
"","5.6400","4.7019","0.1457","4.7019","11.7548","14.5683","0.0000"
"","5.7000","4.7516","0.1468","4.7516","11.8790","14.6800","0.0000"
"","5.7600","4.8021","0.1481","4.8021","12.0054","14.8069","0.0000"
"","5.8200","4.8517","0.1493","4.8517","12.1293","14.9301","0.0000"
"","5.8800","4.9017","0.1504","4.9017","12.2542","15.0412","0.0000"
"","5.9400","4.9517","0.1516","4.9517","12.3793","15.1581","0.0000"
"","6.0000","5.0019","0.1527","5.0019","12.5047","15.2730","0.0000"
"","6.0600","5.0520","0.1540","5.0520","12.6299","15.4045","0.0000"
"","6.1200","5.1014","0.1553","5.1014","12.7535","15.5350","0.0000"
"","6.1800","5.1517","0.1567","5.1517","12.8793","15.6724","0.0000"
"","6.2400","5.2015","0.1581","5.2015","13.0038","15.8069","0.0000"
"","6.3000","5.2518","0.1594","5.2518","13.1296","15.9397","0.0000"
"","6.3600","5.3022","0.1606","5.3022","13.2556","16.0623","0.0000"
"","6.4200","5.3517","0.1619","5.3517","13.3792","16.1941","0.0000"
"","6.4800","5.4019","0.1633","5.4019","13.5047","16.3278","0.0000"
"","6.5400","5.4516","0.1647","5.4516","13.6289","16.4664","0.0000"
"","6.6000","5.5016","0.1659","5.5016","13.7541","16.5941","0.0000"
"","6.6600","5.5518","0.1673","5.5518","13.8795","16.7319","0.0000"
"","6.7200","5.6017","0.1686","5.6017","14.0043","16.8555","0.0000"
"","6.7800","5.6518","0.1699","5.6518","14.1295","16.9886","0.0000"
"","6.8400","5.7014","0.1712","5.7014","14.2534","17.1172","0.0000"
"","6.9000","5.7518","0.1726","5.7518","14.3795","17.2575","0.0000"
"","6.9600","5.8018","0.1739","5.8018","14.5046","17.3918","0.0000"
"","7.0200","5.8519","0.1754","5.8519","14.6297","17.5360","0.0000"
"","7.0800","5.9018","0.1767","5.9018","14.7546","17.6750","0.0000"
"","7.1400","5.9517","0.1782","5.9517","14.8791","17.8234","0.0000"
"","7.2000","6.0019","0.1798","6.0019","15.0049","17.9800","0.0000"
"","7.2600","6.0518","0.1813","6.0518","15.1294","18.1320","0.0000"
"","7.3200","6.1021","0.1828","6.1021","15.2551","18.2850","0.0000"
"","7.3800","6.1515","0.1842","6.1515","15.3788","18.4164","0.0000"
"","7.4400","6.2018","0.1855","6.2018","15.5045","18.5544","0.0000"
"","7.5000","6.2519","0.1870","6.2519","15.6297","18.7038","0.0000"
"","7.5600","6.3018","0.1884","6.3018","15.7545","18.8426","0.0000"
"","7.6200","6.3520","0.1899","6.3520","15.8799","18.9883","0.0000"
"","7.6800","6.4016","0.1911","6.4016","16.0039","19.1123","0.0000"
"","7.7400","6.4517","0.1924","6.4517","16.1293","19.2376","0.0000"
"","7.8000","6.5017","0.1935","6.5017","16.2542","19.3520","0.0000"
"","7.8600","6.5520","0.1947","6.5520","16.3799","19.4679","0.0000"
"","7.9200","6.6021","0.1959","6.6021","16.5053","19.5945","0.0000"
"","7.9800","6.6511","0.1972","6.6511","16.6278","19.7155","0.0000"
"","8.0400","6.7015","0.1986","6.7015","16.7539","19.8574","0.0000"
"","8.1000","6.7517","0.2001","6.7517","16.8793","20.0116","0.0000"
"","8.1600","6.8022","0.2016","6.8022","17.0056","20.1561","0.0000"
"","8.2200","6.8519","0.2030","6.8519","17.1299","20.3015","0.0000"
"","8.2800","6.9018","0.2040","6.9018","17.2544","20.4025","0.0000"
"","8.3400","6.9519","0.2050","6.9519","17.3798","20.4967","0.0000"
"","8.4000","7.0018","0.2059","7.0018","17.5044","20.5858","0.0000"
"","8.4600","7.0522","0.2069","7.0522","17.6304","20.6907","0.0000"
"","8.5200","7.1017","0.2079","7.1017","17.7544","20.7903","0.0000"
"","8.5800","7.1517","0.2086","7.1517","17.8792","20.8644","0.0000"
"","8.6400","7.2014","0.2095","7.2014","18.0035","20.9518","0.0000"
"","8.7000","7.2518","0.2104","7.2518","18.1295","21.0388","0.0000"
"","8.7600","7.3022","0.2113","7.3022","18.2555","21.1295","0.0000"
"","8.8200","7.3516","0.2122","7.3516","18.3789","21.2195","0.0000"
"","8.8800","7.4017","0.2132","7.4017","18.5043","21.3197","0.0000"
"","8.9400","7.4514","0.2143","7.4514","18.6286","21.4281","0.0000"
"","9.0000","7.5018","0.2156","7.5018","18.7546","21.5553","0.0000"
"","9.0600","7.5519","0.2169","7.5519","18.8797","21.6909","0.0000"
"","9.1200","7.6017","0.2182","7.6017","19.0043","21.8246","0.0000"
"","9.1800","7.6519","0.2196","7.6519","19.1297","21.9638","0.0000"
"","9.2400","7.7015","0.2210","7.7015","19.2537","22.0966","0.0000"
"","9.3000","7.7520","0.2225","7.7520","19.3800","22.2475","0.0000"
"","9.3600","7.8018","0.2238","7.8018","19.5046","22.3768","0.0000"
"","9.4200","7.8521","0.2250","7.8521","19.6303","22.5006","0.0000"
"","9.4800","7.9017","0.2263","7.9017","19.7542","22.6264","0.0000"
"","9.5400","7.9516","0.2275","7.9516","19.8791","22.7496","0.0000"
"","9.6000","8.0020","0.2287","8.0020","20.0051","22.8716","0.0000"
"","9.6600","8.0515","0.2299","8.0515","20.1288","22.9894","0.0000"
"","9.7200","8.1018","0.2312","8.1018","20.2545","23.1158","0.0000"
"","9.7800","8.1521","0.2326","8.1521","20.3802","23.2602","0.0000"
"","9.8400","8.2020","0.2340","8.2020","20.5051","23.3975","0.0000"
"","9.9000","8.2520","0.2353","8.2520","20.6299","23.5279","0.0000"
"","9.9600","8.3015","0.2365","8.3015","20.7539","23.6481","0.0000"
"","10.0200","8.3520","0.2377","8.3520","20.8799","23.7736","0.0000"
"","10.0800","8.4018","0.2389","8.4018","21.0044","23.8932","0.0000"
"","10.1400","8.4520","0.2400","8.4520","21.1299","24.0023","0.0000"
"","10.2000","8.5017","0.2412","8.5017","21.2541","24.1167","0.0000"
"","10.2600","8.5517","0.2423","8.5517","21.3793","24.2343","0.0000"
"","10.3200","8.6020","0.2438","8.6020","21.5050","24.3793","0.0000"
"","10.3800","8.6515","0.2450","8.6515","21.6287","24.4955","0.0000"
"","10.4400","8.7016","0.2462","8.7016","21.7541","24.6201","0.0000"
"","10.5000","8.7517","0.2474","8.7517","21.8792","24.7421","0.0000"
"","10.5600","8.8018","0.2485","8.8018","22.0044","24.8523","0.0000"
"","10.6200","8.8518","0.2498","8.8518","22.1295","24.9775","0.0000"
"","10.6800","8.9019","0.2510","8.9019","22.2547","25.0951","0.0000"
"","10.7400","8.9519","0.2521","8.9519","22.3798","25.2115","0.0000"
"","10.8000","9.0014","0.2533","9.0014","22.5035","25.3298","0.0000"
"","10.8600","9.0517","0.2546","9.0517","22.6292","25.4597","0.0000"
"","10.9200","9.1018","0.2559","9.1018","22.7546","25.5938","0.0000"
"","10.9800","9.1520","0.2575","9.1520","22.8801","25.7491","0.0000"
"","11.0400","9.2020","0.2588","9.2020","23.0049","25.8776","0.0000"
"","11.1000","9.2517","0.2600","9.2517","23.1291","25.9978","0.0000"
"","11.1600","9.3018","0.2611","9.3018","23.2546","26.1088","0.0000"
"","11.2200","9.3517","0.2621","9.3517","23.3791","26.2127","0.0000"
"","11.2800","9.4018","0.2632","9.4018","23.5046","26.3203","0.0000"
"","11.3400","9.4518","0.2643","9.4518","23.6294","26.4334","0.0000"
"","11.4000","9.5017","0.2653","9.5017","23.7543","26.5306","0.0000"
"","11.4600","9.5519","0.2663","9.5519","23.8797","26.6254","0.0000"
"","11.5200","9.6017","0.2672","9.6017","24.0042","26.7242","0.0000"
"","11.5800","9.6519","0.2682","9.6519","24.1297","26.8209","0.0000"
"","11.6400","9.7018","0.2692","9.7018","24.2545","26.9230","0.0000"
"","11.7000","9.7521","0.2702","9.7521","24.3802","27.0152","0.0000"
"","11.7600","9.8017","0.2709","9.8017","24.5042","27.0939","0.0000"
"","11.8200","9.8516","0.2718","9.8516","24.6290","27.1784","0.0000"
"","11.8800","9.9019","0.2728","9.9019","24.7548","27.2788","0.0000"
"","11.9400","9.9516","0.2737","9.9516","24.8790","27.3710","0.0000"
"","12.0000","10.0019","0.2747","10.0019","25.0048","27.4732","0.0000"
"","12.0600","10.0518","0.2758","10.0518","25.1296","27.5754","0.0000"
"","12.1200","10.1018","0.2768","10.1018","25.2544","27.6798","0.0000"
"","12.1800","10.1517","0.2778","10.1517","25.3793","27.7830","0.0000"
"","12.2400","10.2017","0.2787","10.2017","25.5041","27.8716","0.0000"
"","12.3000","10.2518","0.2797","10.2518","25.6296","27.9720","0.0000"
"","12.3600","10.3016","0.2809","10.3016","25.7541","28.0877","0.0000"
"","12.4200","10.3518","0.2821","10.3518","25.8795","28.2104","0.0000"
"","12.4800","10.4014","0.2834","10.4014","26.0035","28.3379","0.0000"
"","12.5400","10.4516","0.2843","10.4516","26.1289","28.4291","0.0000"
"","12.6000","10.5020","0.2853","10.5020","26.2550","28.5314","0.0000"
"","12.6600","10.5519","0.2862","10.5519","26.3798","28.6231","0.0000"
"","12.7200","10.6022","0.2872","10.6022","26.5055","28.7194","0.0000"
"","12.7800","10.6516","0.2882","10.6516","26.6289","28.8172","0.0000"
"","12.8400","10.7017","0.2893","10.7017","26.7543","28.9317","0.0000"
"","12.9000","10.7518","0.2905","10.7518","26.8795","29.0512","0.0000"
"","12.9600","10.8017","0.2919","10.8017","27.0043","29.1879","0.0000"
"","13.0200","10.8519","0.2935","10.8519","27.1298","29.3498","0.0000"
"","13.0800","10.9017","0.2949","10.9017","27.2543","29.4946","0.0000"
"","13.1400","10.9519","0.2963","10.9519","27.3797","29.6334","0.0000"
"","13.2000","11.0016","0.2974","11.0016","27.5040","29.7394","0.0000"
"","13.2600","11.0519","0.2985","11.0519","27.6297","29.8533","0.0000"
"","13.3200","11.1016","0.2998","11.1016","27.7540","29.9800","0.0000"
"","13.3800","11.1516","0.3010","11.1516","27.8791","30.1039","0.0000"
"","13.4400","11.2018","0.3024","11.2018","28.0045","30.2438","0.0000"
"","13.5000","11.2518","0.3037","11.2518","28.1294","30.3740","0.0000"
"","13.5600","11.3019","0.3052","11.3019","28.2548","30.5223","0.0000"
"","13.6200","11.3519","0.3066","11.3519","28.3797","30.6635","0.0000"
"","13.6800","11.4018","0.3080","11.4018","28.5045","30.7969","0.0000"
"","13.7400","11.4517","0.3091","11.4517","28.6294","30.9125","0.0000"
"","13.8000","11.5016","0.3102","11.5016","28.7539","31.0168","0.0000"
"","13.8600","11.5520","0.3114","11.5520","28.8799","31.1394","0.0000"
"","13.9200","11.6018","0.3126","11.6018","29.0045","31.2597","0.0000"
"","13.9800","11.6518","0.3138","11.6518","29.1296","31.3776","0.0000"
"","14.0400","11.7017","0.3150","11.7017","29.2542","31.4989","0.0000"
"","14.1000","11.7520","0.3162","11.7520","29.3799","31.6248","0.0000"
"","14.1600","11.8018","0.3175","11.8018","29.5044","31.7528","0.0000"
"","14.2200","11.8517","0.3186","11.8517","29.6293","31.8641","0.0000"
"","14.2800","11.9019","0.3200","11.9019","29.7547","31.9954","0.0000"
"","14.3400","11.9516","0.3211","11.9516","29.8790","32.1060","0.0000"
"","14.4000","12.0021","0.3224","12.0021","30.0053","32.2358","0.0000"
"","14.4600","12.0516","0.3235","12.0516","30.1290","32.3503","0.0000"
"","14.5200","12.1018","0.3245","12.1018","30.2544","32.4542","0.0000"
"","14.5800","12.1517","0.3257","12.1517","30.3792","32.5740","0.0000"
"","14.6400","12.2015","0.3269","12.2015","30.5038","32.6913","0.0000"
"","14.7000","12.2522","0.3285","12.2522","30.6304","32.8475","0.0000"
"","14.7600","12.3019","0.3298","12.3019","30.7547","32.9812","0.0000"
"","14.8200","12.3520","0.3311","12.3520","30.8801","33.1134","0.0000"
"","14.8800","12.4016","0.3323","12.4016","31.0040","33.2348","0.0000"
"","14.9400","12.4517","0.3335","12.4517","31.1292","33.3495","0.0000"
"","15.0000","12.5021","0.3348","12.5021","31.2552","33.4813","0.0000"
"","15.0600","12.5518","0.3357","12.5518","31.3795","33.5730","0.0000"
"","15.1200","12.6017","0.3368","12.6017","31.5043","33.6849","0.0000"
"","15.1800","12.6515","0.3379","12.6515","31.6289","33.7916","0.0000"
"","15.2400","12.7017","0.3390","12.7017","31.7543","33.9008","0.0000"
"","15.3000","12.7514","0.3401","12.7514","31.8785","34.0069","0.0000"
"","15.3600","12.8017","0.3411","12.8017","32.0043","34.1110","0.0000"
"","15.4200","12.8521","0.3422","12.8521","32.1303","34.2159","0.0000"
"","15.4800","12.9018","0.3430","12.9018","32.2545","34.2980","0.0000"
"","15.5400","12.9521","0.3440","12.9521","32.3803","34.3975","0.0000"
"","15.6000","13.0016","0.3450","13.0016","32.5039","34.5041","0.0000"
"","15.6600","13.0518","0.3463","13.0518","32.6294","34.6275","0.0000"
"","15.7200","13.1019","0.3477","13.1019","32.7548","34.7707","0.0000"
"","15.7800","13.1519","0.3492","13.1519","32.8797","34.9154","0.0000"
"","15.8400","13.2020","0.3505","13.2020","33.0051","35.0473","0.0000"
"","15.9000","13.2517","0.3517","13.2517","33.1293","35.1700","0.0000"
"","15.9600","13.3020","0.3532","13.3020","33.2551","35.3191","0.0000"
"","16.0200","13.3518","0.3547","13.3518","33.3796","35.4659","0.0000"
"","16.0800","13.4018","0.3560","13.4018","33.5045","35.6014","0.0000"
"","16.1400","13.4518","0.3574","13.4518","33.6296","35.7387","0.0000"
"","16.2000","13.5014","0.3585","13.5014","33.7536","35.8509","0.0000"
"","16.2600","13.5522","0.3597","13.5522","33.8805","35.9710","0.0000"
"","16.3200","13.6018","0.3607","13.6018","34.0044","36.0702","0.0000"
"","16.3800","13.6517","0.3618","13.6517","34.1293","36.1787","0.0000"
"","16.4400","13.7015","0.3631","13.7015","34.2538","36.3057","0.0000"
"","16.5000","13.7517","0.3643","13.7517","34.3792","36.4320","0.0000"
"","16.5600","13.8020","0.3657","13.8020","34.5050","36.5694","0.0000"
"","16.6200","13.8515","0.3669","13.8515","34.6286","36.6942","0.0000"
"","16.6800","13.9019","0.3683","13.9019","34.7547","36.8272","0.0000"
"","16.7400","13.9517","0.3695","13.9517","34.8792","36.9491","0.0000"
"","16.8000","14.0019","0.3707","14.0019","35.0047","37.0666","0.0000"
"","16.8600","14.0518","0.3721","14.0518","35.1295","37.2095","0.0000"
"","16.9200","14.1019","0.3732","14.1019","35.2546","37.3226","0.0000"
"","16.9800","14.1519","0.3747","14.1519","35.3798","37.4719","0.0000"
"","17.0400","14.2015","0.3760","14.2015","35.5037","37.5965","0.0000"
"","17.1000","14.2519","0.3773","14.2519","35.6298","37.7348","0.0000"
"","17.1600","14.3018","0.3786","14.3018","35.7546","37.8567","0.0000"
"","17.2200","14.3519","0.3798","14.3519","35.8797","37.9813","0.0000"
"","17.2800","14.4020","0.3812","14.4020","36.0049","38.1206","0.0000"
"","17.3400","14.4518","0.3825","14.4518","36.1294","38.2526","0.0000"
"","17.4000","14.5021","0.3840","14.5021","36.2552","38.3997","0.0000"
"","17.4600","14.5515","0.3852","14.5515","36.3788","38.5218","0.0000"
"","17.5200","14.6018","0.3865","14.6018","36.5045","38.6478","0.0000"
"","17.5800","14.6516","0.3877","14.6516","36.6291","38.7705","0.0000"
"","17.6400","14.7017","0.3890","14.7017","36.7542","38.8960","0.0000"
"","17.7000","14.7519","0.3907","14.7519","36.8797","39.0663","0.0000"
"","17.7600","14.8016","0.3922","14.8016","37.0039","39.2192","0.0000"
"","17.8200","14.8520","0.3940","14.8520","37.1299","39.3959","0.0000"
"","17.8800","14.9013","0.3954","14.9013","37.2533","39.5407","0.0000"
"","17.9400","14.9520","0.3971","14.9520","37.3799","39.7062","0.0000"
"","18.0000","15.0016","0.3983","15.0016","37.5039","39.8267","0.0000"
"","18.0600","15.0516","0.3994","15.0516","37.6290","39.9416","0.0000"
"","18.1200","15.1018","0.4007","15.1018","37.7545","40.0719","0.0000"
"","18.1800","15.1510","0.4017","15.1510","37.8775","40.1719","0.0000"
"","18.2400","15.2019","0.4031","15.2019","38.0047","40.3054","0.0000"
"","18.3000","15.2521","0.4045","15.2521","38.1302","40.4467","0.0000"
"","18.3600","15.3024","0.4059","15.3024","38.2559","40.5859","0.0000"
"","18.4200","15.3518","0.4072","15.3518","38.3796","40.7151","0.0000"
"","18.4800","15.4016","0.4083","15.4016","38.5041","40.8264","0.0000"
"","18.5400","15.4521","0.4098","15.4521","38.6301","40.9769","0.0000"
"","18.6000","15.5015","0.4110","15.5015","38.7538","41.0975","0.0000"
"","18.6600","15.5522","0.4124","15.5522","38.8804","41.2383","0.0000"
"","18.7200","15.6019","0.4137","15.6019","39.0047","41.3654","0.0000"
"","18.7800","15.6517","0.4148","15.6517","39.1292","41.4776","0.0000"
"","18.8400","15.7015","0.4159","15.7015","39.2538","41.5941","0.0000"
"","18.9000","15.7517","0.4172","15.7517","39.3792","41.7175","0.0000"
"","18.9600","15.8021","0.4191","15.8021","39.5052","41.9063","0.0000"
"","19.0200","15.8516","0.4208","15.8516","39.6289","42.0760","0.0000"
"","19.0800","15.9018","0.4228","15.9018","39.7546","42.2800","0.0000"
"","19.1400","15.9517","0.4246","15.9517","39.8792","42.4556","0.0000"
"","19.2000","16.0020","0.4264","16.0020","40.0049","42.6358","0.0000"
"","19.2600","16.0519","0.4283","16.0519","40.1297","42.8278","0.0000"
"","19.3200","16.1018","0.4298","16.1018","40.2546","42.9837","0.0000"
"","19.3800","16.1518","0.4315","16.1518","40.3794","43.1536","0.0000"
"","19.4400","16.2015","0.4328","16.2015","40.5037","43.2784","0.0000"
"","19.5000","16.2519","0.4343","16.2519","40.6297","43.4254","0.0000"
"","19.5600","16.3017","0.4358","16.3017","40.7543","43.5786","0.0000"
"","19.6200","16.3519","0.4374","16.3519","40.8797","43.7370","0.0000"
"","19.6800","16.4018","0.4391","16.4018","41.0045","43.9062","0.0000"
"","19.7400","16.4515","0.4407","16.4515","41.1288","44.0714","0.0000"
"","19.8000","16.5020","0.4424","16.5020","41.2551","44.2390","0.0000"
"","19.8600","16.5516","0.4440","16.5516","41.3791","44.3982","0.0000"
"","19.9200","16.6018","0.4455","16.6018","41.5045","44.5466","0.0000"
"","19.9800","16.6519","0.4472","16.6519","41.6296","44.7221","0.0000"
"","20.0400","16.7020","0.4490","16.7020","41.7551","44.9014","0.0000"
"","20.1000","16.7520","0.4509","16.7520","41.8799","45.0876","0.0000"
"","20.1600","16.8018","0.4524","16.8018","42.0045","45.2379","0.0000"
"","20.2200","16.8520","0.4543","16.8520","42.1299","45.4327","0.0000"
"","20.2800","16.9015","0.4560","16.9015","42.2539","45.6046","0.0000"
"","20.3400","16.9520","0.4578","16.9520","42.3799","45.7843","0.0000"
"","20.4000","17.0018","0.4597","17.0018","42.5044","45.9685","0.0000"
"","20.4600","17.0519","0.4616","17.0519","42.6299","46.1567","0.0000"
"","20.5200","17.1021","0.4636","17.1021","42.7553","46.3566","0.0000"
"","20.5800","17.1515","0.4651","17.1515","42.8787","46.5141","0.0000"
"","20.6400","17.2016","0.4672","17.2016","43.0041","46.7179","0.0000"
"","20.7000","17.2515","0.4689","17.2515","43.1286","46.8927","0.0000"
"","20.7600","17.3021","0.4706","17.3021","43.2553","47.0581","0.0000"
"","20.8200","17.3519","0.4727","17.3519","43.3798","47.2741","0.0000"
"","20.8800","17.4017","0.4750","17.4017","43.5044","47.4970","0.0000"
"","20.9400","17.4518","0.4778","17.4518","43.6295","47.7816","0.0000"
"","21.0000","17.5014","0.4804","17.5014","43.7535","48.0354","0.0000"
"","21.0600","17.5519","0.4830","17.5519","43.8798","48.2950","0.0000"
"","21.1200","17.6020","0.4854","17.6020","44.0049","48.5362","0.0000"
"","21.1800","17.6521","0.4877","17.6521","44.1303","48.7684","0.0000"
"","21.2400","17.7018","0.4902","17.7018","44.2546","49.0178","0.0000"
"","21.3000","17.7515","0.4925","17.7515","44.3789","49.2505","0.0000"
"","21.3600","17.8022","0.4952","17.8022","44.5055","49.5222","0.0000"
"","21.4200","17.8518","0.4975","17.8518","44.6294","49.7463","0.0000"
"","21.4800","17.9018","0.4997","17.9018","44.7546","49.9729","0.0000"
"","21.5400","17.9515","0.5018","17.9515","44.8788","50.1822","0.0000"
"","21.6000","18.0018","0.5037","18.0018","45.0046","50.3718","0.0000"
"","21.6600","18.0519","0.5057","18.0519","45.1297","50.5691","0.0000"
"","21.7200","18.1017","0.5072","18.1017","45.2542","50.7151","0.0000"
"","21.7800","18.1520","0.5089","18.1520","45.3800","50.8864","0.0000"
"","21.8400","18.2015","0.5101","18.2015","45.5036","51.0134","0.0000"
"","21.9000","18.2520","0.5113","18.2520","45.6299","51.1326","0.0000"
"","21.9600","18.3017","0.5125","18.3017","45.7542","51.2475","0.0000"
"","22.0200","18.3517","0.5137","18.3517","45.8793","51.3666","0.0000"
"","22.0800","18.4020","0.5156","18.4020","46.0051","51.5610","0.0000"
"","22.1400","18.4517","0.5172","18.4517","46.1293","51.7166","0.0000"
"","22.2000","18.5020","0.5189","18.5020","46.2551","51.8942","0.0000"
"","22.2600","18.5516","0.5202","18.5516","46.3790","52.0168","0.0000"
"","22.3200","18.6018","0.5218","18.6018","46.5044","52.1808","0.0000"
"","22.3800","18.6517","0.5234","18.6517","46.6293","52.3357","0.0000"
"","22.4400","18.7018","0.5250","18.7018","46.7544","52.5038","0.0000"
"","22.5000","18.7522","0.5268","18.7522","46.8805","52.6822","0.0000"
"","22.5600","18.8016","0.5281","18.8016","47.0041","52.8119","0.0000"
"","22.6200","18.8518","0.5295","18.8518","47.1296","52.9536","0.0000"
"","22.6800","18.9015","0.5309","18.9015","47.2538","53.0940","0.0000"
"","22.7400","18.9516","0.5325","18.9516","47.3789","53.2507","0.0000"
"","22.8000","19.0019","0.5343","19.0019","47.5047","53.4286","0.0000"
"","22.8600","19.0519","0.5358","19.0519","47.6298","53.5751","0.0000"
"","22.9200","19.1021","0.5372","19.1021","47.7552","53.7240","0.0000"
"","22.9800","19.1514","0.5384","19.1514","47.8786","53.8406","0.0000"
"","23.0400","19.2019","0.5403","19.2019","48.0046","54.0341","0.0000"
"","23.1000","19.2516","0.5422","19.2516","48.1289","54.2184","0.0000"
"","23.1600","19.3018","0.5441","19.3018","48.2546","54.4077","0.0000"
"","23.2200","19.3519","0.5461","19.3519","48.3798","54.6142","0.0000"
"","23.2800","19.4016","0.5479","19.4016","48.5040","54.7938","0.0000"
"","23.3400","19.4518","0.5500","19.4518","48.6294","54.9996","0.0000"
"","23.4000","19.5016","0.5517","19.5016","48.7540","55.1721","0.0000"
"","23.4600","19.5519","0.5535","19.5519","48.8797","55.3546","0.0000"
"","23.5200","19.6016","0.5552","19.6016","49.0040","55.5213","0.0000"
"","23.5800","19.6519","0.5570","19.6519","49.1297","55.7018","0.0000"
"","23.6400","19.7019","0.5590","19.7019","49.2548","55.9023","0.0000"
"","23.7000","19.7516","0.5607","19.7516","49.3791","56.0682","0.0000"
"","23.7600","19.8019","0.5628","19.8019","49.5048","56.2770","0.0000"
"","23.8200","19.8514","0.5645","19.8514","49.6285","56.4456","0.0000"
"","23.8800","19.9015","0.5664","19.9015","49.7536","56.6420","0.0000"
"","23.9400","19.9515","0.5685","19.9515","49.8788","56.8547","0.0000"
"","24.0000","20.0022","0.5707","20.0022","50.0054","57.0738","0.0000"
"","24.0600","20.0522","0.5730","20.0522","50.1305","57.3046","0.0000"
"","24.1200","20.1016","0.5747","20.1016","50.2539","57.4744","0.0000"
"","24.1800","20.1517","0.5769","20.1517","50.3793","57.6851","0.0000"
"","24.2400","20.2015","0.5788","20.2015","50.5039","57.8839","0.0000"
"","24.3000","20.2520","0.5809","20.2520","50.6299","58.0912","0.0000"
"","24.3600","20.3020","0.5831","20.3020","50.7550","58.3139","0.0000"
"","24.4200","20.3517","0.5857","20.3517","50.8793","58.5706","0.0000"
"","24.4800","20.4019","0.5937","20.4019","51.0047","59.3739","0.0000"
"","24.5400","20.4515","0.6019","20.4515","51.1287","60.1902","0.0000"
"","24.6000","20.5018","0.6103","20.5018","51.2544","61.0281","0.0000"
"","24.6600","20.5516","0.6187","20.5516","51.3790","61.8694","0.0000"
"","24.7200","20.6018","0.6266","20.6018","51.5044","62.6615","0.0000"
"","24.7800","20.6517","0.6342","20.6517","51.6292","63.4198","0.0000"
"","24.8400","20.7018","0.6411","20.7018","51.7544","64.1121","0.0000"
"","24.9000","20.7518","0.6478","20.7518","51.8795","64.7782","0.0000"
"","24.9600","20.8016","0.6542","20.8016","52.0041","65.4236","0.0000"
"","25.0200","20.8517","0.6600","20.8517","52.1292","66.0041","0.0000"
"","25.0800","20.9020","0.6655","20.9020","52.2549","66.5456","0.0000"
"","25.1400","20.9518","0.6701","20.9518","52.3795","67.0085","0.0000"
"","25.2000","21.0018","0.6749","21.0019","52.5046","67.4885","0.0000"
"","25.2600","21.0513","0.6792","21.0513","52.6283","67.9209","0.0000"
"","25.3200","21.1020","0.6846","21.1020","52.7549","68.4571","0.0000"
"","25.3800","21.1517","0.6896","21.1517","52.8792","68.9569","0.0000"
"","25.4400","21.2018","0.6951","21.2018","53.0046","69.5089","0.0000"
"","25.5000","21.2519","0.7010","21.2519","53.1297","70.1049","0.0000"
"","25.5600","21.3016","0.7065","21.3016","53.2540","70.6537","0.0000"
"","25.6200","21.3519","0.7124","21.3519","53.3797","71.2379","0.0000"
"","25.6800","21.4015","0.7184","21.4015","53.5037","71.8353","0.0000"
"","25.7400","21.4519","0.7246","21.4519","53.6297","72.4598","0.0000"
"","25.8000","21.5017","0.7311","21.5017","53.7542","73.1140","0.0000"
"","25.8600","21.5518","0.7370","21.5518","53.8794","73.7029","0.0000"
"","25.9200","21.6019","0.7436","21.6019","54.0048","74.3642","0.0000"
"","25.9800","21.6519","0.7500","21.6519","54.1297","74.9994","0.0000"
"","26.0400","21.7019","0.7568","21.7019","54.2548","75.6782","0.0000"
"","26.1000","21.7513","0.7632","21.7513","54.3782","76.3202","0.0000"
"","26.1600","21.8018","0.7696","21.8018","54.5045","76.9595","0.0000"
"","26.2200","21.8516","0.7732","21.8516","54.6290","77.3163","0.0000"
"","26.2800","21.9019","0.7723","21.9019","54.7548","77.2341","0.0000"
"","26.3400","21.9520","0.7671","21.9520","54.8799","76.7126","0.0000"
"","26.4000","22.0019","0.7580","22.0019","55.0047","75.8002","0.0000"
"","26.4600","22.0521","0.7480","22.0521","55.1302","74.8005","0.0000"
"","26.5200","22.1018","0.7392","22.1018","55.2544","73.9204","0.0000"
"","26.5800","22.1517","0.7339","22.1517","55.3793","73.3921","0.0000"
"","26.6400","22.2016","0.7332","22.2016","55.5041","73.3191","0.0000"
"","26.7000","22.2517","0.7364","22.2517","55.6293","73.6409","0.0000"
"","26.7600","22.3020","0.7426","22.3020","55.7550","74.2599","0.0000"
"","26.8200","22.3518","0.7489","22.3518","55.8795","74.8869","0.0000"
"","26.8800","22.4021","0.7559","22.4021","56.0053","75.5939","0.0000"
"","26.9400","22.4515","0.7619","22.4515","56.1286","76.1871","0.0000"
"","27.0000","22.5019","0.7685","22.5019","56.2547","76.8493","0.0000"
"","27.0600","22.5518","0.7752","22.5518","56.3795","77.5232","0.0000"
"","27.1200","22.6017","0.7817","22.6017","56.5043","78.1673","0.0000"
"","27.1800","22.6519","0.7891","22.6519","56.6298","78.9063","0.0000"
"","27.2400","22.7016","0.7959","22.7016","56.7540","79.5948","0.0000"
"","27.3000","22.7519","0.8037","22.7519","56.8798","80.3746","0.0000"
"","27.3600","22.8016","0.8116","22.8016","57.0040","81.1601","0.0000"
"","27.4200","22.8520","0.8195","22.8520","57.1300","81.9507","0.0000"
"","27.4800","22.9020","0.8275","22.9020","57.2549","82.7451","0.0000"
"","27.5400","22.9517","0.8345","22.9517","57.3791","83.4499","0.0000"
"","27.6000","23.0019","0.8421","23.0019","57.5049","84.2064","0.0000"
"","27.6600","23.0514","0.8486","23.0514","57.6285","84.8558","0.0000"
"","27.7200","23.1019","0.8552","23.1019","57.7548","85.5233","0.0000"
"","27.7800","23.1519","0.8620","23.1519","57.8797","86.2024","0.0000"
"","27.8400","23.2019","0.8676","23.2019","58.0048","86.7552","0.0000"
"","27.9000","23.2519","0.8732","23.2519","58.1297","87.3208","0.0000"
"","27.9600","23.3017","0.8784","23.3017","58.2542","87.8362","0.0000"
"","28.0200","23.3516","0.8833","23.3516","58.3791","88.3313","0.0000"
"","28.0800","23.4016","0.8881","23.4016","58.5039","88.8121","0.0000"
"","28.1400","23.4517","0.8930","23.4517","58.6293","89.3001","0.0000"
"","28.2000","23.5016","0.8971","23.5016","58.7539","89.7074","0.0000"
"","28.2600","23.5518","0.9004","23.5518","58.8796","90.0360","0.0000"
"","28.3200","23.6020","0.9036","23.6020","59.0051","90.3572","0.0000"
"","28.3800","23.6512","0.9058","23.6512","59.1281","90.5754","0.0000"
"","28.4400","23.7017","0.9081","23.7017","59.2541","90.8064","0.0000"
"","28.5000","23.7517","0.9103","23.7517","59.3793","91.0303","0.0000"
"","28.5600","23.8020","0.9119","23.8020","59.5050","91.1943","0.0000"
"","28.6200","23.8519","0.9134","23.8519","59.6299","91.3352","0.0000"
"","28.6800","23.9018","0.9141","23.9018","59.7544","91.4088","0.0000"
"","28.7400","23.9519","0.9153","23.9519","59.8798","91.5256","0.0000"
"","28.8000","24.0016","0.9151","24.0016","60.0041","91.5150","0.0000"
"","28.8600","24.0522","0.9150","24.0522","60.1304","91.4983","0.0000"
"","28.9200","24.1018","0.9138","24.1018","60.2544","91.3778","0.0000"
"","28.9800","24.1518","0.9122","24.1518","60.3795","91.2241","0.0000"
"","29.0400","24.2016","0.9112","24.2016","60.5041","91.1195","0.0000"
"","29.1000","24.2516","0.9093","24.2516","60.6289","90.9334","0.0000"
"","29.1600","24.3021","0.9079","24.3021","60.7552","90.7930","0.0000"
"","29.2200","24.3516","0.9056","24.3516","60.8789","90.5589","0.0000"
"","29.2800","24.4020","0.9032","24.4020","61.0049","90.3191","0.0000"
"","29.3400","24.4517","0.9001","24.4517","61.1292","90.0085","0.0000"
"","29.4000","24.5018","0.8958","24.5018","61.2546","89.5841","0.0000"
"","29.4600","24.5519","0.8915","24.5519","61.3797","89.1488","0.0000"
"","29.5200","24.6016","0.8848","24.6016","61.5040","88.4824","0.0000"
"","29.5800","24.6518","0.8778","24.6518","61.6294","87.7781","0.0000"
"","29.6400","24.7017","0.8688","24.7017","61.7543","86.8827","0.0000"
"","29.7000","24.7520","0.8581","24.7520","61.8800","85.8060","0.0000"
"","29.7600","24.8018","0.8453","24.8018","62.0046","84.5341","0.0000"
"","29.8200","24.8519","0.8309","24.8519","62.1297","83.0916","0.0000"
"","29.8800","24.9018","0.8185","24.9018","62.2545","81.8515","0.0000"
"","29.9400","24.9516","0.8077","24.9516","62.3791","80.7692","0.0000"
"","30.0000","25.0020","0.7991","25.0020","62.5051","79.9149","0.0000"
"","30.0600","25.0519","0.7914","25.0519","62.6297","79.1437","0.0000"
"","30.1200","25.1020","0.7844","25.1020","62.7551","78.4441","0.0000"
"","30.1800","25.1517","0.7779","25.1517","62.8793","77.7936","0.0000"
"","30.2400","25.2018","0.7715","25.2018","63.0045","77.1515","0.0000"
"","30.3000","25.2518","0.7659","25.2518","63.1296","76.5869","0.0000"
"","30.3600","25.3017","0.7601","25.3017","63.2542","76.0105","0.0000"
"","30.4200","25.3518","0.7548","25.3518","63.3796","75.4815","0.0000"
"","30.4800","25.4017","0.7497","25.4017","63.5041","74.9709","0.0000"
"","30.5400","25.4520","0.7447","25.4520","63.6299","74.4698","0.0000"
"","30.6000","25.5019","0.7397","25.5019","63.7547","73.9718","0.0000"
"","30.6600","25.5518","0.7346","25.5518","63.8796","73.4580","0.0000"
"","30.7200","25.6020","0.7299","25.6020","64.0050","72.9883","0.0000"
"","30.7800","25.6515","0.7245","25.6515","64.1287","72.4549","0.0000"
"","30.8400","25.7019","0.7195","25.7019","64.2547","71.9479","0.0000"
"","30.9000","25.7516","0.7138","25.7516","64.3789","71.3771","0.0000"
"","30.9600","25.8019","0.7071","25.8019","64.5047","70.7084","0.0000"
"","31.0200","25.8518","0.6990","25.8518","64.6295","69.9037","0.0000"
"","31.0800","25.9017","0.6894","25.9017","64.7544","68.9411","0.0000"
"","31.1400","25.9519","0.6808","25.9519","64.8798","68.0754","0.0000"
"","31.2000","26.0013","0.6740","26.0013","65.0032","67.4040","0.0000"
"","31.2600","26.0518","0.6692","26.0518","65.1295","66.9201","0.0000"
"","31.3200","26.1020","0.6655","26.1020","65.2549","66.5527","0.0000"
"","31.3800","26.1520","0.6622","26.1520","65.3800","66.2249","0.0000"
"","31.4400","26.2020","0.6595","26.2020","65.5049","65.9495","0.0000"
"","31.5000","26.2519","0.6567","26.2519","65.6297","65.6672","0.0000"
"","31.5600","26.3021","0.6545","26.3021","65.7552","65.4539","0.0000"
"","31.6200","26.3517","0.6523","26.3517","65.8791","65.2269","0.0000"
"","31.6800","26.4017","0.6503","26.4017","66.0043","65.0301","0.0000"
"","31.7400","26.4515","0.6485","26.4515","66.1288","64.8545","0.0000"
"","31.8000","26.5019","0.6464","26.5019","66.2548","64.6361","0.0000"
"","31.8600","26.5521","0.6449","26.5521","66.3803","64.4871","0.0000"
"","31.9200","26.6017","0.6430","26.6017","66.5042","64.2973","0.0000"
"","31.9800","26.6519","0.6415","26.6519","66.6297","64.1507","0.0000"
"","32.0400","26.7015","0.6400","26.7015","66.7536","63.9959","0.0000"
"","32.1000","26.7517","0.6386","26.7517","66.8794","63.8559","0.0000"
"","32.1600","26.8019","0.6374","26.8019","67.0048","63.7398","0.0000"
"","32.2200","26.8516","0.6359","26.8516","67.1290","63.5883","0.0000"
"","32.2800","26.9018","0.6350","26.9018","67.2545","63.4963","0.0000"
"","32.3400","26.9515","0.6337","26.9515","67.3787","63.3721","0.0000"
"","32.4000","27.0018","0.6330","27.0018","67.5045","63.2955","0.0000"
"","32.4600","27.0517","0.6320","27.0517","67.6293","63.2017","0.0000"
"","32.5200","27.1020","0.6311","27.1020","67.7550","63.1113","0.0000"
"","32.5800","27.1518","0.6307","27.1518","67.8796","63.0668","0.0000"
"","32.6400","27.2019","0.6304","27.2019","68.0047","63.0403","0.0000"
"","32.7000","27.2519","0.6311","27.2519","68.1299","63.1100","0.0000"
"","32.7600","27.3019","0.6319","27.3019","68.2547","63.1940","0.0000"
"","32.8200","27.3522","0.6340","27.3522","68.3804","63.3973","0.0000"
"","32.8800","27.4015","0.6370","27.4015","68.5038","63.6991","0.0000"
"","32.9400","27.4517","0.6396","27.4517","68.6292","63.9647","0.0000"
"","33.0000","27.5018","0.6427","27.5018","68.7544","64.2686","0.0000"
"","33.0600","27.5518","0.6453","27.5518","68.8795","64.5298","0.0000"
"","33.1200","27.6020","0.6479","27.6020","69.0050","64.7945","0.0000"
"","33.1800","27.6514","0.6502","27.6514","69.1286","65.0238","0.0000"
"","33.2400","27.7016","0.6534","27.7016","69.2540","65.3443","0.0000"
"","33.3000","27.7516","0.6565","27.7516","69.3789","65.6473","0.0000"
"","33.3600","27.8021","0.6592","27.8021","69.5052","65.9193","0.0000"
"","33.4200","27.8520","0.6617","27.8520","69.6301","66.1730","0.0000"
"","33.4800","27.9017","0.6637","27.9017","69.7543","66.3675","0.0000"
"","33.5400","27.9518","0.6659","27.9518","69.8794","66.5936","0.0000"
"","33.6000","28.0017","0.6676","28.0017","70.0043","66.7625","0.0000"
"","33.6600","28.0519","0.6692","28.0519","70.1297","66.9237","0.0000"
"","33.7200","28.1017","0.6709","28.1017","70.2543","67.0862","0.0000"
"","33.7800","28.1516","0.6720","28.1516","70.3791","67.1952","0.0000"
"","33.8400","28.2017","0.6733","28.2017","70.5042","67.3309","0.0000"
"","33.9000","28.2519","0.6742","28.2519","70.6297","67.4200","0.0000"
"","33.9600","28.3022","0.6751","28.3022","70.7554","67.5138","0.0000"
"","34.0200","28.3514","0.6754","28.3514","70.8785","67.5443","0.0000"
"","34.0800","28.4017","0.6760","28.4017","71.0042","67.6031","0.0000"
"","34.1400","28.4516","0.6771","28.4516","71.1291","67.7072","0.0000"
"","34.2000","28.5020","0.6776","28.5020","71.2551","67.7617","0.0000"
"","34.2600","28.5522","0.6780","28.5522","71.3805","67.8030","0.0000"
"","34.3200","28.6017","0.6780","28.6017","71.5042","67.7959","0.0000"
"","34.3800","28.6518","0.6784","28.6518","71.6296","67.8403","0.0000"
"","34.4400","28.7014","0.6785","28.7014","71.7536","67.8543","0.0000"
"","34.5000","28.7520","0.6793","28.7520","71.8799","67.9323","0.0000"
"","34.5600","28.8020","0.6799","28.8020","72.0050","67.9915","0.0000"
"","34.6200","28.8520","0.6804","28.8520","72.1299","68.0433","0.0000"
"","34.6800","28.9019","0.6809","28.9019","72.2547","68.0900","0.0000"
"","34.7400","28.9516","0.6814","28.9516","72.3790","68.1393","0.0000"
"","34.8000","29.0019","0.6817","29.0019","72.5047","68.1655","0.0000"
"","34.8600","29.0518","0.6822","29.0518","72.6295","68.2239","0.0000"
"","34.9200","29.1020","0.6823","29.1020","72.7550","68.2298","0.0000"
"","34.9800","29.1518","0.6827","29.1518","72.8795","68.2697","0.0000"
"","35.0400","29.2016","0.6824","29.2016","73.0041","68.2404","0.0000"
"","35.1000","29.2520","0.6827","29.2520","73.1301","68.2686","0.0000"
"","35.1600","29.3017","0.6825","29.3017","73.2544","68.2540","0.0000"
"","35.2200","29.3519","0.6826","29.3519","73.3798","68.2583","0.0000"
"","35.2800","29.4017","0.6824","29.4017","73.5043","68.2445","0.0000"
"","35.3400","29.4519","0.6823","29.4519","73.6298","68.2321","0.0000"
"","35.4000","29.5020","0.6820","29.5020","73.7549","68.1969","0.0000"
"","35.4600","29.5515","0.6816","29.5515","73.8789","68.1626","0.0000"
"","35.5200","29.6018","0.6811","29.6018","74.0046","68.1095","0.0000"
"","35.5800","29.6517","0.6807","29.6517","74.1292","68.0749","0.0000"
"","35.6400","29.7020","0.6800","29.7020","74.2549","68.0021","0.0000"
"","35.7000","29.7518","0.6796","29.7518","74.3794","67.9634","0.0000"
"","35.7600","29.8018","0.6785","29.8018","74.5046","67.8482","0.0000"
"","35.8200","29.8519","0.6780","29.8519","74.6297","67.8000","0.0000"
"","35.8800","29.9015","0.6768","29.9015","74.7537","67.6809","0.0000"
"","35.9400","29.9519","0.6758","29.9519","74.8797","67.5828","0.0000"
"","36.0000","30.0016","0.6747","30.0016","75.0039","67.4706","0.0000"
"","36.0600","30.0518","0.6730","30.0518","75.1294","67.2999","0.0000"
"","36.1200","30.1018","0.6719","30.1018","75.2545","67.1884","0.0000"
"","36.1800","30.1517","0.6698","30.1517","75.3794","66.9820","0.0000"
"","36.2400","30.2018","0.6684","30.2018","75.5045","66.8406","0.0000"
"","36.3000","30.2516","0.6664","30.2516","75.6290","66.6381","0.0000"
"","36.3600","30.3020","0.6646","30.3020","75.7551","66.4625","0.0000"
"","36.4200","30.3518","0.6630","30.3518","75.8796","66.3019","0.0000"
"","36.4800","30.4020","0.6608","30.4020","76.0051","66.0807","0.0000"
"","36.5400","30.4517","0.6592","30.4517","76.1293","65.9210","0.0000"
"","36.6000","30.5017","0.6568","30.5017","76.2541","65.6847","0.0000"
"","36.6600","30.5520","0.6552","30.5520","76.3799","65.5217","0.0000"
"","36.7200","30.6018","0.6535","30.6018","76.5044","65.3538","0.0000"
"","36.7800","30.6519","0.6517","30.6519","76.6299","65.1701","0.0000"
"","36.8400","30.7016","0.6506","30.7016","76.7541","65.0555","0.0000"
"","36.9000","30.7516","0.6517","30.7516","76.8790","65.1691","0.0000"
"","36.9600","30.8020","0.6558","30.8020","77.0050","65.5794","0.0000"
"","37.0200","30.8517","0.6586","30.8517","77.1292","65.8636","0.0000"
"","37.0800","30.9021","0.6617","30.9021","77.2553","66.1655","0.0000"
"","37.1400","30.9518","0.6640","30.9518","77.3795","66.3994","0.0000"
"","37.2000","31.0020","0.6660","31.0020","77.5050","66.6022","0.0000"
"","37.2600","31.0517","0.6682","31.0517","77.6292","66.8159","0.0000"
"","37.3200","31.1017","0.6694","31.1017","77.7543","66.9403","0.0000"
"","37.3800","31.1519","0.6713","31.1519","77.8798","67.1316","0.0000"
"","37.4400","31.2015","0.6728","31.2015","78.0037","67.2784","0.0000"
"","37.5000","31.2520","0.6744","31.2520","78.1301","67.4405","0.0000"
"","37.5600","31.3020","0.6764","31.3020","78.2549","67.6393","0.0000"
"","37.6200","31.3518","0.6781","31.3518","78.3794","67.8139","0.0000"
"","37.6800","31.4020","0.6802","31.4020","78.5049","68.0185","0.0000"
"","37.7400","31.4518","0.6818","31.4518","78.6294","68.1842","0.0000"
"","37.8000","31.5019","0.6835","31.5019","78.7549","68.3501","0.0000"
"","37.8600","31.5516","0.6852","31.5516","78.8791","68.5198","0.0000"
"","37.9200","31.6019","0.6867","31.6019","79.0048","68.6675","0.0000"
"","37.9800","31.6516","0.6886","31.6516","79.1291","68.8584","0.0000"
"","38.0400","31.7018","0.6901","31.7018","79.2545","69.0069","0.0000"
"","38.1000","31.7518","0.6924","31.7518","79.3794","69.2412","0.0000"
"","38.1600","31.8017","0.6943","31.8017","79.5042","69.4308","0.0000"
"","38.2200","31.8521","0.6967","31.8521","79.6302","69.6733","0.0000"
"","38.2800","31.9016","0.6990","31.9016","79.7539","69.8960","0.0000"
"","38.3400","31.9520","0.7012","31.9520","79.8799","70.1210","0.0000"
"","38.4000","32.0014","0.7034","32.0014","80.0036","70.3445","0.0000"
"","38.4600","32.0516","0.7053","32.0516","80.1290","70.5315","0.0000"
"","38.5200","32.1019","0.7079","32.1019","80.2548","70.7923","0.0000"
"","38.5800","32.1516","0.7101","32.1516","80.3790","71.0082","0.0000"
"","38.6400","32.2018","0.7129","32.2018","80.5044","71.2870","0.0000"
"","38.7000","32.2516","0.7162","32.2516","80.6290","71.6204","0.0000"
"","38.7600","32.3020","0.7190","32.3020","80.7550","71.9032","0.0000"
"","38.8200","32.3516","0.7213","32.3516","80.8790","72.1336","0.0000"
"","38.8800","32.4016","0.7232","32.4016","81.0041","72.3183","0.0000"
"","38.9400","32.4517","0.7265","32.4517","81.1293","72.6519","0.0000"
"","39.0000","32.5015","0.7296","32.5015","81.2538","72.9643","0.0000"
"","39.0600","32.5520","0.7335","32.5520","81.3801","73.3514","0.0000"
"","39.1200","32.6019","0.7375","32.6019","81.5047","73.7503","0.0000"
"","39.1800","32.6519","0.7408","32.6519","81.6298","74.0811","0.0000"
"","39.2400","32.7017","0.7439","32.7017","81.7544","74.3886","0.0000"
"","39.3000","32.7514","0.7466","32.7514","81.8786","74.6640","0.0000"
"","39.3600","32.8021","0.7505","32.8021","82.0052","75.0459","0.0000"
"","39.4200","32.8516","0.7536","32.8516","82.1289","75.3551","0.0000"
"","39.4800","32.9018","0.7566","32.9018","82.2546","75.6610","0.0000"
"","39.5400","32.9514","0.7598","32.9514","82.3786","75.9782","0.0000"
"","39.6000","33.0020","0.7625","33.0020","82.5049","76.2534","0.0000"
"","39.6600","33.0519","0.7651","33.0519","82.6297","76.5121","0.0000"
"","39.7200","33.1014","0.7674","33.1014","82.7534","76.7432","0.0000"
"","39.7800","33.1518","0.7741","33.1518","82.8794","77.4083","0.0000"
"","39.8400","33.2016","0.7826","33.2016","83.0040","78.2585","0.0000"
"","39.9000","33.2522","0.7932","33.2522","83.1306","79.3181","0.0000"
"","39.9600","33.3017","0.8051","33.3017","83.2543","80.5141","0.0000"
"","40.0200","33.3518","0.8175","33.3518","83.3794","81.7451","0.0000"
"","40.0800","33.4017","0.8305","33.4017","83.5042","83.0475","0.0000"
"","40.1400","33.4515","0.8421","33.4515","83.6288","84.2118","0.0000"
"","40.2000","33.5022","0.8550","33.5022","83.7554","85.4999","0.0000"
"","40.2600","33.5516","0.8669","33.5516","83.8791","86.6900","0.0000"
"","40.3200","33.6018","0.8781","33.6018","84.0045","87.8060","0.0000"
"","40.3800","33.6516","0.8891","33.6516","84.1290","88.9145","0.0000"
"","40.4400","33.7016","0.8994","33.7016","84.2539","89.9367","0.0000"
"","40.5000","33.7518","0.9108","33.7518","84.3796","91.0760","0.0000"
"","40.5600","33.8015","0.9206","33.8015","84.5039","92.0554","0.0000"
"","40.6200","33.8520","0.9300","33.8520","84.6299","93.0044","0.0000"
"","40.6800","33.9015","0.9397","33.9015","84.7539","93.9704","0.0000"
"","40.7400","33.9517","0.9500","33.9517","84.8793","94.9993","0.0000"
"","40.8000","34.0017","0.9598","34.0017","85.0041","95.9814","0.0000"
"","40.8600","34.0517","0.9692","34.0517","85.1293","96.9248","0.0000"
"","40.9200","34.1020","0.9796","34.1020","85.2550","97.9592","0.0000"
"","40.9800","34.1515","0.9882","34.1515","85.3787","98.8211","0.0000"
"","41.0400","34.2020","1.0001","34.2020","85.5050","100.0119","0.0000"
"","41.1000","34.2515","1.0116","34.2515","85.6286","101.1628","0.0000"
"","41.1600","34.3018","1.0227","34.3018","85.7544","102.2688","0.0000"
"","41.2200","34.3516","1.0355","34.3516","85.8789","103.5485","0.0000"
"","41.2800","34.4016","1.0469","34.4016","86.0041","104.6897","0.0000"
"","41.3400","34.4519","1.0596","34.4519","86.1298","105.9605","0.0000"
"","41.4000","34.5014","1.0721","34.5014","86.2535","107.2064","0.0000"
"","41.4600","34.5519","1.0836","34.5519","86.3798","108.3626","0.0000"
"","41.5200","34.6017","1.0976","34.6017","86.5043","109.7583","0.0000"
"","41.5800","34.6518","1.1107","34.6518","86.6295","111.0660","0.0000"
"","41.6400","34.7016","1.1263","34.7016","86.7540","112.6267","0.0000"
"","41.7000","34.7517","1.1423","34.7517","86.8791","114.2286","0.0000"
"","41.7600","34.8021","1.1595","34.8021","87.0052","115.9544","0.0000"
"","41.8200","34.8515","1.1777","34.8515","87.1288","117.7695","0.0000"
"","41.8800","34.9016","1.1958","34.9016","87.2540","119.5805","0.0000"
"","41.9400","34.9515","1.2167","34.9515","87.3788","121.6704","0.0000"
"","42.0000","35.0016","1.2373","35.0016","87.5040","123.7258","0.0000"