File: Fig6C/211130_Instron/211130/PureCompression_TTball_1_1.csv
Results Table 1


Results Table 2


1,Time,Displacement,Force,Compressive displacement,Compressive strain (Displacement),Compressive stress,PIP count
,(s),(mm),(kN),(mm),(%),(MPa),
"","0.0000","0.0000","0.0000","0.0000","0.0000","0.0005","0.0000"
"","0.0600","0.0272","0.0001","0.0272","0.0679","0.0071","0.0000"
"","0.1200","0.0940","0.0000","0.0940","0.2349","-0.0020","0.0000"
"","0.1800","0.1497","0.0004","0.1497","0.3742","0.0380","0.0000"
"","0.2400","0.2014","0.0027","0.2014","0.5035","0.2750","0.0000"
"","0.3000","0.2516","0.0051","0.2516","0.6289","0.5149","0.0000"
"","0.3600","0.3019","0.0075","0.3019","0.7547","0.7465","0.0000"
"","0.4200","0.3518","0.0098","0.3518","0.8795","0.9778","0.0000"
"","0.4800","0.4016","0.0121","0.4016","1.0041","1.2092","0.0000"
"","0.5400","0.4520","0.0144","0.4520","1.1301","1.4383","0.0000"
"","0.6000","0.5014","0.0167","0.5014","1.2535","1.6653","0.0000"
"","0.6600","0.5519","0.0189","0.5519","1.3798","1.8902","0.0000"
"","0.7200","0.6017","0.0212","0.6017","1.5043","2.1196","0.0000"
"","0.7800","0.6518","0.0235","0.6518","1.6295","2.3465","0.0000"
"","0.8400","0.7017","0.0258","0.7017","1.7543","2.5785","0.0000"
"","0.9000","0.7519","0.0280","0.7519","1.8797","2.8042","0.0000"
"","0.9600","0.8021","0.0304","0.8021","2.0052","3.0386","0.0000"
"","1.0200","0.8515","0.0326","0.8515","2.1288","3.2649","0.0000"
"","1.0800","0.9017","0.0349","0.9017","2.2543","3.4916","0.0000"
"","1.1400","0.9516","0.0372","0.9516","2.3791","3.7214","0.0000"
"","1.2000","1.0017","0.0395","1.0017","2.5043","3.9498","0.0000"
"","1.2600","1.0521","0.0419","1.0521","2.6303","4.1855","0.0000"
"","1.3200","1.1018","0.0442","1.1018","2.7545","4.4153","0.0000"
"","1.3800","1.1520","0.0465","1.1520","2.8800","4.6479","0.0000"
"","1.4400","1.2017","0.0487","1.2017","3.0042","4.8742","0.0000"
"","1.5000","1.2519","0.0511","1.2519","3.1297","5.1104","0.0000"
"","1.5600","1.3017","0.0534","1.3017","3.2542","5.3417","0.0000"
"","1.6200","1.3519","0.0558","1.3519","3.3796","5.5757","0.0000"
"","1.6800","1.4019","0.0581","1.4019","3.5048","5.8054","0.0000"
"","1.7400","1.4516","0.0603","1.4516","3.6290","6.0288","0.0000"
"","1.8000","1.5019","0.0626","1.5019","3.7548","6.2633","0.0000"
"","1.8600","1.5514","0.0648","1.5514","3.8784","6.4838","0.0000"
"","1.9200","1.6019","0.0671","1.6019","4.0047","6.7144","0.0000"
"","1.9800","1.6518","0.0694","1.6518","4.1296","6.9365","0.0000"
"","2.0400","1.7018","0.0716","1.7018","4.2544","7.1559","0.0000"
"","2.1000","1.7519","0.0738","1.7519","4.3799","7.3823","0.0000"
"","2.1600","1.8014","0.0760","1.8014","4.5035","7.6040","0.0000"
"","2.2200","1.8521","0.0783","1.8521","4.6301","7.8271","0.0000"
"","2.2800","1.9016","0.0806","1.9016","4.7541","8.0562","0.0000"
"","2.3400","1.9516","0.0829","1.9516","4.8789","8.2897","0.0000"
"","2.4000","2.0019","0.0855","2.0019","5.0047","8.5496","0.0000"
"","2.4600","2.0518","0.0880","2.0518","5.1295","8.8014","0.0000"
"","2.5200","2.1021","0.0906","2.1021","5.2552","9.0590","0.0000"
"","2.5800","2.1517","0.0931","2.1517","5.3792","9.3121","0.0000"
"","2.6400","2.2021","0.0958","2.2021","5.5052","9.5773","0.0000"
"","2.7000","2.2516","0.0984","2.2516","5.6289","9.8432","0.0000"
"","2.7600","2.3018","0.1010","2.3018","5.7546","10.0959","0.0000"
"","2.8200","2.3518","0.1035","2.3518","5.8795","10.3500","0.0000"
"","2.8800","2.4015","0.1059","2.4015","6.0037","10.5928","0.0000"
"","2.9400","2.4518","0.1084","2.4518","6.1294","10.8363","0.0000"
"","3.0000","2.5015","0.1106","2.5015","6.2537","11.0620","0.0000"
"","3.0600","2.5517","0.1124","2.5517","6.3791","11.2448","0.0000"
"","3.1200","2.6021","0.1134","2.6021","6.5052","11.3372","0.0000"
"","3.1800","2.6518","0.1128","2.6518","6.6294","11.2755","0.0000"
"","3.2400","2.7019","0.1128","2.7019","6.7548","11.2803","0.0000"
"","3.3000","2.7518","0.1137","2.7518","6.8794","11.3662","0.0000"
"","3.3600","2.8020","0.1148","2.8020","7.0051","11.4802","0.0000"
"","3.4200","2.8519","0.1160","2.8519","7.1297","11.5971","0.0000"
"","3.4800","2.9019","0.1173","2.9019","7.2548","11.7290","0.0000"
"","3.5400","2.9517","0.1187","2.9517","7.3794","11.8737","0.0000"
"","3.6000","3.0017","0.1203","3.0017","7.5042","12.0259","0.0000"
"","3.6600","3.0521","0.1218","3.0521","7.6302","12.1805","0.0000"
"","3.7200","3.1017","0.1232","3.1017","7.7542","12.3195","0.0000"
"","3.7800","3.1517","0.1246","3.1517","7.8793","12.4633","0.0000"
"","3.8400","3.2013","0.1259","3.2013","8.0033","12.5917","0.0000"
"","3.9000","3.2517","0.1274","3.2517","8.1293","12.7402","0.0000"
"","3.9600","3.3020","0.1287","3.3020","8.2550","12.8730","0.0000"
"","4.0200","3.3515","0.1301","3.3515","8.3787","13.0068","0.0000"
"","4.0800","3.4018","0.1315","3.4018","8.5044","13.1536","0.0000"
"","4.1400","3.4518","0.1328","3.4518","8.6296","13.2819","0.0000"
"","4.2000","3.5020","0.1338","3.5020","8.7550","13.3824","0.0000"
"","4.2600","3.5517","0.1345","3.5517","8.8793","13.4460","0.0000"
"","4.3200","3.6019","0.1348","3.6019","9.0047","13.4824","0.0000"
"","4.3800","3.6519","0.1345","3.6519","9.1298","13.4549","0.0000"
"","4.4400","3.7015","0.1337","3.7015","9.2538","13.3708","0.0000"
"","4.5000","3.7522","0.1333","3.7522","9.3804","13.3338","0.0000"
"","4.5600","3.8020","0.1330","3.8020","9.5049","13.3013","0.0000"
"","4.6200","3.8520","0.1316","3.8520","9.6301","13.1567","0.0000"
"","4.6800","3.9019","0.1312","3.9019","9.7546","13.1240","0.0000"
"","4.7400","3.9517","0.1315","3.9517","9.8792","13.1460","0.0000"
"","4.8000","4.0017","0.1322","4.0017","10.0043","13.2177","0.0000"
"","4.8600","4.0515","0.1330","4.0515","10.1289","13.2967","0.0000"
"","4.9200","4.1018","0.1339","4.1018","10.2546","13.3876","0.0000"
"","4.9800","4.1518","0.1349","4.1518","10.3794","13.4851","0.0000"
"","5.0400","4.2018","0.1361","4.2018","10.5046","13.6051","0.0000"
"","5.1000","4.2517","0.1371","4.2517","10.6291","13.7137","0.0000"
"","5.1600","4.3016","0.1381","4.3016","10.7540","13.8133","0.0000"
"","5.2200","4.3520","0.1392","4.3520","10.8800","13.9157","0.0000"
"","5.2800","4.4017","0.1402","4.4017","11.0043","14.0237","0.0000"
"","5.3400","4.4520","0.1414","4.4520","11.1300","14.1351","0.0000"
"","5.4000","4.5017","0.1427","4.5017","11.2542","14.2668","0.0000"
"","5.4600","4.5518","0.1440","4.5518","11.3794","14.4022","0.0000"
"","5.5200","4.6019","0.1454","4.6019","11.5048","14.5424","0.0000"
"","5.5800","4.6517","0.1466","4.6517","11.6294","14.6592","0.0000"
"","5.6400","4.7020","0.1478","4.7020","11.7551","14.7811","0.0000"
"","5.7000","4.7515","0.1490","4.7515","11.8788","14.9036","0.0000"
"","5.7600","4.8020","0.1502","4.8020","12.0051","15.0176","0.0000"
"","5.8200","4.8517","0.1512","4.8517","12.1293","15.1236","0.0000"
"","5.8800","4.9017","0.1522","4.9017","12.2542","15.2184","0.0000"
"","5.9400","4.9518","0.1532","4.9518","12.3796","15.3234","0.0000"
"","6.0000","5.0018","0.1543","5.0018","12.5044","15.4315","0.0000"
"","6.0600","5.0518","0.1554","5.0518","12.6296","15.5396","0.0000"
"","6.1200","5.1014","0.1566","5.1014","12.7535","15.6569","0.0000"
"","6.1800","5.1517","0.1577","5.1517","12.8793","15.7713","0.0000"
"","6.2400","5.2016","0.1587","5.2016","13.0041","15.8741","0.0000"
"","6.3000","5.2519","0.1597","5.2519","13.1298","15.9727","0.0000"
"","6.3600","5.3022","0.1607","5.3022","13.2556","16.0696","0.0000"
"","6.4200","5.3516","0.1615","5.3516","13.3789","16.1484","0.0000"
"","6.4800","5.4019","0.1623","5.4019","13.5047","16.2275","0.0000"
"","6.5400","5.4515","0.1630","5.4515","13.6286","16.3049","0.0000"
"","6.6000","5.5017","0.1637","5.5017","13.7544","16.3742","0.0000"
"","6.6600","5.5517","0.1644","5.5517","13.8792","16.4407","0.0000"
"","6.7200","5.6017","0.1651","5.6017","14.0043","16.5142","0.0000"
"","6.7800","5.6518","0.1659","5.6518","14.1295","16.5894","0.0000"
"","6.8400","5.7013","0.1666","5.7013","14.2531","16.6569","0.0000"
"","6.9000","5.7518","0.1674","5.7518","14.3795","16.7432","0.0000"
"","6.9600","5.8018","0.1683","5.8018","14.5046","16.8257","0.0000"
"","7.0200","5.8521","0.1691","5.8521","14.6303","16.9145","0.0000"
"","7.0800","5.9018","0.1701","5.9018","14.7546","17.0113","0.0000"
"","7.1400","5.9517","0.1712","5.9517","14.8791","17.1162","0.0000"
"","7.2000","6.0019","0.1720","6.0019","15.0049","17.2046","0.0000"
"","7.2600","6.0518","0.1729","6.0518","15.1294","17.2889","0.0000"
"","7.3200","6.1022","0.1739","6.1022","15.2554","17.3924","0.0000"
"","7.3800","6.1516","0.1749","6.1516","15.3791","17.4880","0.0000"
"","7.4400","6.2018","0.1760","6.2018","15.5045","17.5981","0.0000"
"","7.5000","6.2520","0.1774","6.2520","15.6300","17.7354","0.0000"
"","7.5600","6.3017","0.1784","6.3017","15.7542","17.8409","0.0000"
"","7.6200","6.3520","0.1795","6.3520","15.8799","17.9540","0.0000"
"","7.6800","6.4016","0.1806","6.4016","16.0039","18.0643","0.0000"
"","7.7400","6.4517","0.1818","6.4517","16.1293","18.1815","0.0000"
"","7.8000","6.5017","0.1831","6.5017","16.2542","18.3109","0.0000"
"","7.8600","6.5521","0.1842","6.5521","16.3802","18.4236","0.0000"
"","7.9200","6.6020","0.1856","6.6020","16.5051","18.5592","0.0000"
"","7.9800","6.6511","0.1867","6.6511","16.6278","18.6696","0.0000"
"","8.0400","6.7015","0.1879","6.7015","16.7539","18.7929","0.0000"
"","8.1000","6.7517","0.1891","6.7517","16.8793","18.9133","0.0000"
"","8.1600","6.8021","0.1903","6.8021","17.0053","19.0289","0.0000"
"","8.2200","6.8519","0.1916","6.8519","17.1299","19.1551","0.0000"
"","8.2800","6.9016","0.1926","6.9016","17.2541","19.2592","0.0000"
"","8.3400","6.9521","0.1939","6.9521","17.3801","19.3856","0.0000"
"","8.4000","7.0018","0.1950","7.0018","17.5044","19.4961","0.0000"
"","8.4600","7.0522","0.1962","7.0522","17.6304","19.6159","0.0000"
"","8.5200","7.1017","0.1973","7.1017","17.7544","19.7262","0.0000"
"","8.5800","7.1517","0.1984","7.1517","17.8792","19.8366","0.0000"
"","8.6400","7.2014","0.1995","7.2014","18.0035","19.9463","0.0000"
"","8.7000","7.2518","0.2005","7.2518","18.1295","20.0505","0.0000"
"","8.7600","7.3023","0.2016","7.3023","18.2558","20.1595","0.0000"
"","8.8200","7.3516","0.2026","7.3516","18.3789","20.2572","0.0000"
"","8.8800","7.4017","0.2036","7.4017","18.5043","20.3607","0.0000"
"","8.9400","7.4513","0.2047","7.4513","18.6283","20.4700","0.0000"
"","9.0000","7.5018","0.2058","7.5018","18.7546","20.5776","0.0000"
"","9.0600","7.5519","0.2068","7.5519","18.8797","20.6793","0.0000"
"","9.1200","7.6018","0.2078","7.6018","19.0046","20.7787","0.0000"
"","9.1800","7.6519","0.2088","7.6519","19.1297","20.8799","0.0000"
"","9.2400","7.7015","0.2099","7.7015","19.2537","20.9872","0.0000"
"","9.3000","7.7519","0.2112","7.7519","19.3797","21.1172","0.0000"
"","9.3600","7.8018","0.2125","7.8018","19.5046","21.2539","0.0000"
"","9.4200","7.8520","0.2137","7.8520","19.6300","21.3696","0.0000"
"","9.4800","7.9017","0.2148","7.9017","19.7542","21.4751","0.0000"
"","9.5400","7.9515","0.2157","7.9515","19.8788","21.5652","0.0000"
"","9.6000","8.0020","0.2167","8.0020","20.0051","21.6733","0.0000"
"","9.6600","8.0514","0.2178","8.0514","20.1285","21.7774","0.0000"
"","9.7200","8.1018","0.2188","8.1018","20.2545","21.8812","0.0000"
"","9.7800","8.1520","0.2199","8.1520","20.3799","21.9927","0.0000"
"","9.8400","8.2021","0.2210","8.2021","20.5054","22.1027","0.0000"
"","9.9000","8.2520","0.2221","8.2520","20.6299","22.2148","0.0000"
"","9.9600","8.3015","0.2231","8.3015","20.7539","22.3122","0.0000"
"","10.0200","8.3518","0.2242","8.3518","20.8796","22.4223","0.0000"
"","10.0800","8.4017","0.2254","8.4017","21.0041","22.5401","0.0000"
"","10.1400","8.4520","0.2266","8.4520","21.1299","22.6557","0.0000"
"","10.2000","8.5018","0.2278","8.5018","21.2544","22.7772","0.0000"
"","10.2600","8.5517","0.2287","8.5517","21.3793","22.8749","0.0000"
"","10.3200","8.6020","0.2298","8.6020","21.5050","22.9788","0.0000"
"","10.3800","8.6515","0.2307","8.6515","21.6287","23.0717","0.0000"
"","10.4400","8.7018","0.2318","8.7018","21.7544","23.1813","0.0000"
"","10.5000","8.7515","0.2330","8.7515","21.8786","23.2991","0.0000"
"","10.5600","8.8019","0.2339","8.8019","22.0047","23.3901","0.0000"
"","10.6200","8.8519","0.2347","8.8519","22.1298","23.4740","0.0000"
"","10.6800","8.9019","0.2357","8.9019","22.2547","23.5736","0.0000"
"","10.7400","8.9519","0.2369","8.9519","22.3798","23.6919","0.0000"
"","10.8000","9.0015","0.2381","9.0015","22.5038","23.8100","0.0000"
"","10.8600","9.0518","0.2392","9.0518","22.6295","23.9187","0.0000"
"","10.9200","9.1020","0.2402","9.1020","22.7549","24.0160","0.0000"
"","10.9800","9.1521","0.2411","9.1521","22.8803","24.1102","0.0000"
"","11.0400","9.2017","0.2421","9.2017","23.0043","24.2134","0.0000"
"","11.1000","9.2517","0.2433","9.2517","23.1291","24.3255","0.0000"
"","11.1600","9.3020","0.2444","9.3020","23.2549","24.4369","0.0000"
"","11.2200","9.3517","0.2453","9.3517","23.3791","24.5290","0.0000"
"","11.2800","9.4019","0.2463","9.4019","23.5049","24.6316","0.0000"
"","11.3400","9.4518","0.2473","9.4518","23.6294","24.7347","0.0000"
"","11.4000","9.5017","0.2483","9.5017","23.7543","24.8337","0.0000"
"","11.4600","9.5518","0.2495","9.5518","23.8794","24.9523","0.0000"
"","11.5200","9.6016","0.2506","9.6016","24.0039","25.0625","0.0000"
"","11.5800","9.6519","0.2519","9.6519","24.1297","25.1916","0.0000"
"","11.6400","9.7018","0.2530","9.7018","24.2545","25.3048","0.0000"
"","11.7000","9.7521","0.2542","9.7521","24.3802","25.4168","0.0000"
"","11.7600","9.8017","0.2551","9.8017","24.5042","25.5121","0.0000"
"","11.8200","9.8517","0.2560","9.8517","24.6293","25.6020","0.0000"
"","11.8800","9.9019","0.2570","9.9019","24.7548","25.6991","0.0000"
"","11.9400","9.9516","0.2580","9.9516","24.8790","25.8033","0.0000"
"","12.0000","10.0020","0.2593","10.0020","25.0051","25.9293","0.0000"
"","12.0600","10.0518","0.2605","10.0518","25.1296","26.0488","0.0000"
"","12.1200","10.1018","0.2617","10.1018","25.2544","26.1656","0.0000"
"","12.1800","10.1517","0.2628","10.1517","25.3793","26.2771","0.0000"
"","12.2400","10.2015","0.2637","10.2015","25.5038","26.3663","0.0000"
"","12.3000","10.2519","0.2647","10.2519","25.6299","26.4704","0.0000"
"","12.3600","10.3015","0.2656","10.3015","25.7538","26.5633","0.0000"
"","12.4200","10.3519","0.2666","10.3519","25.8798","26.6644","0.0000"
"","12.4800","10.4012","0.2675","10.4012","26.0029","26.7474","0.0000"
"","12.5400","10.4517","0.2683","10.4517","26.1292","26.8336","0.0000"
"","12.6000","10.5020","0.2693","10.5020","26.2550","26.9267","0.0000"
"","12.6600","10.5519","0.2700","10.5519","26.3798","26.9969","0.0000"
"","12.7200","10.6023","0.2709","10.6023","26.5058","27.0927","0.0000"
"","12.7800","10.6517","0.2717","10.6517","26.6292","27.1739","0.0000"
"","12.8400","10.7017","0.2728","10.7017","26.7543","27.2751","0.0000"
"","12.9000","10.7517","0.2738","10.7517","26.8792","27.3825","0.0000"
"","12.9600","10.8017","0.2746","10.8017","27.0043","27.4614","0.0000"
"","13.0200","10.8521","0.2759","10.8521","27.1303","27.5879","0.0000"
"","13.0800","10.9016","0.2770","10.9016","27.2540","27.6981","0.0000"
"","13.1400","10.9519","0.2782","10.9519","27.3797","27.8237","0.0000"
"","13.2000","11.0017","0.2794","11.0017","27.5043","27.9430","0.0000"
"","13.2600","11.0518","0.2804","11.0518","27.6294","28.0407","0.0000"
"","13.3200","11.1016","0.2816","11.1016","27.7540","28.1591","0.0000"
"","13.3800","11.1516","0.2826","11.1516","27.8791","28.2556","0.0000"
"","13.4400","11.2019","0.2837","11.2019","28.0048","28.3739","0.0000"
"","13.5000","11.2518","0.2848","11.2518","28.1294","28.4806","0.0000"
"","13.5600","11.3020","0.2859","11.3020","28.2551","28.5875","0.0000"
"","13.6200","11.3519","0.2869","11.3519","28.3797","28.6883","0.0000"
"","13.6800","11.4019","0.2879","11.4019","28.5048","28.7880","0.0000"
"","13.7400","11.4519","0.2891","11.4519","28.6297","28.9096","0.0000"
"","13.8000","11.5016","0.2901","11.5016","28.7539","29.0144","0.0000"
"","13.8600","11.5520","0.2914","11.5520","28.8799","29.1359","0.0000"
"","13.9200","11.6017","0.2925","11.6017","29.0042","29.2477","0.0000"
"","13.9800","11.6518","0.2935","11.6518","29.1296","29.3530","0.0000"
"","14.0400","11.7017","0.2946","11.7017","29.2542","29.4580","0.0000"
"","14.1000","11.7521","0.2956","11.7521","29.3802","29.5568","0.0000"
"","14.1600","11.8018","0.2966","11.8018","29.5044","29.6624","0.0000"
"","14.2200","11.8517","0.2976","11.8517","29.6293","29.7610","0.0000"
"","14.2800","11.9018","0.2987","11.9018","29.7544","29.8680","0.0000"
"","14.3400","11.9515","0.2995","11.9515","29.8787","29.9471","0.0000"
"","14.4000","12.0021","0.3004","12.0021","30.0053","30.0382","0.0000"
"","14.4600","12.0516","0.3014","12.0516","30.1290","30.1419","0.0000"
"","14.5200","12.1018","0.3024","12.1018","30.2544","30.2402","0.0000"
"","14.5800","12.1517","0.3035","12.1517","30.3792","30.3544","0.0000"
"","14.6400","12.2016","0.3046","12.2016","30.5041","30.4613","0.0000"
"","14.7000","12.2522","0.3060","12.2522","30.6304","30.5953","0.0000"
"","14.7600","12.3019","0.3069","12.3019","30.7547","30.6863","0.0000"
"","14.8200","12.3520","0.3078","12.3520","30.8801","30.7848","0.0000"
"","14.8800","12.4017","0.3088","12.4017","31.0043","30.8823","0.0000"
"","14.9400","12.4516","0.3098","12.4516","31.1289","30.9823","0.0000"
"","15.0000","12.5018","0.3109","12.5018","31.2546","31.0931","0.0000"
"","15.0600","12.5517","0.3120","12.5517","31.3792","31.1954","0.0000"
"","15.1200","12.6018","0.3130","12.6018","31.5046","31.3021","0.0000"
"","15.1800","12.6515","0.3140","12.6515","31.6289","31.4038","0.0000"
"","15.2400","12.7018","0.3152","12.7018","31.7546","31.5184","0.0000"
"","15.3000","12.7515","0.3163","12.7515","31.8788","31.6311","0.0000"
"","15.3600","12.8016","0.3172","12.8016","32.0040","31.7185","0.0000"
"","15.4200","12.8521","0.3184","12.8521","32.1303","31.8379","0.0000"
"","15.4800","12.9019","0.3193","12.9019","32.2548","31.9320","0.0000"
"","15.5400","12.9521","0.3204","12.9521","32.3803","32.0442","0.0000"
"","15.6000","13.0015","0.3214","13.0015","32.5036","32.1429","0.0000"
"","15.6600","13.0519","0.3224","13.0519","32.6297","32.2434","0.0000"
"","15.7200","13.1018","0.3235","13.1018","32.7545","32.3519","0.0000"
"","15.7800","13.1517","0.3244","13.1517","32.8794","32.4420","0.0000"
"","15.8400","13.2019","0.3256","13.2019","33.0048","32.5576","0.0000"
"","15.9000","13.2519","0.3267","13.2519","33.1296","32.6734","0.0000"
"","15.9600","13.3021","0.3278","13.3021","33.2554","32.7843","0.0000"
"","16.0200","13.3518","0.3292","13.3518","33.3796","32.9206","0.0000"
"","16.0800","13.4017","0.3306","13.4017","33.5042","33.0586","0.0000"
"","16.1400","13.4518","0.3320","13.4518","33.6296","33.2028","0.0000"
"","16.2000","13.5015","0.3331","13.5015","33.7539","33.3092","0.0000"
"","16.2600","13.5523","0.3341","13.5523","33.8808","33.4088","0.0000"
"","16.3200","13.6018","0.3348","13.6018","34.0044","33.4759","0.0000"
"","16.3800","13.6517","0.3355","13.6517","34.1293","33.5547","0.0000"
"","16.4400","13.7015","0.3366","13.7015","34.2538","33.6591","0.0000"
"","16.5000","13.7517","0.3377","13.7517","34.3792","33.7679","0.0000"
"","16.5600","13.8021","0.3391","13.8021","34.5053","33.9100","0.0000"
"","16.6200","13.8516","0.3402","13.8516","34.6289","34.0217","0.0000"
"","16.6800","13.9019","0.3418","13.9019","34.7547","34.1783","0.0000"
"","16.7400","13.9516","0.3437","13.9516","34.8789","34.3695","0.0000"
"","16.8000","14.0019","0.3457","14.0019","35.0047","34.5702","0.0000"
"","16.8600","14.0519","0.3477","14.0519","35.1298","34.7711","0.0000"
"","16.9200","14.1019","0.3495","14.1019","35.2546","34.9492","0.0000"
"","16.9800","14.1519","0.3512","14.1519","35.3798","35.1153","0.0000"
"","17.0400","14.2015","0.3527","14.2015","35.5037","35.2688","0.0000"
"","17.1000","14.2518","0.3545","14.2518","35.6295","35.4520","0.0000"
"","17.1600","14.3018","0.3563","14.3018","35.7546","35.6285","0.0000"
"","17.2200","14.3518","0.3581","14.3518","35.8794","35.8117","0.0000"
"","17.2800","14.4020","0.3600","14.4020","36.0049","35.9982","0.0000"
"","17.3400","14.4517","0.3618","14.4517","36.1291","36.1796","0.0000"
"","17.4000","14.5022","0.3633","14.5022","36.2555","36.3325","0.0000"
"","17.4600","14.5514","0.3647","14.5514","36.3785","36.4672","0.0000"
"","17.5200","14.6018","0.3660","14.6018","36.5045","36.6016","0.0000"
"","17.5800","14.6516","0.3671","14.6516","36.6291","36.7078","0.0000"
"","17.6400","14.7017","0.3679","14.7017","36.7542","36.7893","0.0000"
"","17.7000","14.7520","0.3688","14.7520","36.8800","36.8799","0.0000"
"","17.7600","14.8017","0.3695","14.8017","37.0042","36.9485","0.0000"
"","17.8200","14.8519","0.3702","14.8519","37.1297","37.0229","0.0000"
"","17.8800","14.9013","0.3707","14.9013","37.2533","37.0701","0.0000"
"","17.9400","14.9520","0.3713","14.9520","37.3799","37.1271","0.0000"
"","18.0000","15.0016","0.3718","15.0016","37.5039","37.1823","0.0000"
"","18.0600","15.0517","0.3723","15.0517","37.6293","37.2319","0.0000"
"","18.1200","15.1018","0.3733","15.1018","37.7545","37.3288","0.0000"
"","18.1800","15.1512","0.3740","15.1513","37.8781","37.3959","0.0000"
"","18.2400","15.2018","0.3751","15.2018","38.0044","37.5085","0.0000"
"","18.3000","15.2520","0.3761","15.2520","38.1299","37.6075","0.0000"
"","18.3600","15.3024","0.3770","15.3024","38.2559","37.7028","0.0000"
"","18.4200","15.3517","0.3779","15.3517","38.3793","37.7873","0.0000"
"","18.4800","15.4015","0.3789","15.4015","38.5038","37.8893","0.0000"
"","18.5400","15.4519","0.3802","15.4519","38.6298","38.0230","0.0000"
"","18.6000","15.5014","0.3814","15.5014","38.7535","38.1357","0.0000"
"","18.6600","15.5520","0.3828","15.5520","38.8801","38.2775","0.0000"
"","18.7200","15.6019","0.3843","15.6019","39.0047","38.4280","0.0000"
"","18.7800","15.6518","0.3857","15.6518","39.1295","38.5652","0.0000"
"","18.8400","15.7016","0.3869","15.7016","39.2541","38.6932","0.0000"
"","18.9000","15.7517","0.3882","15.7517","39.3792","38.8166","0.0000"
"","18.9600","15.8021","0.3896","15.8021","39.5052","38.9649","0.0000"
"","19.0200","15.8516","0.3910","15.8516","39.6289","39.0968","0.0000"
"","19.0800","15.9020","0.3927","15.9020","39.7549","39.2745","0.0000"
"","19.1400","15.9517","0.3946","15.9517","39.8792","39.4602","0.0000"
"","19.2000","16.0020","0.3963","16.0020","40.0049","39.6263","0.0000"
"","19.2600","16.0519","0.3982","16.0519","40.1297","39.8181","0.0000"
"","19.3200","16.1018","0.3998","16.1018","40.2546","39.9781","0.0000"
"","19.3800","16.1518","0.4016","16.1518","40.3794","40.1556","0.0000"
"","19.4400","16.2015","0.4030","16.2015","40.5037","40.2970","0.0000"
"","19.5000","16.2520","0.4043","16.2520","40.6300","40.4277","0.0000"
"","19.5600","16.3017","0.4054","16.3017","40.7543","40.5373","0.0000"
"","19.6200","16.3518","0.4064","16.3518","40.8794","40.6434","0.0000"
"","19.6800","16.4016","0.4079","16.4016","41.0039","40.7868","0.0000"
"","19.7400","16.4515","0.4092","16.4515","41.1288","40.9182","0.0000"
"","19.8000","16.5022","0.4109","16.5022","41.2554","41.0925","0.0000"
"","19.8600","16.5517","0.4125","16.5517","41.3794","41.2478","0.0000"
"","19.9200","16.6018","0.4140","16.6018","41.5045","41.3970","0.0000"
"","19.9800","16.6517","0.4153","16.6517","41.6293","41.5317","0.0000"
"","20.0400","16.7020","0.4167","16.7020","41.7551","41.6693","0.0000"
"","20.1000","16.7521","0.4182","16.7521","41.8802","41.8227","0.0000"
"","20.1600","16.8017","0.4193","16.8017","42.0042","41.9311","0.0000"
"","20.2200","16.8520","0.4206","16.8520","42.1299","42.0620","0.0000"
"","20.2800","16.9015","0.4218","16.9015","42.2539","42.1841","0.0000"
"","20.3400","16.9517","0.4231","16.9517","42.3793","42.3097","0.0000"
"","20.4000","17.0018","0.4245","17.0018","42.5044","42.4531","0.0000"
"","20.4600","17.0519","0.4258","17.0519","42.6299","42.5788","0.0000"
"","20.5200","17.1020","0.4271","17.1020","42.7550","42.7129","0.0000"
"","20.5800","17.1516","0.4285","17.1516","42.8790","42.8504","0.0000"
"","20.6400","17.2015","0.4301","17.2015","43.0038","43.0148","0.0000"
"","20.7000","17.2513","0.4320","17.2513","43.1283","43.2032","0.0000"
"","20.7600","17.3021","0.4336","17.3021","43.2553","43.3646","0.0000"
"","20.8200","17.3520","0.4352","17.3520","43.3801","43.5246","0.0000"
"","20.8800","17.4019","0.4365","17.4019","43.5046","43.6470","0.0000"
"","20.9400","17.4518","0.4379","17.4518","43.6295","43.7950","0.0000"
"","21.0000","17.5013","0.4390","17.5013","43.7532","43.9046","0.0000"
"","21.0600","17.5519","0.4406","17.5519","43.8798","44.0642","0.0000"
"","21.1200","17.6020","0.4422","17.6020","44.0049","44.2196","0.0000"
"","21.1800","17.6520","0.4437","17.6520","44.1301","44.3741","0.0000"
"","21.2400","17.7018","0.4454","17.7018","44.2546","44.5360","0.0000"
"","21.3000","17.7517","0.4467","17.7517","44.3791","44.6684","0.0000"
"","21.3600","17.8020","0.4482","17.8020","44.5049","44.8205","0.0000"
"","21.4200","17.8517","0.4498","17.8517","44.6291","44.9752","0.0000"
"","21.4800","17.9019","0.4517","17.9019","44.7549","45.1728","0.0000"
"","21.5400","17.9515","0.4535","17.9515","44.8788","45.3528","0.0000"
"","21.6000","18.0018","0.4552","18.0018","45.0046","45.5248","0.0000"
"","21.6600","18.0518","0.4570","18.0518","45.1294","45.7033","0.0000"
"","21.7200","18.1016","0.4586","18.1016","45.2539","45.8566","0.0000"
"","21.7800","18.1520","0.4604","18.1520","45.3800","46.0379","0.0000"
"","21.8400","18.2016","0.4619","18.2016","45.5039","46.1881","0.0000"
"","21.9000","18.2519","0.4632","18.2519","45.6297","46.3250","0.0000"
"","21.9600","18.3018","0.4648","18.3018","45.7545","46.4793","0.0000"
"","22.0200","18.3517","0.4661","18.3517","45.8793","46.6074","0.0000"
"","22.0800","18.4020","0.4679","18.4020","46.0051","46.7944","0.0000"
"","22.1400","18.4517","0.4695","18.4517","46.1293","46.9473","0.0000"
"","22.2000","18.5020","0.4714","18.5020","46.2551","47.1393","0.0000"
"","22.2600","18.5516","0.4734","18.5516","46.3790","47.3424","0.0000"
"","22.3200","18.6020","0.4755","18.6020","46.5050","47.5528","0.0000"
"","22.3800","18.6517","0.4775","18.6517","46.6293","47.7461","0.0000"
"","22.4400","18.7018","0.4793","18.7018","46.7544","47.9292","0.0000"
"","22.5000","18.7521","0.4812","18.7521","46.8802","48.1196","0.0000"
"","22.5600","18.8016","0.4828","18.8016","47.0041","48.2803","0.0000"
"","22.6200","18.8519","0.4847","18.8519","47.1298","48.4675","0.0000"
"","22.6800","18.9015","0.4861","18.9015","47.2538","48.6069","0.0000"
"","22.7400","18.9516","0.4874","18.9516","47.3789","48.7439","0.0000"
"","22.8000","19.0019","0.4893","19.0019","47.5047","48.9343","0.0000"
"","22.8600","19.0519","0.4910","19.0519","47.6298","49.0975","0.0000"
"","22.9200","19.1021","0.4929","19.1021","47.7552","49.2880","0.0000"
"","22.9800","19.1514","0.4948","19.1514","47.8786","49.4821","0.0000"
"","23.0400","19.2020","0.4970","19.2020","48.0049","49.7003","0.0000"
"","23.1000","19.2517","0.4991","19.2517","48.1292","49.9148","0.0000"
"","23.1600","19.3016","0.5008","19.3016","48.2540","50.0799","0.0000"
"","23.2200","19.3518","0.5027","19.3518","48.3795","50.2683","0.0000"
"","23.2800","19.4016","0.5042","19.4016","48.5040","50.4159","0.0000"
"","23.3400","19.4519","0.5060","19.4519","48.6297","50.5973","0.0000"
"","23.4000","19.5017","0.5076","19.5017","48.7543","50.7620","0.0000"
"","23.4600","19.5519","0.5096","19.5519","48.8797","50.9551","0.0000"
"","23.5200","19.6017","0.5115","19.6017","49.0043","51.1534","0.0000"
"","23.5800","19.6518","0.5135","19.6518","49.1294","51.3473","0.0000"
"","23.6400","19.7019","0.5158","19.7019","49.2548","51.5807","0.0000"
"","23.7000","19.7516","0.5177","19.7516","49.3791","51.7711","0.0000"
"","23.7600","19.8020","0.5197","19.8020","49.5051","51.9661","0.0000"
"","23.8200","19.8514","0.5212","19.8514","49.6285","52.1179","0.0000"
"","23.8800","19.9016","0.5228","19.9016","49.7539","52.2764","0.0000"
"","23.9400","19.9515","0.5257","19.9515","49.8788","52.5729","0.0000"
"","24.0000","20.0019","0.5380","20.0019","50.0048","53.7955","0.0000"
"","24.0600","20.0521","0.5511","20.0521","50.1302","55.1079","0.0000"
"","24.1200","20.1016","0.5628","20.1016","50.2539","56.2824","0.0000"
"","24.1800","20.1516","0.5742","20.1516","50.3790","57.4193","0.0000"
"","24.2400","20.2017","0.5848","20.2017","50.5042","58.4764","0.0000"
"","24.3000","20.2518","0.5944","20.2518","50.6296","59.4415","0.0000"
"","24.3600","20.3019","0.6046","20.3019","50.7547","60.4565","0.0000"
"","24.4200","20.3517","0.6143","20.3517","50.8793","61.4328","0.0000"
"","24.4800","20.4019","0.6237","20.4019","51.0047","62.3694","0.0000"
"","24.5400","20.4515","0.6325","20.4515","51.1287","63.2464","0.0000"
"","24.6000","20.5018","0.6411","20.5018","51.2544","64.1064","0.0000"
"","24.6600","20.5517","0.6495","20.5517","51.3793","64.9489","0.0000"
"","24.7200","20.6019","0.6576","20.6019","51.5047","65.7611","0.0000"
"","24.7800","20.6518","0.6657","20.6518","51.6295","66.5705","0.0000"
"","24.8400","20.7016","0.6733","20.7016","51.7541","67.3260","0.0000"
"","24.9000","20.7518","0.6810","20.7518","51.8795","68.1019","0.0000"
"","24.9600","20.8015","0.6888","20.8015","52.0038","68.8761","0.0000"
"","25.0200","20.8518","0.6966","20.8518","52.1295","69.6607","0.0000"
"","25.0800","20.9020","0.7045","20.9020","52.2549","70.4501","0.0000"
"","25.1400","20.9518","0.7120","20.9518","52.3795","71.1994","0.0000"
"","25.2000","21.0018","0.7197","21.0019","52.5046","71.9665","0.0000"
"","25.2600","21.0513","0.7266","21.0513","52.6283","72.6596","0.0000"
"","25.3200","21.1017","0.7340","21.1017","52.7543","73.4033","0.0000"
"","25.3800","21.1515","0.7411","21.1515","52.8789","74.1083","0.0000"
"","25.4400","21.2018","0.7482","21.2018","53.0046","74.8187","0.0000"
"","25.5000","21.2519","0.7556","21.2519","53.1297","75.5623","0.0000"
"","25.5600","21.3016","0.7627","21.3016","53.2540","76.2658","0.0000"
"","25.6200","21.3516","0.7701","21.3516","53.3791","77.0123","0.0000"
"","25.6800","21.4017","0.7780","21.4017","53.5043","77.7960","0.0000"
"","25.7400","21.4520","0.7851","21.4520","53.6300","78.5113","0.0000"
"","25.8000","21.5016","0.7921","21.5016","53.7539","79.2116","0.0000"
"","25.8600","21.5518","0.7987","21.5518","53.8794","79.8692","0.0000"
"","25.9200","21.6019","0.8058","21.6019","54.0048","80.5805","0.0000"
"","25.9800","21.6517","0.8122","21.6517","54.1294","81.2170","0.0000"
"","26.0400","21.7019","0.8193","21.7019","54.2548","81.9289","0.0000"
"","26.1000","21.7513","0.8258","21.7513","54.3782","82.5753","0.0000"
"","26.1600","21.8019","0.8325","21.8019","54.5048","83.2476","0.0000"
"","26.2200","21.8520","0.8393","21.8520","54.6299","83.9259","0.0000"
"","26.2800","21.9019","0.8455","21.9019","54.7548","84.5492","0.0000"
"","26.3400","21.9518","0.8519","21.9518","54.8796","85.1947","0.0000"
"","26.4000","22.0018","0.8581","22.0018","55.0044","85.8070","0.0000"
"","26.4600","22.0520","0.8644","22.0519","55.1299","86.4421","0.0000"
"","26.5200","22.1017","0.8701","22.1017","55.2541","87.0145","0.0000"
"","26.5800","22.1517","0.8764","22.1517","55.3793","87.6418","0.0000"
"","26.6400","22.2018","0.8829","22.2018","55.5044","88.2900","0.0000"
"","26.7000","22.2518","0.8890","22.2518","55.6296","88.9020","0.0000"
"","26.7600","22.3020","0.8952","22.3020","55.7550","89.5189","0.0000"
"","26.8200","22.3517","0.9011","22.3517","55.8792","90.1133","0.0000"
"","26.8800","22.4019","0.9076","22.4019","56.0047","90.7565","0.0000"
"","26.9400","22.4516","0.9130","22.4516","56.1289","91.2978","0.0000"
"","27.0000","22.5019","0.9189","22.5019","56.2547","91.8915","0.0000"
"","27.0600","22.5517","0.9245","22.5517","56.3792","92.4527","0.0000"
"","27.1200","22.6017","0.9297","22.6017","56.5043","92.9730","0.0000"
"","27.1800","22.6518","0.9355","22.6518","56.6295","93.5535","0.0000"
"","27.2400","22.7016","0.9406","22.7016","56.7540","94.0608","0.0000"
"","27.3000","22.7519","0.9461","22.7519","56.8798","94.6087","0.0000"
"","27.3600","22.8016","0.9512","22.8016","57.0040","95.1160","0.0000"
"","27.4200","22.8520","0.9563","22.8520","57.1300","95.6265","0.0000"
"","27.4800","22.9018","0.9612","22.9018","57.2546","96.1223","0.0000"
"","27.5400","22.9517","0.9653","22.9517","57.3791","96.5255","0.0000"
"","27.6000","23.0019","0.9696","23.0019","57.5049","96.9591","0.0000"
"","27.6600","23.0515","0.9731","23.0515","57.6288","97.3119","0.0000"
"","27.7200","23.1021","0.9767","23.1021","57.7551","97.6688","0.0000"
"","27.7800","23.1519","0.9801","23.1519","57.8797","98.0107","0.0000"
"","27.8400","23.2018","0.9827","23.2018","58.0045","98.2663","0.0000"
"","27.9000","23.2519","0.9855","23.2519","58.1297","98.5464","0.0000"
"","27.9600","23.3017","0.9873","23.3017","58.2542","98.7303","0.0000"
"","28.0200","23.3519","0.9893","23.3519","58.3797","98.9288","0.0000"
"","28.0800","23.4016","0.9907","23.4016","58.5039","99.0713","0.0000"
"","28.1400","23.4517","0.9924","23.4517","58.6293","99.2430","0.0000"
"","28.2000","23.5014","0.9940","23.5014","58.7536","99.3965","0.0000"
"","28.2600","23.5518","0.9953","23.5518","58.8796","99.5330","0.0000"
"","28.3200","23.6020","0.9968","23.6020","59.0051","99.6804","0.0000"
"","28.3800","23.6512","0.9976","23.6512","59.1281","99.7594","0.0000"
"","28.4400","23.7017","0.9989","23.7017","59.2541","99.8909","0.0000"
"","28.5000","23.7518","1.0005","23.7518","59.3796","100.0496","0.0000"
"","28.5600","23.8020","1.0012","23.8020","59.5050","100.1247","0.0000"
"","28.6200","23.8521","1.0019","23.8521","59.6302","100.1874","0.0000"
"","28.6800","23.9018","1.0021","23.9018","59.7544","100.2097","0.0000"
"","28.7400","23.9519","1.0030","23.9519","59.8798","100.3022","0.0000"
"","28.8000","24.0016","1.0034","24.0016","60.0041","100.3428","0.0000"
"","28.8600","24.0522","1.0045","24.0522","60.1304","100.4530","0.0000"
"","28.9200","24.1019","1.0050","24.1019","60.2547","100.5043","0.0000"
"","28.9800","24.1519","1.0055","24.1519","60.3798","100.5542","0.0000"
"","29.0400","24.2016","1.0073","24.2016","60.5041","100.7287","0.0000"
"","29.1000","24.2516","1.0101","24.2516","60.6289","101.0130","0.0000"
"","29.1600","24.3020","1.0140","24.3020","60.7549","101.3965","0.0000"
"","29.2200","24.3514","1.0171","24.3514","60.8786","101.7086","0.0000"
"","29.2800","24.4018","1.0208","24.4018","61.0046","102.0781","0.0000"
"","29.3400","24.4517","1.0258","24.4517","61.1292","102.5773","0.0000"
"","29.4000","24.5018","1.0308","24.5018","61.2546","103.0844","0.0000"
"","29.4600","24.5518","1.0384","24.5518","61.3794","103.8381","0.0000"
"","29.5200","24.6017","1.0457","24.6017","61.5043","104.5704","0.0000"
"","29.5800","24.6518","1.0536","24.6518","61.6294","105.3569","0.0000"
"","29.6400","24.7015","1.0606","24.7015","61.7537","106.0634","0.0000"
"","29.7000","24.7519","1.0677","24.7519","61.8797","106.7673","0.0000"
"","29.7600","24.8018","1.0760","24.8018","62.0046","107.5966","0.0000"
"","29.8200","24.8519","1.0834","24.8519","62.1297","108.3378","0.0000"
"","29.8800","24.9017","1.0917","24.9017","62.2542","109.1658","0.0000"
"","29.9400","24.9514","1.0983","24.9514","62.3785","109.8327","0.0000"
"","30.0000","25.0019","1.1058","25.0019","62.5048","110.5777","0.0000"
"","30.0600","25.0519","1.1122","25.0519","62.6297","111.2227","0.0000"
"","30.1200","25.1019","1.1182","25.1019","62.7548","111.8218","0.0000"
"","30.1800","25.1516","1.1242","25.1516","62.8790","112.4156","0.0000"
"","30.2400","25.2018","1.1291","25.2018","63.0045","112.9121","0.0000"
"","30.3000","25.2517","1.1347","25.2517","63.1293","113.4681","0.0000"
"","30.3600","25.3017","1.1391","25.3017","63.2542","113.9102","0.0000"
"","30.4200","25.3518","1.1436","25.3518","63.3796","114.3584","0.0000"
"","30.4800","25.4017","1.1476","25.4017","63.5041","114.7596","0.0000"
"","30.5400","25.4518","1.1514","25.4518","63.6296","115.1369","0.0000"
"","30.6000","25.5018","1.1548","25.5018","63.7544","115.4773","0.0000"
"","30.6600","25.5518","1.1574","25.5518","63.8796","115.7448","0.0000"
"","30.7200","25.6020","1.1611","25.6020","64.0050","116.1070","0.0000"
"","30.7800","25.6516","1.1635","25.6516","64.1290","116.3490","0.0000"
"","30.8400","25.7019","1.1663","25.7019","64.2547","116.6329","0.0000"
"","30.9000","25.7516","1.1690","25.7516","64.3789","116.9043","0.0000"
"","30.9600","25.8019","1.1716","25.8019","64.5047","117.1553","0.0000"
"","31.0200","25.8517","1.1744","25.8517","64.6292","117.4368","0.0000"
"","31.0800","25.9016","1.1767","25.9016","64.7541","117.6732","0.0000"
"","31.1400","25.9518","1.1793","25.9518","64.8795","117.9271","0.0000"
"","31.2000","26.0011","1.1804","26.0011","65.0029","118.0372","0.0000"
"","31.2600","26.0521","1.1827","26.0521","65.1304","118.2671","0.0000"
"","31.3200","26.1018","1.1843","26.1018","65.2546","118.4271","0.0000"
"","31.3800","26.1520","1.1850","26.1520","65.3800","118.4983","0.0000"
"","31.4400","26.2020","1.1859","26.2020","65.5049","118.5858","0.0000"
"","31.5000","26.2520","1.1856","26.2520","65.6300","118.5642","0.0000"
"","31.5600","26.3021","1.1858","26.3021","65.7552","118.5802","0.0000"
"","31.6200","26.3517","1.1847","26.3517","65.8791","118.4736","0.0000"
"","31.6800","26.4017","1.1838","26.4017","66.0043","118.3787","0.0000"
"","31.7400","26.4516","1.1818","26.4516","66.1291","118.1790","0.0000"
"","31.8000","26.5019","1.1779","26.5019","66.2548","117.7888","0.0000"
"","31.8600","26.5522","1.1724","26.5522","66.3806","117.2383","0.0000"
"","31.9200","26.6017","1.1619","26.6017","66.5042","116.1858","0.0000"
"","31.9800","26.6520","1.1489","26.6520","66.6300","114.8905","0.0000"
"","32.0400","26.7016","1.1348","26.7016","66.7539","113.4789","0.0000"
"","32.1000","26.7517","1.1230","26.7517","66.8794","112.2994","0.0000"
"","32.1600","26.8018","1.1131","26.8018","67.0045","111.3120","0.0000"
"","32.2200","26.8519","1.1041","26.8519","67.1296","110.4076","0.0000"
"","32.2800","26.9018","1.0967","26.9018","67.2545","109.6680","0.0000"
"","32.3400","26.9516","1.0891","26.9516","67.3790","108.9098","0.0000"
"","32.4000","27.0019","1.0826","27.0019","67.5048","108.2639","0.0000"
"","32.4600","27.0517","1.0760","27.0517","67.6293","107.5962","0.0000"
"","32.5200","27.1019","1.0698","27.1019","67.7547","106.9776","0.0000"
"","32.5800","27.1518","1.0639","27.1518","67.8796","106.3877","0.0000"
"","32.6400","27.2020","1.0578","27.2020","68.0050","105.7816","0.0000"
"","32.7000","27.2521","1.0527","27.2521","68.1302","105.2694","0.0000"
"","32.7600","27.3018","1.0472","27.3018","68.2544","104.7215","0.0000"
"","32.8200","27.3522","1.0427","27.3522","68.3804","104.2737","0.0000"
"","32.8800","27.4015","1.0385","27.4015","68.5038","103.8516","0.0000"
"","32.9400","27.4518","1.0346","27.4518","68.6295","103.4618","0.0000"
"","33.0000","27.5019","1.0314","27.5019","68.7547","103.1422","0.0000"
"","33.0600","27.5520","1.0280","27.5520","68.8801","102.8024","0.0000"
"","33.1200","27.6019","1.0251","27.6019","69.0046","102.5122","0.0000"
"","33.1800","27.6514","1.0220","27.6514","69.1286","102.1950","0.0000"
"","33.2400","27.7015","1.0193","27.7015","69.2537","101.9339","0.0000"
"","33.3000","27.7516","1.0169","27.7516","69.3789","101.6860","0.0000"
"","33.3600","27.8022","1.0142","27.8022","69.5055","101.4161","0.0000"
"","33.4200","27.8519","1.0114","27.8519","69.6298","101.1441","0.0000"
"","33.4800","27.9016","1.0089","27.9016","69.7540","100.8910","0.0000"
"","33.5400","27.9518","1.0069","27.9518","69.8794","100.6908","0.0000"
"","33.6000","28.0017","1.0044","28.0017","70.0043","100.4396","0.0000"
"","33.6600","28.0520","1.0024","28.0520","70.1300","100.2371","0.0000"
"","33.7200","28.1018","1.0003","28.1018","70.2546","100.0331","0.0000"
"","33.7800","28.1516","0.9982","28.1516","70.3791","99.8213","0.0000"
"","33.8400","28.2017","0.9967","28.2017","70.5042","99.6677","0.0000"
"","33.9000","28.2518","0.9947","28.2518","70.6294","99.4689","0.0000"
"","33.9600","28.3022","0.9933","28.3022","70.7554","99.3302","0.0000"
"","34.0200","28.3514","0.9915","28.3514","70.8785","99.1485","0.0000"
"","34.0800","28.4017","0.9904","28.4017","71.0042","99.0412","0.0000"
"","34.1400","28.4515","0.9897","28.4515","71.1288","98.9728","0.0000"
"","34.2000","28.5020","0.9887","28.5020","71.2551","98.8748","0.0000"
"","34.2600","28.5522","0.9879","28.5522","71.3805","98.7923","0.0000"
"","34.3200","28.6018","0.9867","28.6018","71.5045","98.6696","0.0000"
"","34.3800","28.6520","0.9860","28.6520","71.6299","98.6034","0.0000"
"","34.4400","28.7012","0.9851","28.7012","71.7530","98.5071","0.0000"
"","34.5000","28.7521","0.9846","28.7521","71.8802","98.4607","0.0000"
"","34.5600","28.8020","0.9844","28.8020","72.0050","98.4395","0.0000"
"","34.6200","28.8518","0.9836","28.8518","72.1296","98.3622","0.0000"
"","34.6800","28.9018","0.9834","28.9018","72.2544","98.3361","0.0000"
"","34.7400","28.9516","0.9828","28.9516","72.3790","98.2827","0.0000"
"","34.8000","29.0019","0.9826","29.0019","72.5047","98.2584","0.0000"
"","34.8600","29.0517","0.9825","29.0517","72.6293","98.2460","0.0000"
"","34.9200","29.1019","0.9824","29.1019","72.7547","98.2374","0.0000"
"","34.9800","29.1517","0.9825","29.1517","72.8792","98.2510","0.0000"
"","35.0400","29.2017","0.9825","29.2018","73.0044","98.2513","0.0000"
"","35.1000","29.2520","0.9829","29.2520","73.1301","98.2856","0.0000"
"","35.1600","29.3017","0.9829","29.3017","73.2544","98.2904","0.0000"
"","35.2200","29.3518","0.9831","29.3518","73.3795","98.3121","0.0000"
"","35.2800","29.4017","0.9834","29.4017","73.5043","98.3447","0.0000"
"","35.3400","29.4518","0.9838","29.4518","73.6295","98.3750","0.0000"
"","35.4000","29.5018","0.9843","29.5018","73.7546","98.4283","0.0000"
"","35.4600","29.5515","0.9844","29.5515","73.8789","98.4376","0.0000"
"","35.5200","29.6018","0.9849","29.6018","74.0046","98.4855","0.0000"
"","35.5800","29.6517","0.9851","29.6517","74.1292","98.5111","0.0000"
"","35.6400","29.7018","0.9854","29.7018","74.2546","98.5405","0.0000"
"","35.7000","29.7518","0.9858","29.7518","74.3794","98.5797","0.0000"
"","35.7600","29.8017","0.9857","29.8017","74.5043","98.5745","0.0000"
"","35.8200","29.8519","0.9862","29.8519","74.6297","98.6204","0.0000"
"","35.8800","29.9015","0.9863","29.9015","74.7537","98.6277","0.0000"
"","35.9400","29.9519","0.9865","29.9519","74.8797","98.6525","0.0000"
"","36.0000","30.0016","0.9868","30.0016","75.0039","98.6768","0.0000"
"","36.0600","30.0518","0.9867","30.0518","75.1294","98.6741","0.0000"
"","36.1200","30.1018","0.9874","30.1018","75.2545","98.7359","0.0000"
"","36.1800","30.1517","0.9876","30.1517","75.3794","98.7593","0.0000"
"","36.2400","30.2019","0.9881","30.2019","75.5048","98.8093","0.0000"
"","36.3000","30.2516","0.9881","30.2516","75.6290","98.8067","0.0000"
"","36.3600","30.3019","0.9887","30.3019","75.7548","98.8686","0.0000"
"","36.4200","30.3517","0.9890","30.3517","75.8793","98.8990","0.0000"
"","36.4800","30.4020","0.9895","30.4020","76.0051","98.9494","0.0000"
"","36.5400","30.4517","0.9898","30.4517","76.1293","98.9816","0.0000"
"","36.6000","30.5015","0.9899","30.5015","76.2539","98.9933","0.0000"
"","36.6600","30.5518","0.9913","30.5518","76.3796","99.1311","0.0000"
"","36.7200","30.6017","0.9927","30.6017","76.5041","99.2708","0.0000"
"","36.7800","30.6518","0.9945","30.6518","76.6296","99.4513","0.0000"
"","36.8400","30.7018","0.9962","30.7018","76.7544","99.6167","0.0000"
"","36.9000","30.7515","0.9976","30.7515","76.8787","99.7585","0.0000"
"","36.9600","30.8019","0.9994","30.8019","77.0047","99.9396","0.0000"
"","37.0200","30.8517","1.0010","30.8517","77.1292","100.0983","0.0000"
"","37.0800","30.9022","1.0029","30.9022","77.2556","100.2895","0.0000"
"","37.1400","30.9518","1.0042","30.9518","77.3795","100.4205","0.0000"
"","37.2000","31.0020","1.0056","31.0020","77.5050","100.5595","0.0000"
"","37.2600","31.0518","1.0072","31.0518","77.6295","100.7178","0.0000"
"","37.3200","31.1016","1.0083","31.1016","77.7540","100.8298","0.0000"
"","37.3800","31.1518","1.0102","31.1518","77.8795","101.0191","0.0000"
"","37.4400","31.2015","1.0116","31.2015","78.0037","101.1642","0.0000"
"","37.5000","31.2520","1.0134","31.2520","78.1301","101.3379","0.0000"
"","37.5600","31.3017","1.0156","31.3017","78.2543","101.5645","0.0000"
"","37.6200","31.3517","1.0176","31.3517","78.3791","101.7608","0.0000"
"","37.6800","31.4018","1.0198","31.4018","78.5046","101.9811","0.0000"
"","37.7400","31.4518","1.0222","31.4518","78.6294","102.2187","0.0000"
"","37.8000","31.5019","1.0248","31.5019","78.7549","102.4775","0.0000"
"","37.8600","31.5518","1.0273","31.5518","78.8794","102.7256","0.0000"
"","37.9200","31.6019","1.0294","31.6019","79.0048","102.9404","0.0000"
"","37.9800","31.6518","1.0313","31.6518","79.1294","103.1326","0.0000"
"","38.0400","31.7018","1.0329","31.7018","79.2545","103.2947","0.0000"
"","38.1000","31.7516","1.0356","31.7516","79.3791","103.5563","0.0000"
"","38.1600","31.8017","1.0380","31.8017","79.5042","103.7973","0.0000"
"","38.2200","31.8521","1.0405","31.8521","79.6302","104.0482","0.0000"
"","38.2800","31.9017","1.0425","31.9017","79.7542","104.2461","0.0000"
"","38.3400","31.9519","1.0444","31.9519","79.8796","104.4355","0.0000"
"","38.4000","32.0014","1.0462","32.0014","80.0036","104.6205","0.0000"
"","38.4600","32.0515","1.0474","32.0515","80.1287","104.7403","0.0000"
"","38.5200","32.1020","1.0492","32.1020","80.2551","104.9216","0.0000"
"","38.5800","32.1516","1.0505","32.1516","80.3790","105.0472","0.0000"
"","38.6400","32.2019","1.0519","32.2019","80.5047","105.1899","0.0000"
"","38.7000","32.2518","1.0532","32.2518","80.6296","105.3232","0.0000"
"","38.7600","32.3020","1.0545","32.3020","80.7550","105.4488","0.0000"
"","38.8200","32.3516","1.0561","32.3516","80.8790","105.6050","0.0000"
"","38.8800","32.4016","1.0578","32.4016","81.0041","105.7802","0.0000"
"","38.9400","32.4519","1.0604","32.4519","81.1298","106.0370","0.0000"
"","39.0000","32.5016","1.0632","32.5016","81.2541","106.3239","0.0000"
"","39.0600","32.5520","1.0667","32.5520","81.3801","106.6656","0.0000"
"","39.1200","32.6020","1.0701","32.6020","81.5050","107.0144","0.0000"
"","39.1800","32.6519","1.0735","32.6519","81.6298","107.3483","0.0000"
"","39.2400","32.7017","1.0781","32.7017","81.7544","107.8072","0.0000"
"","39.3000","32.7516","1.0834","32.7516","81.8789","108.3362","0.0000"
"","39.3600","32.8021","1.0903","32.8021","82.0052","109.0329","0.0000"
"","39.4200","32.8516","1.1010","32.8516","82.1289","110.1030","0.0000"
"","39.4800","32.9016","1.1126","32.9016","82.2540","111.2640","0.0000"
"","39.5400","32.9513","1.1238","32.9513","82.3783","112.3840","0.0000"
"","39.6000","33.0020","1.1350","33.0020","82.5049","113.5004","0.0000"
"","39.6600","33.0518","1.1465","33.0518","82.6294","114.6526","0.0000"
"","39.7200","33.1016","1.1580","33.1016","82.7540","115.7976","0.0000"
"","39.7800","33.1517","1.1705","33.1517","82.8791","117.0475","0.0000"
"","39.8400","33.2015","1.1823","33.2015","83.0037","118.2311","0.0000"
"","39.9000","33.2521","1.1946","33.2521","83.1303","119.4630","0.0000"
"","39.9600","33.3017","1.2061","33.3017","83.2543","120.6098","0.0000"
"","40.0200","33.3518","1.2169","33.3518","83.3794","121.6884","0.0000"
"","40.0800","33.4017","1.2282","33.4017","83.5042","122.8150","0.0000"
"","40.1400","33.4516","1.2389","33.4516","83.6291","123.8890","0.0000"
"","40.2000","33.5020","1.2508","33.5020","83.7551","125.0810","0.0000"
"","40.2600","33.5516","1.2628","33.5516","83.8791","126.2771","0.0000"
"","40.3200","33.6019","1.2755","33.6019","84.0048","127.5484","0.0000"
"","40.3800","33.6516","1.2885","33.6516","84.1290","128.8499","0.0000"
"","40.4400","33.7016","1.3011","33.7016","84.2539","130.1071","0.0000"
"","40.5000","33.7520","1.3152","33.7520","84.3799","131.5199","0.0000"
"","40.5600","33.8014","1.3299","33.8014","84.5036","132.9867","0.0000"
"","40.6200","33.8518","1.3460","33.8518","84.6296","134.5999","0.0000"
"","40.6800","33.9014","1.3626","33.9014","84.7536","136.2563","0.0000"
"","40.7400","33.9517","1.3796","33.9517","84.8793","137.9562","0.0000"
"","40.8000","34.0015","1.3971","34.0015","85.0038","139.7082","0.0000"
"","40.8600","34.0517","1.4148","34.0517","85.1293","141.4777","0.0000"
"","40.9200","34.1019","1.4339","34.1019","85.2547","143.3898","0.0000"
"","40.9800","34.1515","1.4523","34.1515","85.3787","145.2321","0.0000"
"","41.0400","34.2018","1.4719","34.2018","85.5044","147.1858","0.0000"
"","41.1000","34.2515","1.4913","34.2515","85.6286","149.1254","0.0000"
"","41.1600","34.3019","1.5104","34.3019","85.7547","151.0426","0.0000"
"","41.2200","34.3516","1.5300","34.3516","85.8789","152.9982","0.0000"
"","41.2800","34.4014","1.5503","34.4014","86.0035","155.0340","0.0000"
"","41.3400","34.4520","1.5735","34.4520","86.1301","157.3543","0.0000"
"","41.4000","34.5015","1.5977","34.5015","86.2538","159.7662","0.0000"
"","41.4600","34.5519","1.6253","34.5519","86.3798","162.5317","0.0000"
"","41.5200","34.6016","1.6543","34.6016","86.5040","165.4329","0.0000"
"","41.5800","34.6516","1.6824","34.6516","86.6289","168.2400","0.0000"
"","41.6400","34.7015","1.7153","34.7015","86.7537","171.5320","0.0000"
"","41.7000","34.7515","1.7497","34.7515","86.8789","174.9655","0.0000"
"","41.7600","34.8021","1.7853","34.8021","87.0052","178.5277","0.0000"
"","41.8200","34.8514","1.8187","34.8514","87.1285","181.8693","0.0000"
"","41.8800","34.9016","1.8530","34.9016","87.2540","185.2955","0.0000"
"","41.9400","34.9514","1.8877","34.9514","87.3785","188.7672","0.0000"
"","42.0000","35.0016","1.9215","35.0016","87.5040","192.1509","0.0000"