File: Fig6C/211130_Instron/211130/PureCompression_TTball_1.csv
Results Table 1


Results Table 2


1,Time,Displacement,Force,Compressive displacement,Compressive strain (Displacement),Compressive stress,PIP count
,(s),(mm),(kN),(mm),(%),(MPa),
"","0.0000","0.0000","0.0000","0.0000","0.0000","-0.0010","0.0000"
"","0.0600","0.0236","0.0001","0.0236","0.0590","0.0069","0.0000"
"","0.1200","0.0940","0.0000","0.0940","0.2349","-0.0010","0.0000"
"","0.1800","0.1502","0.0010","0.1502","0.3754","0.1037","0.0000"
"","0.2400","0.2016","0.0038","0.2016","0.5041","0.3804","0.0000"
"","0.3000","0.2516","0.0064","0.2516","0.6289","0.6406","0.0000"
"","0.3600","0.3019","0.0089","0.3019","0.7547","0.8886","0.0000"
"","0.4200","0.3519","0.0114","0.3519","0.8798","1.1363","0.0000"
"","0.4800","0.4017","0.0138","0.4017","1.0044","1.3786","0.0000"
"","0.5400","0.4519","0.0162","0.4519","1.1298","1.6195","0.0000"
"","0.6000","0.5013","0.0185","0.5013","1.2532","1.8485","0.0000"
"","0.6600","0.5518","0.0208","0.5518","1.3795","2.0807","0.0000"
"","0.7200","0.6018","0.0230","0.6018","1.5046","2.3024","0.0000"
"","0.7800","0.6518","0.0253","0.6518","1.6295","2.5262","0.0000"
"","0.8400","0.7017","0.0275","0.7017","1.7543","2.7519","0.0000"
"","0.9000","0.7517","0.0298","0.7517","1.8791","2.9777","0.0000"
"","0.9600","0.8016","0.0320","0.8016","2.0040","3.2009","0.0000"
"","1.0200","0.8514","0.0343","0.8514","2.1285","3.4337","0.0000"
"","1.0800","0.9016","0.0367","0.9016","2.2540","3.6652","0.0000"
"","1.1400","0.9518","0.0391","0.9518","2.3794","3.9085","0.0000"
"","1.2000","1.0016","0.0414","1.0016","2.5040","4.1392","0.0000"
"","1.2600","1.0519","0.0438","1.0519","2.6297","4.3798","0.0000"
"","1.3200","1.1017","0.0462","1.1017","2.7542","4.6247","0.0000"
"","1.3800","1.1519","0.0487","1.1519","2.8797","4.8711","0.0000"
"","1.4400","1.2016","0.0511","1.2016","3.0039","5.1102","0.0000"
"","1.5000","1.2519","0.0537","1.2519","3.1297","5.3680","0.0000"
"","1.5600","1.3017","0.0562","1.3017","3.2542","5.6214","0.0000"
"","1.6200","1.3516","0.0587","1.3516","3.3790","5.8723","0.0000"
"","1.6800","1.4019","0.0613","1.4019","3.5048","6.1288","0.0000"
"","1.7400","1.4515","0.0638","1.4515","3.6287","6.3830","0.0000"
"","1.8000","1.5019","0.0664","1.5019","3.7548","6.6428","0.0000"
"","1.8600","1.5514","0.0690","1.5514","3.8784","6.9031","0.0000"
"","1.9200","1.6019","0.0715","1.6019","4.0047","7.1504","0.0000"
"","1.9800","1.6517","0.0741","1.6517","4.1293","7.4096","0.0000"
"","2.0400","1.7017","0.0766","1.7017","4.2541","7.6587","0.0000"
"","2.1000","1.7518","0.0791","1.7518","4.3796","7.9149","0.0000"
"","2.1600","1.8014","0.0817","1.8014","4.5035","8.1688","0.0000"
"","2.2200","1.8521","0.0843","1.8521","4.6301","8.4274","0.0000"
"","2.2800","1.9018","0.0870","1.9018","4.7544","8.6958","0.0000"
"","2.3400","1.9515","0.0896","1.9515","4.8786","8.9572","0.0000"
"","2.4000","2.0016","0.0922","2.0016","5.0041","9.2155","0.0000"
"","2.4600","2.0517","0.0948","2.0517","5.1292","9.4828","0.0000"
"","2.5200","2.1020","0.0974","2.1020","5.2549","9.7438","0.0000"
"","2.5800","2.1516","0.1000","2.1516","5.3789","9.9977","0.0000"
"","2.6400","2.2019","0.1026","2.2019","5.5046","10.2604","0.0000"
"","2.7000","2.2513","0.1051","2.2513","5.6283","10.5136","0.0000"
"","2.7600","2.3018","0.1078","2.3018","5.7546","10.7759","0.0000"
"","2.8200","2.3519","0.1104","2.3519","5.8798","11.0355","0.0000"
"","2.8800","2.4015","0.1131","2.4015","6.0037","11.3083","0.0000"
"","2.9400","2.4517","0.1159","2.4517","6.1291","11.5945","0.0000"
"","3.0000","2.5015","0.1189","2.5015","6.2537","11.8865","0.0000"
"","3.0600","2.5515","0.1218","2.5515","6.3788","12.1763","0.0000"
"","3.1200","2.6018","0.1247","2.6018","6.5046","12.4678","0.0000"
"","3.1800","2.6516","0.1276","2.6516","6.6291","12.7618","0.0000"
"","3.2400","2.7019","0.1306","2.7019","6.7548","13.0567","0.0000"
"","3.3000","2.7518","0.1335","2.7518","6.8794","13.3514","0.0000"
"","3.3600","2.8020","0.1364","2.8020","7.0051","13.6380","0.0000"
"","3.4200","2.8517","0.1392","2.8517","7.1294","13.9239","0.0000"
"","3.4800","2.9018","0.1419","2.9018","7.2545","14.1908","0.0000"
"","3.5400","2.9517","0.1442","2.9517","7.3794","14.4237","0.0000"
"","3.6000","3.0017","0.1452","3.0017","7.5042","14.5231","0.0000"
"","3.6600","3.0520","0.1443","3.0520","7.6299","14.4262","0.0000"
"","3.7200","3.1016","0.1436","3.1016","7.7539","14.3581","0.0000"
"","3.7800","3.1516","0.1440","3.1516","7.8790","14.3962","0.0000"
"","3.8400","3.2013","0.1447","3.2013","8.0033","14.4728","0.0000"
"","3.9000","3.2518","0.1459","3.2518","8.1296","14.5888","0.0000"
"","3.9600","3.3020","0.1474","3.3020","8.2550","14.7435","0.0000"
"","4.0200","3.3514","0.1490","3.3514","8.3784","14.8991","0.0000"
"","4.0800","3.4018","0.1504","3.4018","8.5044","15.0437","0.0000"
"","4.1400","3.4517","0.1519","3.4517","8.6293","15.1910","0.0000"
"","4.2000","3.5018","0.1531","3.5018","8.7544","15.3100","0.0000"
"","4.2600","3.5518","0.1543","3.5518","8.8795","15.4288","0.0000"
"","4.3200","3.6021","0.1555","3.6021","9.0053","15.5478","0.0000"
"","4.3800","3.6518","0.1566","3.6518","9.1295","15.6565","0.0000"
"","4.4400","3.7014","0.1577","3.7014","9.2535","15.7696","0.0000"
"","4.5000","3.7520","0.1586","3.7520","9.3801","15.8625","0.0000"
"","4.5600","3.8017","0.1597","3.8017","9.5044","15.9655","0.0000"
"","4.6200","3.8519","0.1610","3.8519","9.6298","16.0985","0.0000"
"","4.6800","3.9017","0.1625","3.9017","9.7543","16.2533","0.0000"
"","4.7400","3.9517","0.1638","3.9517","9.8792","16.3841","0.0000"
"","4.8000","4.0016","0.1651","4.0016","10.0040","16.5103","0.0000"
"","4.8600","4.0514","0.1665","4.0514","10.1286","16.6504","0.0000"
"","4.9200","4.1018","0.1682","4.1018","10.2546","16.8197","0.0000"
"","4.9800","4.1517","0.1698","4.1517","10.3791","16.9829","0.0000"
"","5.0400","4.2018","0.1714","4.2018","10.5046","17.1393","0.0000"
"","5.1000","4.2518","0.1731","4.2518","10.6294","17.3140","0.0000"
"","5.1600","4.3016","0.1750","4.3016","10.7540","17.4955","0.0000"
"","5.2200","4.3519","0.1768","4.3519","10.8797","17.6829","0.0000"
"","5.2800","4.4012","0.1786","4.4012","11.0031","17.8612","0.0000"
"","5.3400","4.4521","0.1806","4.4521","11.1303","18.0614","0.0000"
"","5.4000","4.5016","0.1826","4.5016","11.2539","18.2553","0.0000"
"","5.4600","4.5518","0.1843","4.5518","11.3794","18.4315","0.0000"
"","5.5200","4.6017","0.1864","4.6017","11.5042","18.6375","0.0000"
"","5.5800","4.6515","0.1884","4.6515","11.6288","18.8428","0.0000"
"","5.6400","4.7018","0.1906","4.7018","11.7545","19.0586","0.0000"
"","5.7000","4.7515","0.1927","4.7515","11.8788","19.2675","0.0000"
"","5.7600","4.8020","0.1946","4.8020","12.0051","19.4571","0.0000"
"","5.8200","4.8516","0.1965","4.8516","12.1290","19.6499","0.0000"
"","5.8800","4.9015","0.1983","4.9015","12.2539","19.8349","0.0000"
"","5.9400","4.9517","0.2004","4.9517","12.3793","20.0450","0.0000"
"","6.0000","5.0018","0.2024","5.0018","12.5044","20.2398","0.0000"
"","6.0600","5.0518","0.2043","5.0518","12.6296","20.4294","0.0000"
"","6.1200","5.1014","0.2063","5.1014","12.7535","20.6276","0.0000"
"","6.1800","5.1516","0.2083","5.1516","12.8790","20.8313","0.0000"
"","6.2400","5.2015","0.2103","5.2015","13.0038","21.0270","0.0000"
"","6.3000","5.2515","0.2124","5.2515","13.1287","21.2372","0.0000"
"","6.3600","5.3022","0.2144","5.3022","13.2556","21.4407","0.0000"
"","6.4200","5.3517","0.2163","5.3517","13.3792","21.6269","0.0000"
"","6.4800","5.4018","0.2181","5.4018","13.5044","21.8099","0.0000"
"","6.5400","5.4515","0.2199","5.4515","13.6286","21.9904","0.0000"
"","6.6000","5.5015","0.2216","5.5015","13.7538","22.1593","0.0000"
"","6.6600","5.5517","0.2233","5.5517","13.8792","22.3253","0.0000"
"","6.7200","5.6016","0.2248","5.6016","14.0040","22.4820","0.0000"
"","6.7800","5.6518","0.2264","5.6518","14.1295","22.6412","0.0000"
"","6.8400","5.7011","0.2281","5.7011","14.2528","22.8142","0.0000"
"","6.9000","5.7518","0.2299","5.7518","14.3795","22.9902","0.0000"
"","6.9600","5.8018","0.2316","5.8018","14.5046","23.1604","0.0000"
"","7.0200","5.8521","0.2332","5.8521","14.6303","23.3155","0.0000"
"","7.0800","5.9020","0.2349","5.9020","14.7549","23.4860","0.0000"
"","7.1400","5.9515","0.2365","5.9515","14.8788","23.6451","0.0000"
"","7.2000","6.0019","0.2382","6.0019","15.0049","23.8165","0.0000"
"","7.2600","6.0516","0.2400","6.0516","15.1291","24.0013","0.0000"
"","7.3200","6.1019","0.2417","6.1019","15.2548","24.1716","0.0000"
"","7.3800","6.1515","0.2432","6.1515","15.3788","24.3163","0.0000"
"","7.4400","6.2017","0.2449","6.2017","15.5042","24.4879","0.0000"
"","7.5000","6.2519","0.2466","6.2519","15.6297","24.6644","0.0000"
"","7.5600","6.3016","0.2482","6.3016","15.7539","24.8215","0.0000"
"","7.6200","6.3519","0.2499","6.3519","15.8797","24.9907","0.0000"
"","7.6800","6.4014","0.2514","6.4014","16.0036","25.1438","0.0000"
"","7.7400","6.4517","0.2531","6.4517","16.1293","25.3058","0.0000"
"","7.8000","6.5018","0.2546","6.5018","16.2545","25.4624","0.0000"
"","7.8600","6.5520","0.2563","6.5520","16.3799","25.6333","0.0000"
"","7.9200","6.6020","0.2580","6.6020","16.5051","25.8005","0.0000"
"","7.9800","6.6514","0.2543","6.6514","16.6284","25.4312","0.0000"
"","8.0000","6.6687","0.2114","6.6687","16.6718","21.1391","0.0000"
"","8.0380","6.7002","0.1705","6.7002","16.7506","17.0535","0.0000"
"","8.0980","6.7499","0.1759","6.7499","16.8749","17.5881","0.0000"
"","8.1580","6.8005","0.1799","6.8005","17.0012","17.9901","0.0000"
"","8.2180","6.8501","0.1838","6.8501","17.1251","18.3788","0.0000"
"","8.2780","6.9000","0.1873","6.9000","17.2500","18.7269","0.0000"
"","8.3380","6.9502","0.1907","6.9502","17.3754","19.0715","0.0000"
"","8.3980","7.0000","0.1937","7.0000","17.5000","19.3679","0.0000"
"","8.4580","7.0504","0.1961","7.0504","17.6260","19.6107","0.0000"
"","8.5180","7.1000","0.1982","7.1000","17.7499","19.8155","0.0000"
"","8.5780","7.1499","0.2002","7.1499","17.8748","20.0183","0.0000"
"","8.6380","7.1997","0.2023","7.1997","17.9993","20.2341","0.0000"
"","8.6980","7.2500","0.2042","7.2500","18.1251","20.4189","0.0000"
"","8.7580","7.3004","0.2059","7.3004","18.2511","20.5857","0.0000"
"","8.8180","7.3499","0.2073","7.3499","18.3748","20.7259","0.0000"
"","8.8780","7.4000","0.2087","7.4000","18.4999","20.8734","0.0000"
"","8.9380","7.4497","0.2101","7.4497","18.6241","21.0081","0.0000"
"","8.9980","7.5001","0.2115","7.5001","18.7502","21.1472","0.0000"
"","9.0580","7.5502","0.2129","7.5502","18.8756","21.2916","0.0000"
"","9.1180","7.5999","0.2140","7.5999","18.9999","21.4031","0.0000"
"","9.1780","7.6502","0.2155","7.6502","19.1256","21.5457","0.0000"
"","9.2380","7.6997","0.2166","7.6997","19.2493","21.6645","0.0000"
"","9.2980","7.7501","0.2181","7.7501","19.3753","21.8064","0.0000"
"","9.3580","7.8000","0.2193","7.8000","19.5001","21.9263","0.0000"
"","9.4180","7.8502","0.2204","7.8502","19.6256","22.0425","0.0000"
"","9.4780","7.9000","0.2218","7.9000","19.7501","22.1767","0.0000"
"","9.5380","7.9499","0.2231","7.9499","19.8747","22.3086","0.0000"
"","9.5980","8.0003","0.2245","8.0003","20.0007","22.4543","0.0000"
"","9.6580","8.0496","0.2258","8.0496","20.1240","22.5825","0.0000"
"","9.7180","8.1003","0.2273","8.1003","20.2507","22.7336","0.0000"
"","9.7780","8.1501","0.2288","8.1501","20.3752","22.8836","0.0000"
"","9.8380","8.2004","0.2304","8.2004","20.5009","23.0359","0.0000"
"","9.8980","8.2503","0.2319","8.2503","20.6258","23.1915","0.0000"
"","9.9580","8.2999","0.2335","8.2999","20.7497","23.3469","0.0000"
"","10.0180","8.3502","0.2351","8.3502","20.8755","23.5066","0.0000"
"","10.0780","8.3999","0.2367","8.3999","20.9997","23.6668","0.0000"
"","10.1380","8.4501","0.2382","8.4501","21.1252","23.8197","0.0000"
"","10.1980","8.5000","0.2399","8.5000","21.2500","23.9882","0.0000"
"","10.2580","8.5499","0.2416","8.5499","21.3748","24.1621","0.0000"
"","10.3180","8.6002","0.2434","8.6002","21.5006","24.3365","0.0000"
"","10.3780","8.6498","0.2449","8.6498","21.6245","24.4901","0.0000"
"","10.4380","8.7000","0.2466","8.7000","21.7500","24.6615","0.0000"
"","10.4980","8.7497","0.2483","8.7497","21.8742","24.8267","0.0000"
"","10.5580","8.8001","0.2501","8.8001","22.0002","25.0055","0.0000"
"","10.6180","8.8502","0.2518","8.8502","22.1254","25.1771","0.0000"
"","10.6780","8.9002","0.2533","8.9002","22.2505","25.3309","0.0000"
"","10.7380","8.9503","0.2550","8.9503","22.3757","25.4958","0.0000"
"","10.7980","8.9997","0.2565","8.9997","22.4993","25.6477","0.0000"
"","10.8580","9.0501","0.2581","9.0501","22.6253","25.8134","0.0000"
"","10.9180","9.1002","0.2597","9.1002","22.7505","25.9720","0.0000"
"","10.9780","9.1504","0.2612","9.1504","22.8759","26.1184","0.0000"
"","11.0380","9.2002","0.2627","9.2002","23.0005","26.2704","0.0000"
"","11.0980","9.2498","0.2640","9.2498","23.1244","26.4036","0.0000"
"","11.1580","9.3001","0.2655","9.3001","23.2502","26.5478","0.0000"
"","11.2180","9.3499","0.2666","9.3499","23.3747","26.6637","0.0000"
"","11.2780","9.4002","0.2680","9.4002","23.5004","26.7962","0.0000"
"","11.3380","9.4500","0.2692","9.4500","23.6250","26.9217","0.0000"
"","11.3980","9.4999","0.2704","9.4999","23.7498","27.0400","0.0000"
"","11.4580","9.5500","0.2720","9.5500","23.8750","27.1969","0.0000"
"","11.5180","9.5999","0.2733","9.5999","23.9998","27.3284","0.0000"
"","11.5780","9.6501","0.2746","9.6501","24.1252","27.4636","0.0000"
"","11.6380","9.7000","0.2760","9.7000","24.2501","27.5991","0.0000"
"","11.6980","9.7503","0.2773","9.7503","24.3758","27.7251","0.0000"
"","11.7580","9.8000","0.2784","9.8000","24.5001","27.8375","0.0000"
"","11.8180","9.8500","0.2795","9.8500","24.6249","27.9534","0.0000"
"","11.8780","9.9000","0.2807","9.9000","24.7501","28.0726","0.0000"
"","11.9380","9.9500","0.2819","9.9500","24.8749","28.1852","0.0000"
"","11.9980","10.0003","0.2830","10.0002","25.0006","28.3039","0.0000"
"","12.0580","10.0501","0.2842","10.0501","25.1252","28.4190","0.0000"
"","12.1180","10.1001","0.2854","10.1001","25.2503","28.5366","0.0000"
"","12.1780","10.1499","0.2865","10.1499","25.3749","28.6501","0.0000"
"","12.2380","10.1999","0.2875","10.1999","25.4997","28.7466","0.0000"
"","12.2980","10.2502","0.2884","10.2502","25.6254","28.8433","0.0000"
"","12.3580","10.2999","0.2893","10.2999","25.7497","28.9335","0.0000"
"","12.4180","10.3502","0.2903","10.3502","25.8754","29.0316","0.0000"
"","12.4780","10.3995","0.2911","10.3995","25.9988","29.1120","0.0000"
"","12.5380","10.4499","0.2921","10.4499","26.1248","29.2132","0.0000"
"","12.5980","10.5000","0.2933","10.5000","26.2500","29.3267","0.0000"
"","12.6580","10.5500","0.2942","10.5500","26.3751","29.4231","0.0000"
"","12.7180","10.6007","0.2953","10.6007","26.5017","29.5266","0.0000"
"","12.7780","10.6499","0.2961","10.6499","26.6248","29.6135","0.0000"
"","12.8380","10.7001","0.2970","10.7001","26.7502","29.7011","0.0000"
"","12.8980","10.7500","0.2980","10.7500","26.8751","29.8025","0.0000"
"","12.9580","10.8000","0.2989","10.8000","26.9999","29.8892","0.0000"
"","13.0180","10.8503","0.3001","10.8503","27.1256","30.0118","0.0000"
"","13.0780","10.9000","0.3012","10.9000","27.2499","30.1245","0.0000"
"","13.1380","10.9502","0.3024","10.9502","27.3756","30.2419","0.0000"
"","13.1980","10.9999","0.3034","10.9999","27.4999","30.3399","0.0000"
"","13.2580","11.0501","0.3044","11.0501","27.6253","30.4404","0.0000"
"","13.3180","11.0999","0.3056","11.0999","27.7498","30.5594","0.0000"
"","13.3780","11.1498","0.3066","11.1498","27.8744","30.6630","0.0000"
"","13.4380","11.2003","0.3080","11.2003","28.0007","30.7972","0.0000"
"","13.4980","11.2500","0.3092","11.2500","28.1250","30.9179","0.0000"
"","13.5580","11.3003","0.3104","11.3003","28.2507","31.0363","0.0000"
"","13.6180","11.3501","0.3114","11.3501","28.3752","31.1385","0.0000"
"","13.6780","11.4003","0.3125","11.4003","28.5007","31.2457","0.0000"
"","13.7380","11.4501","0.3135","11.4501","28.6252","31.3485","0.0000"
"","13.7980","11.4999","0.3146","11.4999","28.7498","31.4556","0.0000"
"","13.8580","11.5503","0.3158","11.5503","28.8758","31.5812","0.0000"
"","13.9180","11.5999","0.3167","11.5999","28.9998","31.6655","0.0000"
"","13.9780","11.6501","0.3176","11.6501","29.1252","31.7601","0.0000"
"","14.0380","11.6999","0.3185","11.6999","29.2497","31.8506","0.0000"
"","14.0980","11.7503","0.3195","11.7503","29.3758","31.9512","0.0000"
"","14.1580","11.8001","0.3206","11.8001","29.5003","32.0579","0.0000"
"","14.2180","11.8501","0.3216","11.8501","29.6252","32.1589","0.0000"
"","14.2780","11.9001","0.3228","11.9001","29.7503","32.2777","0.0000"
"","14.3380","11.9498","0.3239","11.9498","29.8745","32.3924","0.0000"
"","14.3980","12.0002","0.3252","12.0002","30.0006","32.5156","0.0000"
"","14.4580","12.0500","0.3262","12.0500","30.1251","32.6202","0.0000"
"","14.5180","12.1001","0.3273","12.1001","30.2503","32.7274","0.0000"
"","14.5780","12.1498","0.3285","12.1498","30.3745","32.8516","0.0000"
"","14.6380","12.1999","0.3295","12.1999","30.4997","32.9500","0.0000"
"","14.6980","12.2504","0.3308","12.2504","30.6260","33.0828","0.0000"
"","14.7580","12.3000","0.3320","12.3000","30.7499","33.1958","0.0000"
"","14.8180","12.3501","0.3331","12.3501","30.8754","33.3087","0.0000"
"","14.8780","12.4000","0.3343","12.4000","30.9999","33.4286","0.0000"
"","14.9380","12.4498","0.3352","12.4498","31.1245","33.5186","0.0000"
"","14.9980","12.5002","0.3362","12.5002","31.2505","33.6219","0.0000"
"","15.0580","12.5499","0.3373","12.5499","31.3747","33.7256","0.0000"
"","15.1180","12.6001","0.3384","12.6001","31.5002","33.8368","0.0000"
"","15.1780","12.6500","0.3396","12.6500","31.6250","33.9583","0.0000"
"","15.2380","12.7001","0.3407","12.7001","31.7502","34.0730","0.0000"
"","15.2980","12.7499","0.3420","12.7499","31.8747","34.2038","0.0000"
"","15.3580","12.7999","0.3431","12.7999","31.9998","34.3146","0.0000"
"","15.4180","12.8502","0.3445","12.8502","32.1256","34.4475","0.0000"
"","15.4780","12.8999","0.3455","12.8999","32.2498","34.5471","0.0000"
"","15.5380","12.9502","0.3466","12.9502","32.3756","34.6644","0.0000"
"","15.5980","12.9998","0.3477","12.9998","32.4995","34.7748","0.0000"
"","15.6580","13.0501","0.3489","13.0501","32.6252","34.8928","0.0000"
"","15.7180","13.1002","0.3500","13.1002","32.7504","35.0038","0.0000"
"","15.7780","13.1500","0.3510","13.1500","32.8749","35.0959","0.0000"
"","15.8380","13.2003","0.3520","13.2003","33.0007","35.1960","0.0000"
"","15.8980","13.2501","0.3529","13.2501","33.1252","35.2924","0.0000"
"","15.9580","13.3004","0.3540","13.3004","33.2509","35.3984","0.0000"
"","16.0180","13.3503","0.3552","13.3503","33.3758","35.5162","0.0000"
"","16.0780","13.4000","0.3562","13.4000","33.5000","35.6156","0.0000"
"","16.1380","13.4498","0.3573","13.4498","33.6246","35.7326","0.0000"
"","16.1980","13.4999","0.3584","13.4999","33.7497","35.8439","0.0000"
"","16.2580","13.5505","0.3597","13.5505","33.8763","35.9737","0.0000"
"","16.3180","13.6000","0.3607","13.6000","34.0000","36.0664","0.0000"
"","16.3780","13.6501","0.3616","13.6501","34.1251","36.1561","0.0000"
"","16.4380","13.6999","0.3626","13.6999","34.2497","36.2627","0.0000"
"","16.4980","13.7498","0.3636","13.7498","34.3745","36.3598","0.0000"
"","16.5580","13.8002","0.3647","13.8002","34.5006","36.4746","0.0000"
"","16.6180","13.8498","0.3657","13.8498","34.6245","36.5716","0.0000"
"","16.6780","13.9003","0.3669","13.9003","34.7508","36.6892","0.0000"
"","16.7380","13.9498","0.3678","13.9498","34.8745","36.7840","0.0000"
"","16.7980","14.0001","0.3687","14.0001","35.0002","36.8723","0.0000"
"","16.8580","14.0499","0.3698","14.0499","35.1248","36.9781","0.0000"
"","16.9180","14.1001","0.3708","14.1001","35.2502","37.0777","0.0000"
"","16.9780","14.1503","0.3721","14.1503","35.3756","37.2110","0.0000"
"","17.0380","14.1996","0.3732","14.1996","35.4990","37.3202","0.0000"
"","17.0980","14.2503","0.3747","14.2503","35.6256","37.4687","0.0000"
"","17.1580","14.3002","0.3760","14.3002","35.7505","37.6042","0.0000"
"","17.2180","14.3501","0.3771","14.3501","35.8753","37.7079","0.0000"
"","17.2780","14.4002","0.3783","14.4002","36.0005","37.8251","0.0000"
"","17.3380","14.4500","0.3791","14.4500","36.1250","37.9144","0.0000"
"","17.3980","14.5004","0.3803","14.5004","36.2510","38.0291","0.0000"
"","17.4580","14.5498","0.3813","14.5498","36.3744","38.1252","0.0000"
"","17.5180","14.6002","0.3825","14.6002","36.5004","38.2542","0.0000"
"","17.5780","14.6500","0.3839","14.6500","36.6250","38.3896","0.0000"
"","17.6380","14.7000","0.3853","14.7000","36.7501","38.5275","0.0000"
"","17.6980","14.7502","0.3867","14.7502","36.8755","38.6712","0.0000"
"","17.7580","14.7999","0.3879","14.7999","36.9998","38.7880","0.0000"
"","17.8180","14.8501","0.3892","14.8501","37.1252","38.9247","0.0000"
"","17.8780","14.8997","0.3903","14.8997","37.2492","39.0336","0.0000"
"","17.9380","14.9501","0.3914","14.9501","37.3752","39.1437","0.0000"
"","17.9980","14.9999","0.3926","14.9999","37.4998","39.2593","0.0000"
"","18.0580","15.0500","0.3938","15.0500","37.6249","39.3770","0.0000"
"","18.1180","15.1003","0.3951","15.1003","37.7506","39.5108","0.0000"
"","18.1780","15.1494","0.3963","15.1494","37.8734","39.6280","0.0000"
"","18.2380","15.2001","0.3979","15.2001","38.0003","39.7897","0.0000"
"","18.2980","15.2501","0.3992","15.2501","38.1252","39.9150","0.0000"
"","18.3580","15.3004","0.4003","15.3004","38.2509","40.0318","0.0000"
"","18.4180","15.3501","0.4014","15.3501","38.3751","40.1422","0.0000"
"","18.4780","15.3999","0.4023","15.3999","38.4997","40.2275","0.0000"
"","18.5380","15.4503","0.4037","15.4503","38.6257","40.3708","0.0000"
"","18.5980","15.4996","0.4051","15.4996","38.7491","40.5106","0.0000"
"","18.6580","15.5504","0.4067","15.5504","38.8760","40.6680","0.0000"
"","18.7180","15.6001","0.4083","15.6001","39.0002","40.8285","0.0000"
"","18.7780","15.6500","0.4097","15.6500","39.1251","40.9663","0.0000"
"","18.8380","15.6999","0.4109","15.6999","39.2496","41.0919","0.0000"
"","18.8980","15.7500","0.4121","15.7500","39.3751","41.2114","0.0000"
"","18.9580","15.8003","0.4135","15.8003","39.5008","41.3470","0.0000"
"","19.0180","15.8498","0.4146","15.8498","39.6245","41.4563","0.0000"
"","19.0780","15.9001","0.4159","15.9001","39.7502","41.5888","0.0000"
"","19.1380","15.9499","0.4172","15.9499","39.8747","41.7189","0.0000"
"","19.1980","16.0003","0.4184","16.0003","40.0008","41.8411","0.0000"
"","19.2580","16.0502","0.4197","16.0502","40.1256","41.9710","0.0000"
"","19.3180","16.0999","0.4209","16.0999","40.2499","42.0869","0.0000"
"","19.3780","16.1500","0.4224","16.1500","40.3750","42.2403","0.0000"
"","19.4380","16.1997","0.4238","16.1997","40.4993","42.3782","0.0000"
"","19.4980","16.2502","0.4253","16.2502","40.6256","42.5261","0.0000"
"","19.5580","16.3002","0.4268","16.3002","40.7504","42.6815","0.0000"
"","19.6180","16.3501","0.4279","16.3501","40.8753","42.7931","0.0000"
"","19.6780","16.3998","0.4292","16.3998","40.9995","42.9156","0.0000"
"","19.7380","16.4497","0.4302","16.4497","41.1244","43.0200","0.0000"
"","19.7980","16.5004","0.4317","16.5004","41.2510","43.1678","0.0000"
"","19.8580","16.5501","0.4329","16.5501","41.3752","43.2864","0.0000"
"","19.9180","16.6001","0.4343","16.6001","41.5004","43.4264","0.0000"
"","19.9780","16.6498","0.4360","16.6498","41.6246","43.5986","0.0000"
"","20.0380","16.7004","0.4377","16.7004","41.7509","43.7725","0.0000"
"","20.0980","16.7503","0.4395","16.7503","41.8758","43.9489","0.0000"
"","20.1580","16.7999","0.4409","16.7999","41.9997","44.0856","0.0000"
"","20.2180","16.8502","0.4426","16.8502","42.1255","44.2561","0.0000"
"","20.2780","16.8998","0.4440","16.8998","42.2494","44.3962","0.0000"
"","20.3380","16.9501","0.4454","16.9501","42.3752","44.5418","0.0000"
"","20.3980","16.9999","0.4472","16.9999","42.4997","44.7155","0.0000"
"","20.4580","17.0502","0.4489","17.0502","42.6254","44.8898","0.0000"
"","20.5180","17.1003","0.4508","17.1003","42.7509","45.0810","0.0000"
"","20.5780","17.1498","0.4523","17.1498","42.8745","45.2285","0.0000"
"","20.6380","17.1999","0.4537","17.1999","42.9997","45.3657","0.0000"
"","20.6980","17.2497","0.4550","17.2497","43.1242","45.5031","0.0000"
"","20.7580","17.3002","0.4565","17.3002","43.2505","45.6458","0.0000"
"","20.8180","17.3502","0.4580","17.3502","43.3754","45.7964","0.0000"
"","20.8780","17.4000","0.4593","17.4000","43.4999","45.9331","0.0000"
"","20.9380","17.4503","0.4608","17.4503","43.6257","46.0792","0.0000"
"","20.9980","17.4997","0.4620","17.4997","43.7493","46.1957","0.0000"
"","21.0580","17.5501","0.4634","17.5501","43.8753","46.3368","0.0000"
"","21.1180","17.6001","0.4649","17.6001","44.0002","46.4886","0.0000"
"","21.1780","17.6502","0.4663","17.6502","44.1256","46.6303","0.0000"
"","21.2380","17.7001","0.4679","17.7001","44.2502","46.7886","0.0000"
"","21.2980","17.7499","0.4690","17.7499","44.3747","46.9036","0.0000"
"","21.3580","17.8003","0.4705","17.8003","44.5007","47.0525","0.0000"
"","21.4180","17.8499","0.4716","17.8499","44.6247","47.1597","0.0000"
"","21.4780","17.9002","0.4729","17.9002","44.7504","47.2862","0.0000"
"","21.5380","17.9499","0.4741","17.9499","44.8747","47.4116","0.0000"
"","21.5980","18.0000","0.4753","18.0000","45.0001","47.5281","0.0000"
"","21.6580","18.0501","0.4768","18.0501","45.1253","47.6838","0.0000"
"","21.7180","18.0999","0.4781","18.0999","45.2498","47.8082","0.0000"
"","21.7780","18.1502","0.4796","18.1502","45.3755","47.9618","0.0000"
"","21.8380","18.1997","0.4811","18.1997","45.4992","48.1080","0.0000"
"","21.8980","18.2502","0.4828","18.2502","45.6255","48.2775","0.0000"
"","21.9580","18.3000","0.4846","18.3000","45.7501","48.4578","0.0000"
"","22.0180","18.3501","0.4861","18.3501","45.8752","48.6117","0.0000"
"","22.0780","18.4001","0.4882","18.4001","46.0004","48.8154","0.0000"
"","22.1380","18.4501","0.4899","18.4501","46.1252","48.9942","0.0000"
"","22.1980","18.5002","0.4918","18.5002","46.2506","49.1794","0.0000"
"","22.2580","18.5498","0.4934","18.5498","46.3746","49.3394","0.0000"
"","22.3180","18.6001","0.4950","18.6001","46.5003","49.4974","0.0000"
"","22.3780","18.6501","0.4968","18.6501","46.6252","49.6750","0.0000"
"","22.4380","18.7001","0.4983","18.7001","46.7503","49.8287","0.0000"
"","22.4980","18.7503","0.5000","18.7503","46.8757","49.9991","0.0000"
"","22.5580","18.8000","0.5017","18.8000","47.0000","50.1653","0.0000"
"","22.6180","18.8502","0.5035","18.8502","47.1254","50.3503","0.0000"
"","22.6780","18.8999","0.5054","18.8999","47.2497","50.5407","0.0000"
"","22.7380","18.9497","0.5070","18.9497","47.3742","50.7019","0.0000"
"","22.7980","19.0002","0.5091","19.0002","47.5005","50.9053","0.0000"
"","22.8580","19.0500","0.5106","19.0500","47.6251","51.0616","0.0000"
"","22.9180","19.1003","0.5123","19.1003","47.7508","51.2319","0.0000"
"","22.9780","19.1498","0.5138","19.1498","47.8745","51.3792","0.0000"
"","23.0380","19.2002","0.5155","19.2002","48.0005","51.5550","0.0000"
"","23.0980","19.2500","0.5173","19.2500","48.1251","51.7298","0.0000"
"","23.1580","19.3000","0.5189","19.3000","48.2499","51.8880","0.0000"
"","23.2180","19.3503","0.5210","19.3503","48.3756","52.0962","0.0000"
"","23.2780","19.3997","0.5229","19.3997","48.4993","52.2903","0.0000"
"","23.3380","19.4501","0.5252","19.4501","48.6253","52.5161","0.0000"
"","23.3980","19.4999","0.5273","19.4999","48.7499","52.7279","0.0000"
"","23.4580","19.5501","0.5294","19.5501","48.8753","52.9450","0.0000"
"","23.5180","19.6001","0.5316","19.6001","49.0001","53.1579","0.0000"
"","23.5780","19.6500","0.5331","19.6500","49.1250","53.3113","0.0000"
"","23.6380","19.7000","0.5351","19.7000","49.2501","53.5056","0.0000"
"","23.6980","19.7500","0.5366","19.7500","49.3750","53.6557","0.0000"
"","23.7580","19.8004","0.5380","19.8004","49.5010","53.8032","0.0000"
"","23.8180","19.8499","0.5420","19.8499","49.6246","54.1969","0.0000"
"","23.8780","19.8997","0.5540","19.8997","49.7492","55.3991","0.0000"
"","23.9380","19.9496","0.5669","19.9496","49.8740","56.6857","0.0000"
"","23.9980","20.0000","0.5787","20.0000","50.0001","57.8686","0.0000"
"","24.0580","20.0503","0.5901","20.0503","50.1258","59.0060","0.0000"
"","24.1180","20.0998","0.6005","20.0998","50.2495","60.0500","0.0000"
"","24.1780","20.1498","0.6108","20.1498","50.3746","61.0763","0.0000"
"","24.2380","20.1999","0.6212","20.1999","50.4997","62.1207","0.0000"
"","24.2980","20.2501","0.6321","20.2501","50.6252","63.2147","0.0000"
"","24.3580","20.3001","0.6434","20.3001","50.7503","64.3390","0.0000"
"","24.4180","20.3499","0.6536","20.3499","50.8749","65.3558","0.0000"
"","24.4780","20.4002","0.6638","20.4002","51.0006","66.3816","0.0000"
"","24.5380","20.4498","0.6730","20.4498","51.1245","67.2974","0.0000"
"","24.5980","20.5000","0.6816","20.5000","51.2500","68.1604","0.0000"
"","24.6580","20.5499","0.6896","20.5499","51.3748","68.9637","0.0000"
"","24.7180","20.6001","0.6967","20.6001","51.5003","69.6715","0.0000"
"","24.7780","20.6502","0.7019","20.6502","51.6254","70.1862","0.0000"
"","24.8380","20.6999","0.7032","20.6999","51.7497","70.3166","0.0000"
"","24.8980","20.7503","0.7048","20.7503","51.8757","70.4790","0.0000"
"","24.9580","20.7999","0.7101","20.7999","51.9996","71.0132","0.0000"
"","25.0180","20.8501","0.7169","20.8501","52.1254","71.6891","0.0000"
"","25.0780","20.9001","0.7241","20.9001","52.2502","72.4133","0.0000"
"","25.1380","20.9500","0.7317","20.9500","52.3751","73.1676","0.0000"
"","25.1980","21.0001","0.7405","21.0001","52.5002","74.0523","0.0000"
"","25.2580","21.0495","0.7490","21.0495","52.6239","74.9006","0.0000"
"","25.3180","21.1001","0.7582","21.1001","52.7502","75.8219","0.0000"
"","25.3780","21.1497","0.7668","21.1497","52.8741","76.6826","0.0000"
"","25.4380","21.2001","0.7756","21.2001","53.0002","77.5639","0.0000"
"","25.4980","21.2501","0.7850","21.2501","53.1253","78.4999","0.0000"
"","25.5580","21.2998","0.7937","21.2998","53.2495","79.3726","0.0000"
"","25.6180","21.3501","0.8033","21.3501","53.3753","80.3305","0.0000"
"","25.6780","21.4000","0.8125","21.4000","53.5001","81.2545","0.0000"
"","25.7380","21.4502","0.8212","21.4502","53.6256","82.1155","0.0000"
"","25.7980","21.4998","0.8294","21.4998","53.7495","82.9414","0.0000"
"","25.8580","21.5500","0.8370","21.5500","53.8750","83.6996","0.0000"
"","25.9180","21.6003","0.8453","21.6003","54.0007","84.5332","0.0000"
"","25.9780","21.6501","0.8523","21.6501","54.1252","85.2296","0.0000"
"","26.0380","21.7001","0.8603","21.7001","54.2504","86.0272","0.0000"
"","26.0980","21.7495","0.8671","21.7495","54.3737","86.7086","0.0000"
"","26.1580","21.8000","0.8746","21.8000","54.5001","87.4613","0.0000"
"","26.2180","21.8501","0.8822","21.8501","54.6252","88.2177","0.0000"
"","26.2780","21.9003","0.8891","21.9003","54.7506","88.9094","0.0000"
"","26.3380","21.9501","0.8963","21.9501","54.8752","89.6343","0.0000"
"","26.3980","22.0000","0.9032","22.0000","55.0000","90.3167","0.0000"
"","26.4580","22.0501","0.9101","22.0501","55.1252","91.0114","0.0000"
"","26.5180","22.0998","0.9169","22.0998","55.2494","91.6937","0.0000"
"","26.5780","22.1499","0.9241","22.1499","55.3748","92.4050","0.0000"
"","26.6380","22.2001","0.9313","22.2001","55.5003","93.1287","0.0000"
"","26.6980","22.2503","0.9384","22.2503","55.6257","93.8372","0.0000"
"","26.7580","22.3002","0.9453","22.3002","55.7506","94.5252","0.0000"
"","26.8180","22.3499","0.9519","22.3499","55.8748","95.1860","0.0000"
"","26.8780","22.4001","0.9589","22.4001","56.0002","95.8949","0.0000"
"","26.9380","22.4498","0.9656","22.4498","56.1245","96.5569","0.0000"
"","26.9980","22.5001","0.9720","22.5001","56.2502","97.2036","0.0000"
"","27.0580","22.5500","0.9786","22.5500","56.3751","97.8565","0.0000"
"","27.1180","22.6000","0.9841","22.6000","56.4999","98.4138","0.0000"
"","27.1780","22.6500","0.9902","22.6500","56.6251","99.0192","0.0000"
"","27.2380","22.6998","0.9953","22.6998","56.7496","99.5338","0.0000"
"","27.2980","22.7501","1.0009","22.7501","56.8753","100.0880","0.0000"
"","27.3580","22.7998","1.0053","22.7998","56.9996","100.5323","0.0000"
"","27.4180","22.8502","1.0092","22.8502","57.1256","100.9195","0.0000"
"","27.4780","22.9002","1.0127","22.9002","57.2505","101.2704","0.0000"
"","27.5380","22.9499","1.0144","22.9499","57.3747","101.4398","0.0000"
"","27.5980","23.0003","1.0164","23.0003","57.5007","101.6446","0.0000"
"","27.6580","23.0499","1.0168","23.0499","57.6247","101.6769","0.0000"
"","27.7180","23.1002","1.0171","23.1002","57.7504","101.7054","0.0000"
"","27.7780","23.1502","1.0166","23.1502","57.8756","101.6580","0.0000"
"","27.8380","23.2000","1.0148","23.2000","58.0001","101.4752","0.0000"
"","27.8980","23.2501","1.0124","23.2501","58.1252","101.2386","0.0000"
"","27.9580","23.3000","1.0086","23.3000","58.2501","100.8607","0.0000"
"","28.0180","23.3501","1.0043","23.3501","58.3752","100.4277","0.0000"
"","28.0780","23.3999","0.9989","23.3999","58.4998","99.8867","0.0000"
"","28.1380","23.4502","0.9931","23.4502","58.6255","99.3069","0.0000"
"","28.1980","23.4998","0.9865","23.4998","58.7495","98.6526","0.0000"
"","28.2580","23.5501","0.9793","23.5501","58.8752","97.9283","0.0000"
"","28.3180","23.6003","0.9723","23.6003","59.0006","97.2338","0.0000"
"","28.3780","23.6496","0.9640","23.6496","59.1240","96.4003","0.0000"
"","28.4380","23.7001","0.9570","23.7001","59.2503","95.6952","0.0000"
"","28.4980","23.7501","0.9494","23.7501","59.3752","94.9376","0.0000"
"","28.5580","23.8005","0.9414","23.8005","59.5012","94.1404","0.0000"
"","28.6180","23.8504","0.9338","23.8504","59.6260","93.3802","0.0000"
"","28.6780","23.9001","0.9257","23.9001","59.7503","92.5676","0.0000"
"","28.7380","23.9503","0.9185","23.9503","59.8757","91.8471","0.0000"
"","28.7980","24.0000","0.9110","24.0000","60.0000","91.1045","0.0000"
"","28.8580","24.0504","0.9044","24.0504","60.1260","90.4387","0.0000"
"","28.9180","24.1001","0.8976","24.1001","60.2502","89.7636","0.0000"
"","28.9780","24.1502","0.8913","24.1502","60.3754","89.1306","0.0000"
"","29.0380","24.2000","0.8858","24.2000","60.4999","88.5770","0.0000"
"","29.0980","24.2499","0.8797","24.2499","60.6248","87.9717","0.0000"
"","29.1580","24.3003","0.8746","24.3003","60.7508","87.4641","0.0000"
"","29.2180","24.3498","0.8693","24.3498","60.8745","86.9335","0.0000"
"","29.2780","24.4002","0.8646","24.4002","61.0005","86.4611","0.0000"
"","29.3380","24.4499","0.8602","24.4499","61.1247","86.0193","0.0000"
"","29.3980","24.5001","0.8558","24.5001","61.2502","85.5767","0.0000"
"","29.4580","24.5504","0.8522","24.5504","61.3759","85.2168","0.0000"
"","29.5180","24.5999","0.8486","24.5999","61.4999","84.8624","0.0000"
"","29.5780","24.6502","0.8461","24.6502","61.6256","84.6115","0.0000"
"","29.6380","24.6998","0.8438","24.6998","61.7495","84.3755","0.0000"
"","29.6980","24.7502","0.8420","24.7502","61.8756","84.1983","0.0000"
"","29.7580","24.8000","0.8405","24.8000","62.0001","84.0534","0.0000"
"","29.8180","24.8501","0.8393","24.8501","62.1253","83.9310","0.0000"
"","29.8780","24.9002","0.8390","24.9002","62.2504","83.9015","0.0000"
"","29.9380","24.9497","0.8395","24.9497","62.3744","83.9514","0.0000"
"","29.9980","25.0002","0.8430","25.0002","62.5004","84.3047","0.0000"
"","30.0580","25.0500","0.8481","25.0500","62.6249","84.8051","0.0000"
"","30.1180","25.1000","0.8530","25.1000","62.7501","85.3037","0.0000"
"","30.1780","25.1500","0.8585","25.1500","62.8749","85.8503","0.0000"
"","30.2380","25.2000","0.8645","25.2000","63.0000","86.4470","0.0000"
"","30.2980","25.2502","0.8707","25.2502","63.1255","87.0674","0.0000"
"","30.3580","25.2998","0.8762","25.2998","63.2494","87.6221","0.0000"
"","30.4180","25.3500","0.8817","25.3500","63.3749","88.1675","0.0000"
"","30.4780","25.3999","0.8869","25.3999","63.4997","88.6877","0.0000"
"","30.5380","25.4502","0.8914","25.4502","63.6254","89.1355","0.0000"
"","30.5980","25.5001","0.8959","25.5001","63.7503","89.5917","0.0000"
"","30.6580","25.5501","0.8997","25.5501","63.8751","89.9668","0.0000"
"","30.7180","25.6002","0.9041","25.6002","64.0006","90.4120","0.0000"
"","30.7780","25.6497","0.9076","25.6497","64.1242","90.7600","0.0000"
"","30.8380","25.7001","0.9112","25.7001","64.2503","91.1186","0.0000"
"","30.8980","25.7499","0.9144","25.7499","64.3748","91.4413","0.0000"
"","30.9580","25.8001","0.9169","25.8001","64.5002","91.6872","0.0000"
"","31.0180","25.8499","0.9194","25.8499","64.6248","91.9354","0.0000"
"","31.0780","25.8999","0.9215","25.8999","64.7496","92.1482","0.0000"
"","31.1380","25.9500","0.9240","25.9500","64.8751","92.3971","0.0000"
"","31.1980","25.9994","0.9259","25.9994","64.9984","92.5851","0.0000"
"","31.2580","26.0501","0.9289","26.0501","65.1253","92.8870","0.0000"
"","31.3180","26.1002","0.9325","26.1002","65.2505","93.2539","0.0000"
"","31.3780","26.1501","0.9352","26.1501","65.3753","93.5181","0.0000"
"","31.4380","26.2003","0.9380","26.2003","65.5008","93.8005","0.0000"
"","31.4980","26.2501","0.9401","26.2501","65.6253","94.0141","0.0000"
"","31.5580","26.3003","0.9428","26.3003","65.7507","94.2805","0.0000"
"","31.6180","26.3499","0.9452","26.3499","65.8747","94.5188","0.0000"
"","31.6780","26.3999","0.9476","26.3999","65.9998","94.7594","0.0000"
"","31.7380","26.4498","0.9499","26.4498","66.1244","94.9852","0.0000"
"","31.7980","26.5000","0.9516","26.5000","66.2501","95.1586","0.0000"
"","31.8580","26.5505","0.9540","26.5505","66.3761","95.3991","0.0000"
"","31.9180","26.5999","0.9554","26.5999","66.4998","95.5398","0.0000"
"","31.9780","26.6501","0.9571","26.6501","66.6252","95.7121","0.0000"
"","32.0380","26.6998","0.9581","26.6998","66.7495","95.8141","0.0000"
"","32.0980","26.7500","0.9590","26.7500","66.8749","95.9002","0.0000"
"","32.1580","26.8000","0.9596","26.8000","67.0001","95.9634","0.0000"
"","32.2180","26.8500","0.9587","26.8500","67.1249","95.8663","0.0000"
"","32.2780","26.9003","0.9598","26.9003","67.2506","95.9830","0.0000"
"","32.3380","26.9498","0.9607","26.9498","67.3746","96.0702","0.0000"
"","32.3980","27.0001","0.9628","27.0001","67.5003","96.2841","0.0000"
"","32.4580","27.0499","0.9653","27.0499","67.6249","96.5263","0.0000"
"","32.5180","27.1001","0.9676","27.1001","67.7503","96.7622","0.0000"
"","32.5780","27.1501","0.9702","27.1501","67.8752","97.0164","0.0000"
"","32.6380","27.2002","0.9716","27.2002","68.0006","97.1641","0.0000"
"","32.6980","27.2503","0.9734","27.2503","68.1257","97.3428","0.0000"
"","32.7580","27.3001","0.9739","27.3001","68.2503","97.3885","0.0000"
"","32.8180","27.3503","0.9751","27.3503","68.3757","97.5079","0.0000"
"","32.8780","27.3997","0.9757","27.3997","68.4994","97.5747","0.0000"
"","32.9380","27.4498","0.9764","27.4498","68.6245","97.6396","0.0000"
"","32.9980","27.5000","0.9775","27.5000","68.7499","97.7522","0.0000"
"","33.0580","27.5503","0.9782","27.5503","68.8757","97.8188","0.0000"
"","33.1180","27.6002","0.9789","27.6002","69.0005","97.8940","0.0000"
"","33.1780","27.6497","0.9790","27.6497","69.1242","97.8986","0.0000"
"","33.2380","27.6997","0.9795","27.6997","69.2493","97.9550","0.0000"
"","33.2980","27.7499","0.9802","27.7499","69.3748","98.0192","0.0000"
"","33.3580","27.8004","0.9808","27.8004","69.5011","98.0761","0.0000"
"","33.4180","27.8503","0.9814","27.8503","69.6256","98.1434","0.0000"
"","33.4780","27.9000","0.9822","27.9000","69.7499","98.2168","0.0000"
"","33.5380","27.9500","0.9835","27.9500","69.8750","98.3545","0.0000"
"","33.5980","27.9998","0.9843","27.9998","69.9996","98.4300","0.0000"
"","33.6580","28.0504","0.9861","28.0504","70.1259","98.6079","0.0000"
"","33.7180","28.1002","0.9875","28.1002","70.2504","98.7526","0.0000"
"","33.7780","28.1500","0.9886","28.1500","70.3750","98.8604","0.0000"
"","33.8380","28.1999","0.9900","28.1999","70.4998","99.0028","0.0000"
"","33.8980","28.2500","0.9909","28.2500","70.6250","99.0890","0.0000"
"","33.9580","28.3004","0.9920","28.3004","70.7510","99.2025","0.0000"
"","34.0180","28.3496","0.9923","28.3496","70.8741","99.2315","0.0000"
"","34.0780","28.3999","0.9934","28.3999","70.9998","99.3397","0.0000"
"","34.1380","28.4497","0.9946","28.4497","71.1243","99.4623","0.0000"
"","34.1980","28.5003","0.9962","28.5003","71.2507","99.6176","0.0000"
"","34.2580","28.5506","0.9983","28.5506","71.3764","99.8278","0.0000"
"","34.3180","28.5999","0.9997","28.5999","71.4998","99.9745","0.0000"
"","34.3780","28.6501","1.0021","28.6501","71.6252","100.2141","0.0000"
"","34.4380","28.6997","1.0037","28.6997","71.7492","100.3685","0.0000"
"","34.4980","28.7502","1.0052","28.7502","71.8755","100.5222","0.0000"
"","34.5580","28.8004","1.0066","28.8004","72.0009","100.6645","0.0000"
"","34.6180","28.8501","1.0066","28.8501","72.1252","100.6561","0.0000"
"","34.6780","28.9001","1.0060","28.9001","72.2503","100.6006","0.0000"
"","34.7200","28.9352","0.9768","28.9352","72.3379","97.6773","0.0000"
"","34.7620","28.9701","0.9375","28.9701","72.4253","93.7453","0.0000"
"","34.8220","29.0203","0.9338","29.0203","72.5507","93.3789","0.0000"
"","34.8820","29.0699","0.9310","29.0699","72.6747","93.1046","0.0000"
"","34.9420","29.1202","0.9293","29.1202","72.8004","92.9346","0.0000"
"","35.0020","29.1700","0.9276","29.1700","72.9250","92.7625","0.0000"
"","35.0620","29.2202","0.9259","29.2202","73.0504","92.5866","0.0000"
"","35.1220","29.2702","0.9243","29.2702","73.1756","92.4305","0.0000"
"","35.1820","29.3200","0.9217","29.3200","73.3001","92.1722","0.0000"
"","35.2420","29.3702","0.9191","29.3702","73.4255","91.9107","0.0000"
"","35.3020","29.4200","0.9157","29.4200","73.5501","91.5679","0.0000"
"","35.3620","29.4700","0.9120","29.4700","73.6749","91.2021","0.0000"
"","35.4220","29.5198","0.9095","29.5198","73.7995","90.9457","0.0000"
"","35.4820","29.5700","0.9065","29.5700","73.9249","90.6461","0.0000"
"","35.5420","29.6201","0.9024","29.6201","74.0503","90.2446","0.0000"
"","35.6020","29.6700","0.8966","29.6700","74.1749","89.6576","0.0000"
"","35.6620","29.7203","0.8913","29.7203","74.3006","89.1335","0.0000"
"","35.7220","29.7697","0.8876","29.7697","74.4243","88.7595","0.0000"
"","35.7820","29.8201","0.8851","29.8201","74.5503","88.5097","0.0000"
"","35.8420","29.8701","0.8836","29.8701","74.6752","88.3559","0.0000"
"","35.9020","29.9200","0.8820","29.9200","74.8000","88.1966","0.0000"
"","35.9620","29.9701","0.8808","29.9701","74.9251","88.0830","0.0000"
"","36.0220","30.0198","0.8793","30.0198","75.0494","87.9310","0.0000"
"","36.0820","30.0699","0.8780","30.0699","75.1748","87.7964","0.0000"
"","36.1420","30.1200","0.8765","30.1200","75.3000","87.6508","0.0000"
"","36.2020","30.1704","0.8749","30.1704","75.4260","87.4913","0.0000"
"","36.2620","30.2201","0.8733","30.2201","75.5502","87.3266","0.0000"
"","36.3220","30.2700","0.8712","30.2700","75.6751","87.1245","0.0000"
"","36.3820","30.3202","0.8697","30.3202","75.8005","86.9736","0.0000"
"","36.4420","30.3700","0.8676","30.3700","75.9251","86.7637","0.0000"
"","36.5020","30.4203","0.8661","30.4203","76.0508","86.6051","0.0000"
"","36.5620","30.4699","0.8639","30.4699","76.1748","86.3917","0.0000"
"","36.6220","30.5200","0.8617","30.5200","76.2999","86.1749","0.0000"
"","36.6820","30.5700","0.8597","30.5700","76.4250","85.9741","0.0000"
"","36.7420","30.6202","0.8573","30.6202","76.5505","85.7314","0.0000"
"","36.8020","30.6702","0.8552","30.6702","76.6756","85.5168","0.0000"
"","36.8620","30.7197","0.8526","30.7197","76.7993","85.2618","0.0000"
"","36.9220","30.7701","0.8502","30.7701","76.9253","85.0247","0.0000"
"","36.9820","30.8201","0.8479","30.8201","77.0501","84.7932","0.0000"
"","37.0420","30.8701","0.8448","30.8701","77.1753","84.4795","0.0000"
"","37.1020","30.9202","0.8427","30.9202","77.3004","84.2692","0.0000"
"","37.1620","30.9700","0.8406","30.9700","77.4250","84.0588","0.0000"
"","37.2220","31.0204","0.8394","31.0204","77.5510","83.9356","0.0000"
"","37.2820","31.0700","0.8376","31.0700","77.6749","83.7598","0.0000"
"","37.3420","31.1200","0.8356","31.1200","77.8001","83.5623","0.0000"
"","37.4020","31.1697","0.8337","31.1697","77.9243","83.3694","0.0000"
"","37.4620","31.2200","0.8313","31.2200","78.0501","83.1311","0.0000"
"","37.5220","31.2703","0.8293","31.2703","78.1758","82.9332","0.0000"
"","37.5820","31.3201","0.8267","31.3201","78.3003","82.6659","0.0000"
"","37.6420","31.3702","0.8255","31.3702","78.4255","82.5460","0.0000"
"","37.7020","31.4199","0.8257","31.4199","78.5497","82.5667","0.0000"
"","37.7620","31.4701","0.8257","31.4701","78.6752","82.5658","0.0000"
"","37.8220","31.5201","0.8258","31.5201","78.8003","82.5805","0.0000"
"","37.8820","31.5702","0.8251","31.5702","78.9255","82.5091","0.0000"
"","37.9420","31.6204","0.8250","31.6204","79.0509","82.4973","0.0000"
"","38.0020","31.6697","0.8243","31.6697","79.1743","82.4302","0.0000"
"","38.0620","31.7201","0.8253","31.7201","79.3003","82.5335","0.0000"
"","38.1220","31.7699","0.8275","31.7699","79.4248","82.7494","0.0000"
"","38.1820","31.8200","0.8297","31.8200","79.5500","82.9695","0.0000"
"","38.2420","31.8702","0.8328","31.8702","79.6754","83.2848","0.0000"
"","38.3020","31.9201","0.8353","31.9201","79.8002","83.5319","0.0000"
"","38.3620","31.9701","0.8377","31.9701","79.9254","83.7661","0.0000"
"","38.4220","32.0195","0.8400","32.0195","80.0488","84.0029","0.0000"
"","38.4820","32.0701","0.8450","32.0701","80.1754","84.5014","0.0000"
"","38.5420","32.1200","0.8504","32.1200","80.2999","85.0358","0.0000"
"","38.6020","32.1699","0.8549","32.1699","80.4247","85.4902","0.0000"
"","38.6620","32.2203","0.8615","32.2203","80.5508","86.1485","0.0000"
"","38.7220","32.2700","0.8673","32.2700","80.6750","86.7304","0.0000"
"","38.7820","32.3203","0.8741","32.3203","80.8008","87.4132","0.0000"
"","38.8420","32.3697","0.8804","32.3697","80.9241","88.0390","0.0000"
"","38.9020","32.4201","0.8876","32.4201","81.0502","88.7567","0.0000"
"","38.9620","32.4699","0.8956","32.4699","81.1747","89.5569","0.0000"
"","39.0220","32.5199","0.9030","32.5199","81.2998","90.3045","0.0000"
"","39.0820","32.5701","0.9112","32.5701","81.4253","91.1220","0.0000"
"","39.1420","32.6198","0.9191","32.6198","81.5495","91.9083","0.0000"
"","39.2020","32.6701","0.9263","32.6701","81.6753","92.6277","0.0000"
"","39.2620","32.7198","0.9338","32.7198","81.7995","93.3769","0.0000"
"","39.3220","32.7699","0.9408","32.7699","81.9246","94.0770","0.0000"
"","39.3820","32.8200","0.9482","32.8200","82.0501","94.8244","0.0000"
"","39.4420","32.8701","0.9549","32.8701","82.1752","95.4884","0.0000"
"","39.5020","32.9201","0.9621","32.9201","82.3004","96.2138","0.0000"
"","39.5620","32.9698","0.9684","32.9698","82.4246","96.8405","0.0000"
"","39.6220","33.0204","0.9753","33.0204","82.5509","97.5284","0.0000"
"","39.6820","33.0698","0.9812","33.0698","82.6746","98.1188","0.0000"
"","39.7420","33.1201","0.9869","33.1201","82.8003","98.6900","0.0000"
"","39.8020","33.1700","0.9929","33.1700","82.9249","99.2934","0.0000"
"","39.8620","33.2200","0.9984","33.2200","83.0500","99.8378","0.0000"
"","39.9220","33.2703","1.0049","33.2703","83.1757","100.4904","0.0000"
"","39.9820","33.3199","1.0098","33.3199","83.2997","100.9801","0.0000"
"","40.0420","33.3701","1.0161","33.3701","83.4251","101.6143","0.0000"
"","40.1020","33.4199","1.0239","33.4199","83.5497","102.3879","0.0000"
"","40.1620","33.4702","1.0316","33.4702","83.6754","103.1589","0.0000"
"","40.2220","33.5202","1.0378","33.5202","83.8006","103.7838","0.0000"
"","40.2820","33.5699","1.0447","33.5699","83.9248","104.4688","0.0000"
"","40.3420","33.6201","1.0525","33.6201","84.0502","105.2478","0.0000"
"","40.4020","33.6698","1.0595","33.6698","84.1745","105.9501","0.0000"
"","40.4620","33.7201","1.0668","33.7201","84.3002","106.6822","0.0000"
"","40.5220","33.7700","1.0749","33.7700","84.4251","107.4859","0.0000"
"","40.5820","33.8198","1.0831","33.8198","84.5496","108.3063","0.0000"
"","40.6420","33.8700","1.0933","33.8700","84.6751","109.3287","0.0000"
"","40.7020","33.9197","1.1023","33.9197","84.7993","110.2292","0.0000"
"","40.7620","33.9701","1.1128","33.9701","84.9253","111.2823","0.0000"
"","40.8220","34.0198","1.1223","34.0198","85.0496","112.2311","0.0000"
"","40.8820","34.0701","1.1330","34.0701","85.1753","113.3012","0.0000"
"","40.9420","34.1198","1.1438","34.1198","85.2996","114.3813","0.0000"
"","41.0020","34.1700","1.1475","34.1700","85.4250","114.7505","0.0000"
"","41.0220","34.1872","1.0993","34.1872","85.4681","109.9342","0.0000"
"","41.0420","34.2040","1.0579","34.2040","85.5100","105.7925","0.0000"
"","41.0980","34.2499","1.0486","34.2499","85.6248","104.8624","0.0000"
"","41.1580","34.3001","1.0635","34.3001","85.7502","106.3465","0.0000"
"","41.2180","34.3499","1.0789","34.3499","85.8748","107.8893","0.0000"
"","41.2780","34.3999","1.0945","34.3999","85.9996","109.4536","0.0000"
"","41.3380","34.4503","1.1121","34.4503","86.1257","111.2094","0.0000"
"","41.3980","34.4997","1.1278","34.4997","86.2493","112.7797","0.0000"
"","41.4580","34.5500","1.1442","34.5500","86.3751","114.4169","0.0000"
"","41.5180","34.6000","1.1623","34.6000","86.4999","116.2294","0.0000"
"","41.5780","34.6500","1.1802","34.6500","86.6250","118.0184","0.0000"
"","41.6380","34.7000","1.1991","34.7000","86.7499","119.9052","0.0000"
"","41.6980","34.7498","1.2162","34.7498","86.8744","121.6157","0.0000"
"","41.7580","34.8004","1.2353","34.8004","87.0010","123.5286","0.0000"
"","41.8180","34.8496","1.2521","34.8496","87.1241","125.2130","0.0000"
"","41.8780","34.9001","1.2710","34.9001","87.2501","127.1033","0.0000"
"","41.9380","34.9499","1.2900","34.9499","87.3747","128.9983","0.0000"
"","41.9980","34.9999","1.3089","34.9999","87.4998","130.8910","0.0000"
"","42.0000","35.0016","1.3096","35.0016","87.5040","130.9610","0.0000"