File: Fig6C/211130_Instron/211130/tensile_curtain_7_1.csv
Results Table 1


Results Table 2


1,Time,Displacement,Force,Tensile displacement,Tensile strain (Displacement),Tensile stress
,(s),(mm),(kN),(mm),(%),(MPa)
2,Time,Displacement,Force,Tensile displacement,Tensile strain (Displacement),Tensile stress
,(s),(mm),(kN),(mm),(%),(MPa)
3,Time,Displacement,Force,Tensile displacement,Tensile strain (Displacement),Tensile stress
,(s),(mm),(kN),(mm),(%),(MPa)
"","0.0000","0.1065","0.0006","0.1065","0.2173","0.2441"
"","0.0200","0.1088","0.0006","0.1088","0.2221","0.2490"
"","0.0400","0.1176","0.0007","0.1176","0.2400","0.2840"
"","0.0600","0.1338","0.0007","0.1338","0.2730","0.3027"
"","0.0800","0.1549","0.0008","0.1549","0.3161","0.3454"
"","0.1000","0.1774","0.0010","0.1774","0.3621","0.4014"
"","0.1200","0.1990","0.0012","0.1990","0.4062","0.4811"
"","0.1400","0.2190","0.0013","0.2190","0.4469","0.5480"
"","0.1600","0.2376","0.0015","0.2376","0.4850","0.6160"
"","0.1800","0.2552","0.0016","0.2552","0.5209","0.6860"
"","0.2000","0.2724","0.0018","0.2724","0.5558","0.7379"
"","0.2200","0.2891","0.0019","0.2891","0.5900","0.8015"
"","0.2400","0.3061","0.0020","0.3061","0.6247","0.8518"
"","0.2600","0.3231","0.0022","0.3231","0.6594","0.9004"
"","0.2800","0.3400","0.0023","0.3400","0.6939","0.9532"
"","0.3000","0.3566","0.0024","0.3566","0.7278","1.0093"
"","0.3200","0.3732","0.0025","0.3732","0.7616","1.0572"
"","0.3400","0.3898","0.0026","0.3898","0.7955","1.0946"
"","0.3600","0.4063","0.0027","0.4063","0.8293","1.1337"
"","0.3800","0.4230","0.0028","0.4230","0.8633","1.1812"
"","0.4000","0.4399","0.0029","0.4399","0.8977","1.2284"
"","0.4200","0.4569","0.0031","0.4569","0.9324","1.2825"
"","0.4400","0.4734","0.0032","0.4734","0.9661","1.3298"
"","0.4600","0.4899","0.0033","0.4899","0.9999","1.3585"
"","0.4800","0.5065","0.0033","0.5065","1.0336","1.3896"
"","0.5000","0.5231","0.0034","0.5231","1.0676","1.4097"
"","0.5200","0.5399","0.0035","0.5399","1.1018","1.4452"
"","0.5400","0.5566","0.0036","0.5566","1.1360","1.4893"
"","0.5600","0.5736","0.0037","0.5736","1.1707","1.5289"
"","0.5800","0.5903","0.0038","0.5903","1.2046","1.5823"
"","0.6000","0.6067","0.0039","0.6067","1.2381","1.6100"
"","0.6200","0.6231","0.0040","0.6231","1.2716","1.6493"
"","0.6400","0.6397","0.0040","0.6397","1.3056","1.6809"
"","0.6600","0.6563","0.0041","0.6563","1.3393","1.7172"
"","0.6800","0.6729","0.0042","0.6729","1.3733","1.7441"
"","0.7000","0.6898","0.0043","0.6898","1.4078","1.7814"
"","0.7200","0.7066","0.0044","0.7066","1.4420","1.8256"
"","0.7400","0.7231","0.0045","0.7231","1.4757","1.8547"
"","0.7600","0.7395","0.0045","0.7395","1.5092","1.8808"
"","0.7800","0.7563","0.0046","0.7563","1.5434","1.9052"
"","0.8000","0.7731","0.0046","0.7731","1.5778","1.9374"
"","0.8200","0.7898","0.0048","0.7898","1.6118","1.9805"
"","0.8400","0.8068","0.0048","0.8068","1.6465","2.0036"
"","0.8600","0.8237","0.0049","0.8237","1.6810","2.0308"
"","0.8800","0.8403","0.0049","0.8403","1.7149","2.0576"
"","0.9000","0.8566","0.0050","0.8566","1.7482","2.0913"
"","0.9200","0.8731","0.0051","0.8731","1.7819","2.1214"
"","0.9400","0.8899","0.0051","0.8899","1.8161","2.1274"
"","0.9600","0.9067","0.0051","0.9067","1.8503","2.1379"
"","0.9800","0.9233","0.0052","0.9233","1.8843","2.1548"
"","1.0000","0.9400","0.0053","0.9400","1.9183","2.2184"
"","1.0200","0.9566","0.0054","0.9566","1.9523","2.2558"
"","1.0400","0.9731","0.0055","0.9731","1.9860","2.2767"
"","1.0600","0.9894","0.0055","0.9894","2.0192","2.2982"
"","1.0800","1.0063","0.0056","1.0063","2.0537","2.3152"
"","1.1000","1.0233","0.0056","1.0233","2.0884","2.3303"
"","1.1200","1.0400","0.0057","1.0400","2.1223","2.3623"
"","1.1400","1.0566","0.0057","1.0566","2.1563","2.3933"
"","1.1600","1.0734","0.0058","1.0734","2.1905","2.4026"
"","1.1800","1.0898","0.0058","1.0898","2.2240","2.4212"
"","1.2000","1.1061","0.0059","1.1061","2.2573","2.4397"
"","1.2200","1.1226","0.0059","1.1226","2.2910","2.4623"
"","1.2400","1.1396","0.0060","1.1396","2.3257","2.4827"
"","1.2600","1.1566","0.0060","1.1566","2.3604","2.5050"
"","1.2800","1.1734","0.0061","1.1734","2.3946","2.5231"
"","1.3000","1.1900","0.0061","1.1900","2.4286","2.5358"
"","1.3200","1.2066","0.0062","1.2066","2.4625","2.5697"
"","1.3400","1.2232","0.0062","1.2232","2.4963","2.5910"
"","1.3600","1.2397","0.0062","1.2397","2.5300","2.5876"
"","1.3800","1.2565","0.0062","1.2565","2.5642","2.6006"
"","1.4000","1.2735","0.0063","1.2735","2.5989","2.6387"
"","1.4200","1.2902","0.0064","1.2902","2.6331","2.6737"
"","1.4400","1.3068","0.0065","1.3068","2.6669","2.6886"
"","1.4600","1.3232","0.0065","1.3232","2.7003","2.6973"
"","1.4800","1.3397","0.0065","1.3397","2.7341","2.7094"
"","1.5000","1.3563","0.0065","1.3563","2.7680","2.7284"
"","1.5200","1.3731","0.0066","1.3731","2.8023","2.7548"
"","1.5400","1.3900","0.0067","1.3900","2.8367","2.7844"
"","1.5600","1.4069","0.0067","1.4069","2.8712","2.8038"
"","1.5800","1.4234","0.0068","1.4234","2.9049","2.8253"
"","1.6000","1.4398","0.0068","1.4398","2.9384","2.8375"
"","1.6200","1.4566","0.0069","1.4566","2.9726","2.8677"
"","1.6400","1.4731","0.0069","1.4731","3.0063","2.8861"
"","1.6600","1.4896","0.0069","1.4896","3.0401","2.8930"
"","1.6800","1.5062","0.0070","1.5062","3.0738","2.9102"
"","1.7000","1.5229","0.0070","1.5229","3.1080","2.9346"
"","1.7200","1.5397","0.0071","1.5397","3.1422","2.9627"
"","1.7400","1.5562","0.0072","1.5562","3.1759","2.9798"
"","1.7600","1.5727","0.0072","1.5727","3.2097","2.9891"
"","1.7800","1.5896","0.0072","1.5896","3.2441","3.0124"
"","1.8000","1.6067","0.0073","1.6067","3.2791","3.0394"
"","1.8200","1.6233","0.0074","1.6233","3.3128","3.0771"
"","1.8400","1.6400","0.0074","1.6400","3.3470","3.0972"
"","1.8600","1.6568","0.0075","1.6568","3.3812","3.1145"
"","1.8800","1.6734","0.0075","1.6734","3.4152","3.1294"
"","1.9000","1.6896","0.0075","1.6896","3.4482","3.1336"
"","1.9200","1.7064","0.0076","1.7064","3.4824","3.1536"
"","1.9400","1.7234","0.0076","1.7234","3.5171","3.1806"
"","1.9600","1.7401","0.0077","1.7401","3.5513","3.2071"
"","1.9800","1.7568","0.0077","1.7568","3.5853","3.2144"
"","2.0000","1.7734","0.0077","1.7734","3.6192","3.2276"
"","2.0200","1.7900","0.0078","1.7900","3.6530","3.2655"
"","2.0400","1.8062","0.0079","1.8062","3.6862","3.2884"
"","2.0600","1.8228","0.0079","1.8228","3.7200","3.2967"
"","2.0800","1.8398","0.0079","1.8398","3.7546","3.3067"
"","2.1000","1.8564","0.0080","1.8564","3.7886","3.3438"
"","2.1200","1.8730","0.0080","1.8730","3.8223","3.3352"
"","2.1400","1.8897","0.0080","1.8897","3.8566","3.3452"
"","2.1600","1.9066","0.0081","1.9066","3.8910","3.3755"
"","2.1800","1.9230","0.0082","1.9230","3.9245","3.4029"
"","2.2000","1.9394","0.0082","1.9394","3.9580","3.4193"
"","2.2200","1.9565","0.0083","1.9565","3.9929","3.4414"
"","2.2400","1.9735","0.0083","1.9735","4.0276","3.4522"
"","2.2600","1.9902","0.0083","1.9902","4.0616","3.4691"
"","2.2800","2.0065","0.0084","2.0065","4.0948","3.4943"
"","2.3000","2.0230","0.0085","2.0230","4.1286","3.5286"
"","2.3200","2.0394","0.0085","2.0394","4.1621","3.5414"
"","2.3400","2.0558","0.0085","2.0558","4.1955","3.5500"
"","2.3600","2.0727","0.0086","2.0727","4.2300","3.5678"
"","2.3800","2.0899","0.0086","2.0899","4.2652","3.5808"
"","2.4000","2.1069","0.0086","2.1069","4.2999","3.5977"
"","2.4200","2.1233","0.0087","2.1233","4.3334","3.6164"
"","2.4400","2.1400","0.0087","2.1400","4.3673","3.6431"
"","2.4600","2.1569","0.0088","2.1569","4.4018","3.6628"
"","2.4800","2.1733","0.0089","2.1733","4.4353","3.6959"
"","2.5000","2.1900","0.0089","2.1900","4.4695","3.7165"
"","2.5200","2.2069","0.0090","2.2069","4.5039","3.7645"
"","2.5400","2.2236","0.0090","2.2236","4.5379","3.7578"
"","2.5600","2.2401","0.0090","2.2401","4.5716","3.7474"
"","2.5800","2.2566","0.0090","2.2566","4.6054","3.7671"
"","2.6000","2.2733","0.0091","2.2733","4.6393","3.7981"
"","2.6200","2.2898","0.0092","2.2898","4.6731","3.8158"
"","2.6400","2.3063","0.0092","2.3063","4.7068","3.8302"
"","2.6600","2.3230","0.0092","2.3230","4.7408","3.8483"
"","2.6800","2.3401","0.0093","2.3401","4.7757","3.8699"
"","2.7000","2.3567","0.0094","2.3567","4.8097","3.9045"
"","2.7200","2.3730","0.0094","2.3730","4.8429","3.9030"
"","2.7400","2.3897","0.0094","2.3897","4.8769","3.9024"
"","2.7600","2.4064","0.0094","2.4064","4.9111","3.9213"
"","2.7800","2.4232","0.0095","2.4232","4.9453","3.9443"
"","2.8000","2.4397","0.0095","2.4397","4.9791","3.9583"
"","2.8200","2.4565","0.0096","2.4565","5.0133","3.9897"
"","2.8400","2.4735","0.0096","2.4735","5.0480","4.0134"
"","2.8600","2.4900","0.0097","2.4900","5.0817","4.0242"
"","2.8800","2.5064","0.0097","2.5064","5.1152","4.0308"
"","2.9000","2.5230","0.0097","2.5230","5.1489","4.0362"
"","2.9200","2.5398","0.0098","2.5398","5.1834","4.0730"
"","2.9400","2.5565","0.0098","2.5565","5.2173","4.1019"
"","2.9600","2.5733","0.0099","2.5733","5.2515","4.1401"
"","2.9800","2.5901","0.0100","2.5901","5.2860","4.1664"
"","3.0000","2.6067","0.0100","2.6067","5.3197","4.1790"
"","3.0200","2.6231","0.0101","2.6231","5.3532","4.2050"
"","3.0400","2.6398","0.0101","2.6398","5.3874","4.2208"
"","3.0600","2.6567","0.0102","2.6567","5.4219","4.2430"
"","3.0800","2.6734","0.0103","2.6734","5.4559","4.2767"
"","3.1000","2.6899","0.0103","2.6899","5.4896","4.2888"
"","3.1200","2.7069","0.0104","2.7069","5.5243","4.3153"
"","3.1400","2.7235","0.0104","2.7235","5.5582","4.3438"
"","3.1600","2.7397","0.0105","2.7397","5.5913","4.3715"
"","3.1800","2.7561","0.0105","2.7561","5.6247","4.3801"
"","3.2000","2.7730","0.0105","2.7730","5.6592","4.3769"
"","3.2200","2.7900","0.0106","2.7900","5.6939","4.3975"
"","3.2400","2.8067","0.0106","2.8067","5.7279","4.4260"
"","3.2600","2.8232","0.0107","2.8232","5.7616","4.4568"
"","3.2800","2.8401","0.0108","2.8401","5.7960","4.4866"
"","3.3000","2.8566","0.0108","2.8566","5.8298","4.5113"
"","3.3200","2.8728","0.0109","2.8728","5.8628","4.5330"
"","3.3400","2.8895","0.0109","2.8895","5.8970","4.5509"
"","3.3600","2.9066","0.0110","2.9066","5.9319","4.5633"
"","3.3800","2.9233","0.0110","2.9233","5.9659","4.5802"
"","3.4000","2.9399","0.0111","2.9399","5.9999","4.6132"
"","3.4200","2.9568","0.0111","2.9568","6.0343","4.6332"
"","3.4400","2.9733","0.0112","2.9733","6.0681","4.6506"
"","3.4600","2.9896","0.0112","2.9896","6.1013","4.6656"
"","3.4800","3.0060","0.0113","3.0060","6.1348","4.6892"
"","3.5000","3.0230","0.0113","3.0230","6.1695","4.7139"
"","3.5200","3.0398","0.0114","3.0398","6.2037","4.7423"
"","3.5400","3.0565","0.0114","3.0565","6.2377","4.7518"
"","3.5600","3.0733","0.0115","3.0733","6.2721","4.7754"
"","3.5800","3.0902","0.0115","3.0902","6.3066","4.7974"
"","3.6000","3.1066","0.0116","3.1066","6.3401","4.8177"
"","3.6200","3.1230","0.0116","3.1230","6.3736","4.8438"
"","3.6400","3.1400","0.0117","3.1400","6.4082","4.8671"
"","3.6600","3.1569","0.0117","3.1569","6.4427","4.8944"
"","3.6800","3.1735","0.0119","3.1735","6.4764","4.9487"
"","3.7000","3.1900","0.0119","3.1900","6.5102","4.9521"
"","3.7200","3.2069","0.0119","3.2069","6.5446","4.9703"
"","3.7400","3.2233","0.0120","3.2233","6.5781","4.9951"
"","3.7600","3.2394","0.0121","3.2394","6.6111","5.0297"
"","3.7800","3.2563","0.0121","3.2563","6.6456","5.0594"
"","3.8000","3.2733","0.0122","3.2733","6.6803","5.0925"
"","3.8200","3.2903","0.0123","3.2903","6.7150","5.1233"
"","3.8400","3.3067","0.0123","3.3067","6.7484","5.1296"
"","3.8600","3.3233","0.0124","3.3233","6.7822","5.1488"
"","3.8800","3.3399","0.0124","3.3399","6.8161","5.1740"
"","3.9000","3.3566","0.0125","3.3566","6.8501","5.1885"
"","3.9200","3.3731","0.0125","3.3731","6.8838","5.2032"
"","3.9400","3.3900","0.0126","3.3900","6.9183","5.2330"
"","3.9600","3.4068","0.0126","3.4068","6.9527","5.2464"
"","3.9800","3.4233","0.0126","3.4233","6.9862","5.2543"
"","4.0000","3.4395","0.0126","3.4395","7.0195","5.2606"
"","4.0200","3.4564","0.0127","3.4564","7.0539","5.2979"
"","4.0400","3.4733","0.0128","3.4733","7.0884","5.3424"
"","4.0600","3.4901","0.0130","3.4901","7.1226","5.4018"
"","4.0800","3.5067","0.0130","3.5067","7.1566","5.4121"
"","4.1000","3.5237","0.0130","3.5237","7.1913","5.4161"
"","4.1200","3.5402","0.0131","3.5402","7.2250","5.4435"
"","4.1400","3.5565","0.0131","3.5565","7.2582","5.4720"
"","4.1600","3.5730","0.0132","3.5730","7.2917","5.4990"
"","4.1800","3.5897","0.0133","3.5897","7.3259","5.5212"
"","4.2000","3.6065","0.0133","3.6065","7.3602","5.5386"
"","4.2200","3.6231","0.0134","3.6231","7.3941","5.5772"
"","4.2400","3.6400","0.0134","3.6400","7.4286","5.5997"
"","4.2600","3.6568","0.0135","3.6568","7.4628","5.6325"
"","4.2800","3.6733","0.0136","3.6733","7.4965","5.6488"
"","4.3000","3.6896","0.0136","3.6896","7.5298","5.6665"
"","4.3200","3.7064","0.0137","3.7064","7.5640","5.6921"
"","4.3400","3.7235","0.0137","3.7235","7.5989","5.7199"
"","4.3600","3.7401","0.0138","3.7401","7.6329","5.7493"
"","4.3800","3.7566","0.0139","3.7566","7.6666","5.7719"
"","4.4000","3.7734","0.0140","3.7734","7.7008","5.8173"
"","4.4200","3.7903","0.0141","3.7903","7.7353","5.8598"
"","4.4400","3.8065","0.0141","3.8065","7.7683","5.8676"
"","4.4600","3.8229","0.0141","3.8229","7.8018","5.8684"
"","4.4800","3.8398","0.0141","3.8398","7.8362","5.8808"
"","4.5000","3.8564","0.0142","3.8564","7.8702","5.9174"
"","4.5200","3.8729","0.0142","3.8729","7.9039","5.9343"
"","4.5400","3.8897","0.0143","3.8897","7.9382","5.9590"
"","4.5600","3.9067","0.0144","3.9067","7.9728","6.0041"
"","4.5800","3.9232","0.0145","3.9232","8.0066","6.0279"
"","4.6000","3.9397","0.0145","3.9397","8.0403","6.0470"
"","4.6200","3.9566","0.0146","3.9566","8.0748","6.0830"
"","4.6400","3.9735","0.0146","3.9735","8.1092","6.1005"
"","4.6600","3.9900","0.0147","3.9900","8.1429","6.1076"
"","4.6800","4.0067","0.0147","4.0067","8.1769","6.1258"
"","4.7000","4.0235","0.0148","4.0235","8.2111","6.1622"
"","4.7200","4.0401","0.0149","4.0401","8.2451","6.2058"
"","4.7400","4.0563","0.0149","4.0563","8.2781","6.2174"
"","4.7600","4.0730","0.0149","4.0730","8.3123","6.2287"
"","4.7800","4.0900","0.0150","4.0900","8.3470","6.2485"
"","4.8000","4.1067","0.0151","4.1067","8.3810","6.2716"
"","4.8200","4.1232","0.0151","4.1232","8.4147","6.2995"
"","4.8400","4.1400","0.0152","4.1400","8.4489","6.3273"
"","4.8600","4.1567","0.0153","4.1567","8.4831","6.3605"
"","4.8800","4.1730","0.0153","4.1730","8.5164","6.3939"
"","4.9000","4.1896","0.0154","4.1896","8.5501","6.4124"
"","4.9200","4.2064","0.0154","4.2064","8.5846","6.4329"
"","4.9400","4.2234","0.0155","4.2234","8.6193","6.4506"
"","4.9600","4.2398","0.0155","4.2398","8.6527","6.4753"
"","4.9800","4.2565","0.0156","4.2565","8.6867","6.5131"
"","5.0000","4.2730","0.0157","4.2730","8.7204","6.5406"
"","5.0200","4.2895","0.0158","4.2895","8.7542","6.5708"
"","5.0400","4.3061","0.0159","4.3061","8.7879","6.6069"
"","5.0600","4.3230","0.0159","4.3230","8.8224","6.6328"
"","5.0800","4.3401","0.0160","4.3401","8.8573","6.6609"
"","5.1000","4.3572","0.0160","4.3572","8.8922","6.6855"
"","5.1200","4.3736","0.0161","4.3736","8.9257","6.7190"
"","5.1400","4.3902","0.0162","4.3902","8.9597","6.7459"
"","5.1600","4.4067","0.0163","4.4067","8.9932","6.7803"
"","5.1800","4.4231","0.0163","4.4231","9.0267","6.8015"
"","5.2000","4.4397","0.0164","4.4397","9.0606","6.8346"
"","5.2200","4.4566","0.0164","4.4566","9.0951","6.8432"
"","5.2400","4.4736","0.0165","4.4736","9.1298","6.8742"
"","5.2600","4.4900","0.0166","4.4900","9.1633","6.9263"
"","5.2800","4.5065","0.0167","4.5065","9.1970","6.9603"
"","5.3000","4.5232","0.0168","4.5232","9.2310","6.9829"
"","5.3200","4.5398","0.0169","4.5398","9.2649","7.0219"
"","5.3400","4.5565","0.0170","4.5565","9.2989","7.0662"
"","5.3600","4.5734","0.0170","4.5734","9.3334","7.0965"
"","5.3800","4.5902","0.0171","4.5902","9.3678","7.1230"
"","5.4000","4.6069","0.0171","4.6069","9.4018","7.1429"
"","5.4200","4.6233","0.0172","4.6233","9.4353","7.1707"
"","5.4400","4.6398","0.0173","4.6398","9.4690","7.2029"
"","5.4600","4.6567","0.0174","4.6567","9.5035","7.2365"
"","5.4800","4.6733","0.0174","4.6733","9.5374","7.2582"
"","5.5000","4.6898","0.0175","4.6898","9.5709","7.2892"
"","5.5200","4.7065","0.0176","4.7065","9.6051","7.3266"
"","5.5400","4.7232","0.0176","4.7232","9.6391","7.3514"
"","5.5600","4.7396","0.0177","4.7396","9.6726","7.3773"
"","5.5800","4.7562","0.0178","4.7562","9.7066","7.4018"
"","5.6000","4.7731","0.0179","4.7731","9.7410","7.4726"
"","5.6200","4.7902","0.0180","4.7902","9.7760","7.4990"
"","5.6400","4.8067","0.0180","4.8067","9.8097","7.5053"
"","5.6600","4.8234","0.0181","4.8234","9.8437","7.5397"
"","5.6800","4.8403","0.0182","4.8403","9.8781","7.5742"
"","5.7000","4.8567","0.0182","4.8567","9.9116","7.5934"
"","5.7200","4.8730","0.0183","4.8730","9.9449","7.6379"
"","5.7400","4.8896","0.0184","4.8896","9.9788","7.6757"
"","5.7600","4.9066","0.0185","4.9066","10.0135","7.7125"
"","5.7800","4.9232","0.0186","4.9232","10.0472","7.7326"
"","5.8000","4.9399","0.0186","4.9399","10.0815","7.7607"
"","5.8200","4.9567","0.0187","4.9567","10.1157","7.8107"
"","5.8400","4.9736","0.0188","4.9736","10.1501","7.8284"
"","5.8600","4.9897","0.0188","4.9897","10.1831","7.8482"
"","5.8800","5.0061","0.0189","5.0061","10.2166","7.8764"
"","5.9000","5.0231","0.0190","5.0231","10.2513","7.9028"
"","5.9200","5.0399","0.0191","5.0399","10.2855","7.9380"
"","5.9400","5.0566","0.0191","5.0566","10.3195","7.9546"
"","5.9600","5.0733","0.0192","5.0733","10.3537","7.9932"
"","5.9800","5.0902","0.0192","5.0902","10.3882","8.0123"
"","6.0000","5.1066","0.0193","5.1066","10.4217","8.0256"
"","6.0200","5.1230","0.0193","5.1230","10.4551","8.0598"
"","6.0400","5.1397","0.0194","5.1397","10.4891","8.1002"
"","6.0600","5.1567","0.0195","5.1567","10.5238","8.1376"
"","6.0800","5.1733","0.0196","5.1733","10.5578","8.1761"
"","6.1000","5.1900","0.0197","5.1900","10.5918","8.2011"
"","6.1200","5.2068","0.0198","5.2068","10.6262","8.2405"
"","6.1400","5.2235","0.0199","5.2235","10.6602","8.2846"
"","6.1600","5.2395","0.0200","5.2395","10.6929","8.3203"
"","6.1800","5.2562","0.0200","5.2562","10.7269","8.3393"
"","6.2000","5.2733","0.0201","5.2733","10.7618","8.3551"
"","6.2200","5.2902","0.0201","5.2902","10.7963","8.3851"
"","6.2400","5.3066","0.0202","5.3066","10.8298","8.4189"
"","6.2600","5.3232","0.0203","5.3232","10.8638","8.4612"
"","6.2800","5.3400","0.0204","5.3400","10.8980","8.4953"
"","6.3000","5.3564","0.0205","5.3564","10.9315","8.5238"
"","6.3200","5.3728","0.0205","5.3728","10.9650","8.5521"
"","6.3400","5.3897","0.0206","5.3897","10.9994","8.6015"
"","6.3600","5.4067","0.0207","5.4067","11.0341","8.6324"
"","6.3800","5.4235","0.0208","5.4235","11.0683","8.6618"
"","6.4000","5.4399","0.0208","5.4399","11.1018","8.6854"
"","6.4200","5.4565","0.0210","5.4565","11.1358","8.7297"
"","6.4400","5.4732","0.0210","5.4732","11.1697","8.7584"
"","6.4600","5.4896","0.0211","5.4896","11.2032","8.7851"
"","6.4800","5.5062","0.0212","5.5062","11.2372","8.8180"
"","6.5000","5.5231","0.0213","5.5231","11.2717","8.8547"
"","6.5200","5.5401","0.0213","5.5401","11.3063","8.8853"
"","6.5400","5.5566","0.0214","5.5566","11.3401","8.9185"
"","6.5600","5.5730","0.0215","5.5730","11.3736","8.9500"
"","6.5800","5.5898","0.0216","5.5898","11.4078","8.9875"
"","6.6000","5.6065","0.0216","5.6065","11.4418","9.0208"
"","6.6200","5.6230","0.0218","5.6230","11.4755","9.0643"
"","6.6400","5.6399","0.0218","5.6399","11.5099","9.0980"
"","6.6600","5.6570","0.0219","5.6570","11.5449","9.1303"
"","6.6800","5.6736","0.0220","5.6736","11.5788","9.1645"
"","6.7000","5.6899","0.0221","5.6899","11.6121","9.2011"
"","6.7200","5.7065","0.0222","5.7065","11.6458","9.2511"
"","6.7400","5.7231","0.0223","5.7231","11.6798","9.2912"
"","6.7600","5.7397","0.0223","5.7397","11.7138","9.2904"
"","6.7800","5.7565","0.0224","5.7565","11.7480","9.3325"
"","6.8000","5.7734","0.0225","5.7734","11.7824","9.3860"
"","6.8200","5.7900","0.0226","5.7900","11.8164","9.4250"
"","6.8400","5.8063","0.0227","5.8063","11.8496","9.4438"
"","6.8600","5.8229","0.0227","5.8229","11.8834","9.4755"
"","6.8800","5.8400","0.0228","5.8400","11.9183","9.5077"
"","6.9000","5.8569","0.0229","5.8569","11.9528","9.5507"
"","6.9200","5.8733","0.0230","5.8733","11.9862","9.5994"
"","6.9400","5.8900","0.0231","5.8900","12.0205","9.6317"
"","6.9600","5.9068","0.0232","5.9068","12.0547","9.6662"
"","6.9800","5.9233","0.0233","5.9233","12.0884","9.6968"
"","7.0000","5.9395","0.0233","5.9395","12.1214","9.7221"
"","7.0200","5.9563","0.0234","5.9563","12.1556","9.7452"
"","7.0400","5.9733","0.0235","5.9733","12.1903","9.7754"
"","7.0600","5.9900","0.0236","5.9900","12.2245","9.8218"
"","7.0800","6.0067","0.0237","6.0067","12.2585","9.8644"
"","7.1000","6.0234","0.0238","6.0234","12.2927","9.8975"
"","7.1200","6.0402","0.0239","6.0402","12.3269","9.9568"
"","7.1400","6.0564","0.0240","6.0564","12.3599","9.9958"
"","7.1600","6.0729","0.0241","6.0729","12.3937","10.0311"
"","7.1800","6.0898","0.0241","6.0898","12.4281","10.0226"
"","7.2000","6.1067","0.0241","6.1067","12.4626","10.0481"
"","7.2200","6.1233","0.0242","6.1233","12.4965","10.0944"
"","7.2400","6.1401","0.0243","6.1401","12.5308","10.1452"
"","7.2600","6.1570","0.0244","6.1569","12.5652","10.1856"
"","7.2800","6.1731","0.0245","6.1731","12.5982","10.2157"
"","7.3000","6.1895","0.0246","6.1895","12.6317","10.2370"
"","7.3200","6.2064","0.0247","6.2064","12.6662","10.2717"
"","7.3400","6.2234","0.0248","6.2234","12.7008","10.3172"
"","7.3600","6.2399","0.0249","6.2399","12.7346","10.3590"
"","7.3800","6.2565","0.0249","6.2565","12.7683","10.3891"
"","7.4000","6.2734","0.0250","6.2734","12.8028","10.4336"
"","7.4200","6.2900","0.0251","6.2900","12.8367","10.4694"
"","7.4400","6.3064","0.0252","6.3064","12.8702","10.4978"
"","7.4600","6.3232","0.0253","6.3232","12.9044","10.5382"
"","7.4800","6.3402","0.0254","6.3402","12.9391","10.5706"
"","7.5000","6.3569","0.0255","6.3569","12.9733","10.6130"
"","7.5200","6.3733","0.0255","6.3733","13.0068","10.6416"
"","7.5400","6.3900","0.0256","6.3900","13.0408","10.6687"
"","7.5600","6.4064","0.0257","6.4064","13.0743","10.6969"
"","7.5800","6.4229","0.0258","6.4229","13.1080","10.7560"
"","7.6000","6.4396","0.0259","6.4396","13.1420","10.7979"
"","7.6200","6.4566","0.0260","6.4566","13.1767","10.8305"
"","7.6400","6.4736","0.0261","6.4736","13.2114","10.8612"
"","7.6600","6.4901","0.0261","6.4901","13.2451","10.8939"
"","7.6800","6.5066","0.0262","6.5066","13.2788","10.9322"
"","7.7000","6.5233","0.0263","6.5233","13.3128","10.9790"
"","7.7200","6.5397","0.0264","6.5397","13.3463","11.0083"
"","7.7400","6.5563","0.0265","6.5563","13.3803","11.0409"
"","7.7600","6.5730","0.0266","6.5730","13.4142","11.0698"
"","7.7800","6.5901","0.0266","6.5901","13.4492","11.1032"
"","7.8000","6.6069","0.0267","6.6069","13.4834","11.1404"
"","7.8200","6.6233","0.0268","6.6233","13.5169","11.1774"
"","7.8400","6.6397","0.0269","6.6397","13.5504","11.2052"
"","7.8600","6.6566","0.0270","6.6566","13.5848","11.2425"
"","7.8800","6.6731","0.0271","6.6731","13.6185","11.2793"
"","7.9000","6.6896","0.0271","6.6896","13.6523","11.3119"
"","7.9200","6.7067","0.0272","6.7067","13.6872","11.3475"
"","7.9400","6.7237","0.0273","6.7237","13.7219","11.3778"
"","7.9600","6.7401","0.0274","6.7401","13.7554","11.4105"
"","7.9800","6.7563","0.0275","6.7563","13.7884","11.4550"
"","8.0000","6.7728","0.0275","6.7728","13.8221","11.4779"
"","8.0200","6.7894","0.0276","6.7894","13.8559","11.5034"
"","8.0400","6.8061","0.0277","6.8061","13.8901","11.5382"
"","8.0600","6.8230","0.0278","6.8230","13.9245","11.5734"
"","8.0800","6.8400","0.0278","6.8400","13.9592","11.6027"
"","8.1000","6.8567","0.0279","6.8567","13.9932","11.6387"
"","8.1200","6.8731","0.0280","6.8731","14.0267","11.6754"
"","8.1400","6.8896","0.0281","6.8896","14.0604","11.7018"
"","8.1600","6.9065","0.0282","6.9065","14.0949","11.7372"
"","8.1800","6.9231","0.0283","6.9231","14.1288","11.7732"
"","8.2000","6.9398","0.0284","6.9398","14.1628","11.8140"
"","8.2200","6.9568","0.0284","6.9568","14.1975","11.8432"
"","8.2400","6.9735","0.0285","6.9735","14.2317","11.8767"
"","8.2600","6.9900","0.0286","6.9900","14.2652","11.9204"
"","8.2800","7.0062","0.0287","7.0062","14.2985","11.9620"
"","8.3000","7.0231","0.0288","7.0231","14.3329","12.0115"
"","8.3200","7.0399","0.0289","7.0399","14.3671","12.0459"
"","8.3400","7.0564","0.0289","7.0564","14.4008","12.0532"
"","8.3600","7.0733","0.0290","7.0733","14.4353","12.0919"
"","8.3800","7.0902","0.0291","7.0902","14.4698","12.1224"
"","8.4000","7.1065","0.0291","7.1065","14.5030","12.1403"
"","8.4200","7.1225","0.0292","7.1225","14.5358","12.1805"
"","8.4400","7.1393","0.0293","7.1393","14.5700","12.2127"
"","8.4600","7.1564","0.0294","7.1564","14.6049","12.2481"
"","8.4800","7.1731","0.0295","7.1731","14.6389","12.2779"
"","8.5000","7.1897","0.0295","7.1897","14.6729","12.3088"
"","8.5200","7.2067","0.0296","7.2067","14.7076","12.3433"
"","8.5400","7.2233","0.0297","7.2233","14.7415","12.3731"
"","8.5600","7.2396","0.0298","7.2396","14.7748","12.4129"
"","8.5800","7.2563","0.0299","7.2563","14.8087","12.4527"
"","8.6000","7.2734","0.0300","7.2734","14.8437","12.4913"
"","8.6200","7.2903","0.0301","7.2903","14.8781","12.5368"
"","8.6400","7.3068","0.0302","7.3068","14.9119","12.5729"
"","8.6600","7.3236","0.0303","7.3236","14.9461","12.6185"
"","8.6800","7.3403","0.0303","7.3403","14.9803","12.6333"
"","8.7000","7.3565","0.0304","7.3565","15.0133","12.6691"
"","8.7200","7.3728","0.0304","7.3728","15.0465","12.6772"
"","8.7400","7.3897","0.0305","7.3897","15.0810","12.7049"
"","8.7600","7.4067","0.0306","7.4067","15.1157","12.7433"
"","8.7800","7.4235","0.0307","7.4235","15.1499","12.7833"
"","8.8000","7.4399","0.0308","7.4399","15.1834","12.8132"
"","8.8200","7.4566","0.0308","7.4566","15.2176","12.8479"
"","8.8400","7.4732","0.0309","7.4732","15.2513","12.8705"
"","8.8600","7.4896","0.0310","7.4896","15.2848","12.8985"
"","8.8800","7.5063","0.0310","7.5063","15.3190","12.9268"
"","8.9000","7.5233","0.0311","7.5233","15.3537","12.9558"
"","8.9200","7.5402","0.0312","7.5402","15.3882","12.9953"
"","8.9400","7.5567","0.0313","7.5567","15.4219","13.0216"
"","8.9600","7.5734","0.0313","7.5734","15.4559","13.0549"
"","8.9800","7.5900","0.0314","7.5900","15.4899","13.0900"
"","9.0000","7.6064","0.0315","7.6064","15.5233","13.1135"
"","9.0200","7.6230","0.0315","7.6230","15.5571","13.1447"
"","9.0400","7.6400","0.0316","7.6400","15.5918","13.1815"
"","9.0600","7.6570","0.0317","7.6570","15.6265","13.2182"
"","9.0800","7.6734","0.0317","7.6734","15.6599","13.2240"
"","9.1000","7.6899","0.0318","7.6899","15.6937","13.2486"
"","9.1200","7.7065","0.0319","7.7065","15.7276","13.2891"
"","9.1400","7.7230","0.0320","7.7230","15.7611","13.3174"
"","9.1600","7.7395","0.0320","7.7395","15.7949","13.3422"
"","9.1800","7.7564","0.0321","7.7564","15.8293","13.3733"
"","9.2000","7.7734","0.0322","7.7734","15.8640","13.4082"
"","9.2200","7.7900","0.0322","7.7900","15.8980","13.4350"
"","9.2400","7.8064","0.0323","7.8064","15.9315","13.4703"
"","9.2600","7.8229","0.0324","7.8229","15.9652","13.4985"
"","9.2800","7.8399","0.0324","7.8399","15.9999","13.5128"
"","9.3000","7.8566","0.0324","7.8566","16.0339","13.5157"
"","9.3200","7.8732","0.0325","7.8732","16.0678","13.5425"
"","9.3400","7.8902","0.0326","7.8902","16.1025","13.5750"
"","9.3600","7.9072","0.0326","7.9072","16.1372","13.5960"
"","9.3800","7.9235","0.0327","7.9235","16.1705","13.6184"
"","9.4000","7.9397","0.0327","7.9397","16.2035","13.6449"
"","9.4200","7.9565","0.0328","7.9565","16.2377","13.6736"
"","9.4400","7.9731","0.0329","7.9731","16.2717","13.6941"
"","9.4600","7.9898","0.0330","7.9898","16.3056","13.7332"
"","9.4800","8.0064","0.0331","8.0064","16.3396","13.7815"
"","9.5000","8.0233","0.0332","8.0233","16.3741","13.8165"
"","9.5200","8.0399","0.0332","8.0399","16.4080","13.8467"
"","9.5400","8.0563","0.0333","8.0563","16.4415","13.8679"
"","9.5600","8.0729","0.0333","8.0729","16.4753","13.8854"
"","9.5800","8.0896","0.0334","8.0896","16.5095","13.9148"
"","9.6000","8.1065","0.0335","8.1065","16.5439","13.9497"
"","9.6200","8.1233","0.0336","8.1233","16.5781","13.9900"
"","9.6400","8.1403","0.0337","8.1403","16.6128","14.0252"
"","9.6600","8.1570","0.0337","8.1570","16.6470","14.0609"
"","9.6800","8.1732","0.0338","8.1732","16.6800","14.0956"
"","9.7000","8.1895","0.0339","8.1895","16.7133","14.1233"
"","9.7200","8.2063","0.0340","8.2063","16.7475","14.1503"
"","9.7400","8.2233","0.0340","8.2233","16.7822","14.1682"
"","9.7600","8.2400","0.0341","8.2400","16.8164","14.2045"
"","9.7800","8.2567","0.0342","8.2567","16.8504","14.2366"
"","9.8000","8.2734","0.0342","8.2734","16.8846","14.2524"
"","9.8200","8.2897","0.0342","8.2897","16.9178","14.2705"
"","9.8400","8.3059","0.0343","8.3059","16.9508","14.2961"
"","9.8600","8.3227","0.0343","8.3227","16.9851","14.3113"
"","9.8800","8.3398","0.0345","8.3398","17.0200","14.3748"
"","9.9000","8.3567","0.0346","8.3567","17.0544","14.4176"
"","9.9200","8.3733","0.0347","8.3733","17.0884","14.4584"
"","9.9400","8.3902","0.0348","8.3902","17.1229","14.4831"
"","9.9600","8.4069","0.0348","8.4069","17.1568","14.5060"
"","9.9800","8.4231","0.0349","8.4231","17.1901","14.5220"
"","10.0000","8.4397","0.0349","8.4397","17.2238","14.5482"
"","10.0200","8.4567","0.0350","8.4567","17.2585","14.5760"
"","10.0400","8.4736","0.0351","8.4736","17.2930","14.6089"
"","10.0600","8.4901","0.0352","8.4901","17.3267","14.6546"
"","10.0800","8.5068","0.0352","8.5068","17.3609","14.6850"
"","10.1000","8.5235","0.0353","8.5235","17.3949","14.7156"
"","10.1200","8.5399","0.0354","8.5399","17.4284","14.7492"
"","10.1400","8.5563","0.0355","8.5563","17.4619","14.7736"
"","10.1600","8.5731","0.0355","8.5731","17.4961","14.8007"
"","10.1800","8.5900","0.0356","8.5900","17.5305","14.8167"
"","10.2000","8.6066","0.0356","8.6066","17.5645","14.8483"
"","10.2200","8.6232","0.0357","8.6232","17.5985","14.8790"
"","10.2400","8.6399","0.0358","8.6399","17.6324","14.9050"
"","10.2600","8.6565","0.0358","8.6565","17.6664","14.9208"
"","10.2800","8.6731","0.0358","8.6731","17.7001","14.9340"
"","10.3000","8.6897","0.0359","8.6897","17.7341","14.9741"
"","10.3200","8.7067","0.0360","8.7067","17.7688","15.0037"
"","10.3400","8.7236","0.0361","8.7236","17.8033","15.0280"
"","10.3600","8.7401","0.0361","8.7401","17.8370","15.0296"
"","10.3800","8.7567","0.0360","8.7567","17.8707","14.9891"
"","10.4000","8.7733","0.0359","8.7733","17.9047","14.9779"
"","10.4200","8.7898","0.0360","8.7898","17.9384","15.0141"
"","10.4400","8.8065","0.0361","8.8065","17.9724","15.0448"
"","10.4600","8.8234","0.0362","8.8234","18.0068","15.0684"
"","10.4800","8.8401","0.0362","8.8401","18.0411","15.1021"
"","10.5000","8.8566","0.0363","8.8566","18.0748","15.1107"
"","10.5200","8.8731","0.0363","8.8731","18.1083","15.1308"
"","10.5400","8.8896","0.0364","8.8896","18.1420","15.1527"
"","10.5600","8.9065","0.0364","8.9065","18.1765","15.1736"
"","10.5800","8.9231","0.0365","8.9231","18.2104","15.1963"
"","10.6000","8.9399","0.0365","8.9399","18.2446","15.2187"
"","10.6200","8.9568","0.0367","8.9568","18.2791","15.2745"
"","10.6400","8.9736","0.0367","8.9736","18.3135","15.2988"
"","10.6600","8.9900","0.0367","8.9900","18.3470","15.3013"
"","10.6800","9.0065","0.0368","9.0065","18.3805","15.3245"
"","10.7000","9.0232","0.0368","9.0232","18.4147","15.3492"
"","10.7200","9.0399","0.0369","9.0399","18.4487","15.3811"
"","10.7400","9.0566","0.0370","9.0566","18.4829","15.4227"
"","10.7600","9.0734","0.0371","9.0734","18.5171","15.4541"
"","10.7800","9.0903","0.0372","9.0903","18.5516","15.4817"
"","10.8000","9.1066","0.0372","9.1066","18.5848","15.5028"
"","10.8200","9.1229","0.0373","9.1229","18.6181","15.5338"
"","10.8400","9.1396","0.0373","9.1396","18.6523","15.5606"
"","10.8600","9.1566","0.0374","9.1566","18.6870","15.5826"
"","10.8800","9.1734","0.0374","9.1734","18.7212","15.5973"
"","10.9000","9.1900","0.0375","9.1900","18.7552","15.6213"
"","10.9200","9.2069","0.0375","9.2069","18.7896","15.6419"
"","10.9400","9.2233","0.0376","9.2233","18.8231","15.6796"
"","10.9600","9.2395","0.0377","9.2395","18.8561","15.7144"
"","10.9800","9.2560","0.0378","9.2560","18.8898","15.7384"
"","11.0000","9.2731","0.0378","9.2731","18.9248","15.7566"
"","11.0200","9.2900","0.0379","9.2900","18.9592","15.7767"
"","11.0400","9.3066","0.0379","9.3066","18.9930","15.8016"
"","11.0600","9.3234","0.0380","9.3234","19.0274","15.8334"
"","11.0800","9.3401","0.0381","9.3401","19.0614","15.8574"
"","11.1000","9.3564","0.0381","9.3564","19.0946","15.8799"
"","11.1200","9.3728","0.0382","9.3728","19.1281","15.9050"
"","11.1400","9.3897","0.0382","9.3897","19.1626","15.9251"
"","11.1600","9.4067","0.0383","9.4067","19.1973","15.9499"
"","11.1800","9.4233","0.0384","9.4233","19.2312","15.9827"
"","11.2000","9.4401","0.0384","9.4401","19.2655","16.0104"
"","11.2200","9.4568","0.0385","9.4568","19.2997","16.0366"
"","11.2400","9.4735","0.0385","9.4735","19.3336","16.0356"
"","11.2600","9.4898","0.0385","9.4898","19.3669","16.0501"
"","11.2800","9.5063","0.0386","9.5063","19.4006","16.0792"
"","11.3000","9.5233","0.0386","9.5233","19.4353","16.0979"
"","11.3200","9.5399","0.0387","9.5399","19.4693","16.1141"
"","11.3400","9.5565","0.0387","9.5565","19.5030","16.1352"
"","11.3600","9.5732","0.0387","9.5732","19.5372","16.1457"
"","11.3800","9.5900","0.0388","9.5900","19.5714","16.1686"
"","11.4000","9.6063","0.0389","9.6063","19.6047","16.1876"
"","11.4200","9.6229","0.0388","9.6229","19.6387","16.1582"
"","11.4400","9.6399","0.0388","9.6399","19.6734","16.1624"
"","11.4600","9.6569","0.0388","9.6569","19.7080","16.1824"
"","11.4800","9.6735","0.0389","9.6735","19.7418","16.2134"
"","11.5000","9.6900","0.0390","9.6900","19.7755","16.2329"
"","11.5200","9.7066","0.0391","9.7066","19.8095","16.2768"
"","11.5400","9.7231","0.0391","9.7231","19.8430","16.3082"
"","11.5600","9.7396","0.0392","9.7396","19.8767","16.3128"
"","11.5800","9.7565","0.0392","9.7565","19.9112","16.3247"
"","11.6000","9.7736","0.0392","9.7736","19.9461","16.3396"
"","11.6200","9.7902","0.0393","9.7902","19.9801","16.3719"
"","11.6400","9.8066","0.0393","9.8066","20.0135","16.3846"
"","11.6600","9.8232","0.0393","9.8232","20.0473","16.3876"
"","11.6800","9.8398","0.0394","9.8398","20.0812","16.4069"
"","11.7000","9.8563","0.0394","9.8563","20.1150","16.4230"
"","11.7200","9.8730","0.0395","9.8730","20.1489","16.4501"
"","11.7400","9.8900","0.0395","9.8900","20.1836","16.4722"
"","11.7600","9.9070","0.0397","9.9070","20.2183","16.5229"
"","11.7800","9.9234","0.0397","9.9234","20.2518","16.5263"
"","11.8000","9.9397","0.0397","9.9397","20.2851","16.5487"
"","11.8200","9.9562","0.0398","9.9562","20.3188","16.5989"
"","11.8400","9.9731","0.0398","9.9731","20.3533","16.5978"
"","11.8600","9.9899","0.0398","9.9899","20.3875","16.6033"
"","11.8800","10.0066","0.0399","10.0066","20.4217","16.6189"
"","11.9000","10.0236","0.0399","10.0236","20.4564","16.6337"
"","11.9200","10.0403","0.0400","10.0403","20.4903","16.6564"
"","11.9400","10.0567","0.0400","10.0567","20.5238","16.6829"
"","11.9600","10.0731","0.0401","10.0731","20.5573","16.7123"
"","11.9800","10.0899","0.0402","10.0899","20.5915","16.7297"
"","12.0000","10.1066","0.0402","10.1066","20.6257","16.7600"
"","12.0200","10.1233","0.0403","10.1233","20.6597","16.7930"
"","12.0400","10.1400","0.0403","10.1400","20.6939","16.8098"
"","12.0600","10.1568","0.0403","10.1568","20.7281","16.8093"
"","12.0800","10.1733","0.0403","10.1733","20.7619","16.7920"
"","12.1000","10.1897","0.0403","10.1897","20.7954","16.7890"
"","12.1200","10.2064","0.0404","10.2064","20.8293","16.8158"
"","12.1400","10.2233","0.0404","10.2233","20.8638","16.8321"
"","12.1600","10.2400","0.0404","10.2400","20.8980","16.8523"
"","12.1800","10.2567","0.0405","10.2567","20.9320","16.8664"
"","12.2000","10.2735","0.0406","10.2735","20.9664","16.8995"
"","12.2200","10.2901","0.0406","10.2901","21.0002","16.9295"
"","12.2400","10.3064","0.0407","10.3064","21.0334","16.9549"
"","12.2600","10.3229","0.0407","10.3229","21.0671","16.9767"
"","12.2800","10.3399","0.0408","10.3399","21.1018","16.9873"
"","12.3000","10.3568","0.0408","10.3568","21.1363","17.0088"
"","12.3200","10.3733","0.0409","10.3733","21.1700","17.0481"
"","12.3400","10.3901","0.0410","10.3901","21.2042","17.0744"
"","12.3600","10.4067","0.0410","10.4067","21.2382","17.0938"
"","12.3800","10.4231","0.0411","10.4231","21.2717","17.1078"
"","12.4000","10.4395","0.0411","10.4395","21.3052","17.1237"
"","12.4200","10.4563","0.0412","10.4563","21.3394","17.1547"
"","12.4400","10.4733","0.0413","10.4733","21.3741","17.1894"
"","12.4600","10.4899","0.0413","10.4899","21.4080","17.2130"
"","12.4800","10.5065","0.0413","10.5065","21.4418","17.2284"
"","12.5000","10.5230","0.0414","10.5230","21.4755","17.2378"
"","12.5200","10.5395","0.0414","10.5395","21.5092","17.2531"
"","12.5400","10.5561","0.0415","10.5561","21.5430","17.2722"
"","12.5600","10.5728","0.0415","10.5728","21.5772","17.3005"
"","12.5800","10.5898","0.0415","10.5898","21.6119","17.3118"
"","12.6000","10.6067","0.0416","10.6067","21.6463","17.3243"
"","12.6200","10.6232","0.0417","10.6232","21.6801","17.3554"
"","12.6400","10.6399","0.0417","10.6399","21.7140","17.3900"
"","12.6600","10.6565","0.0418","10.6565","21.7480","17.4055"
"","12.6800","10.6729","0.0418","10.6729","21.7815","17.4355"
"","12.7000","10.6895","0.0419","10.6895","21.8152","17.4490"
"","12.7200","10.7063","0.0419","10.7063","21.8497","17.4715"
"","12.7400","10.7232","0.0420","10.7232","21.8841","17.4961"
"","12.7600","10.7400","0.0421","10.7400","21.9183","17.5236"
"","12.7800","10.7565","0.0421","10.7565","21.9521","17.5438"
"","12.8000","10.7730","0.0421","10.7730","21.9858","17.5468"
"","12.8200","10.7896","0.0421","10.7896","22.0195","17.5549"
"","12.8400","10.8063","0.0422","10.8063","22.0537","17.5737"
"","12.8600","10.8233","0.0423","10.8233","22.0884","17.6068"
"","12.8800","10.8401","0.0423","10.8401","22.1226","17.6276"
"","12.9000","10.8569","0.0423","10.8569","22.1569","17.6453"
"","12.9200","10.8734","0.0424","10.8734","22.1906","17.6649"
"","12.9400","10.8899","0.0424","10.8899","22.2243","17.6588"
"","12.9600","10.9064","0.0424","10.9064","22.2580","17.6484"
"","12.9800","10.9232","0.0424","10.9232","22.2923","17.6483"
"","13.0000","10.9399","0.0423","10.9399","22.3262","17.6238"
"","13.0200","10.9566","0.0423","10.9566","22.3604","17.6175"
"","13.0400","10.9735","0.0423","10.9735","22.3949","17.6237"
"","13.0600","10.9900","0.0423","10.9900","22.4286","17.6191"
"","13.0800","11.0066","0.0423","11.0066","22.4624","17.6187"
"","13.1000","11.0231","0.0423","11.0231","22.4961","17.6368"
"","13.1200","11.0398","0.0423","11.0398","22.5303","17.6418"
"","13.1400","11.0565","0.0424","11.0565","22.5643","17.6465"
"","13.1600","11.0733","0.0424","11.0733","22.5985","17.6710"
"","13.1800","11.0901","0.0424","11.0901","22.6329","17.6839"
"","13.2000","11.1068","0.0424","11.1068","22.6669","17.6782"
"","13.2200","11.1232","0.0425","11.1232","22.7004","17.6913"
"","13.2400","11.1398","0.0425","11.1398","22.7344","17.7110"
"","13.2600","11.1566","0.0425","11.1566","22.7686","17.7191"
"","13.2800","11.1734","0.0425","11.1734","22.8028","17.7209"
"","13.3000","11.1900","0.0426","11.1900","22.8368","17.7313"
"","13.3200","11.2069","0.0426","11.2069","22.8712","17.7574"
"","13.3400","11.2234","0.0427","11.2234","22.9049","17.8018"
"","13.3600","11.2398","0.0427","11.2398","22.9384","17.7999"
"","13.3800","11.2561","0.0427","11.2561","22.9717","17.8083"
"","13.4000","11.2728","0.0428","11.2728","23.0057","17.8297"
"","13.4200","11.2898","0.0429","11.2898","23.0403","17.8630"
"","13.4400","11.3064","0.0430","11.3064","23.0743","17.8961"
"","13.4600","11.3232","0.0430","11.3232","23.1085","17.9129"
"","13.4800","11.3399","0.0430","11.3399","23.1427","17.9348"
"","13.5000","11.3565","0.0431","11.3565","23.1765","17.9551"
"","13.5200","11.3729","0.0431","11.3729","23.2100","17.9774"
"","13.5400","11.3898","0.0432","11.3898","23.2444","17.9932"
"","13.5600","11.4068","0.0432","11.4068","23.2791","18.0122"
"","13.5800","11.4234","0.0433","11.4234","23.3131","18.0334"
"","13.6000","11.4399","0.0433","11.4399","23.3468","18.0445"
"","13.6200","11.4567","0.0434","11.4567","23.3810","18.0755"
"","13.6400","11.4733","0.0434","11.4733","23.4150","18.1005"
"","13.6600","11.4896","0.0435","11.4896","23.4482","18.1310"
"","13.6800","11.5063","0.0435","11.5063","23.4822","18.1428"
"","13.7000","11.5230","0.0436","11.5230","23.5164","18.1705"
"","13.7200","11.5399","0.0436","11.5399","23.5509","18.1580"
"","13.7400","11.5565","0.0436","11.5565","23.5846","18.1745"
"","13.7600","11.5732","0.0437","11.5732","23.6188","18.2092"
"","13.7800","11.5899","0.0438","11.5899","23.6528","18.2437"
"","13.8000","11.6063","0.0438","11.6063","23.6863","18.2677"
"","13.8200","11.6228","0.0439","11.6228","23.7200","18.2824"
"","13.8400","11.6398","0.0439","11.6398","23.7547","18.2910"
"","13.8600","11.6568","0.0439","11.6568","23.7894","18.2996"
"","13.8800","11.6734","0.0440","11.6734","23.8234","18.3149"
"","13.9000","11.6901","0.0440","11.6901","23.8573","18.3354"
"","13.9200","11.7067","0.0440","11.7067","23.8913","18.3519"
"","13.9400","11.7232","0.0441","11.7232","23.9248","18.3705"
"","13.9600","11.7396","0.0441","11.7396","23.9583","18.3940"
"","13.9800","11.7563","0.0442","11.7563","23.9925","18.4053"
"","14.0000","11.7733","0.0440","11.7733","24.0272","18.3515"
"","14.0200","11.7901","0.0437","11.7901","24.0614","18.1910"
"","14.0400","11.8066","0.0434","11.8066","24.0951","18.0932"
"","14.0600","11.8231","0.0434","11.8231","24.1289","18.0750"
"","14.0800","11.8399","0.0434","11.8399","24.1631","18.0903"
"","14.1000","11.8563","0.0434","11.8563","24.1966","18.0967"
"","14.1200","11.8730","0.0435","11.8730","24.2305","18.1072"
"","14.1400","11.8897","0.0435","11.8897","24.2647","18.1249"
"","14.1600","11.9067","0.0435","11.9067","24.2994","18.1250"
"","14.1800","11.9234","0.0435","11.9234","24.3334","18.1333"
"","14.2000","11.9398","0.0435","11.9398","24.3669","18.1367"
"","14.2200","11.9563","0.0435","11.9563","24.4006","18.1357"
"","14.2400","11.9730","0.0435","11.9730","24.4346","18.1388"
"","14.2600","11.9897","0.0436","11.9897","24.4688","18.1544"
"","14.2800","12.0065","0.0436","12.0065","24.5030","18.1820"
"","14.3000","12.0235","0.0436","12.0235","24.5377","18.1858"
"","14.3200","12.0404","0.0436","12.0404","24.5722","18.1821"
"","14.3400","12.0567","0.0436","12.0567","24.6054","18.1832"
"","14.3600","12.0732","0.0437","12.0732","24.6392","18.1927"
"","14.3800","12.0899","0.0437","12.0899","24.6734","18.2048"
"","14.4000","12.1067","0.0437","12.1067","24.7076","18.2104"
"","14.4200","12.1232","0.0437","12.1232","24.7413","18.2075"
"","14.4400","12.1401","0.0431","12.1401","24.7758","17.9719"
"","14.4600","12.1569","0.0428","12.1569","24.8100","17.8261"
"","14.4800","12.1734","0.0424","12.1734","24.8437","17.6813"
"","14.5000","12.1897","0.0417","12.1897","24.8770","17.3546"
"","14.5200","12.2064","0.0414","12.2064","24.9109","17.2305"
"","14.5400","12.2232","0.0413","12.2232","24.9454","17.2261"
"","14.5600","12.2400","0.0413","12.2400","24.9796","17.2094"
"","14.5800","12.2566","0.0404","12.2566","25.0136","16.8509"
"","14.6000","12.2735","0.0398","12.2735","25.0480","16.5911"
"","14.6200","12.2903","0.0397","12.2903","25.0822","16.5281"
"","14.6400","12.3066","0.0397","12.3066","25.1155","16.5379"
"","14.6600","12.3230","0.0397","12.3230","25.1490","16.5623"
"","14.6800","12.3399","0.0398","12.3399","25.1834","16.5831"
"","14.7000","12.3568","0.0398","12.3568","25.2179","16.5986"
"","14.7200","12.3732","0.0392","12.3732","25.2514","16.3467"
"","14.7400","12.3898","0.0386","12.3898","25.2853","16.1041"
"","14.7600","12.4067","0.0385","12.4067","25.3198","16.0309"
"","14.7800","12.4231","0.0385","12.4231","25.3533","16.0389"
"","14.8000","12.4393","0.0384","12.4393","25.3863","15.9941"
"","14.8200","12.4560","0.0382","12.4560","25.4205","15.9221"
"","14.8400","12.4729","0.0381","12.4729","25.4549","15.8686"
"","14.8600","12.4897","0.0381","12.4897","25.4892","15.8728"
"","14.8800","12.5064","0.0380","12.5064","25.5234","15.8392"
"","14.9000","12.5233","0.0380","12.5233","25.5578","15.8466"
"","14.9200","12.5399","0.0381","12.5399","25.5915","15.8588"
"","14.9400","12.5562","0.0381","12.5562","25.6248","15.8905"
"","14.9600","12.5729","0.0382","12.5729","25.6590","15.9180"
"","14.9800","12.5901","0.0382","12.5901","25.6942","15.9327"
"","15.0000","12.6068","0.0383","12.6068","25.7282","15.9584"
"","15.0200","12.6233","0.0384","12.6233","25.7619","15.9866"
"","15.0400","12.6400","0.0384","12.6400","25.7959","15.9908"
"","15.0600","12.6567","0.0381","12.6567","25.8301","15.8847"
"","15.0800","12.6730","0.0376","12.6730","25.8633","15.6732"
"","15.1000","12.6897","0.0372","12.6897","25.8973","15.5053"
"","15.1200","12.7067","0.0353","12.7067","25.9320","14.7232"
"","15.1400","12.7234","0.0334","12.7234","25.9662","13.9139"
"","15.1600","12.7400","0.0326","12.7400","25.9999","13.5949"
"","15.1800","12.7565","0.0326","12.7565","26.0337","13.5821"
"","15.2000","12.7730","0.0327","12.7730","26.0674","13.6450"
"","15.2200","12.7897","0.0328","12.7897","26.1014","13.6837"
"","15.2400","12.8063","0.0329","12.8063","26.1353","13.6961"
"","15.2600","12.8231","0.0329","12.8231","26.1695","13.7188"
"","15.2800","12.8400","0.0330","12.8400","26.2040","13.7420"
"","15.3000","12.8567","0.0330","12.8567","26.2382","13.7404"
"","15.3200","12.8732","0.0330","12.8732","26.2719","13.7597"
"","15.3400","12.8898","0.0331","12.8898","26.3057","13.7739"
"","15.3600","12.9063","0.0331","12.9063","26.3394","13.7795"
"","15.3800","12.9229","0.0331","12.9229","26.3734","13.7874"
"","15.4000","12.9396","0.0331","12.9396","26.4073","13.8073"
"","15.4200","12.9567","0.0331","12.9567","26.4423","13.8062"
"","15.4400","12.9737","0.0325","12.9737","26.4770","13.5362"
"","15.4600","12.9904","0.0319","12.9904","26.5109","13.2883"
"","15.4800","13.0067","0.0311","13.0067","26.5442","12.9485"
"","15.5000","13.0232","0.0306","13.0232","26.5779","12.7632"
"","15.5200","13.0397","0.0306","13.0397","26.6116","12.7426"
"","15.5400","13.0564","0.0306","13.0564","26.6456","12.7692"
"","15.5600","13.0731","0.0307","13.0731","26.6798","12.7869"
"","15.5800","13.0901","0.0307","13.0901","26.7145","12.8100"
"","15.6000","13.1068","0.0308","13.1068","26.7485","12.8220"
"","15.6200","13.1232","0.0308","13.1232","26.7820","12.8488"
"","15.6400","13.1397","0.0309","13.1397","26.8157","12.8667"
"","15.6600","13.1566","0.0305","13.1566","26.8502","12.7285"
"","15.6800","13.1733","0.0298","13.1733","26.8844","12.4146"
"","15.7000","13.1899","0.0290","13.1899","26.9181","12.0949"
"","15.7200","13.2069","0.0283","13.2069","26.9528","11.8073"
"","15.7400","13.2236","0.0281","13.2236","26.9870","11.7096"
"","15.7600","13.2400","0.0281","13.2400","27.0205","11.7102"
"","15.7800","13.2563","0.0282","13.2563","27.0538","11.7388"
"","15.8000","13.2730","0.0282","13.2730","27.0877","11.7615"
"","15.8200","13.2899","0.0276","13.2899","27.1222","11.4949"
"","15.8400","13.3064","0.0269","13.3064","27.1559","11.2220"
"","15.8520","13.3163","0.0265","13.3163","27.1761","11.0224"