File: Fig6C/211130_Instron/211130/tensile_curtain_5_1.csv
Results Table 1


Results Table 2


1,Time,Displacement,Force,Tensile displacement,Tensile strain (Displacement),Tensile stress
,(s),(mm),(kN),(mm),(%),(MPa)
2,Time,Displacement,Force,Tensile displacement,Tensile strain (Displacement),Tensile stress
,(s),(mm),(kN),(mm),(%),(MPa)
"","0.0000","0.0000","0.0000","0.0000","0.0000","0.0099"
"","0.0200","0.0019","0.0000","0.0019","0.0039","0.0139"
"","0.0400","0.0130","0.0001","0.0130","0.0265","0.0257"
"","0.0600","0.0325","0.0001","0.0325","0.0663","0.0328"
"","0.0800","0.0550","0.0002","0.0550","0.1123","0.0698"
"","0.1000","0.0770","0.0003","0.0770","0.1571","0.1347"
"","0.1200","0.0970","0.0004","0.0970","0.1980","0.1838"
"","0.1400","0.1157","0.0006","0.1157","0.2361","0.2422"
"","0.1600","0.1335","0.0007","0.1335","0.2725","0.2992"
"","0.1800","0.1505","0.0008","0.1505","0.3072","0.3503"
"","0.2000","0.1674","0.0010","0.1674","0.3416","0.4034"
"","0.2200","0.1845","0.0011","0.1845","0.3766","0.4454"
"","0.2400","0.2014","0.0012","0.2014","0.4110","0.5044"
"","0.2600","0.2183","0.0013","0.2183","0.4455","0.5312"
"","0.2800","0.2352","0.0013","0.2352","0.4799","0.5570"
"","0.3000","0.2518","0.0014","0.2518","0.5139","0.6042"
"","0.3200","0.2683","0.0015","0.2683","0.5476","0.6326"
"","0.3400","0.2850","0.0016","0.2850","0.5816","0.6862"
"","0.3600","0.3016","0.0018","0.3016","0.6156","0.7326"
"","0.3800","0.3184","0.0017","0.3184","0.6498","0.7259"
"","0.4000","0.3352","0.0018","0.3352","0.6840","0.7634"
"","0.4200","0.3518","0.0020","0.3518","0.7180","0.8147"
"","0.4400","0.3683","0.0021","0.3683","0.7517","0.8683"
"","0.4600","0.3849","0.0022","0.3849","0.7854","0.8966"
"","0.4800","0.4015","0.0022","0.4015","0.8194","0.9282"
"","0.5000","0.4182","0.0023","0.4182","0.8534","0.9684"
"","0.5200","0.4349","0.0024","0.4349","0.8876","0.9956"
"","0.5400","0.4519","0.0024","0.4519","0.9223","1.0183"
"","0.5600","0.4687","0.0025","0.4687","0.9565","1.0517"
"","0.5800","0.4852","0.0026","0.4852","0.9902","1.0870"
"","0.6000","0.5017","0.0027","0.5017","1.0240","1.1230"
"","0.6200","0.5184","0.0028","0.5184","1.0579","1.1587"
"","0.6400","0.5350","0.0029","0.5350","1.0919","1.1947"
"","0.6600","0.5518","0.0029","0.5518","1.1261","1.2097"
"","0.6800","0.5687","0.0030","0.5687","1.1606","1.2411"
"","0.7000","0.5853","0.0031","0.5853","1.1945","1.2810"
"","0.7200","0.6018","0.0031","0.6018","1.2283","1.2971"
"","0.7400","0.6183","0.0032","0.6183","1.2617","1.3416"
"","0.7600","0.6348","0.0032","0.6348","1.2955","1.3417"
"","0.7800","0.6514","0.0032","0.6514","1.3294","1.3402"
"","0.8000","0.6682","0.0033","0.6682","1.3637","1.3952"
"","0.8200","0.6850","0.0034","0.6850","1.3979","1.4133"
"","0.8400","0.7018","0.0035","0.7018","1.4323","1.4383"
"","0.8600","0.7185","0.0035","0.7185","1.4663","1.4501"
"","0.8800","0.7349","0.0035","0.7349","1.4998","1.4706"
"","0.9000","0.7514","0.0036","0.7514","1.5335","1.4899"
"","0.9200","0.7683","0.0036","0.7683","1.5680","1.5117"
"","0.9400","0.7850","0.0037","0.7850","1.6019","1.5303"
"","0.9600","0.8017","0.0037","0.8017","1.6362","1.5428"
"","0.9800","0.8185","0.0038","0.8185","1.6704","1.5760"
"","1.0000","0.8351","0.0038","0.8351","1.7043","1.5882"
"","1.0200","0.8517","0.0038","0.8517","1.7381","1.5983"
"","1.0400","0.8682","0.0039","0.8682","1.7718","1.6205"
"","1.0600","0.8848","0.0039","0.8848","1.8058","1.6423"
"","1.0800","0.9017","0.0040","0.9017","1.8402","1.6663"
"","1.1000","0.9185","0.0041","0.9185","1.8744","1.6929"
"","1.1200","0.9351","0.0041","0.9351","1.9084","1.7039"
"","1.1400","0.9518","0.0041","0.9518","1.9424","1.7159"
"","1.1600","0.9682","0.0042","0.9682","1.9759","1.7317"
"","1.1800","0.9846","0.0042","0.9846","2.0094","1.7522"
"","1.2000","1.0012","0.0042","1.0012","2.0433","1.7613"
"","1.2200","1.0182","0.0043","1.0182","2.0780","1.7812"
"","1.2400","1.0351","0.0043","1.0351","2.1125","1.8120"
"","1.2600","1.0519","0.0043","1.0519","2.1467","1.8122"
"","1.2800","1.0686","0.0044","1.0686","2.1809","1.8286"
"","1.3000","1.0853","0.0044","1.0853","2.2149","1.8457"
"","1.3200","1.1016","0.0044","1.1016","2.2481","1.8499"
"","1.3400","1.1180","0.0045","1.1180","2.2816","1.8597"
"","1.3600","1.1349","0.0045","1.1349","2.3161","1.8662"
"","1.3800","1.1519","0.0045","1.1519","2.3508","1.8853"
"","1.4000","1.1685","0.0046","1.1685","2.3847","1.9189"
"","1.4200","1.1852","0.0046","1.1852","2.4187","1.9305"
"","1.4400","1.2018","0.0047","1.2018","2.4527","1.9382"
"","1.4600","1.2182","0.0047","1.2182","2.4862","1.9452"
"","1.4800","1.2346","0.0047","1.2346","2.5196","1.9566"
"","1.5000","1.2513","0.0047","1.2513","2.5536","1.9731"
"","1.5200","1.2683","0.0048","1.2683","2.5883","2.0046"
"","1.5400","1.2852","0.0049","1.2852","2.6228","2.0440"
"","1.5600","1.3018","0.0050","1.3018","2.6567","2.0653"
"","1.5800","1.3182","0.0050","1.3182","2.6902","2.0741"
"","1.6000","1.3347","0.0050","1.3347","2.7240","2.0771"
"","1.6200","1.3514","0.0050","1.3514","2.7579","2.0835"
"","1.6400","1.3681","0.0050","1.3681","2.7921","2.0993"
"","1.6600","1.3850","0.0051","1.3850","2.8266","2.1131"
"","1.6800","1.4019","0.0051","1.4019","2.8610","2.1398"
"","1.7000","1.4184","0.0052","1.4184","2.8948","2.1557"
"","1.7200","1.4350","0.0052","1.4350","2.9285","2.1623"
"","1.7400","1.4516","0.0052","1.4516","2.9625","2.1787"
"","1.7600","1.4684","0.0053","1.4684","2.9967","2.1923"
"","1.7800","1.4849","0.0052","1.4849","3.0304","2.1860"
"","1.8000","1.5015","0.0053","1.5015","3.0644","2.1894"
"","1.8200","1.5184","0.0053","1.5184","3.0988","2.2057"
"","1.8400","1.5352","0.0053","1.5352","3.1330","2.2227"
"","1.8600","1.5517","0.0053","1.5517","3.1668","2.2291"
"","1.8800","1.5681","0.0054","1.5681","3.2003","2.2529"
"","1.9000","1.5847","0.0055","1.5847","3.2340","2.2889"
"","1.9200","1.6014","0.0055","1.6014","3.2682","2.2933"
"","1.9400","1.6183","0.0054","1.6183","3.3027","2.2610"
"","1.9600","1.6352","0.0055","1.6352","3.3371","2.2983"
"","1.9800","1.6518","0.0056","1.6518","3.3711","2.3237"
"","2.0000","1.6684","0.0056","1.6684","3.4048","2.3490"
"","2.0200","1.6847","0.0057","1.6847","3.4381","2.3689"
"","2.0400","1.7012","0.0057","1.7012","3.4718","2.3858"
"","2.0600","1.7182","0.0057","1.7182","3.5065","2.3942"
"","2.0800","1.7349","0.0058","1.7349","3.5407","2.4104"
"","2.1000","1.7515","0.0058","1.7515","3.5744","2.4337"
"","2.1200","1.7684","0.0059","1.7684","3.6089","2.4451"
"","2.1400","1.7851","0.0059","1.7851","3.6431","2.4615"
"","2.1600","1.8013","0.0060","1.8013","3.6761","2.4859"
"","2.1800","1.8177","0.0060","1.8177","3.7096","2.5033"
"","2.2000","1.8347","0.0060","1.8347","3.7443","2.5201"
"","2.2200","1.8516","0.0061","1.8516","3.7787","2.5216"
"","2.2400","1.8682","0.0061","1.8682","3.8127","2.5321"
"","2.2600","1.8851","0.0061","1.8851","3.8472","2.5396"
"","2.2800","1.9020","0.0062","1.9020","3.8816","2.5683"
"","2.3000","1.9185","0.0062","1.9185","3.9153","2.5919"
"","2.3200","1.9347","0.0062","1.9347","3.9484","2.5891"
"","2.3400","1.9516","0.0062","1.9516","3.9828","2.5982"
"","2.3600","1.9686","0.0063","1.9686","4.0175","2.6309"
"","2.3800","1.9852","0.0063","1.9852","4.0515","2.6426"
"","2.4000","2.0016","0.0064","2.0016","4.0850","2.6612"
"","2.4200","2.0183","0.0064","2.0183","4.1189","2.6808"
"","2.4400","2.0349","0.0065","2.0349","4.1529","2.6945"
"","2.4600","2.0512","0.0065","2.0512","4.1862","2.7092"
"","2.4800","2.0680","0.0065","2.0680","4.2204","2.7279"
"","2.5000","2.0850","0.0066","2.0850","4.2551","2.7528"
"","2.5200","2.1019","0.0066","2.1019","4.2895","2.7695"
"","2.5400","2.1182","0.0067","2.1182","4.3228","2.7813"
"","2.5600","2.1348","0.0067","2.1348","4.3567","2.7823"
"","2.5800","2.1517","0.0067","2.1517","4.3912","2.7938"
"","2.6000","2.1683","0.0067","2.1683","4.4252","2.8096"
"","2.6200","2.1849","0.0068","2.1849","4.4589","2.8155"
"","2.6400","2.2017","0.0068","2.2017","4.4933","2.8418"
"","2.6600","2.2187","0.0069","2.2187","4.5280","2.8551"
"","2.6800","2.2350","0.0069","2.2350","4.5613","2.8719"
"","2.7000","2.2514","0.0069","2.2514","4.5948","2.8802"
"","2.7200","2.2681","0.0069","2.2681","4.6287","2.8918"
"","2.7400","2.2850","0.0070","2.2850","4.6632","2.9161"
"","2.7600","2.3015","0.0071","2.3015","4.6969","2.9383"
"","2.7800","2.3181","0.0071","2.3181","4.7309","2.9624"
"","2.8000","2.3350","0.0072","2.3350","4.7653","2.9846"
"","2.8200","2.3520","0.0072","2.3520","4.8000","3.0008"
"","2.8400","2.3684","0.0072","2.3684","4.8335","3.0156"
"","2.8600","2.3851","0.0073","2.3851","4.8675","3.0224"
"","2.8800","2.4018","0.0073","2.4018","4.9017","3.0473"
"","2.9000","2.4185","0.0074","2.4185","4.9357","3.0680"
"","2.9200","2.4349","0.0074","2.4349","4.9692","3.0815"
"","2.9400","2.4518","0.0075","2.4518","5.0036","3.1152"
"","2.9600","2.4687","0.0075","2.4687","5.0381","3.1369"
"","2.9800","2.4854","0.0075","2.4854","5.0723","3.1439"
"","3.0000","2.5017","0.0076","2.5017","5.1055","3.1667"
"","3.0200","2.5180","0.0077","2.5180","5.1388","3.1941"
"","3.0400","2.5347","0.0077","2.5347","5.1728","3.2184"
"","3.0600","2.5513","0.0077","2.5513","5.2067","3.2249"
"","3.0800","2.5681","0.0078","2.5681","5.2409","3.2498"
"","3.1000","2.5851","0.0078","2.5851","5.2756","3.2445"
"","3.1200","2.6019","0.0079","2.6019","5.3101","3.2790"
"","3.1400","2.6184","0.0080","2.6184","5.3436","3.3182"
"","3.1600","2.6348","0.0080","2.6348","5.3771","3.3309"
"","3.1800","2.6518","0.0080","2.6518","5.4118","3.3480"
"","3.2000","2.6685","0.0081","2.6685","5.4460","3.3649"
"","3.2200","2.6851","0.0081","2.6851","5.4797","3.3795"
"","3.2400","2.7017","0.0082","2.7017","5.5137","3.4117"
"","3.2600","2.7186","0.0083","2.7186","5.5481","3.4376"
"","3.2800","2.7351","0.0083","2.7351","5.5819","3.4582"
"","3.3000","2.7513","0.0083","2.7513","5.6149","3.4712"
"","3.3200","2.7680","0.0083","2.7680","5.6491","3.4788"
"","3.3400","2.7852","0.0084","2.7852","5.6840","3.5024"
"","3.3600","2.8018","0.0085","2.8018","5.7180","3.5312"
"","3.3800","2.8185","0.0085","2.8185","5.7520","3.5507"
"","3.4000","2.8355","0.0086","2.8355","5.7866","3.5760"
"","3.4200","2.8521","0.0086","2.8521","5.8206","3.5983"
"","3.4400","2.8682","0.0087","2.8682","5.8534","3.6117"
"","3.4600","2.8846","0.0086","2.8846","5.8869","3.5985"
"","3.4800","2.9015","0.0086","2.9015","5.9213","3.6013"
"","3.5000","2.9185","0.0087","2.9185","5.9560","3.6155"
"","3.5200","2.9351","0.0088","2.9351","5.9900","3.6599"
"","3.5400","2.9517","0.0089","2.9517","6.0240","3.6923"
"","3.5600","2.9686","0.0089","2.9686","6.0584","3.7130"
"","3.5800","2.9849","0.0089","2.9849","6.0917","3.7191"
"","3.6000","3.0013","0.0090","3.0013","6.1252","3.7327"
"","3.6200","3.0181","0.0090","3.0181","6.1594","3.7514"
"","3.6400","3.0350","0.0091","3.0350","6.1938","3.7790"
"","3.6600","3.0515","0.0091","3.0515","6.2275","3.8002"
"","3.6800","3.0683","0.0092","3.0683","6.2618","3.8183"
"","3.7000","3.0851","0.0092","3.0851","6.2962","3.8513"
"","3.7200","3.1017","0.0093","3.1017","6.3299","3.8759"
"","3.7400","3.1181","0.0094","3.1181","6.3634","3.9018"
"","3.7600","3.1348","0.0094","3.1348","6.3976","3.9135"
"","3.7800","3.1518","0.0094","3.1518","6.4323","3.9371"
"","3.8000","3.1686","0.0095","3.1686","6.4666","3.9590"
"","3.8200","3.1850","0.0095","3.1850","6.5000","3.9697"
"","3.8400","3.2018","0.0096","3.2018","6.5343","3.9903"
"","3.8600","3.2183","0.0096","3.2183","6.5680","4.0157"
"","3.8800","3.2348","0.0098","3.2348","6.6017","4.0677"
"","3.9000","3.2516","0.0099","3.2516","6.6359","4.1149"
"","3.9200","3.2686","0.0099","3.2686","6.6706","4.1147"
"","3.9400","3.2855","0.0099","3.2855","6.7051","4.1056"
"","3.9600","3.3020","0.0098","3.3020","6.7388","4.1021"
"","3.9800","3.3185","0.0099","3.3185","6.7725","4.1286"
"","4.0000","3.3352","0.0100","3.3352","6.8065","4.1695"
"","4.0200","3.3516","0.0101","3.3516","6.8400","4.2003"
"","4.0400","3.3680","0.0101","3.3680","6.8735","4.2165"
"","4.0600","3.3848","0.0101","3.3848","6.9077","4.2170"
"","4.0800","3.4019","0.0102","3.4019","6.9426","4.2433"
"","4.1000","3.4185","0.0103","3.4185","6.9766","4.2837"
"","4.1200","3.4349","0.0104","3.4349","7.0101","4.3145"
"","4.1400","3.4517","0.0104","3.4517","7.0443","4.3347"
"","4.1600","3.4684","0.0104","3.4684","7.0783","4.3433"
"","4.1800","3.4851","0.0105","3.4851","7.1125","4.3807"
"","4.2000","3.5016","0.0106","3.5016","7.1462","4.4213"
"","4.2200","3.5185","0.0107","3.5185","7.1807","4.4390"
"","4.2400","3.5354","0.0107","3.5354","7.2151","4.4582"
"","4.2600","3.5517","0.0107","3.5517","7.2484","4.4689"
"","4.2800","3.5680","0.0107","3.5680","7.2816","4.4770"
"","4.3000","3.5848","0.0108","3.5848","7.3158","4.5058"
"","4.3200","3.6015","0.0109","3.6015","7.3500","4.5359"
"","4.3400","3.6180","0.0110","3.6180","7.3838","4.5669"
"","4.3600","3.6349","0.0110","3.6349","7.4182","4.5870"
"","4.3800","3.6519","0.0111","3.6519","7.4529","4.6135"
"","4.4000","3.6686","0.0112","3.6686","7.4869","4.6484"
"","4.4200","3.6849","0.0112","3.6849","7.5201","4.6784"
"","4.4400","3.7015","0.0113","3.7015","7.5541","4.7101"
"","4.4600","3.7185","0.0113","3.7185","7.5888","4.7158"
"","4.4800","3.7353","0.0114","3.7353","7.6230","4.7381"
"","4.5000","3.7518","0.0114","3.7518","7.6567","4.7708"
"","4.5200","3.7686","0.0115","3.7686","7.6910","4.7911"
"","4.5400","3.7853","0.0116","3.7853","7.7252","4.8193"
"","4.5600","3.8017","0.0116","3.8017","7.7587","4.8415"
"","4.5800","3.8182","0.0117","3.8182","7.7921","4.8772"
"","4.6000","3.8350","0.0118","3.8350","7.8266","4.9155"
"","4.6200","3.8519","0.0119","3.8519","7.8611","4.9439"
"","4.6400","3.8684","0.0119","3.8684","7.8948","4.9639"
"","4.6600","3.8850","0.0119","3.8850","7.9285","4.9613"
"","4.6800","3.9020","0.0120","3.9020","7.9632","5.0046"
"","4.7000","3.9184","0.0121","3.9184","7.9967","5.0501"
"","4.7200","3.9347","0.0122","3.9347","8.0299","5.0627"
"","4.7400","3.9514","0.0122","3.9514","8.0642","5.0862"
"","4.7600","3.9686","0.0123","3.9686","8.0991","5.1206"
"","4.7800","3.9852","0.0124","3.9852","8.1331","5.1527"
"","4.8000","4.0016","0.0124","4.0016","8.1666","5.1803"
"","4.8200","4.0185","0.0125","4.0185","8.2010","5.2060"
"","4.8400","4.0351","0.0126","4.0351","8.2350","5.2343"
"","4.8600","4.0514","0.0126","4.0514","8.2682","5.2667"
"","4.8800","4.0680","0.0127","4.0680","8.3020","5.2997"
"","4.9000","4.0850","0.0128","4.0850","8.3366","5.3213"
"","4.9200","4.1018","0.0128","4.1018","8.3711","5.3405"
"","4.9400","4.1185","0.0129","4.1185","8.4051","5.3754"
"","4.9600","4.1350","0.0129","4.1350","8.4388","5.3915"
"","4.9800","4.1519","0.0130","4.1519","8.4733","5.4259"
"","5.0000","4.1684","0.0131","4.1684","8.5070","5.4382"
"","5.0200","4.1847","0.0131","4.1847","8.5402","5.4652"
"","5.0400","4.2015","0.0133","4.2015","8.5744","5.5279"
"","5.0600","4.2185","0.0133","4.2185","8.6091","5.5387"
"","5.0800","4.2351","0.0133","4.2351","8.6431","5.5453"
"","5.1000","4.2515","0.0134","4.2515","8.6766","5.5698"
"","5.1200","4.2683","0.0134","4.2683","8.7108","5.5784"
"","5.1400","4.2851","0.0134","4.2851","8.7450","5.5853"
"","5.1600","4.3016","0.0134","4.3016","8.7788","5.5960"
"","5.1800","4.3181","0.0135","4.3181","8.8125","5.6199"
"","5.2000","4.3351","0.0136","4.3351","8.8472","5.6532"
"","5.2200","4.3521","0.0136","4.3521","8.8819","5.6662"
"","5.2400","4.3685","0.0137","4.3685","8.9154","5.6943"
"","5.2600","4.3852","0.0138","4.3852","8.9493","5.7294"
"","5.2800","4.4017","0.0138","4.4017","8.9831","5.7571"
"","5.3000","4.4182","0.0139","4.4182","9.0168","5.7858"
"","5.3200","4.4348","0.0139","4.4348","9.0505","5.8103"
"","5.3400","4.4515","0.0140","4.4515","9.0847","5.8406"
"","5.3600","4.4686","0.0141","4.4686","9.1197","5.8708"
"","5.3800","4.4852","0.0142","4.4852","9.1534","5.9016"
"","5.4000","4.5017","0.0142","4.5017","9.1871","5.9213"
"","5.4200","4.5183","0.0143","4.5183","9.2211","5.9421"
"","5.4400","4.5349","0.0143","4.5349","9.2548","5.9707"
"","5.4600","4.5516","0.0144","4.5516","9.2890","6.0167"
"","5.4800","4.5684","0.0145","4.5684","9.3233","6.0246"
"","5.5000","4.5853","0.0142","4.5853","9.3577","5.9277"
"","5.5200","4.6020","0.0140","4.6020","9.3919","5.8456"
"","5.5400","4.6185","0.0140","4.6185","9.4254","5.8352"
"","5.5600","4.6349","0.0141","4.6349","9.4589","5.8600"
"","5.5800","4.6517","0.0141","4.6517","9.4934","5.8883"
"","5.6000","4.6685","0.0142","4.6685","9.5276","5.9207"
"","5.6200","4.6852","0.0143","4.6852","9.5615","5.9596"
"","5.6400","4.7018","0.0144","4.7018","9.5955","6.0083"
"","5.6600","4.7187","0.0145","4.7187","9.6300","6.0369"
"","5.6800","4.7352","0.0145","4.7352","9.6637","6.0614"
"","5.7000","4.7515","0.0146","4.7515","9.6969","6.0826"
"","5.7200","4.7681","0.0147","4.7681","9.7309","6.1085"
"","5.7400","4.7850","0.0147","4.7850","9.7654","6.1408"
"","5.7600","4.8017","0.0148","4.8017","9.7993","6.1708"
"","5.7800","4.8183","0.0149","4.8183","9.8333","6.2046"
"","5.8000","4.8351","0.0150","4.8351","9.8675","6.2378"
"","5.8200","4.8517","0.0150","4.8517","9.9015","6.2675"
"","5.8400","4.8681","0.0151","4.8681","9.9350","6.3015"
"","5.8600","4.8845","0.0152","4.8845","9.9685","6.3338"
"","5.8800","4.9015","0.0153","4.9015","10.0032","6.3548"
"","5.9000","4.9184","0.0153","4.9184","10.0376","6.3789"
"","5.9200","4.9350","0.0154","4.9350","10.0713","6.4184"
"","5.9400","4.9517","0.0155","4.9517","10.1056","6.4519"
"","5.9600","4.9686","0.0155","4.9686","10.1400","6.4772"
"","5.9800","4.9851","0.0156","4.9851","10.1737","6.5056"
"","6.0000","5.0014","0.0157","5.0014","10.2070","6.5532"
"","6.0200","5.0182","0.0158","5.0182","10.2412","6.5729"
"","6.0400","5.0352","0.0158","5.0352","10.2759","6.6010"
"","6.0600","5.0517","0.0159","5.0517","10.3096","6.6238"
"","6.0800","5.0684","0.0160","5.0684","10.3436","6.6516"
"","6.1000","5.0852","0.0160","5.0852","10.3780","6.6810"
"","6.1200","5.1018","0.0161","5.1018","10.4118","6.7108"
"","6.1400","5.1182","0.0162","5.1182","10.4453","6.7432"
"","6.1600","5.1348","0.0162","5.1348","10.4792","6.7705"
"","6.1800","5.1518","0.0163","5.1518","10.5139","6.7864"
"","6.2000","5.1686","0.0164","5.1686","10.5481","6.8364"
"","6.2200","5.1851","0.0165","5.1851","10.5819","6.8686"
"","6.2400","5.2018","0.0165","5.2018","10.6158","6.8789"
"","6.2600","5.2184","0.0166","5.2184","10.6498","6.8986"
"","6.2800","5.2348","0.0166","5.2348","10.6833","6.9346"
"","6.3000","5.2512","0.0167","5.2512","10.7168","6.9690"
"","6.3200","5.2682","0.0168","5.2682","10.7515","6.9889"
"","6.3400","5.2851","0.0168","5.2851","10.7859","7.0124"
"","6.3600","5.3019","0.0169","5.3019","10.8202","7.0212"
"","6.3800","5.3185","0.0169","5.3185","10.8541","7.0588"
"","6.4000","5.3352","0.0171","5.3352","10.8881","7.1080"
"","6.4200","5.3517","0.0171","5.3517","10.9218","7.1376"
"","6.4400","5.3680","0.0172","5.3680","10.9551","7.1734"
"","6.4600","5.3847","0.0173","5.3847","10.9893","7.2044"
"","6.4800","5.4017","0.0174","5.4017","11.0240","7.2419"
"","6.5000","5.4185","0.0175","5.4185","11.0582","7.2723"
"","6.5200","5.4350","0.0175","5.4350","11.0919","7.2930"
"","6.5400","5.4517","0.0176","5.4517","11.1259","7.3236"
"","6.5600","5.4683","0.0176","5.4683","11.1599","7.3487"
"","6.5800","5.4846","0.0177","5.4846","11.1931","7.3678"
"","6.6000","5.5013","0.0177","5.5013","11.2271","7.3725"
"","6.6200","5.5180","0.0178","5.5180","11.2613","7.4249"
"","6.6400","5.5352","0.0179","5.5352","11.2962","7.4708"
"","6.6600","5.5518","0.0180","5.5518","11.3302","7.4919"
"","6.6800","5.5682","0.0180","5.5682","11.3637","7.4991"
"","6.7000","5.5850","0.0181","5.5850","11.3979","7.5216"
"","6.7200","5.6017","0.0181","5.6017","11.4321","7.5463"
"","6.7400","5.6183","0.0182","5.6183","11.4658","7.5835"
"","6.7600","5.6350","0.0183","5.6350","11.5001","7.6099"
"","6.7800","5.6521","0.0183","5.6521","11.5350","7.6381"
"","6.8000","5.6688","0.0184","5.6688","11.5690","7.6634"
"","6.8200","5.6852","0.0185","5.6852","11.6024","7.6953"
"","6.8400","5.7016","0.0185","5.7016","11.6359","7.7189"
"","6.8600","5.7181","0.0186","5.7181","11.6697","7.7528"
"","6.8800","5.7347","0.0187","5.7347","11.7034","7.7767"
"","6.9000","5.7514","0.0187","5.7514","11.7376","7.7961"
"","6.9200","5.7684","0.0188","5.7684","11.7723","7.8377"
"","6.9400","5.7853","0.0189","5.7853","11.8068","7.8679"
"","6.9600","5.8017","0.0189","5.8017","11.8402","7.8736"
"","6.9800","5.8180","0.0189","5.8180","11.8735","7.8743"
"","7.0000","5.8349","0.0190","5.8349","11.9079","7.9269"
"","7.0200","5.8518","0.0191","5.8518","11.9424","7.9723"
"","7.0400","5.8684","0.0192","5.8684","11.9764","8.0119"
"","7.0600","5.8851","0.0193","5.8851","12.0103","8.0294"
"","7.0800","5.9019","0.0193","5.9019","12.0448","8.0624"
"","7.1000","5.9186","0.0194","5.9186","12.0788","8.1012"
"","7.1200","5.9348","0.0195","5.9348","12.1118","8.1112"
"","7.1400","5.9513","0.0195","5.9513","12.1455","8.1427"
"","7.1600","5.9684","0.0196","5.9684","12.1804","8.1681"
"","7.1800","5.9851","0.0197","5.9851","12.2144","8.1982"
"","7.2000","6.0016","0.0198","6.0016","12.2481","8.2366"
"","7.2200","6.0185","0.0198","6.0185","12.2826","8.2571"
"","7.2400","6.0354","0.0199","6.0354","12.3170","8.2817"
"","7.2600","6.0515","0.0199","6.0515","12.3501","8.2909"
"","7.2800","6.0679","0.0199","6.0679","12.3835","8.3102"
"","7.3000","6.0848","0.0200","6.0848","12.4180","8.3295"
"","7.3200","6.1017","0.0201","6.1017","12.4524","8.3634"
"","7.3400","6.1183","0.0202","6.1183","12.4864","8.4070"
"","7.3600","6.1351","0.0202","6.1351","12.5206","8.4352"
"","7.3800","6.1521","0.0203","6.1521","12.5553","8.4635"
"","7.4000","6.1685","0.0204","6.1685","12.5888","8.4925"
"","7.4200","6.1847","0.0204","6.1847","12.6218","8.5022"
"","7.4400","6.2013","0.0205","6.2013","12.6558","8.5300"
"","7.4600","6.2185","0.0206","6.2185","12.6907","8.5640"
"","7.4800","6.2351","0.0206","6.2351","12.7247","8.6024"
"","7.5000","6.2517","0.0207","6.2517","12.7587","8.6243"
"","7.5200","6.2686","0.0207","6.2686","12.7931","8.6441"
"","7.5400","6.2852","0.0208","6.2852","12.8269","8.6803"
"","7.5600","6.3015","0.0209","6.3015","12.8601","8.7131"
"","7.5800","6.3181","0.0210","6.3181","12.8941","8.7424"
"","7.6000","6.3351","0.0210","6.3351","12.9288","8.7520"
"","7.6200","6.3521","0.0210","6.3521","12.9635","8.7559"
"","7.6400","6.3685","0.0211","6.3685","12.9970","8.7792"
"","7.6600","6.3852","0.0212","6.3852","13.0309","8.8165"
"","7.6800","6.4016","0.0212","6.4016","13.0644","8.8351"
"","7.7000","6.4181","0.0213","6.4181","13.0981","8.8644"
"","7.7200","6.4346","0.0213","6.4346","13.1319","8.8940"
"","7.7400","6.4515","0.0214","6.4515","13.1663","8.9269"
"","7.7600","6.4686","0.0214","6.4686","13.2013","8.9341"
"","7.7800","6.4854","0.0215","6.4854","13.2355","8.9731"
"","7.8000","6.5017","0.0216","6.5017","13.2687","9.0168"
"","7.8200","6.5183","0.0217","6.5183","13.3027","9.0397"
"","7.8400","6.5350","0.0218","6.5350","13.3367","9.0679"
"","7.8600","6.5514","0.0218","6.5514","13.3702","9.0858"
"","7.8800","6.5680","0.0219","6.5680","13.4041","9.1071"
"","7.9000","6.5850","0.0219","6.5850","13.4388","9.1296"
"","7.9200","6.6020","0.0219","6.6020","13.4735","9.1443"
"","7.9400","6.6184","0.0220","6.6184","13.5070","9.1821"
"","7.9600","6.6347","0.0221","6.6347","13.5402","9.2179"
"","7.9800","6.6515","0.0222","6.6515","13.5745","9.2438"
"","8.0000","6.6682","0.0222","6.6682","13.6087","9.2657"
"","8.0200","6.6848","0.0223","6.6848","13.6424","9.2714"
"","8.0400","6.7017","0.0223","6.7017","13.6769","9.2785"
"","8.0600","6.7188","0.0223","6.7188","13.7118","9.2961"
"","8.0800","6.7354","0.0224","6.7354","13.7458","9.3322"
"","8.1000","6.7516","0.0224","6.7516","13.7788","9.3459"
"","8.1200","6.7680","0.0224","6.7680","13.8123","9.3489"
"","8.1400","6.7847","0.0226","6.7847","13.8462","9.4180"
"","8.1600","6.8013","0.0227","6.8013","13.8802","9.4515"
"","8.1800","6.8178","0.0227","6.8178","13.9139","9.4682"
"","8.2000","6.8351","0.0228","6.8351","13.9491","9.4880"
"","8.2200","6.8519","0.0228","6.8519","13.9836","9.4994"
"","8.2400","6.8684","0.0228","6.8684","14.0170","9.5165"
"","8.2600","6.8845","0.0229","6.8845","14.0501","9.5241"
"","8.2800","6.9014","0.0229","6.9014","14.0845","9.5585"
"","8.3000","6.9183","0.0230","6.9183","14.1190","9.5933"
"","8.3200","6.9349","0.0231","6.9349","14.1529","9.6119"
"","8.3400","6.9518","0.0231","6.9518","14.1874","9.6205"
"","8.3600","6.9687","0.0231","6.9687","14.2218","9.6157"
"","8.3800","6.9851","0.0231","6.9851","14.2553","9.6231"
"","8.4000","7.0014","0.0232","7.0014","14.2886","9.6596"
"","8.4200","7.0180","0.0232","7.0180","14.3225","9.6862"
"","8.4400","7.0350","0.0233","7.0350","14.3572","9.7153"
"","8.4600","7.0516","0.0233","7.0516","14.3910","9.7257"
"","8.4800","7.0682","0.0234","7.0682","14.4249","9.7454"
"","8.5000","7.0852","0.0235","7.0852","14.4596","9.7794"
"","8.5200","7.1017","0.0235","7.1017","14.4934","9.7817"
"","8.5400","7.1179","0.0235","7.1179","14.5264","9.8005"
"","8.5600","7.1343","0.0236","7.1343","14.5599","9.8394"
"","8.5800","7.1515","0.0237","7.1515","14.5948","9.8761"
"","8.6000","7.1682","0.0238","7.1682","14.6290","9.9052"
"","8.6200","7.1847","0.0238","7.1847","14.6627","9.9242"
"","8.6400","7.2016","0.0238","7.2016","14.6972","9.9114"
"","8.6600","7.2185","0.0238","7.2185","14.7316","9.9081"
"","8.6800","7.2349","0.0238","7.2349","14.7651","9.9279"
"","8.7000","7.2513","0.0239","7.2513","14.7986","9.9575"
"","8.7200","7.2683","0.0239","7.2683","14.8333","9.9687"
"","8.7400","7.2853","0.0240","7.2853","14.8680","9.9905"
"","8.7600","7.3021","0.0240","7.3021","14.9022","10.0173"
"","8.7800","7.3187","0.0241","7.3187","14.9362","10.0521"
"","8.8000","7.3355","0.0242","7.3355","14.9704","10.0766"
"","8.8200","7.3518","0.0242","7.3518","15.0037","10.1006"
"","8.8400","7.3681","0.0243","7.3681","15.0369","10.1109"
"","8.8600","7.3847","0.0243","7.3847","15.0709","10.1210"
"","8.8800","7.4017","0.0243","7.4017","15.1056","10.1444"
"","8.9000","7.4186","0.0244","7.4186","15.1400","10.1740"
"","8.9200","7.4350","0.0245","7.4350","15.1735","10.1903"
"","8.9400","7.4517","0.0245","7.4517","15.2075","10.2084"
"","8.9600","7.4683","0.0245","7.4683","15.2415","10.2253"
"","8.9800","7.4846","0.0246","7.4846","15.2747","10.2475"
"","9.0000","7.5014","0.0247","7.5014","15.3089","10.2787"
"","9.0200","7.5184","0.0247","7.5184","15.3436","10.3109"
"","9.0400","7.5352","0.0248","7.5352","15.3781","10.3301"
"","9.0600","7.5519","0.0248","7.5519","15.4120","10.3488"
"","9.0800","7.5684","0.0249","7.5684","15.4458","10.3787"
"","9.1000","7.5852","0.0250","7.5852","15.4800","10.4150"
"","9.1200","7.6016","0.0251","7.6016","15.5135","10.4404"
"","9.1400","7.6181","0.0251","7.6181","15.5472","10.4679"
"","9.1600","7.6350","0.0251","7.6350","15.5816","10.4637"
"","9.1800","7.6520","0.0252","7.6520","15.6163","10.4821"
"","9.2000","7.6685","0.0252","7.6685","15.6501","10.5121"
"","9.2200","7.6851","0.0253","7.6851","15.6838","10.5410"
"","9.2400","7.7016","0.0253","7.7016","15.7175","10.5598"
"","9.2600","7.7181","0.0254","7.7181","15.7513","10.5694"
"","9.2800","7.7346","0.0254","7.7346","15.7850","10.5932"
"","9.3000","7.7514","0.0254","7.7514","15.8192","10.6028"
"","9.3200","7.7684","0.0255","7.7684","15.8539","10.6267"
"","9.3400","7.7852","0.0256","7.7852","15.8881","10.6752"
"","9.3600","7.8016","0.0256","7.8016","15.9216","10.6874"
"","9.3800","7.8181","0.0257","7.8181","15.9553","10.6924"
"","9.4000","7.8349","0.0257","7.8349","15.9895","10.7132"
"","9.4200","7.8516","0.0258","7.8516","16.0237","10.7368"
"","9.4400","7.8683","0.0258","7.8683","16.0577","10.7687"
"","9.4600","7.8853","0.0259","7.8853","16.0924","10.7993"
"","9.4800","7.9023","0.0260","7.9023","16.1271","10.8316"
"","9.5000","7.9187","0.0261","7.9187","16.1606","10.8543"
"","9.5200","7.9350","0.0261","7.9350","16.1938","10.8658"
"","9.5400","7.9515","0.0261","7.9515","16.2276","10.8872"
"","9.5600","7.9684","0.0262","7.9684","16.2620","10.9112"
"","9.5800","7.9849","0.0262","7.9849","16.2958","10.9319"
"","9.6000","8.0016","0.0263","8.0016","16.3297","10.9515"
"","9.6200","8.0184","0.0263","8.0184","16.3642","10.9551"
"","9.6400","8.0352","0.0263","8.0352","16.3984","10.9790"
"","9.6600","8.0516","0.0264","8.0516","16.4319","11.0142"
"","9.6800","8.0679","0.0265","8.0679","16.4651","11.0453"
"","9.7000","8.0847","0.0266","8.0847","16.4993","11.1004"
"","9.7200","8.1016","0.0267","8.1016","16.5338","11.1086"
"","9.7400","8.1184","0.0267","8.1184","16.5683","11.1120"
"","9.7600","8.1352","0.0267","8.1352","16.6025","11.1192"
"","9.7800","8.1522","0.0267","8.1522","16.6372","11.1455"
"","9.8000","8.1685","0.0268","8.1685","16.6704","11.1613"
"","9.8200","8.1847","0.0268","8.1847","16.7034","11.1530"
"","9.8400","8.2013","0.0268","8.2013","16.7374","11.1682"
"","9.8600","8.2183","0.0269","8.2183","16.7721","11.1994"
"","9.8800","8.2351","0.0270","8.2351","16.8063","11.2322"
"","9.9000","8.2517","0.0270","8.2517","16.8403","11.2538"
"","9.9200","8.2686","0.0270","8.2686","16.8747","11.2664"
"","9.9400","8.2850","0.0271","8.2850","16.9082","11.2834"
"","9.9600","8.3011","0.0271","8.3011","16.9410","11.2740"
"","9.9800","8.3177","0.0269","8.3177","16.9749","11.2288"
"","10.0000","8.3348","0.0269","8.3348","17.0099","11.2078"
"","10.0200","8.3517","0.0269","8.3517","17.0443","11.2112"
"","10.0400","8.3684","0.0270","8.3684","17.0783","11.2297"
"","10.0600","8.3852","0.0270","8.3852","17.1128","11.2493"
"","10.0800","8.4020","0.0271","8.4020","17.1470","11.2908"
"","10.1000","8.4183","0.0270","8.4183","17.1802","11.2704"
"","10.1200","8.4347","0.0270","8.4347","17.2137","11.2527"
"","10.1400","8.4517","0.0271","8.4517","17.2484","11.2731"
"","10.1600","8.4687","0.0271","8.4687","17.2831","11.3007"
"","10.1800","8.4854","0.0272","8.4854","17.3171","11.3357"
"","10.2000","8.5019","0.0273","8.5019","17.3508","11.3560"
"","10.2200","8.5187","0.0273","8.5187","17.3850","11.3665"
"","10.2400","8.5351","0.0273","8.5351","17.4185","11.3927"
"","10.2600","8.5514","0.0274","8.5514","17.4517","11.4071"
"","10.2800","8.5680","0.0274","8.5680","17.4857","11.4075"
"","10.3000","8.5850","0.0274","8.5850","17.5204","11.4194"
"","10.3200","8.6018","0.0274","8.6018","17.5546","11.4330"
"","10.3400","8.6184","0.0275","8.6184","17.5886","11.4663"
"","10.3600","8.6351","0.0275","8.6351","17.6226","11.4777"
"","10.3800","8.6518","0.0276","8.6518","17.6568","11.4974"
"","10.4000","8.6682","0.0277","8.6682","17.6903","11.5280"
"","10.4200","8.6848","0.0277","8.6848","17.7240","11.5425"
"","10.4400","8.7016","0.0277","8.7016","17.7584","11.5567"
"","10.4600","8.7185","0.0278","8.7185","17.7929","11.5652"
"","10.4800","8.7352","0.0278","8.7352","17.8269","11.5996"
"","10.5000","8.7518","0.0279","8.7518","17.8608","11.6269"
"","10.5200","8.7685","0.0279","8.7685","17.8948","11.6426"
"","10.5400","8.7850","0.0279","8.7850","17.9285","11.6317"
"","10.5600","8.8016","0.0276","8.8016","17.9625","11.5067"
"","10.5800","8.8183","0.0275","8.8183","17.9965","11.4394"
"","10.6000","8.8353","0.0275","8.8353","18.0312","11.4563"
"","10.6200","8.8518","0.0275","8.8518","18.0649","11.4780"
"","10.6400","8.8683","0.0276","8.8683","18.0986","11.4975"
"","10.6600","8.8847","0.0276","8.8847","18.1321","11.4879"
"","10.6800","8.9015","0.0275","8.9015","18.1663","11.4787"
"","10.7000","8.9184","0.0273","8.9184","18.2008","11.3638"
"","10.7200","8.9349","0.0269","8.9349","18.2345","11.1969"
"","10.7400","8.9518","0.0266","8.9518","18.2690","11.1002"
"","10.7600","8.9687","0.0266","8.9687","18.3034","11.0710"
"","10.7800","8.9852","0.0266","8.9852","18.3372","11.0916"
"","10.8000","9.0015","0.0267","9.0015","18.3704","11.1113"
"","10.8200","9.0181","0.0267","9.0181","18.4044","11.1417"
"","10.8400","9.0350","0.0268","9.0350","18.4388","11.1633"
"","10.8600","9.0517","0.0268","9.0517","18.4728","11.1506"
"","10.8800","9.0684","0.0268","9.0684","18.5070","11.1694"
"","10.9000","9.0853","0.0269","9.0853","18.5415","11.1919"
"","10.9200","9.1018","0.0269","9.1018","18.5752","11.1965"
"","10.9400","9.1181","0.0269","9.1181","18.6084","11.2040"
"","10.9600","9.1347","0.0269","9.1347","18.6422","11.2043"
"","10.9800","9.1517","0.0269","9.1517","18.6769","11.2232"
"","11.0000","9.1687","0.0270","9.1687","18.7116","11.2531"
"","11.0200","9.1852","0.0270","9.1852","18.7453","11.2700"
"","11.0400","9.2020","0.0271","9.2020","18.7795","11.2960"
"","11.0600","9.2185","0.0272","9.2185","18.8132","11.3171"
"","11.0800","9.2348","0.0272","9.2348","18.8465","11.3431"
"","11.1000","9.2511","0.0273","9.2511","18.8797","11.3545"
"","11.1200","9.2679","0.0273","9.2679","18.9142","11.3550"
"","11.1400","9.2851","0.0273","9.2851","18.9491","11.3672"
"","11.1600","9.3017","0.0273","9.3017","18.9831","11.3926"
"","11.1800","9.3185","0.0274","9.3185","19.0173","11.4199"
"","11.2000","9.3354","0.0274","9.3354","19.0518","11.4357"
"","11.2200","9.3517","0.0275","9.3517","19.0850","11.4497"
"","11.2400","9.3679","0.0276","9.3679","19.1183","11.5028"
"","11.2600","9.3847","0.0276","9.3847","19.1525","11.5165"
"","11.2800","9.4017","0.0276","9.4017","19.1872","11.5008"
"","11.3000","9.4184","0.0276","9.4184","19.2211","11.5169"
"","11.3200","9.4351","0.0277","9.4351","19.2553","11.5376"
"","11.3400","9.4518","0.0277","9.4518","19.2893","11.5610"
"","11.3600","9.4685","0.0278","9.4685","19.3235","11.5687"
"","11.3800","9.4849","0.0278","9.4849","19.3570","11.5811"
"","11.4000","9.5015","0.0278","9.5015","19.3907","11.5948"
"","11.4200","9.5183","0.0279","9.5183","19.4252","11.6141"
"","11.4400","9.5351","0.0279","9.5351","19.4594","11.6372"
"","11.4600","9.5516","0.0280","9.5516","19.4931","11.6568"
"","11.4800","9.5683","0.0280","9.5683","19.5271","11.6732"
"","11.5000","9.5850","0.0281","9.5850","19.5613","11.6999"
"","11.5200","9.6016","0.0281","9.6016","19.5950","11.7173"
"","11.5400","9.6180","0.0282","9.6180","19.6285","11.7314"
"","11.5600","9.6349","0.0282","9.6349","19.6630","11.7447"
"","11.5800","9.6519","0.0282","9.6519","19.6977","11.7572"
"","11.6000","9.6684","0.0282","9.6684","19.7314","11.7657"
"","11.6200","9.6850","0.0283","9.6850","19.7654","11.7860"
"","11.6400","9.7018","0.0283","9.7018","19.7996","11.8053"
"","11.6600","9.7183","0.0283","9.7183","19.8333","11.8097"
"","11.6800","9.7350","0.0284","9.7350","19.8673","11.8379"
"","11.7000","9.7516","0.0285","9.7516","19.9013","11.8569"
"","11.7200","9.7685","0.0285","9.7685","19.9357","11.8594"
"","11.7400","9.7854","0.0285","9.7854","19.9702","11.8748"
"","11.7600","9.8018","0.0285","9.8018","20.0037","11.8729"
"","11.7800","9.8184","0.0285","9.8184","20.0376","11.8828"
"","11.8000","9.8350","0.0286","9.8350","20.0714","11.9054"
"","11.8200","9.8515","0.0286","9.8515","20.1051","11.9224"
"","11.8400","9.8680","0.0286","9.8680","20.1388","11.9334"
"","11.8600","9.8849","0.0287","9.8849","20.1733","11.9378"
"","11.8800","9.9019","0.0287","9.9019","20.2080","11.9661"
"","11.9000","9.9186","0.0287","9.9186","20.2419","11.9791"
"","11.9200","9.9348","0.0288","9.9348","20.2752","11.9998"
"","11.9400","9.9515","0.0288","9.9515","20.3092","12.0139"
"","11.9600","9.9681","0.0289","9.9681","20.3431","12.0243"
"","11.9800","9.9849","0.0289","9.9849","20.3773","12.0406"
"","12.0000","10.0017","0.0289","10.0017","20.4116","12.0578"
"","12.0200","10.0187","0.0290","10.0187","20.4463","12.0716"
"","12.0400","10.0354","0.0290","10.0354","20.4805","12.0787"
"","12.0600","10.0518","0.0289","10.0518","20.5140","12.0602"
"","12.0800","10.0682","0.0289","10.0682","20.5474","12.0505"
"","12.1000","10.0848","0.0289","10.0848","20.5812","12.0568"
"","12.1200","10.1017","0.0289","10.1017","20.6156","12.0556"
"","12.1400","10.1184","0.0289","10.1184","20.6498","12.0550"
"","12.1600","10.1352","0.0288","10.1352","20.6841","11.9978"
"","12.1800","10.1519","0.0288","10.1519","20.7183","11.9829"
"","12.2000","10.1685","0.0287","10.1685","20.7520","11.9640"
"","12.2200","10.1849","0.0286","10.1849","20.7855","11.9348"
"","12.2400","10.2015","0.0286","10.2015","20.8195","11.9250"
"","12.2600","10.2184","0.0286","10.2184","20.8539","11.9145"
"","12.2800","10.2351","0.0287","10.2351","20.8879","11.9404"
"","12.3000","10.2517","0.0287","10.2517","20.9218","11.9606"
"","12.3200","10.2686","0.0287","10.2686","20.9563","11.9665"
"","12.3400","10.2854","0.0287","10.2854","20.9905","11.9670"
"","12.3600","10.3016","0.0287","10.3016","21.0238","11.9756"
"","12.3800","10.3181","0.0287","10.3181","21.0573","11.9777"
"","12.4000","10.3349","0.0288","10.3349","21.0917","12.0200"
"","12.4200","10.3519","0.0287","10.3519","21.1264","11.9509"
"","12.4400","10.3686","0.0285","10.3686","21.1604","11.8792"
"","12.4600","10.3851","0.0280","10.3851","21.1941","11.6796"
"","12.4800","10.4020","0.0273","10.4020","21.2286","11.3727"
"","12.5000","10.4184","0.0270","10.4184","21.2620","11.2351"
"","12.5200","10.4346","0.0269","10.4346","21.2950","11.2080"
"","12.5400","10.4513","0.0270","10.4513","21.3293","11.2367"
"","12.5600","10.4683","0.0270","10.4683","21.3640","11.2597"
"","12.5800","10.4851","0.0271","10.4851","21.3982","11.2757"
"","12.6000","10.5015","0.0271","10.5015","21.4317","11.3106"
"","12.6200","10.5183","0.0272","10.5183","21.4659","11.3210"
"","12.6400","10.5348","0.0272","10.5348","21.4996","11.3198"
"","12.6600","10.5511","0.0272","10.5511","21.5328","11.3242"
"","12.6800","10.5677","0.0272","10.5677","21.5668","11.3241"
"","12.7000","10.5849","0.0272","10.5849","21.6018","11.3442"
"","12.7200","10.6019","0.0268","10.6019","21.6364","11.1619"
"","12.7400","10.6184","0.0261","10.6184","21.6702","10.8826"
"","12.7600","10.6349","0.0259","10.6349","21.7039","10.7762"
"","12.7800","10.6517","0.0259","10.6517","21.7381","10.7905"
"","12.8000","10.6681","0.0260","10.6681","21.7716","10.8443"
"","12.8200","10.6845","0.0260","10.6845","21.8051","10.8474"
"","12.8400","10.7014","0.0260","10.7014","21.8396","10.8531"
"","12.8600","10.7184","0.0261","10.7184","21.8742","10.8650"
"","12.8800","10.7351","0.0261","10.7351","21.9085","10.8779"
"","12.9000","10.7517","0.0262","10.7517","21.9422","10.9053"
"","12.9200","10.7682","0.0262","10.7682","21.9759","10.9145"
"","12.9400","10.7847","0.0262","10.7847","22.0096","10.9155"
"","12.9600","10.8015","0.0262","10.8015","22.0439","10.9142"
"","12.9800","10.8183","0.0262","10.8183","22.0781","10.9232"
"","13.0000","10.8353","0.0262","10.8353","22.1128","10.9152"
"","13.0200","10.8520","0.0254","10.8520","22.1470","10.5857"
"","13.0400","10.8685","0.0249","10.8685","22.1807","10.3702"
"","13.0600","10.8851","0.0247","10.8851","22.2144","10.3122"
"","13.0800","10.9017","0.0248","10.9017","22.2484","10.3298"
"","13.1000","10.9185","0.0248","10.9185","22.2826","10.3524"
"","13.1200","10.9350","0.0248","10.9350","22.3164","10.3470"
"","13.1400","10.9518","0.0249","10.9518","22.3506","10.3581"
"","13.1600","10.9687","0.0249","10.9687","22.3850","10.3571"
"","13.1800","10.9852","0.0249","10.9852","22.4187","10.3934"
"","13.2000","11.0017","0.0249","11.0017","22.4525","10.3932"
"","13.2200","11.0181","0.0249","11.0181","22.4860","10.3837"
"","13.2400","11.0349","0.0249","11.0349","22.5202","10.3933"
"","13.2600","11.0515","0.0250","11.0515","22.5541","10.4075"
"","13.2800","11.0682","0.0250","11.0682","22.5881","10.4325"
"","13.3000","11.0852","0.0251","11.0852","22.6228","10.4599"
"","13.3200","11.1019","0.0251","11.1019","22.6570","10.4745"
"","13.3400","11.1185","0.0252","11.1185","22.6908","10.4878"
"","13.3600","11.1349","0.0252","11.1349","22.7242","10.4871"
"","13.3800","11.1516","0.0252","11.1516","22.7585","10.5153"
"","13.4000","11.1685","0.0253","11.1685","22.7929","10.5411"
"","13.4200","11.1852","0.0253","11.1852","22.8269","10.5437"
"","13.4400","11.2019","0.0253","11.2019","22.8611","10.5517"
"","13.4600","11.2186","0.0251","11.2186","22.8951","10.4541"
"","13.4800","11.2352","0.0244","11.2352","22.9290","10.1783"
"","13.5000","11.2513","0.0241","11.2513","22.9618","10.0452"
"","13.5200","11.2679","0.0241","11.2679","22.9958","10.0251"
"","13.5400","11.2848","0.0241","11.2848","23.0302","10.0373"
"","13.5600","11.3016","0.0241","11.3016","23.0644","10.0577"
"","13.5800","11.3182","0.0242","11.3182","23.0984","10.0648"
"","13.6000","11.3351","0.0242","11.3351","23.1329","10.0791"
"","13.6200","11.3517","0.0242","11.3517","23.1668","10.0963"
"","13.6400","11.3680","0.0243","11.3680","23.2001","10.1247"
"","13.6600","11.3847","0.0243","11.3847","23.2340","10.1325"
"","13.6800","11.4016","0.0243","11.4016","23.2685","10.1397"
"","13.7000","11.4184","0.0244","11.4184","23.3030","10.1564"
"","13.7200","11.4351","0.0244","11.4351","23.3369","10.1712"
"","13.7400","11.4517","0.0244","11.4517","23.3709","10.1738"
"","13.7600","11.4686","0.0244","11.4686","23.4054","10.1752"
"","13.7800","11.4850","0.0243","11.4850","23.4388","10.1397"
"","13.8000","11.5014","0.0237","11.5014","23.4723","9.8594"
"","13.8200","11.5182","0.0232","11.5182","23.5065","9.6785"
"","13.8400","11.5350","0.0231","11.5350","23.5408","9.6437"
"","13.8600","11.5517","0.0232","11.5517","23.5750","9.6609"
"","13.8800","11.5684","0.0233","11.5684","23.6089","9.6952"
"","13.9000","11.5850","0.0233","11.5850","23.6429","9.6981"
"","13.9200","11.6016","0.0226","11.6016","23.6766","9.4085"
"","13.9400","11.6178","0.0221","11.6178","23.7099","9.1991"
"","13.9600","11.6347","0.0216","11.6347","23.7443","8.9847"
"","13.9800","11.6517","0.0209","11.6517","23.7790","8.6876"
"","14.0000","11.6686","0.0206","11.6686","23.8135","8.5806"
"","14.0200","11.6851","0.0206","11.6851","23.8472","8.5776"
"","14.0400","11.7018","0.0206","11.7018","23.8812","8.5899"
"","14.0600","11.7184","0.0206","11.7184","23.9152","8.5950"
"","14.0800","11.7348","0.0207","11.7348","23.9486","8.6170"
"","14.1000","11.7515","0.0207","11.7515","23.9826","8.6242"
"","14.1200","11.7684","0.0202","11.7684","24.0171","8.4246"
"","14.1400","11.7852","0.0196","11.7852","24.0515","8.1597"
"","14.1600","11.8018","0.0194","11.8018","24.0853","8.0655"
"","14.1800","11.8184","0.0194","11.8184","24.1192","8.0834"
"","14.2000","11.8351","0.0195","11.8351","24.1532","8.1202"
"","14.2200","11.8515","0.0195","11.8515","24.1867","8.1296"
"","14.2400","11.8681","0.0196","11.8681","24.2207","8.1511"
"","14.2600","11.8848","0.0196","11.8848","24.2546","8.1559"
"","14.2800","11.9018","0.0196","11.9018","24.2893","8.1615"
"","14.3000","11.9185","0.0196","11.9185","24.3235","8.1675"
"","14.3200","11.9349","0.0196","11.9349","24.3570","8.1827"
"","14.3400","11.9515","0.0196","11.9515","24.3908","8.1583"
"","14.3600","11.9680","0.0196","11.9680","24.4245","8.1539"
"","14.3800","11.9848","0.0197","11.9848","24.4587","8.1982"
"","14.4000","12.0015","0.0197","12.0015","24.4929","8.2085"
"","14.4200","12.0184","0.0197","12.0184","24.5274","8.2122"
"","14.4400","12.0354","0.0197","12.0354","24.5621","8.2184"
"","14.4600","12.0518","0.0197","12.0518","24.5955","8.2170"
"","14.4800","12.0682","0.0198","12.0682","24.6290","8.2365"
"","14.5000","12.0850","0.0198","12.0850","24.6632","8.2477"
"","14.5200","12.1016","0.0198","12.1016","24.6972","8.2447"
"","14.5400","12.1184","0.0198","12.1184","24.7314","8.2594"
"","14.5600","12.1352","0.0198","12.1352","24.7656","8.2704"
"","14.5800","12.1520","0.0199","12.1520","24.8001","8.2808"
"","14.6000","12.1687","0.0199","12.1687","24.8341","8.2915"
"","14.6200","12.1849","0.0199","12.1849","24.8671","8.2910"
"","14.6400","12.2014","0.0199","12.2014","24.9008","8.2979"
"","14.6600","12.2182","0.0194","12.2182","24.9350","8.0763"
"","14.6800","12.2349","0.0187","12.2349","24.9692","7.7914"
"","14.7000","12.2517","0.0184","12.2517","25.0034","7.6848"
"","14.7200","12.2686","0.0184","12.2686","25.0379","7.6727"
"","14.7400","12.2853","0.0185","12.2853","25.0721","7.6956"
"","14.7600","12.3017","0.0186","12.3017","25.1056","7.7303"
"","14.7800","12.3182","0.0186","12.3182","25.1391","7.7580"
"","14.8000","12.3349","0.0186","12.3349","25.1733","7.7646"
"","14.8200","12.3518","0.0186","12.3518","25.2077","7.7666"
"","14.8400","12.3683","0.0187","12.3683","25.2415","7.7741"
"","14.8600","12.3849","0.0187","12.3849","25.2752","7.7775"
"","14.8800","12.4019","0.0187","12.4019","25.3099","7.7898"
"","14.9000","12.4184","0.0187","12.4184","25.3436","7.8050"
"","14.9200","12.4344","0.0184","12.4344","25.3764","7.6695"
"","14.9400","12.4511","0.0177","12.4511","25.4104","7.3697"
"","14.9560","12.4647","0.0174","12.4647","25.4381","7.2392"