File: Fig6C/211130_Instron/211130/tensile_curtain_8_1.csv
Results Table 1


Results Table 2


1,Time,Displacement,Force,Tensile displacement,Tensile strain (Displacement),Tensile stress
,(s),(mm),(kN),(mm),(%),(MPa)
2,Time,Displacement,Force,Tensile displacement,Tensile strain (Displacement),Tensile stress
,(s),(mm),(kN),(mm),(%),(MPa)
3,Time,Displacement,Force,Tensile displacement,Tensile strain (Displacement),Tensile stress
,(s),(mm),(kN),(mm),(%),(MPa)
4,Time,Displacement,Force,Tensile displacement,Tensile strain (Displacement),Tensile stress
,(s),(mm),(kN),(mm),(%),(MPa)
5,Time,Displacement,Force,Tensile displacement,Tensile strain (Displacement),Tensile stress
,(s),(mm),(kN),(mm),(%),(MPa)
6,Time,Displacement,Force,Tensile displacement,Tensile strain (Displacement),Tensile stress
,(s),(mm),(kN),(mm),(%),(MPa)
"","0.0000","0.0565","0.0003","0.0565","0.1154","0.1426"
"","0.0200","0.0586","0.0003","0.0586","0.1195","0.1381"
"","0.0400","0.0666","0.0004","0.0666","0.1359","0.1607"
"","0.0600","0.0830","0.0005","0.0830","0.1694","0.1907"
"","0.0800","0.1045","0.0006","0.1045","0.2132","0.2421"
"","0.1000","0.1275","0.0008","0.1275","0.2602","0.3154"
"","0.1200","0.1489","0.0009","0.1489","0.3038","0.3936"
"","0.1400","0.1685","0.0012","0.1685","0.3438","0.4802"
"","0.1600","0.1872","0.0013","0.1872","0.3821","0.5492"
"","0.1800","0.2051","0.0015","0.2051","0.4185","0.6223"
"","0.2000","0.2224","0.0017","0.2224","0.4539","0.6883"
"","0.2200","0.2395","0.0018","0.2395","0.4888","0.7677"
"","0.2400","0.2564","0.0019","0.2564","0.5233","0.8047"
"","0.2600","0.2729","0.0021","0.2729","0.5570","0.8561"
"","0.2800","0.2896","0.0022","0.2896","0.5910","0.9160"
"","0.3000","0.3064","0.0023","0.3064","0.6252","0.9592"
"","0.3200","0.3232","0.0025","0.3232","0.6597","1.0253"
"","0.3400","0.3400","0.0026","0.3400","0.6939","1.0721"
"","0.3600","0.3566","0.0027","0.3566","0.7278","1.1257"
"","0.3800","0.3732","0.0028","0.3732","0.7616","1.1785"
"","0.4000","0.3898","0.0030","0.3898","0.7955","1.2306"
"","0.4200","0.4063","0.0031","0.4063","0.8293","1.2862"
"","0.4400","0.4231","0.0032","0.4231","0.8635","1.3362"
"","0.4600","0.4401","0.0033","0.4401","0.8982","1.3816"
"","0.4800","0.4569","0.0034","0.4569","0.9324","1.4353"
"","0.5000","0.4735","0.0035","0.4735","0.9664","1.4761"
"","0.5200","0.4899","0.0036","0.4899","0.9999","1.5104"
"","0.5400","0.5066","0.0037","0.5066","1.0338","1.5497"
"","0.5600","0.5231","0.0038","0.5231","1.0676","1.5995"
"","0.5800","0.5399","0.0040","0.5399","1.1018","1.6467"
"","0.6000","0.5566","0.0041","0.5566","1.1360","1.6911"
"","0.6200","0.5734","0.0041","0.5734","1.1702","1.7239"
"","0.6400","0.5900","0.0042","0.5900","1.2042","1.7681"
"","0.6600","0.6065","0.0043","0.6065","1.2377","1.8078"
"","0.6800","0.6229","0.0044","0.6229","1.2711","1.8527"
"","0.7000","0.6394","0.0045","0.6394","1.3049","1.8768"
"","0.7200","0.6563","0.0046","0.6563","1.3393","1.9216"
"","0.7400","0.6732","0.0047","0.6732","1.3738","1.9558"
"","0.7600","0.6902","0.0048","0.6902","1.4085","1.9917"
"","0.7800","0.7069","0.0049","0.7069","1.4427","2.0291"
"","0.8000","0.7233","0.0050","0.7233","1.4762","2.0674"
"","0.8200","0.7399","0.0050","0.7399","1.5099","2.0895"
"","0.8400","0.7565","0.0051","0.7565","1.5439","2.1097"
"","0.8600","0.7734","0.0051","0.7734","1.5783","2.1372"
"","0.8800","0.7900","0.0052","0.7900","1.6123","2.1737"
"","0.9000","0.8069","0.0053","0.8069","1.6468","2.2113"
"","0.9200","0.8236","0.0054","0.8236","1.6807","2.2441"
"","0.9400","0.8402","0.0054","0.8402","1.7147","2.2708"
"","0.9600","0.8565","0.0055","0.8565","1.7479","2.3073"
"","0.9800","0.8730","0.0055","0.8730","1.7817","2.3038"
"","1.0000","0.8898","0.0056","0.8898","1.8159","2.3173"
"","1.0200","0.9065","0.0057","0.9065","1.8501","2.3557"
"","1.0400","0.9232","0.0057","0.9232","1.8841","2.3873"
"","1.0600","0.9398","0.0058","0.9398","1.9180","2.4110"
"","1.0800","0.9565","0.0058","0.9565","1.9520","2.4285"
"","1.1000","0.9729","0.0059","0.9729","1.9855","2.4495"
"","1.1200","0.9891","0.0060","0.9891","2.0185","2.4799"
"","1.1400","1.0060","0.0060","1.0060","2.0530","2.5062"
"","1.1600","1.0230","0.0061","1.0230","2.0877","2.5269"
"","1.1800","1.0398","0.0061","1.0398","2.1221","2.5517"
"","1.2000","1.0567","0.0062","1.0567","2.1566","2.5633"
"","1.2200","1.0736","0.0062","1.0736","2.1910","2.5934"
"","1.2400","1.0901","0.0063","1.0901","2.2247","2.6114"
"","1.2600","1.1063","0.0063","1.1063","2.2578","2.6407"
"","1.2800","1.1228","0.0064","1.1228","2.2915","2.6713"
"","1.3000","1.1397","0.0065","1.1397","2.3259","2.6910"
"","1.3200","1.1568","0.0065","1.1568","2.3609","2.6922"
"","1.3400","1.1734","0.0065","1.1734","2.3946","2.7012"
"","1.3600","1.1900","0.0065","1.1900","2.4286","2.7015"
"","1.3800","1.2068","0.0066","1.2068","2.4628","2.7354"
"","1.4000","1.2233","0.0067","1.2233","2.4965","2.7871"
"","1.4200","1.2399","0.0068","1.2399","2.5305","2.8266"
"","1.4400","1.2566","0.0068","1.2566","2.5645","2.8346"
"","1.4600","1.2735","0.0069","1.2735","2.5989","2.8613"
"","1.4800","1.2902","0.0069","1.2902","2.6331","2.8746"
"","1.5000","1.3068","0.0069","1.3068","2.6669","2.8846"
"","1.5200","1.3232","0.0070","1.3232","2.7003","2.9202"
"","1.5400","1.3398","0.0071","1.3398","2.7343","2.9375"
"","1.5600","1.3563","0.0071","1.3563","2.7680","2.9493"
"","1.5800","1.3730","0.0071","1.3730","2.8020","2.9592"
"","1.6000","1.3896","0.0071","1.3896","2.8360","2.9638"
"","1.6200","1.4064","0.0072","1.4064","2.8702","2.9814"
"","1.6400","1.4230","0.0072","1.4230","2.9042","2.9893"
"","1.6600","1.4395","0.0072","1.4395","2.9377","3.0164"
"","1.6800","1.4561","0.0073","1.4561","2.9716","3.0480"
"","1.7000","1.4729","0.0074","1.4729","3.0058","3.0793"
"","1.7200","1.4896","0.0074","1.4896","3.0401","3.0841"
"","1.7400","1.5065","0.0074","1.5065","3.0745","3.0982"
"","1.7600","1.5234","0.0075","1.5234","3.1090","3.1234"
"","1.7800","1.5400","0.0076","1.5400","3.1429","3.1708"
"","1.8000","1.5563","0.0077","1.5563","3.1762","3.1949"
"","1.8200","1.5729","0.0077","1.5729","3.2099","3.2009"
"","1.8400","1.5896","0.0077","1.5896","3.2441","3.2067"
"","1.8600","1.6065","0.0077","1.6065","3.2786","3.2269"
"","1.8800","1.6234","0.0078","1.6234","3.3130","3.2611"
"","1.9000","1.6403","0.0079","1.6403","3.3475","3.2862"
"","1.9200","1.6571","0.0079","1.6571","3.3819","3.2948"
"","1.9400","1.6737","0.0079","1.6737","3.4157","3.2966"
"","1.9600","1.6898","0.0080","1.6898","3.4487","3.3204"
"","1.9800","1.7064","0.0081","1.7064","3.4824","3.3567"
"","2.0000","1.7234","0.0081","1.7234","3.5171","3.3817"
"","2.0200","1.7399","0.0082","1.7399","3.5508","3.3972"
"","2.0400","1.7563","0.0082","1.7563","3.5843","3.3968"
"","2.0600","1.7730","0.0082","1.7730","3.6183","3.4117"
"","2.0800","1.7897","0.0082","1.7897","3.6525","3.4310"
"","2.1000","1.8060","0.0083","1.8060","3.6857","3.4403"
"","2.1200","1.8227","0.0083","1.8227","3.7197","3.4605"
"","2.1400","1.8398","0.0083","1.8398","3.7546","3.4765"
"","2.1600","1.8567","0.0084","1.8567","3.7891","3.4976"
"","2.1800","1.8733","0.0085","1.8733","3.8231","3.5384"
"","2.2000","1.8902","0.0085","1.8902","3.8575","3.5452"
"","2.2200","1.9070","0.0085","1.9070","3.8917","3.5581"
"","2.2400","1.9231","0.0086","1.9231","3.9247","3.5824"
"","2.2600","1.9392","0.0087","1.9392","3.9575","3.6100"
"","2.2800","1.9561","0.0087","1.9561","3.9920","3.6210"
"","2.3000","1.9732","0.0087","1.9732","4.0269","3.6355"
"","2.3200","1.9898","0.0088","1.9898","4.0609","3.6712"
"","2.3400","2.0064","0.0089","2.0064","4.0946","3.6892"
"","2.3600","2.0232","0.0089","2.0232","4.1291","3.7094"
"","2.3800","2.0398","0.0090","2.0398","4.1628","3.7403"
"","2.4000","2.0563","0.0090","2.0563","4.1965","3.7509"
"","2.4200","2.0733","0.0091","2.0733","4.2312","3.7783"
"","2.4400","2.0904","0.0091","2.0904","4.2661","3.8013"
"","2.4600","2.1071","0.0092","2.1071","4.3001","3.8251"
"","2.4800","2.1235","0.0092","2.1235","4.3336","3.8371"
"","2.5000","2.1400","0.0093","2.1400","4.3673","3.8570"
"","2.5200","2.1568","0.0094","2.1568","4.4015","3.9244"
"","2.5400","2.1733","0.0094","2.1733","4.4353","3.9373"
"","2.5600","2.1898","0.0095","2.1898","4.4690","3.9477"
"","2.5800","2.2067","0.0095","2.2067","4.5035","3.9575"
"","2.6000","2.2235","0.0095","2.2235","4.5377","3.9612"
"","2.6200","2.2399","0.0096","2.2399","4.5712","3.9880"
"","2.6400","2.2563","0.0096","2.2563","4.6046","4.0153"
"","2.6600","2.2730","0.0097","2.2730","4.6389","4.0289"
"","2.6800","2.2898","0.0097","2.2898","4.6731","4.0395"
"","2.7000","2.3062","0.0097","2.3062","4.7066","4.0502"
"","2.7200","2.3230","0.0098","2.3230","4.7408","4.0719"
"","2.7400","2.3401","0.0098","2.3401","4.7757","4.1031"
"","2.7600","2.3567","0.0099","2.3567","4.8097","4.1209"
"","2.7800","2.3732","0.0099","2.3732","4.8432","4.1437"
"","2.8000","2.3897","0.0100","2.3897","4.8769","4.1635"
"","2.8200","2.4062","0.0101","2.4062","4.9106","4.1900"
"","2.8400","2.4230","0.0101","2.4230","4.9448","4.2127"
"","2.8600","2.4397","0.0101","2.4397","4.9791","4.2193"
"","2.8800","2.4567","0.0101","2.4567","5.0137","4.2260"
"","2.9000","2.4737","0.0102","2.4737","5.0484","4.2326"
"","2.9200","2.4903","0.0103","2.4903","5.0822","4.2884"
"","2.9400","2.5067","0.0104","2.5067","5.1157","4.3151"
"","2.9600","2.5232","0.0104","2.5232","5.1494","4.3306"
"","2.9800","2.5400","0.0105","2.5400","5.1836","4.3619"
"","3.0000","2.5565","0.0105","2.5565","5.2173","4.3757"
"","3.0200","2.5733","0.0105","2.5733","5.2515","4.3938"
"","3.0400","2.5903","0.0106","2.5903","5.2862","4.4096"
"","3.0600","2.6068","0.0106","2.6068","5.3200","4.4235"
"","3.0800","2.6231","0.0107","2.6231","5.3532","4.4404"
"","3.1000","2.6397","0.0107","2.6397","5.3872","4.4665"
"","3.1200","2.6566","0.0108","2.6566","5.4216","4.5133"
"","3.1400","2.6731","0.0109","2.6731","5.4554","4.5420"
"","3.1600","2.6897","0.0109","2.6897","5.4891","4.5556"
"","3.1800","2.7067","0.0109","2.7067","5.5238","4.5584"
"","3.2000","2.7234","0.0110","2.7234","5.5580","4.5764"
"","3.2200","2.7397","0.0111","2.7397","5.5913","4.6131"
"","3.2400","2.7561","0.0111","2.7561","5.6247","4.6362"
"","3.2600","2.7730","0.0112","2.7730","5.6592","4.6702"
"","3.2800","2.7901","0.0112","2.7901","5.6941","4.6829"
"","3.3000","2.8068","0.0113","2.8068","5.7281","4.7261"
"","3.3200","2.8233","0.0114","2.8233","5.7618","4.7638"
"","3.3400","2.8402","0.0114","2.8402","5.7963","4.7676"
"","3.3600","2.8566","0.0115","2.8566","5.8298","4.7843"
"","3.3800","2.8728","0.0116","2.8728","5.8628","4.8135"
"","3.4000","2.8895","0.0116","2.8895","5.8970","4.8477"
"","3.4200","2.9064","0.0117","2.9064","5.9314","4.8670"
"","3.4400","2.9231","0.0117","2.9231","5.9654","4.8832"
"","3.4600","2.9397","0.0118","2.9397","5.9994","4.9052"
"","3.4800","2.9569","0.0118","2.9569","6.0346","4.9253"
"","3.5000","2.9736","0.0119","2.9736","6.0685","4.9504"
"","3.5200","2.9899","0.0120","2.9899","6.1018","4.9807"
"","3.5400","3.0063","0.0120","3.0063","6.1353","4.9990"
"","3.5600","3.0233","0.0121","3.0233","6.1700","5.0351"
"","3.5800","3.0399","0.0121","3.0399","6.2039","5.0564"
"","3.6000","3.0565","0.0122","3.0565","6.2377","5.0660"
"","3.6200","3.0732","0.0122","3.0732","6.2719","5.0701"
"","3.6400","3.0900","0.0122","3.0900","6.3061","5.0637"
"","3.6600","3.1065","0.0121","3.1065","6.3398","5.0614"
"","3.6800","3.1229","0.0122","3.1229","6.3733","5.0836"
"","3.7000","3.1399","0.0123","3.1399","6.4080","5.1086"
"","3.7200","3.1568","0.0123","3.1568","6.4425","5.1407"
"","3.7400","3.1733","0.0124","3.1733","6.4762","5.1504"
"","3.7600","3.1899","0.0124","3.1899","6.5099","5.1684"
"","3.7800","3.2067","0.0125","3.2067","6.5444","5.1897"
"","3.8000","3.2234","0.0125","3.2234","6.5783","5.2044"
"","3.8200","3.2398","0.0126","3.2398","6.6118","5.2327"
"","3.8400","3.2564","0.0126","3.2564","6.6458","5.2494"
"","3.8600","3.2733","0.0126","3.2733","6.6803","5.2698"
"","3.8800","3.2902","0.0127","3.2902","6.7147","5.2814"
"","3.9000","3.3066","0.0127","3.3066","6.7482","5.3024"
"","3.9200","3.3231","0.0128","3.3231","6.7819","5.3374"
"","3.9400","3.3398","0.0129","3.3398","6.8159","5.3685"
"","3.9600","3.3563","0.0129","3.3563","6.8496","5.3926"
"","3.9800","3.3728","0.0130","3.3728","6.8834","5.4164"
"","4.0000","3.3900","0.0131","3.3900","6.9183","5.4412"
"","4.0200","3.4071","0.0132","3.4071","6.9532","5.4880"
"","4.0400","3.4236","0.0132","3.4236","6.9870","5.5184"
"","4.0600","3.4400","0.0134","3.4400","7.0204","5.5658"
"","4.0800","3.4568","0.0134","3.4568","7.0547","5.5852"
"","4.1000","3.4733","0.0134","3.4733","7.0884","5.5883"
"","4.1200","3.4898","0.0135","3.4898","7.1221","5.6203"
"","4.1400","3.5065","0.0135","3.5065","7.1561","5.6351"
"","4.1600","3.5235","0.0136","3.5235","7.1908","5.6630"
"","4.1800","3.5401","0.0136","3.5401","7.2248","5.6867"
"","4.2000","3.5564","0.0137","3.5564","7.2580","5.7179"
"","4.2200","3.5728","0.0138","3.5728","7.2915","5.7417"
"","4.2400","3.5896","0.0139","3.5896","7.3257","5.7710"
"","4.2600","3.6064","0.0139","3.6064","7.3599","5.8011"
"","4.2800","3.6230","0.0140","3.6230","7.3939","5.8253"
"","4.3000","3.6400","0.0140","3.6400","7.4286","5.8432"
"","4.3200","3.6569","0.0141","3.6569","7.4630","5.8770"
"","4.3400","3.6734","0.0142","3.6734","7.4968","5.9124"
"","4.3600","3.6896","0.0142","3.6896","7.5298","5.9299"
"","4.3800","3.7064","0.0143","3.7064","7.5640","5.9600"
"","4.4000","3.7234","0.0144","3.7234","7.5987","6.0070"
"","4.4200","3.7400","0.0145","3.7400","7.6327","6.0412"
"","4.4400","3.7565","0.0145","3.7565","7.6664","6.0404"
"","4.4600","3.7732","0.0145","3.7732","7.7004","6.0267"
"","4.4800","3.7901","0.0145","3.7901","7.7348","6.0420"
"","4.5000","3.8065","0.0146","3.8065","7.7683","6.0869"
"","4.5200","3.8232","0.0147","3.8232","7.8025","6.1324"
"","4.5400","3.8401","0.0148","3.8401","7.8370","6.1608"
"","4.5600","3.8569","0.0149","3.8569","7.8712","6.1884"
"","4.5800","3.8734","0.0149","3.8734","7.9049","6.2219"
"","4.6000","3.8900","0.0150","3.8900","7.9389","6.2508"
"","4.6200","3.9068","0.0151","3.9068","7.9731","6.2923"
"","4.6400","3.9231","0.0152","3.9231","8.0063","6.3154"
"","4.6600","3.9395","0.0152","3.9395","8.0398","6.3376"
"","4.6800","3.9564","0.0153","3.9564","8.0743","6.3673"
"","4.7000","3.9734","0.0153","3.9734","8.1090","6.3942"
"","4.7200","3.9899","0.0154","3.9899","8.1427","6.4275"
"","4.7400","4.0067","0.0155","4.0067","8.1769","6.4536"
"","4.7600","4.0236","0.0156","4.0236","8.2114","6.4934"
"","4.7800","4.0401","0.0157","4.0401","8.2451","6.5287"
"","4.8000","4.0563","0.0157","4.0563","8.2781","6.5517"
"","4.8200","4.0729","0.0157","4.0729","8.3121","6.5468"
"","4.8400","4.0899","0.0158","4.0899","8.3468","6.5793"
"","4.8600","4.1067","0.0159","4.1067","8.3810","6.6291"
"","4.8800","4.1232","0.0160","4.1232","8.4147","6.6658"
"","4.9000","4.1399","0.0161","4.1399","8.4487","6.7013"
"","4.9200","4.1565","0.0162","4.1565","8.4827","6.7423"
"","4.9400","4.1729","0.0163","4.1729","8.5161","6.7720"
"","4.9600","4.1892","0.0163","4.1892","8.5494","6.7996"
"","4.9800","4.2062","0.0164","4.2062","8.5841","6.8323"
"","5.0000","4.2232","0.0164","4.2232","8.6188","6.8520"
"","5.0200","4.2400","0.0165","4.2400","8.6530","6.8914"
"","5.0400","4.2566","0.0166","4.2566","8.6870","6.9275"
"","5.0600","4.2735","0.0167","4.2735","8.7214","6.9596"
"","5.0800","4.2901","0.0168","4.2901","8.7554","6.9825"
"","5.1000","4.3064","0.0168","4.3064","8.7886","7.0013"
"","5.1200","4.3232","0.0169","4.3232","8.8228","7.0375"
"","5.1400","4.3402","0.0170","4.3402","8.8575","7.0634"
"","5.1600","4.3571","0.0170","4.3571","8.8920","7.1041"
"","5.1800","4.3734","0.0171","4.3734","8.9252","7.1432"
"","5.2000","4.3900","0.0172","4.3900","8.9592","7.1757"
"","5.2200","4.4065","0.0173","4.4065","8.9929","7.2087"
"","5.2400","4.4230","0.0174","4.4230","9.0264","7.2318"
"","5.2600","4.4396","0.0174","4.4396","9.0604","7.2635"
"","5.2800","4.4565","0.0175","4.4565","9.0949","7.2820"
"","5.3000","4.4736","0.0176","4.4736","9.1298","7.3161"
"","5.3200","4.4901","0.0176","4.4901","9.1635","7.3352"
"","5.3400","4.5065","0.0176","4.5065","9.1970","7.3278"
"","5.3600","4.5232","0.0176","4.5232","9.2310","7.3525"
"","5.3800","4.5398","0.0177","4.5398","9.2649","7.3896"
"","5.4000","4.5566","0.0178","4.5566","9.2992","7.4294"
"","5.4200","4.5732","0.0179","4.5732","9.3331","7.4697"
"","5.4400","4.5902","0.0180","4.5902","9.3678","7.5055"
"","5.4600","4.6066","0.0181","4.6066","9.4013","7.5318"
"","5.4800","4.6229","0.0182","4.6229","9.4346","7.5692"
"","5.5000","4.6396","0.0182","4.6396","9.4685","7.6003"
"","5.5200","4.6566","0.0184","4.6566","9.5032","7.6537"
"","5.5400","4.6735","0.0184","4.6735","9.5377","7.6749"
"","5.5600","4.6901","0.0185","4.6901","9.5717","7.7094"
"","5.5800","4.7070","0.0186","4.7070","9.6061","7.7432"
"","5.6000","4.7236","0.0187","4.7236","9.6401","7.7827"
"","5.6200","4.7400","0.0188","4.7400","9.6736","7.8355"
"","5.6400","4.7565","0.0188","4.7565","9.7071","7.8535"
"","5.6600","4.7731","0.0189","4.7731","9.7410","7.8727"
"","5.6800","4.7900","0.0189","4.7900","9.7755","7.8933"
"","5.7000","4.8066","0.0190","4.8066","9.8095","7.9291"
"","5.7200","4.8233","0.0191","4.8233","9.8434","7.9704"
"","5.7400","4.8400","0.0192","4.8400","9.8776","8.0088"
"","5.7600","4.8566","0.0193","4.8566","9.9114","8.0443"
"","5.7800","4.8727","0.0194","4.8727","9.9444","8.0727"
"","5.8000","4.8895","0.0195","4.8895","9.9786","8.1063"
"","5.8200","4.9066","0.0196","4.9066","10.0135","8.1488"
"","5.8400","4.9232","0.0196","4.9232","10.0472","8.1800"
"","5.8600","4.9398","0.0197","4.9398","10.0812","8.2172"
"","5.8800","4.9568","0.0198","4.9568","10.1159","8.2670"
"","5.9000","4.9736","0.0199","4.9736","10.1501","8.3049"
"","5.9200","4.9897","0.0200","4.9897","10.1831","8.3370"
"","5.9400","5.0061","0.0201","5.0061","10.2166","8.3600"
"","5.9600","5.0230","0.0202","5.0230","10.2511","8.3975"
"","5.9800","5.0399","0.0204","5.0399","10.2855","8.4847"
"","6.0000","5.0564","0.0204","5.0564","10.3193","8.5206"
"","6.0200","5.0732","0.0205","5.0732","10.3535","8.5401"
"","6.0400","5.0901","0.0205","5.0901","10.3879","8.5519"
"","6.0600","5.1066","0.0206","5.1066","10.4217","8.5722"
"","6.0800","5.1230","0.0206","5.1230","10.4551","8.5921"
"","6.1000","5.1399","0.0207","5.1399","10.4896","8.6240"
"","6.1200","5.1569","0.0208","5.1569","10.5243","8.6654"
"","6.1400","5.1734","0.0208","5.1734","10.5580","8.6735"
"","6.1600","5.1900","0.0209","5.1900","10.5918","8.7033"
"","6.1800","5.2067","0.0210","5.2067","10.6260","8.7506"
"","6.2000","5.2232","0.0211","5.2232","10.6597","8.7847"
"","6.2200","5.2395","0.0212","5.2395","10.6929","8.8167"
"","6.2400","5.2562","0.0212","5.2562","10.7269","8.8388"
"","6.2600","5.2732","0.0213","5.2732","10.7616","8.8873"
"","6.2800","5.2901","0.0214","5.2901","10.7961","8.9215"
"","6.3000","5.3066","0.0215","5.3066","10.8298","8.9536"
"","6.3200","5.3232","0.0216","5.3232","10.8638","8.9959"
"","6.3400","5.3400","0.0217","5.3400","10.8980","9.0226"
"","6.3600","5.3564","0.0218","5.3564","10.9315","9.0841"
"","6.3800","5.3728","0.0219","5.3728","10.9650","9.1170"
"","6.4000","5.3897","0.0219","5.3897","10.9994","9.1415"
"","6.4200","5.4067","0.0220","5.4067","11.0341","9.1779"
"","6.4400","5.4235","0.0221","5.4235","11.0683","9.1952"
"","6.4600","5.4400","0.0222","5.4400","11.1020","9.2298"
"","6.4800","5.4565","0.0223","5.4565","11.1358","9.2725"
"","6.5000","5.4732","0.0223","5.4732","11.1697","9.2992"
"","6.5200","5.4895","0.0224","5.4895","11.2030","9.3247"
"","6.5400","5.5062","0.0225","5.5062","11.2372","9.3550"
"","6.5600","5.5231","0.0225","5.5231","11.2717","9.3899"
"","6.5800","5.5401","0.0227","5.5401","11.3063","9.4377"
"","6.6000","5.5565","0.0227","5.5565","11.3398","9.4584"
"","6.6200","5.5730","0.0228","5.5730","11.3736","9.4963"
"","6.6400","5.5899","0.0229","5.5899","11.4080","9.5234"
"","6.6600","5.6066","0.0230","5.6066","11.4420","9.5686"
"","6.6800","5.6231","0.0231","5.6231","11.4757","9.6065"
"","6.7000","5.6399","0.0231","5.6399","11.5099","9.6328"
"","6.7200","5.6571","0.0232","5.6571","11.5451","9.6778"
"","6.7400","5.6736","0.0233","5.6736","11.5788","9.7029"
"","6.7600","5.6900","0.0234","5.6900","11.6123","9.7563"
"","6.7800","5.7065","0.0235","5.7065","11.6458","9.7936"
"","6.8000","5.7230","0.0236","5.7230","11.6795","9.8239"
"","6.8200","5.7396","0.0237","5.7396","11.7135","9.8585"
"","6.8400","5.7564","0.0237","5.7564","11.7477","9.8938"
"","6.8600","5.7735","0.0238","5.7735","11.7827","9.9363"
"","6.8800","5.7902","0.0239","5.7902","11.8166","9.9627"
"","6.9000","5.8064","0.0240","5.8064","11.8499","9.9955"
"","6.9200","5.8231","0.0241","5.8231","11.8839","10.0469"
"","6.9400","5.8400","0.0242","5.8400","11.9183","10.0855"
"","6.9600","5.8566","0.0243","5.8566","11.9523","10.1148"
"","6.9800","5.8733","0.0244","5.8733","11.9862","10.1573"
"","7.0000","5.8900","0.0244","5.8900","12.0205","10.1823"
"","7.0200","5.9068","0.0245","5.9068","12.0547","10.2140"
"","7.0400","5.9233","0.0246","5.9233","12.0884","10.2468"
"","7.0600","5.9395","0.0247","5.9395","12.1214","10.2793"
"","7.0800","5.9563","0.0248","5.9563","12.1556","10.3225"
"","7.1000","5.9733","0.0248","5.9733","12.1903","10.3462"
"","7.1200","5.9900","0.0249","5.9900","12.2245","10.3808"
"","7.1400","6.0067","0.0250","6.0067","12.2585","10.4113"
"","7.1600","6.0234","0.0252","6.0234","12.2927","10.4831"
"","7.1800","6.0402","0.0253","6.0402","12.3269","10.5394"
"","7.2000","6.0564","0.0254","6.0564","12.3599","10.5711"
"","7.2200","6.0729","0.0254","6.0729","12.3937","10.5993"
"","7.2400","6.0898","0.0255","6.0898","12.4281","10.6200"
"","7.2600","6.1067","0.0255","6.1067","12.4626","10.6379"
"","7.2800","6.1233","0.0256","6.1233","12.4965","10.6676"
"","7.3000","6.1401","0.0257","6.1401","12.5308","10.6997"
"","7.3200","6.1568","0.0258","6.1568","12.5650","10.7486"
"","7.3400","6.1731","0.0258","6.1731","12.5982","10.7627"
"","7.3600","6.1895","0.0259","6.1895","12.6317","10.7844"
"","7.3800","6.2064","0.0260","6.2064","12.6662","10.8214"
"","7.4000","6.2234","0.0260","6.2234","12.7008","10.8532"
"","7.4200","6.2399","0.0261","6.2399","12.7346","10.8872"
"","7.4400","6.2566","0.0262","6.2566","12.7686","10.9291"
"","7.4600","6.2735","0.0264","6.2735","12.8030","10.9849"
"","7.4800","6.2900","0.0264","6.2900","12.8367","11.0048"
"","7.5000","6.3064","0.0265","6.3064","12.8702","11.0340"
"","7.5200","6.3231","0.0267","6.3231","12.9042","11.1206"
"","7.5400","6.3401","0.0267","6.3401","12.9389","11.1357"
"","7.5600","6.3569","0.0268","6.3569","12.9733","11.1572"
"","7.5800","6.3733","0.0269","6.3733","13.0068","11.1926"
"","7.6000","6.3899","0.0270","6.3899","13.0406","11.2375"
"","7.6200","6.4064","0.0271","6.4064","13.0743","11.2763"
"","7.6400","6.4228","0.0271","6.4228","13.1078","11.2807"
"","7.6600","6.4396","0.0271","6.4396","13.1420","11.2980"
"","7.6800","6.4566","0.0272","6.4566","13.1767","11.3359"
"","7.7000","6.4735","0.0273","6.4735","13.2111","11.3845"
"","7.7200","6.4900","0.0274","6.4900","13.2449","11.4067"
"","7.7400","6.5065","0.0274","6.5065","13.2786","11.4322"
"","7.7600","6.5232","0.0276","6.5232","13.3126","11.4798"
"","7.7800","6.5397","0.0277","6.5397","13.3463","11.5317"
"","7.8000","6.5562","0.0277","6.5562","13.3800","11.5578"
"","7.8200","6.5730","0.0278","6.5730","13.4142","11.5703"
"","7.8400","6.5901","0.0278","6.5901","13.4492","11.5802"
"","7.8600","6.6069","0.0279","6.6069","13.4834","11.6086"
"","7.8800","6.6233","0.0280","6.6233","13.5169","11.6548"
"","7.9000","6.6398","0.0281","6.6398","13.5506","11.7154"
"","7.9200","6.6566","0.0282","6.6566","13.5848","11.7507"
"","7.9400","6.6732","0.0282","6.6732","13.6188","11.7686"
"","7.9600","6.6897","0.0283","6.6897","13.6525","11.8116"
"","7.9800","6.7066","0.0285","6.7066","13.6870","11.8636"
"","8.0000","6.7236","0.0286","6.7236","13.7217","11.8977"
"","8.0200","6.7401","0.0286","6.7401","13.7554","11.9233"
"","8.0400","6.7563","0.0287","6.7563","13.7884","11.9505"
"","8.0600","6.7728","0.0288","6.7728","13.8221","11.9828"
"","8.0800","6.7895","0.0289","6.7895","13.8561","12.0225"
"","8.1000","6.8060","0.0289","6.8060","13.8898","12.0568"
"","8.1200","6.8230","0.0290","6.8230","13.9245","12.1023"
"","8.1400","6.8400","0.0291","6.8400","13.9592","12.1395"
"","8.1600","6.8567","0.0292","6.8567","13.9932","12.1755"
"","8.1800","6.8731","0.0293","6.8731","14.0267","12.1933"
"","8.2000","6.8896","0.0293","6.8896","14.0604","12.2146"
"","8.2200","6.9065","0.0294","6.9065","14.0949","12.2537"
"","8.2400","6.9231","0.0295","6.9231","14.1288","12.3010"
"","8.2600","6.9398","0.0296","6.9398","14.1628","12.3456"
"","8.2800","6.9568","0.0297","6.9568","14.1975","12.3875"
"","8.3000","6.9735","0.0298","6.9735","14.2317","12.4061"
"","8.3200","6.9898","0.0298","6.9898","14.2650","12.4229"
"","8.3400","7.0062","0.0299","7.0062","14.2985","12.4449"
"","8.3600","7.0230","0.0300","7.0230","14.3327","12.4900"
"","8.3800","7.0398","0.0301","7.0398","14.3669","12.5450"
"","8.4000","7.0564","0.0302","7.0564","14.4008","12.5814"
"","8.4200","7.0732","0.0303","7.0732","14.4351","12.6104"
"","8.4400","7.0901","0.0303","7.0901","14.4695","12.6271"
"","8.4600","7.1065","0.0304","7.1065","14.5030","12.6553"
"","8.4800","7.1226","0.0305","7.1226","14.5360","12.6979"
"","8.5000","7.1394","0.0306","7.1394","14.5702","12.7347"
"","8.5200","7.1564","0.0306","7.1564","14.6049","12.7640"
"","8.5400","7.1731","0.0307","7.1731","14.6389","12.7922"
"","8.5600","7.1897","0.0308","7.1897","14.6729","12.8143"
"","8.5800","7.2067","0.0307","7.2067","14.7076","12.8101"
"","8.6000","7.2233","0.0308","7.2233","14.7415","12.8248"
"","8.6200","7.2396","0.0308","7.2396","14.7748","12.8515"
"","8.6400","7.2563","0.0309","7.2563","14.8087","12.8611"
"","8.6600","7.2733","0.0310","7.2733","14.8434","12.8976"
"","8.6800","7.2903","0.0311","7.2903","14.8781","12.9626"
"","8.7000","7.3068","0.0311","7.3068","14.9119","12.9684"
"","8.7200","7.3236","0.0312","7.3236","14.9461","12.9853"
"","8.7400","7.3405","0.0312","7.3405","14.9805","12.9884"
"","8.7600","7.3565","0.0312","7.3565","15.0133","12.9925"
"","8.7800","7.3728","0.0313","7.3728","15.0465","13.0320"
"","8.8000","7.3897","0.0313","7.3897","15.0810","13.0550"
"","8.8200","7.4067","0.0314","7.4067","15.1157","13.0748"
"","8.8400","7.4233","0.0314","7.4233","15.1497","13.0870"
"","8.8600","7.4399","0.0315","7.4399","15.1834","13.1223"
"","8.8800","7.4566","0.0316","7.4566","15.2176","13.1656"
"","8.9000","7.4730","0.0317","7.4730","15.2511","13.2024"
"","8.9200","7.4896","0.0318","7.4896","15.2848","13.2348"
"","8.9400","7.5064","0.0318","7.5064","15.3193","13.2555"
"","8.9600","7.5234","0.0319","7.5234","15.3540","13.2955"
"","8.9800","7.5403","0.0320","7.5403","15.3884","13.3297"
"","9.0000","7.5567","0.0321","7.5567","15.4219","13.3670"
"","9.0200","7.5733","0.0321","7.5733","15.4556","13.3858"
"","9.0400","7.5900","0.0322","7.5900","15.4899","13.4076"
"","9.0600","7.6064","0.0324","7.6064","15.5233","13.4924"
"","9.0800","7.6230","0.0324","7.6230","15.5571","13.5130"
"","9.1000","7.6400","0.0325","7.6400","15.5918","13.5313"
"","9.1200","7.6568","0.0325","7.6568","15.6262","13.5530"
"","9.1400","7.6734","0.0326","7.6734","15.6599","13.5627"
"","9.1600","7.6898","0.0326","7.6898","15.6934","13.5934"
"","9.1800","7.7064","0.0327","7.7064","15.7274","13.6332"
"","9.2000","7.7230","0.0328","7.7230","15.7611","13.6674"
"","9.2200","7.7395","0.0329","7.7395","15.7949","13.6919"
"","9.2400","7.7564","0.0329","7.7564","15.8293","13.7066"
"","9.2600","7.7734","0.0330","7.7734","15.8640","13.7389"
"","9.2800","7.7900","0.0331","7.7900","15.8980","13.7815"
"","9.3000","7.8064","0.0331","7.8064","15.9315","13.8032"
"","9.3200","7.8231","0.0332","7.8231","15.9654","13.8385"
"","9.3400","7.8398","0.0333","7.8398","15.9997","13.8671"
"","9.3600","7.8566","0.0334","7.8566","16.0339","13.9008"
"","9.3800","7.8732","0.0335","7.8732","16.0678","13.9507"
"","9.4000","7.8902","0.0335","7.8902","16.1025","13.9660"
"","9.4200","7.9071","0.0336","7.9071","16.1370","14.0008"
"","9.4400","7.9235","0.0336","7.9235","16.1705","14.0163"
"","9.4600","7.9397","0.0337","7.9397","16.2035","14.0620"
"","9.4800","7.9564","0.0338","7.9564","16.2375","14.0798"
"","9.5000","7.9732","0.0338","7.9732","16.2719","14.0726"
"","9.5200","7.9898","0.0338","7.9898","16.3056","14.0910"
"","9.5400","8.0064","0.0339","8.0064","16.3396","14.1055"
"","9.5600","8.0233","0.0339","8.0233","16.3741","14.1378"
"","9.5800","8.0399","0.0340","8.0399","16.4080","14.1717"
"","9.6000","8.0565","0.0341","8.0565","16.4418","14.2003"
"","9.6200","8.0729","0.0341","8.0729","16.4753","14.2260"
"","9.6400","8.0896","0.0342","8.0896","16.5095","14.2448"
"","9.6600","8.1065","0.0342","8.1065","16.5439","14.2662"
"","9.6800","8.1233","0.0343","8.1233","16.5781","14.2815"
"","9.7000","8.1402","0.0343","8.1402","16.6126","14.3016"
"","9.7200","8.1570","0.0344","8.1570","16.6470","14.3375"
"","9.7400","8.1732","0.0345","8.1732","16.6800","14.3655"
"","9.7600","8.1894","0.0345","8.1894","16.7130","14.3900"
"","9.7800","8.2063","0.0346","8.2063","16.7475","14.4198"
"","9.8000","8.2233","0.0346","8.2233","16.7822","14.4371"
"","9.8200","8.2400","0.0347","8.2400","16.8164","14.4609"
"","9.8400","8.2567","0.0348","8.2567","16.8504","14.4989"
"","9.8600","8.2734","0.0349","8.2734","16.8846","14.5422"
"","9.8800","8.2897","0.0350","8.2897","16.9178","14.5747"
"","9.9000","8.3059","0.0350","8.3059","16.9508","14.5993"
"","9.9200","8.3227","0.0351","8.3227","16.9851","14.6240"
"","9.9400","8.3399","0.0352","8.3399","17.0202","14.6496"
"","9.9600","8.3567","0.0352","8.3567","17.0544","14.6826"
"","9.9800","8.3734","0.0353","8.3734","17.0887","14.7097"
"","10.0000","8.3902","0.0354","8.3902","17.1229","14.7314"
"","10.0200","8.4069","0.0354","8.4069","17.1568","14.7551"
"","10.0400","8.4230","0.0355","8.4230","17.1899","14.7806"
"","10.0600","8.4396","0.0356","8.4396","17.2236","14.8145"
"","10.0800","8.4567","0.0356","8.4567","17.2585","14.8383"
"","10.1000","8.4736","0.0356","8.4736","17.2930","14.8384"
"","10.1200","8.4901","0.0357","8.4901","17.3267","14.8620"
"","10.1400","8.5067","0.0357","8.5067","17.3607","14.8893"
"","10.1600","8.5235","0.0358","8.5235","17.3949","14.9160"
"","10.1800","8.5398","0.0359","8.5398","17.4281","14.9629"
"","10.2000","8.5563","0.0359","8.5563","17.4619","14.9715"
"","10.2200","8.5730","0.0359","8.5730","17.4958","14.9682"
"","10.2400","8.5900","0.0360","8.5900","17.5305","15.0058"
"","10.2600","8.6066","0.0361","8.6066","17.5645","15.0521"
"","10.2800","8.6232","0.0362","8.6232","17.5985","15.0811"
"","10.3000","8.6400","0.0362","8.6400","17.6327","15.0938"
"","10.3200","8.6565","0.0363","8.6565","17.6664","15.1220"
"","10.3400","8.6731","0.0364","8.6731","17.7001","15.1501"
"","10.3600","8.6897","0.0364","8.6897","17.7341","15.1729"
"","10.3800","8.7067","0.0365","8.7067","17.7688","15.2012"
"","10.4000","8.7236","0.0366","8.7236","17.8033","15.2294"
"","10.4200","8.7401","0.0366","8.7401","17.8370","15.2601"
"","10.4400","8.7567","0.0367","8.7567","17.8707","15.2901"
"","10.4600","8.7733","0.0368","8.7733","17.9047","15.3173"
"","10.4800","8.7898","0.0368","8.7898","17.9384","15.3212"
"","10.5000","8.8065","0.0368","8.8065","17.9724","15.3359"
"","10.5200","8.8232","0.0369","8.8232","18.0066","15.3613"
"","10.5400","8.8401","0.0369","8.8401","18.0411","15.3862"
"","10.5600","8.8565","0.0370","8.8565","18.0745","15.4031"
"","10.5800","8.8729","0.0371","8.8729","18.1080","15.4398"
"","10.6000","8.8896","0.0371","8.8896","18.1420","15.4465"
"","10.6200","8.9065","0.0372","8.9065","18.1765","15.4949"
"","10.6400","8.9231","0.0372","8.9231","18.2104","15.5202"
"","10.6600","8.9399","0.0373","8.9399","18.2446","15.5559"
"","10.6800","8.9568","0.0374","8.9568","18.2791","15.5754"
"","10.7000","8.9735","0.0374","8.9735","18.3133","15.5834"
"","10.7200","8.9899","0.0374","8.9899","18.3468","15.5956"
"","10.7400","9.0063","0.0374","9.0063","18.3803","15.5986"
"","10.7600","9.0232","0.0375","9.0232","18.4147","15.6237"
"","10.7800","9.0399","0.0375","9.0399","18.4487","15.6401"
"","10.8000","9.0565","0.0376","9.0565","18.4827","15.6557"
"","10.8200","9.0734","0.0377","9.0734","18.5171","15.6896"
"","10.8400","9.0902","0.0377","9.0902","18.5513","15.6956"
"","10.8600","9.1066","0.0377","9.1066","18.5848","15.7231"
"","10.8800","9.1230","0.0378","9.1230","18.6183","15.7628"
"","10.9000","9.1396","0.0379","9.1396","18.6523","15.7904"
"","10.9200","9.1566","0.0379","9.1566","18.6870","15.8041"
"","10.9400","9.1734","0.0380","9.1734","18.7212","15.8174"
"","10.9600","9.1900","0.0380","9.1900","18.7552","15.8501"
"","10.9800","9.2068","0.0382","9.2068","18.7894","15.9185"
"","11.0000","9.2233","0.0383","9.2233","18.8231","15.9511"
"","11.0200","9.2395","0.0383","9.2395","18.8561","15.9530"
"","11.0400","9.2560","0.0383","9.2560","18.8898","15.9534"
"","11.0600","9.2730","0.0384","9.2730","18.9245","15.9816"
"","11.0800","9.2900","0.0384","9.2900","18.9592","15.9950"
"","11.1000","9.3066","0.0384","9.3066","18.9930","16.0052"
"","11.1200","9.3234","0.0385","9.3234","19.0274","16.0442"
"","11.1400","9.3402","0.0386","9.3402","19.0616","16.0798"
"","11.1600","9.3564","0.0387","9.3564","19.0946","16.1063"
"","11.1800","9.3728","0.0387","9.3728","19.1281","16.1161"
"","11.2000","9.3898","0.0387","9.3898","19.1628","16.1260"
"","11.2200","9.4067","0.0388","9.4067","19.1973","16.1478"
"","11.2400","9.4233","0.0388","9.4233","19.2312","16.1630"
"","11.2600","9.4400","0.0389","9.4400","19.2652","16.1936"
"","11.2800","9.4568","0.0389","9.4568","19.2997","16.2233"
"","11.3000","9.4735","0.0390","9.4735","19.3336","16.2361"
"","11.3200","9.4898","0.0390","9.4898","19.3669","16.2573"
"","11.3400","9.5063","0.0391","9.5063","19.4006","16.2774"
"","11.3600","9.5233","0.0391","9.5233","19.4353","16.2994"
"","11.3800","9.5399","0.0392","9.5399","19.4693","16.3159"
"","11.4000","9.5565","0.0392","9.5565","19.5030","16.3419"
"","11.4200","9.5732","0.0393","9.5732","19.5372","16.3699"
"","11.4400","9.5900","0.0393","9.5900","19.5714","16.3931"
"","11.4600","9.6063","0.0394","9.6063","19.6047","16.4075"
"","11.4800","9.6228","0.0394","9.6228","19.6384","16.4249"
"","11.5000","9.6398","0.0394","9.6398","19.6731","16.4373"
"","11.5200","9.6568","0.0395","9.6568","19.7078","16.4532"
"","11.5400","9.6736","0.0395","9.6736","19.7420","16.4694"
"","11.5600","9.6900","0.0396","9.6900","19.7755","16.4947"
"","11.5800","9.7065","0.0396","9.7065","19.8092","16.5143"
"","11.6000","9.7231","0.0396","9.7231","19.8430","16.5200"
"","11.6200","9.7396","0.0397","9.7396","19.8767","16.5244"
"","11.6400","9.7565","0.0396","9.7565","19.9112","16.5131"
"","11.6600","9.7735","0.0397","9.7735","19.9458","16.5340"
"","11.6800","9.7902","0.0398","9.7902","19.9801","16.5637"
"","11.7000","9.8066","0.0398","9.8066","20.0135","16.5750"
"","11.7200","9.8232","0.0398","9.8232","20.0473","16.6006"
"","11.7400","9.8397","0.0399","9.8397","20.0810","16.6126"
"","11.7600","9.8563","0.0399","9.8563","20.1150","16.6088"
"","11.7800","9.8730","0.0399","9.8730","20.1489","16.6307"
"","11.8000","9.8900","0.0400","9.8900","20.1836","16.6574"
"","11.8200","9.9070","0.0400","9.9070","20.2183","16.6663"
"","11.8400","9.9234","0.0400","9.9234","20.2518","16.6569"
"","11.8600","9.9397","0.0400","9.9397","20.2851","16.6757"
"","11.8800","9.9563","0.0401","9.9563","20.3190","16.6936"
"","11.9000","9.9731","0.0401","9.9731","20.3533","16.7149"
"","11.9200","9.9899","0.0402","9.9899","20.3875","16.7429"
"","11.9400","10.0066","0.0402","10.0066","20.4217","16.7579"
"","11.9600","10.0235","0.0403","10.0235","20.4561","16.7850"
"","11.9800","10.0403","0.0404","10.0403","20.4903","16.8257"
"","12.0000","10.0567","0.0404","10.0567","20.5238","16.8413"
"","12.0200","10.0730","0.0405","10.0730","20.5571","16.8590"
"","12.0400","10.0899","0.0405","10.0899","20.5915","16.8773"
"","12.0600","10.1067","0.0405","10.1067","20.6260","16.8761"
"","12.0800","10.1233","0.0405","10.1233","20.6597","16.8716"
"","12.1000","10.1401","0.0405","10.1401","20.6942","16.8916"
"","12.1200","10.1568","0.0405","10.1568","20.7281","16.8870"
"","12.1400","10.1733","0.0405","10.1733","20.7619","16.8758"
"","12.1600","10.1897","0.0406","10.1897","20.7954","16.9211"
"","12.1800","10.2065","0.0406","10.2065","20.8296","16.9355"
"","12.2000","10.2234","0.0406","10.2234","20.8640","16.9365"
"","12.2200","10.2400","0.0407","10.2400","20.8980","16.9621"
"","12.2400","10.2567","0.0408","10.2567","20.9320","16.9817"
"","12.2600","10.2735","0.0408","10.2735","20.9664","16.9968"
"","12.2800","10.2901","0.0408","10.2901","21.0002","17.0081"
"","12.3000","10.3064","0.0408","10.3064","21.0334","17.0142"
"","12.3200","10.3229","0.0409","10.3229","21.0671","17.0314"
"","12.3400","10.3399","0.0409","10.3399","21.1018","17.0431"
"","12.3600","10.3569","0.0410","10.3569","21.1365","17.0769"
"","12.3800","10.3733","0.0410","10.3733","21.1700","17.1008"
"","12.4000","10.3899","0.0411","10.3899","21.2040","17.1256"
"","12.4200","10.4067","0.0411","10.4067","21.2382","17.1434"
"","12.4400","10.4231","0.0412","10.4231","21.2717","17.1537"
"","12.4600","10.4394","0.0412","10.4394","21.3049","17.1768"
"","12.4800","10.4563","0.0413","10.4563","21.3394","17.1917"
"","12.5000","10.4733","0.0413","10.4733","21.3741","17.2058"
"","12.5200","10.4898","0.0413","10.4898","21.4078","17.2061"
"","12.5400","10.5064","0.0414","10.5064","21.4415","17.2299"
"","12.5600","10.5231","0.0414","10.5231","21.4757","17.2464"
"","12.5800","10.5395","0.0415","10.5395","21.5092","17.2716"
"","12.6000","10.5561","0.0415","10.5561","21.5430","17.3007"
"","12.6200","10.5728","0.0416","10.5728","21.5772","17.3238"
"","12.6400","10.5898","0.0416","10.5898","21.6119","17.3348"
"","12.6600","10.6067","0.0416","10.6067","21.6463","17.3531"
"","12.6800","10.6233","0.0417","10.6233","21.6803","17.3884"
"","12.7000","10.6399","0.0418","10.6399","21.7140","17.4076"
"","12.7200","10.6564","0.0418","10.6564","21.7478","17.4255"
"","12.7400","10.6729","0.0418","10.6729","21.7815","17.4318"
"","12.7600","10.6896","0.0419","10.6896","21.8155","17.4603"
"","12.7800","10.7063","0.0420","10.7063","21.8497","17.4808"
"","12.8000","10.7233","0.0420","10.7233","21.8844","17.4867"
"","12.8200","10.7399","0.0420","10.7399","21.9181","17.5019"
"","12.8400","10.7564","0.0420","10.7564","21.9518","17.5095"
"","12.8600","10.7730","0.0420","10.7730","21.9858","17.5152"
"","12.8800","10.7896","0.0421","10.7896","22.0195","17.5320"
"","12.9000","10.8063","0.0422","10.8063","22.0537","17.5687"
"","12.9200","10.8233","0.0422","10.8233","22.0884","17.5952"
"","12.9400","10.8402","0.0422","10.8402","22.1229","17.5953"
"","12.9600","10.8569","0.0422","10.8569","22.1569","17.5970"
"","12.9800","10.8734","0.0423","10.8734","22.1906","17.6196"
"","13.0000","10.8900","0.0423","10.8900","22.2246","17.6396"
"","13.0200","10.9066","0.0424","10.9066","22.2583","17.6530"
"","13.0400","10.9232","0.0424","10.9232","22.2923","17.6649"
"","13.0600","10.9399","0.0425","10.9399","22.3262","17.6906"
"","13.0800","10.9566","0.0425","10.9566","22.3604","17.7084"
"","13.1000","10.9734","0.0425","10.9734","22.3947","17.7220"
"","13.1200","10.9900","0.0426","10.9900","22.4286","17.7388"
"","13.1400","11.0064","0.0426","11.0064","22.4621","17.7584"
"","13.1600","11.0231","0.0427","11.0231","22.4961","17.7765"
"","13.1800","11.0398","0.0427","11.0398","22.5303","17.7942"
"","13.2000","11.0565","0.0427","11.0565","22.5643","17.8096"
"","13.2200","11.0734","0.0428","11.0734","22.5987","17.8431"
"","13.2400","11.0903","0.0427","11.0903","22.6332","17.8056"
"","13.2600","11.1068","0.0422","11.1068","22.6669","17.5753"
"","13.2800","11.1233","0.0413","11.1233","22.7006","17.2088"
"","13.3000","11.1398","0.0407","11.1398","22.7344","16.9404"
"","13.3200","11.1566","0.0405","11.1566","22.7686","16.8683"
"","13.3400","11.1732","0.0405","11.1732","22.8025","16.8726"
"","13.3600","11.1899","0.0406","11.1899","22.8365","16.9107"
"","13.3800","11.2069","0.0407","11.2069","22.8712","16.9402"
"","13.4000","11.2235","0.0404","11.2235","22.9052","16.8381"
"","13.4200","11.2398","0.0398","11.2398","22.9384","16.5982"
"","13.4400","11.2561","0.0396","11.2561","22.9717","16.4850"
"","13.4600","11.2728","0.0395","11.2728","23.0057","16.4677"
"","13.4800","11.2897","0.0396","11.2897","23.0401","16.4868"
"","13.5000","11.3064","0.0396","11.3064","23.0743","16.5059"
"","13.5200","11.3232","0.0396","11.3232","23.1085","16.5191"
"","13.5400","11.3401","0.0397","11.3401","23.1430","16.5289"
"","13.5600","11.3566","0.0397","11.3566","23.1767","16.5438"
"","13.5800","11.3730","0.0398","11.3730","23.2102","16.5684"
"","13.6000","11.3898","0.0398","11.3898","23.2444","16.5736"
"","13.6200","11.4066","0.0398","11.4066","23.2789","16.5883"
"","13.6400","11.4234","0.0398","11.4234","23.3131","16.5933"
"","13.6600","11.4399","0.0399","11.4399","23.3468","16.6315"
"","13.6800","11.4568","0.0400","11.4568","23.3813","16.6702"
"","13.7000","11.4733","0.0400","11.4733","23.4150","16.6580"
"","13.7200","11.4898","0.0400","11.4898","23.4485","16.6516"
"","13.7400","11.5063","0.0400","11.5063","23.4822","16.6531"
"","13.7600","11.5232","0.0400","11.5232","23.5167","16.6834"
"","13.7800","11.5398","0.0401","11.5398","23.5506","16.7035"
"","13.8000","11.5565","0.0401","11.5565","23.5846","16.7153"
"","13.8200","11.5732","0.0402","11.5732","23.6188","16.7311"
"","13.8400","11.5899","0.0402","11.5899","23.6528","16.7383"
"","13.8600","11.6063","0.0402","11.6063","23.6863","16.7594"
"","13.8800","11.6228","0.0403","11.6228","23.7200","16.7941"
"","13.9000","11.6397","0.0403","11.6397","23.7545","16.8097"
"","13.9200","11.6567","0.0404","11.6567","23.7892","16.8190"
"","13.9400","11.6734","0.0404","11.6734","23.8234","16.8204"
"","13.9600","11.6901","0.0404","11.6901","23.8573","16.8384"
"","13.9800","11.7066","0.0404","11.7066","23.8911","16.8319"
"","14.0000","11.7232","0.0397","11.7232","23.9248","16.5531"
"","14.0200","11.7397","0.0387","11.7397","23.9585","16.1324"
"","14.0400","11.7563","0.0377","11.7563","23.9925","15.7174"
"","14.0600","11.7734","0.0368","11.7734","24.0274","15.3242"
"","14.0800","11.7902","0.0359","11.7902","24.0616","14.9575"
"","14.1000","11.8066","0.0355","11.8066","24.0951","14.7863"
"","14.1200","11.8231","0.0353","11.8231","24.1289","14.7047"
"","14.1400","11.8398","0.0346","11.8398","24.1628","14.4118"
"","14.1600","11.8563","0.0342","11.8563","24.1966","14.2408"
"","14.1800","11.8728","0.0341","11.8728","24.2303","14.1917"
"","14.2000","11.8897","0.0341","11.8897","24.2647","14.1961"
"","14.2200","11.9067","0.0341","11.9067","24.2994","14.2285"
"","14.2400","11.9235","0.0342","11.9235","24.3337","14.2413"
"","14.2600","11.9398","0.0342","11.9398","24.3669","14.2706"
"","14.2800","11.9563","0.0343","11.9563","24.4006","14.2798"
"","14.3000","11.9730","0.0343","11.9730","24.4346","14.2813"
"","14.3200","11.9897","0.0343","11.9897","24.4688","14.3029"
"","14.3400","12.0064","0.0344","12.0064","24.5028","14.3249"
"","14.3600","12.0235","0.0344","12.0235","24.5377","14.3381"
"","14.3800","12.0404","0.0345","12.0404","24.5722","14.3566"
"","14.4000","12.0567","0.0345","12.0567","24.6054","14.3704"
"","14.4200","12.0732","0.0345","12.0732","24.6392","14.3883"
"","14.4400","12.0899","0.0346","12.0899","24.6734","14.4052"
"","14.4600","12.1067","0.0346","12.1067","24.7076","14.4212"
"","14.4800","12.1232","0.0346","12.1232","24.7413","14.4193"
"","14.5000","12.1401","0.0339","12.1401","24.7758","14.1200"
"","14.5200","12.1569","0.0334","12.1569","24.8100","13.9106"
"","14.5400","12.1734","0.0333","12.1734","24.8437","13.8641"
"","14.5600","12.1897","0.0333","12.1897","24.8770","13.8738"
"","14.5800","12.2062","0.0333","12.2062","24.9107","13.8941"
"","14.6000","12.2231","0.0333","12.2231","24.9451","13.8839"
"","14.6200","12.2399","0.0327","12.2399","24.9793","13.6146"
"","14.6400","12.2568","0.0322","12.2568","25.0138","13.4236"
"","14.6600","12.2735","0.0321","12.2735","25.0480","13.3775"
"","14.6800","12.2902","0.0321","12.2902","25.0820","13.3928"
"","14.7000","12.3066","0.0322","12.3066","25.1155","13.4181"
"","14.7200","12.3230","0.0323","12.3230","25.1490","13.4380"
"","14.7400","12.3399","0.0322","12.3399","25.1834","13.4352"
"","14.7600","12.3568","0.0322","12.3568","25.2179","13.4326"
"","14.7800","12.3732","0.0323","12.3732","25.2514","13.4468"
"","14.8000","12.3898","0.0323","12.3898","25.2853","13.4432"
"","14.8200","12.4067","0.0324","12.4067","25.3198","13.4883"
"","14.8400","12.4231","0.0324","12.4231","25.3533","13.4937"
"","14.8600","12.4393","0.0324","12.4393","25.3863","13.4905"
"","14.8800","12.4562","0.0324","12.4562","25.4207","13.5037"
"","14.9000","12.4730","0.0324","12.4730","25.4552","13.4922"
"","14.9200","12.4897","0.0317","12.4897","25.4892","13.1928"
"","14.9400","12.5066","0.0312","12.5066","25.5236","12.9846"
"","14.9600","12.5234","0.0311","12.5234","25.5581","12.9375"
"","14.9800","12.5400","0.0311","12.5400","25.5918","12.9718"
"","15.0000","12.5562","0.0312","12.5562","25.6248","12.9968"
"","15.0200","12.5729","0.0312","12.5729","25.6590","13.0133"
"","15.0400","12.5900","0.0313","12.5900","25.6939","13.0259"
"","15.0600","12.6068","0.0313","12.6068","25.7282","13.0388"
"","15.0800","12.6233","0.0313","12.6233","25.7619","13.0611"
"","15.1000","12.6401","0.0314","12.6401","25.7961","13.0780"
"","15.1200","12.6567","0.0314","12.6567","25.8301","13.0807"
"","15.1400","12.6730","0.0314","12.6730","25.8633","13.0895"
"","15.1600","12.6897","0.0311","12.6897","25.8973","12.9572"
"","15.1800","12.7067","0.0306","12.7067","25.9320","12.7633"
"","15.2000","12.7234","0.0304","12.7234","25.9662","12.6763"
"","15.2200","12.7400","0.0304","12.7400","25.9999","12.6847"
"","15.2400","12.7565","0.0305","12.7565","26.0337","12.7217"
"","15.2600","12.7731","0.0306","12.7731","26.0676","12.7379"
"","15.2800","12.7897","0.0306","12.7897","26.1014","12.7428"
"","15.3000","12.8062","0.0306","12.8062","26.1351","12.7477"
"","15.3200","12.8231","0.0306","12.8231","26.1695","12.7580"
"","15.3400","12.8400","0.0306","12.8400","26.2040","12.7572"
"","15.3600","12.8566","0.0302","12.8566","26.2380","12.5916"
"","15.3800","12.8731","0.0295","12.8731","26.2717","12.3076"
"","15.4000","12.8899","0.0292","12.8899","26.3059","12.1749"
"","15.4200","12.9064","0.0292","12.9064","26.3396","12.1591"
"","15.4400","12.9231","0.0286","12.9231","26.3736","11.9047"
"","15.4600","12.9397","0.0281","12.9397","26.4076","11.6885"
"","15.4800","12.9567","0.0279","12.9567","26.4423","11.6301"
"","15.5000","12.9737","0.0279","12.9737","26.4770","11.6265"
"","15.5200","12.9902","0.0279","12.9902","26.5107","11.6389"
"","15.5400","13.0065","0.0279","13.0065","26.5439","11.6369"
"","15.5600","13.0229","0.0279","13.0229","26.5774","11.6333"
"","15.5800","13.0396","0.0280","13.0396","26.6114","11.6653"
"","15.6000","13.0564","0.0276","13.0564","26.6456","11.5163"
"","15.6200","13.0731","0.0270","13.0731","26.6798","11.2678"
"","15.6400","13.0901","0.0268","13.0901","26.7145","11.1671"
"","15.6600","13.1069","0.0266","13.1069","26.7487","11.0814"
"","15.6740","13.1183","0.0256","13.1183","26.7721","10.6855"