File: Fig6C/211130_Instron/211130/unentangled/PureCompression_TTball_6.is_comp_Exports/PureCompression_TTball_6_1.csv
Results Table 1


Results Table 2


Time,Displacement,Force,Compressive displacement,Compressive strain (Displacement),Compressive stress,PIP count
(s),(mm),(kN),(mm),(%),(MPa),
"0.0000","0.0000","-0.0002","0.0000","0.0000","-0.0159","0.0000"
"0.1800","0.1499","-0.0002","0.1499","0.1000","-0.0161","0.0000"
"0.3600","0.3019","-0.0002","0.3019","0.2012","-0.0170","0.0000"
"0.5400","0.4519","-0.0002","0.4519","0.3013","-0.0174","0.0000"
"0.7200","0.6016","-0.0002","0.6016","0.4011","-0.0158","0.0000"
"0.9000","0.7517","-0.0002","0.7517","0.5011","-0.0155","0.0000"
"1.0800","0.9018","-0.0001","0.9018","0.6012","-0.0135","0.0000"
"1.2600","1.0516","-0.0001","1.0516","0.7011","-0.0125","0.0000"
"1.4400","1.2016","-0.0001","1.2016","0.8010","-0.0101","0.0000"
"1.6200","1.3517","-0.0001","1.3517","0.9012","-0.0065","0.0000"
"1.8000","1.5020","-0.0001","1.5020","1.0013","-0.0061","0.0000"
"1.9800","1.6516","-0.0001","1.6516","1.1011","-0.0060","0.0000"
"2.1600","1.8016","-0.0001","1.8016","1.2011","-0.0064","0.0000"
"2.3400","1.9519","0.0000","1.9519","1.3013","-0.0024","0.0000"
"2.5200","2.1017","0.0000","2.1017","1.4012","-0.0005","0.0000"
"2.7000","2.2519","-0.0001","2.2519","1.5013","-0.0077","0.0000"
"2.8800","2.4021","0.0000","2.4021","1.6014","-0.0017","0.0000"
"3.0600","2.5520","0.0000","2.5520","1.7013","0.0023","0.0000"
"3.2400","2.7016","0.0000","2.7016","1.8011","-0.0034","0.0000"
"3.4200","2.8517","0.0000","2.8517","1.9012","0.0002","0.0000"
"3.6000","3.0019","-0.0001","3.0019","2.0013","-0.0086","0.0000"
"3.7800","3.1518","0.0000","3.1518","2.1012","0.0043","0.0000"
"3.9600","3.3019","0.0001","3.3019","2.2013","0.0105","0.0000"
"4.1400","3.4515","0.0001","3.4515","2.3010","0.0078","0.0000"
"4.3200","3.6018","0.0001","3.6018","2.4012","0.0066","0.0000"
"4.5000","3.7519","0.0001","3.7519","2.5013","0.0126","0.0000"
"4.6800","3.9016","0.0001","3.9016","2.6011","0.0096","0.0000"
"4.8600","4.0517","0.0001","4.0517","2.7011","0.0149","0.0000"
"5.0400","4.2017","0.0001","4.2017","2.8011","0.0136","0.0000"
"5.2200","4.3519","0.0001","4.3519","2.9013","0.0071","0.0000"
"5.4000","4.5017","0.0001","4.5017","3.0011","0.0121","0.0000"
"5.5800","4.6519","0.0001","4.6519","3.1012","0.0087","0.0000"
"5.7600","4.8019","0.0001","4.8019","3.2013","0.0115","0.0000"
"5.9400","4.9515","0.0001","4.9515","3.3010","0.0128","0.0000"
"6.1200","5.1013","0.0001","5.1013","3.4009","0.0109","0.0000"
"6.3000","5.2522","0.0002","5.2522","3.5014","0.0158","0.0000"
"6.4800","5.4019","0.0002","5.4019","3.6012","0.0160","0.0000"
"6.6600","5.5517","0.0002","5.5517","3.7011","0.0190","0.0000"
"6.8400","5.7018","0.0002","5.7018","3.8012","0.0173","0.0000"
"7.0200","5.8520","0.0002","5.8520","3.9013","0.0164","0.0000"
"7.2000","6.0018","0.0002","6.0018","4.0012","0.0155","0.0000"
"7.3800","6.1516","0.0002","6.1516","4.1011","0.0204","0.0000"
"7.5600","6.3019","0.0002","6.3019","4.2013","0.0247","0.0000"
"7.7400","6.4520","0.0002","6.4520","4.3013","0.0201","0.0000"
"7.9200","6.6018","0.0002","6.6018","4.4012","0.0204","0.0000"
"8.1000","6.7516","0.0002","6.7516","4.5011","0.0235","0.0000"
"8.2800","6.9016","0.0002","6.9016","4.6011","0.0208","0.0000"
"8.4600","7.0519","0.0002","7.0519","4.7013","0.0229","0.0000"
"8.6400","7.2015","0.0002","7.2015","4.8010","0.0233","0.0000"
"8.8200","7.3518","0.0002","7.3518","4.9012","0.0219","0.0000"
"9.0000","7.5018","0.0002","7.5018","5.0012","0.0238","0.0000"
"9.1800","7.6520","0.0003","7.6520","5.1013","0.0261","0.0000"
"9.3600","7.8013","0.0002","7.8013","5.2009","0.0245","0.0000"
"9.5400","7.9521","0.0002","7.9521","5.3014","0.0193","0.0000"
"9.7200","8.1019","0.0002","8.1019","5.4013","0.0225","0.0000"
"9.9000","8.2517","0.0002","8.2517","5.5012","0.0183","0.0000"
"10.0800","8.4017","0.0001","8.4017","5.6011","0.0144","0.0000"
"10.2600","8.5519","0.0001","8.5519","5.7013","0.0132","0.0000"
"10.4400","8.7019","0.0002","8.7019","5.8012","0.0176","0.0000"
"10.6200","8.8519","0.0002","8.8519","5.9013","0.0189","0.0000"
"10.8000","9.0015","0.0002","9.0015","6.0010","0.0171","0.0000"
"10.9800","9.1519","0.0002","9.1519","6.1013","0.0232","0.0000"
"11.1600","9.3021","0.0002","9.3021","6.2014","0.0222","0.0000"
"11.3400","9.4514","0.0002","9.4514","6.3009","0.0215","0.0000"
"11.5200","9.6018","0.0002","9.6018","6.4012","0.0181","0.0000"
"11.7000","9.7521","0.0002","9.7521","6.5014","0.0170","0.0000"
"11.8800","9.9019","0.0002","9.9019","6.6013","0.0215","0.0000"
"12.0600","10.0516","0.0002","10.0516","6.7011","0.0179","0.0000"
"12.2400","10.2019","0.0002","10.2019","6.8013","0.0210","0.0000"
"12.4200","10.3518","0.0002","10.3518","6.9012","0.0183","0.0000"
"12.6000","10.5015","0.0002","10.5015","7.0010","0.0180","0.0000"
"12.7800","10.6514","0.0001","10.6514","7.1010","0.0145","0.0000"
"12.9600","10.8021","0.0002","10.8021","7.2014","0.0181","0.0000"
"13.1400","10.9519","0.0002","10.9519","7.3013","0.0208","0.0000"
"13.3200","11.1017","0.0002","11.1017","7.4011","0.0182","0.0000"
"13.5000","11.2518","0.0002","11.2518","7.5012","0.0157","0.0000"
"13.6800","11.4020","0.0001","11.4020","7.6014","0.0146","0.0000"
"13.8600","11.5517","0.0001","11.5517","7.7012","0.0143","0.0000"
"14.0400","11.7014","0.0001","11.7014","7.8010","0.0136","0.0000"
"14.2200","11.8516","0.0001","11.8516","7.9011","0.0144","0.0000"
"14.4000","12.0019","0.0001","12.0019","8.0013","0.0114","0.0000"
"14.5800","12.1512","0.0001","12.1512","8.1008","0.0144","0.0000"
"14.7600","12.3020","0.0002","12.3020","8.2013","0.0159","0.0000"
"14.9400","12.4517","0.0001","12.4517","8.3011","0.0146","0.0000"
"15.1200","12.6018","0.0002","12.6018","8.4012","0.0153","0.0000"
"15.3000","12.7517","0.0002","12.7517","8.5011","0.0182","0.0000"
"15.4800","12.9017","0.0002","12.9017","8.6011","0.0160","0.0000"
"15.6600","13.0521","0.0002","13.0521","8.7014","0.0169","0.0000"
"15.8400","13.2016","0.0002","13.2016","8.8010","0.0160","0.0000"
"16.0200","13.3515","0.0002","13.3515","8.9010","0.0195","0.0000"
"16.2000","13.5020","0.0001","13.5020","9.0013","0.0144","0.0000"
"16.3800","13.6517","0.0002","13.6517","9.1011","0.0188","0.0000"
"16.5600","13.8019","0.0002","13.8019","9.2013","0.0181","0.0000"
"16.7400","13.9518","0.0002","13.9518","9.3012","0.0211","0.0000"
"16.9200","14.1019","0.0002","14.1019","9.4012","0.0183","0.0000"
"17.1000","14.2520","0.0001","14.2520","9.5013","0.0148","0.0000"
"17.2800","14.4015","0.0002","14.4015","9.6010","0.0160","0.0000"
"17.4600","14.5515","0.0002","14.5515","9.7010","0.0166","0.0000"
"17.6400","14.7018","0.0002","14.7018","9.8012","0.0239","0.0000"
"17.8200","14.8517","0.0002","14.8517","9.9012","0.0204","0.0000"
"18.0000","15.0017","0.0002","15.0017","10.0011","0.0247","0.0000"
"18.1800","15.1517","0.0002","15.1517","10.1011","0.0213","0.0000"
"18.3600","15.3020","0.0002","15.3020","10.2013","0.0211","0.0000"
"18.5400","15.4516","0.0002","15.4516","10.3011","0.0222","0.0000"
"18.7200","15.6015","0.0003","15.6015","10.4010","0.0292","0.0000"
"18.9000","15.7518","0.0002","15.7518","10.5012","0.0248","0.0000"
"19.0800","15.9020","0.0001","15.9020","10.6013","0.0102","0.0000"
"19.2600","16.0518","0.0002","16.0518","10.7012","0.0230","0.0000"
"19.4400","16.2017","0.0002","16.2017","10.8011","0.0210","0.0000"
"19.6200","16.3520","0.0002","16.3520","10.9013","0.0238","0.0000"
"19.8000","16.5017","0.0002","16.5017","11.0011","0.0250","0.0000"
"19.9800","16.6516","0.0003","16.6516","11.1011","0.0309","0.0000"
"20.1600","16.8018","0.0003","16.8018","11.2012","0.0269","0.0000"
"20.3400","16.9520","0.0003","16.9520","11.3013","0.0327","0.0000"
"20.5200","17.1018","0.0003","17.1018","11.4012","0.0324","0.0000"
"20.7000","17.2516","0.0003","17.2516","11.5011","0.0320","0.0000"
"20.8800","17.4020","0.0004","17.4020","11.6013","0.0369","0.0000"
"21.0600","17.5520","0.0004","17.5520","11.7013","0.0358","0.0000"
"21.2400","17.7014","0.0004","17.7014","11.8009","0.0363","0.0000"
"21.4200","17.8515","0.0003","17.8515","11.9010","0.0345","0.0000"
"21.6000","18.0019","0.0004","18.0019","12.0013","0.0376","0.0000"
"21.7800","18.1514","0.0004","18.1514","12.1009","0.0417","0.0000"
"21.9600","18.3018","0.0004","18.3018","12.2012","0.0448","0.0000"
"22.1400","18.4518","0.0004","18.4518","12.3012","0.0431","0.0000"
"22.3200","18.6019","0.0004","18.6019","12.4013","0.0443","0.0000"
"22.5000","18.7518","0.0004","18.7518","12.5012","0.0423","0.0000"
"22.6800","18.9018","0.0005","18.9018","12.6012","0.0459","0.0000"
"22.8600","19.0517","0.0005","19.0517","12.7011","0.0457","0.0000"
"23.0400","19.2021","0.0005","19.2021","12.8014","0.0490","0.0000"
"23.2200","19.3517","0.0005","19.3517","12.9011","0.0503","0.0000"
"23.4000","19.5017","0.0005","19.5017","13.0011","0.0483","0.0000"
"23.5800","19.6518","0.0005","19.6518","13.1012","0.0521","0.0000"
"23.7600","19.8020","0.0005","19.8020","13.2014","0.0485","0.0000"
"23.9400","19.9515","0.0005","19.9515","13.3010","0.0513","0.0000"
"24.1200","20.1017","0.0005","20.1017","13.4011","0.0541","0.0000"
"24.3000","20.2520","0.0005","20.2520","13.5013","0.0498","0.0000"
"24.4800","20.4019","0.0005","20.4019","13.6013","0.0534","0.0000"
"24.6600","20.5517","0.0006","20.5517","13.7011","0.0562","0.0000"
"24.8400","20.7016","0.0005","20.7016","13.8011","0.0541","0.0000"
"25.0200","20.8519","0.0006","20.8519","13.9013","0.0584","0.0000"
"25.2000","21.0016","0.0005","21.0016","14.0011","0.0520","0.0000"
"25.3800","21.1518","0.0006","21.1518","14.1012","0.0575","0.0000"
"25.5600","21.3018","0.0005","21.3018","14.2012","0.0528","0.0000"
"25.7400","21.4520","0.0006","21.4520","14.3013","0.0573","0.0000"
"25.9200","21.6016","0.0005","21.6016","14.4010","0.0516","0.0000"
"26.1000","21.7517","0.0004","21.7517","14.5012","0.0434","0.0000"
"26.2800","21.9019","0.0006","21.9019","14.6013","0.0583","0.0000"
"26.4600","22.0520","0.0007","22.0520","14.7013","0.0690","0.0000"
"26.6400","22.2015","0.0006","22.2015","14.8010","0.0612","0.0000"
"26.8200","22.3516","0.0007","22.3516","14.9011","0.0670","0.0000"
"27.0000","22.5020","0.0007","22.5020","15.0013","0.0698","0.0000"
"27.1800","22.6517","0.0008","22.6517","15.1011","0.0757","0.0000"
"27.3600","22.8016","0.0009","22.8016","15.2011","0.0859","0.0000"
"27.5400","22.9519","0.0009","22.9519","15.3013","0.0865","0.0000"
"27.7200","23.1017","0.0009","23.1017","15.4011","0.0917","0.0000"
"27.9000","23.2519","0.0009","23.2519","15.5012","0.0927","0.0000"
"28.0800","23.4016","0.0010","23.4016","15.6010","0.0987","0.0000"
"28.2600","23.5520","0.0010","23.5520","15.7013","0.0981","0.0000"
"28.4400","23.7018","0.0010","23.7018","15.8012","0.1007","0.0000"
"28.6200","23.8515","0.0010","23.8515","15.9010","0.1003","0.0000"
"28.8000","24.0018","0.0010","24.0018","16.0012","0.1013","0.0000"
"28.9800","24.1518","0.0010","24.1518","16.1012","0.1034","0.0000"
"29.1600","24.3020","0.0010","24.3020","16.2013","0.1027","0.0000"
"29.3400","24.4515","0.0010","24.4515","16.3010","0.1034","0.0000"
"29.5200","24.6019","0.0011","24.6019","16.4013","0.1115","0.0000"
"29.7000","24.7521","0.0011","24.7521","16.5014","0.1087","0.0000"
"29.8800","24.9015","0.0010","24.9015","16.6010","0.1023","0.0000"
"30.0600","25.0517","0.0011","25.0517","16.7012","0.1072","0.0000"
"30.2400","25.2017","0.0011","25.2017","16.8011","0.1081","0.0000"
"30.4200","25.3518","0.0011","25.3518","16.9012","0.1080","0.0000"
"30.6000","25.5018","0.0011","25.5018","17.0012","0.1109","0.0000"
"30.7800","25.6518","0.0011","25.6518","17.1012","0.1106","0.0000"
"30.9600","25.8020","0.0012","25.8020","17.2013","0.1179","0.0000"
"31.1400","25.9519","0.0012","25.9519","17.3013","0.1218","0.0000"
"31.3200","26.1014","0.0012","26.1014","17.4009","0.1154","0.0000"
"31.5000","26.2517","0.0012","26.2517","17.5011","0.1231","0.0000"
"31.6800","26.4018","0.0013","26.4018","17.6012","0.1283","0.0000"
"31.8600","26.5515","0.0013","26.5515","17.7010","0.1317","0.0000"
"32.0400","26.7017","0.0013","26.7017","17.8011","0.1311","0.0000"
"32.2200","26.8517","0.0014","26.8517","17.9012","0.1360","0.0000"
"32.4000","27.0019","0.0014","27.0019","18.0013","0.1351","0.0000"
"32.5800","27.1516","0.0013","27.1516","18.1011","0.1325","0.0000"
"32.7600","27.3018","0.0014","27.3018","18.2012","0.1399","0.0000"
"32.9400","27.4518","0.0014","27.4518","18.3012","0.1432","0.0000"
"33.1200","27.6019","0.0015","27.6019","18.4012","0.1506","0.0000"
"33.3000","27.7513","0.0015","27.7513","18.5009","0.1545","0.0000"
"33.4800","27.9021","0.0016","27.9021","18.6014","0.1577","0.0000"
"33.6600","28.0520","0.0015","28.0520","18.7013","0.1504","0.0000"
"33.8400","28.2019","0.0016","28.2019","18.8013","0.1579","0.0000"
"34.0200","28.3515","0.0016","28.3515","18.9010","0.1601","0.0000"
"34.2000","28.5018","0.0016","28.5018","19.0012","0.1613","0.0000"
"34.3800","28.6518","0.0017","28.6518","19.1012","0.1707","0.0000"
"34.5600","28.8018","0.0018","28.8018","19.2012","0.1792","0.0000"
"34.7400","28.9519","0.0017","28.9519","19.3013","0.1732","0.0000"
"34.9200","29.1016","0.0018","29.1016","19.4011","0.1793","0.0000"
"35.1000","29.2519","0.0018","29.2519","19.5013","0.1809","0.0000"
"35.2800","29.4015","0.0019","29.4015","19.6010","0.1887","0.0000"
"35.4600","29.5518","0.0018","29.5518","19.7012","0.1831","0.0000"
"35.6400","29.7018","0.0019","29.7018","19.8012","0.1937","0.0000"
"35.8200","29.8519","0.0020","29.8519","19.9013","0.1975","0.0000"
"36.0000","30.0016","0.0021","30.0016","20.0011","0.2111","0.0000"
"36.1800","30.1514","0.0021","30.1514","20.1009","0.2143","0.0000"
"36.3600","30.3023","0.0021","30.3023","20.2015","0.2139","0.0000"
"36.5400","30.4515","0.0020","30.4515","20.3010","0.2034","0.0000"
"36.7200","30.6015","0.0020","30.6015","20.4010","0.2032","0.0000"
"36.9000","30.7518","0.0021","30.7518","20.5012","0.2103","0.0000"
"37.0800","30.9019","0.0021","30.9019","20.6012","0.2146","0.0000"
"37.2600","31.0517","0.0022","31.0517","20.7011","0.2206","0.0000"
"37.4400","31.2017","0.0021","31.2017","20.8012","0.2098","0.0000"
"37.6200","31.3518","0.0021","31.3518","20.9012","0.2135","0.0000"
"37.8000","31.5018","0.0022","31.5018","21.0012","0.2175","0.0000"
"37.9800","31.6518","0.0021","31.6518","21.1012","0.2101","0.0000"
"38.1600","31.8019","0.0022","31.8019","21.2013","0.2165","0.0000"
"38.3400","31.9520","0.0022","31.9520","21.3013","0.2235","0.0000"
"38.5200","32.1017","0.0024","32.1017","21.4011","0.2368","0.0000"
"38.7000","32.2515","0.0023","32.2515","21.5010","0.2317","0.0000"
"38.8800","32.4019","0.0024","32.4019","21.6013","0.2351","0.0000"
"39.0600","32.5518","0.0024","32.5518","21.7012","0.2423","0.0000"
"39.2400","32.7015","0.0023","32.7015","21.8010","0.2339","0.0000"
"39.4200","32.8518","0.0025","32.8518","21.9012","0.2470","0.0000"
"39.6000","33.0021","0.0025","33.0021","22.0014","0.2518","0.0000"
"39.7800","33.1519","0.0024","33.1519","22.1013","0.2441","0.0000"
"39.9600","33.3017","0.0026","33.3017","22.2011","0.2562","0.0000"
"40.1400","33.4519","0.0025","33.4519","22.3012","0.2473","0.0000"
"40.3200","33.6018","0.0026","33.6018","22.4012","0.2597","0.0000"
"40.5000","33.7517","0.0026","33.7517","22.5012","0.2623","0.0000"
"40.6800","33.9013","0.0026","33.9013","22.6009","0.2574","0.0000"
"40.8600","34.0521","0.0025","34.0521","22.7014","0.2520","0.0000"
"41.0400","34.2018","0.0025","34.2018","22.8012","0.2464","0.0000"
"41.2200","34.3516","0.0024","34.3516","22.9010","0.2395","0.0000"
"41.4000","34.5017","0.0023","34.5017","23.0012","0.2349","0.0000"
"41.5800","34.6517","0.0022","34.6517","23.1011","0.2236","0.0000"
"41.7600","34.8020","0.0020","34.8020","23.2013","0.2046","0.0000"
"41.9400","34.9518","0.0020","34.9518","23.3012","0.1951","0.0000"
"42.1200","35.1017","0.0017","35.1017","23.4011","0.1721","0.0000"
"42.3000","35.2521","0.0016","35.2521","23.5014","0.1624","0.0000"
"42.4800","35.4016","0.0014","35.4016","23.6010","0.1438","0.0000"
"42.6600","35.5517","0.0015","35.5517","23.7011","0.1500","0.0000"
"42.8400","35.7018","0.0016","35.7018","23.8012","0.1587","0.0000"
"43.0200","35.8518","0.0016","35.8518","23.9012","0.1625","0.0000"
"43.2000","36.0016","0.0017","36.0016","24.0011","0.1692","0.0000"
"43.3800","36.1517","0.0018","36.1517","24.1011","0.1752","0.0000"
"43.5600","36.3018","0.0018","36.3018","24.2012","0.1781","0.0000"
"43.7400","36.4518","0.0016","36.4518","24.3012","0.1636","0.0000"
"43.9200","36.6017","0.0017","36.6017","24.4011","0.1712","0.0000"
"44.1000","36.7518","0.0017","36.7518","24.5012","0.1750","0.0000"
"44.2800","36.9017","0.0018","36.9017","24.6011","0.1782","0.0000"
"44.4600","37.0517","0.0018","37.0517","24.7012","0.1835","0.0000"
"44.6400","37.2015","0.0019","37.2015","24.8010","0.1866","0.0000"
"44.8200","37.3521","0.0019","37.3521","24.9014","0.1908","0.0000"
"45.0000","37.5019","0.0020","37.5019","25.0013","0.1967","0.0000"
"45.1800","37.6517","0.0020","37.6517","25.1011","0.2040","0.0000"
"45.3600","37.8015","0.0022","37.8015","25.2010","0.2152","0.0000"
"45.5400","37.9519","0.0023","37.9519","25.3013","0.2293","0.0000"
"45.7200","38.1018","0.0024","38.1018","25.4012","0.2364","0.0000"
"45.9000","38.2518","0.0024","38.2518","25.5012","0.2420","0.0000"
"46.0800","38.4017","0.0025","38.4017","25.6011","0.2463","0.0000"
"46.2600","38.5520","0.0025","38.5520","25.7013","0.2520","0.0000"
"46.4400","38.7020","0.0025","38.7020","25.8014","0.2544","0.0000"
"46.6200","38.8516","0.0026","38.8516","25.9011","0.2591","0.0000"
"46.8000","39.0018","0.0025","39.0018","26.0012","0.2540","0.0000"
"46.9800","39.1518","0.0026","39.1518","26.1012","0.2583","0.0000"
"47.1600","39.3015","0.0027","39.3015","26.2010","0.2691","0.0000"
"47.3400","39.4516","0.0027","39.4516","26.3010","0.2698","0.0000"
"47.5200","39.6020","0.0027","39.6020","26.4013","0.2749","0.0000"
"47.7000","39.7520","0.0027","39.7520","26.5013","0.2742","0.0000"
"47.8800","39.9017","0.0027","39.9017","26.6011","0.2740","0.0000"
"48.0600","40.0518","0.0028","40.0518","26.7012","0.2766","0.0000"
"48.2400","40.2019","0.0028","40.2019","26.8013","0.2765","0.0000"
"48.4200","40.3516","0.0028","40.3516","26.9011","0.2751","0.0000"
"48.6000","40.5018","0.0029","40.5018","27.0012","0.2894","0.0000"
"48.7800","40.6517","0.0028","40.6517","27.1011","0.2824","0.0000"
"48.9600","40.8020","0.0028","40.8020","27.2013","0.2834","0.0000"
"49.1400","40.9515","0.0029","40.9515","27.3010","0.2874","0.0000"
"49.3200","41.1019","0.0030","41.1019","27.4012","0.2979","0.0000"
"49.5000","41.2517","0.0031","41.2517","27.5011","0.3068","0.0000"
"49.6800","41.4018","0.0030","41.4018","27.6012","0.2995","0.0000"
"49.8600","41.5518","0.0030","41.5518","27.7012","0.2983","0.0000"
"50.0400","41.7016","0.0031","41.7016","27.8011","0.3140","0.0000"
"50.2200","41.8516","0.0031","41.8516","27.9011","0.3109","0.0000"
"50.4000","42.0018","0.0031","42.0018","28.0012","0.3138","0.0000"
"50.5800","42.1515","0.0031","42.1515","28.1010","0.3125","0.0000"
"50.7600","42.3019","0.0031","42.3019","28.2013","0.3096","0.0000"
"50.9400","42.4520","0.0032","42.4519","28.3013","0.3168","0.0000"
"51.1200","42.6018","0.0032","42.6018","28.4012","0.3238","0.0000"
"51.3000","42.7516","0.0032","42.7516","28.5011","0.3227","0.0000"
"51.4800","42.9019","0.0034","42.9019","28.6012","0.3359","0.0000"
"51.6600","43.0520","0.0035","43.0520","28.7014","0.3507","0.0000"
"51.8400","43.2014","0.0036","43.2014","28.8009","0.3558","0.0000"
"52.0200","43.3512","0.0037","43.3512","28.9008","0.3650","0.0000"
"52.2000","43.5022","0.0036","43.5022","29.0015","0.3618","0.0000"
"52.3800","43.6519","0.0038","43.6519","29.1012","0.3767","0.0000"
"52.5600","43.8018","0.0038","43.8018","29.2012","0.3772","0.0000"
"52.7400","43.9517","0.0039","43.9517","29.3012","0.3872","0.0000"
"52.9200","44.1019","0.0039","44.1019","29.4013","0.3931","0.0000"
"53.1000","44.2518","0.0040","44.2518","29.5012","0.3955","0.0000"
"53.2800","44.4014","0.0041","44.4014","29.6009","0.4140","0.0000"
"53.4600","44.5519","0.0041","44.5519","29.7013","0.4107","0.0000"
"53.6400","44.7019","0.0042","44.7019","29.8012","0.4200","0.0000"
"53.8200","44.8518","0.0042","44.8518","29.9012","0.4239","0.0000"
"54.0000","45.0017","0.0044","45.0017","30.0011","0.4449","0.0000"
"54.1800","45.1516","0.0044","45.1516","30.1011","0.4432","0.0000"
"54.3600","45.3020","0.0045","45.3021","30.2014","0.4536","0.0000"
"54.5400","45.4514","0.0045","45.4514","30.3009","0.4471","0.0000"
"54.7200","45.6018","0.0046","45.6018","30.4012","0.4632","0.0000"
"54.9000","45.7518","0.0045","45.7518","30.5012","0.4499","0.0000"
"55.0800","45.9018","0.0045","45.9018","30.6012","0.4525","0.0000"
"55.2600","46.0518","0.0046","46.0518","30.7012","0.4621","0.0000"
"55.4400","46.2018","0.0046","46.2018","30.8012","0.4620","0.0000"
"55.6200","46.3520","0.0047","46.3520","30.9014","0.4737","0.0000"
"55.8000","46.5016","0.0048","46.5016","31.0011","0.4798","0.0000"
"55.9800","46.6517","0.0049","46.6517","31.1011","0.4938","0.0000"
"56.1600","46.8018","0.0048","46.8018","31.2012","0.4796","0.0000"
"56.3400","46.9519","0.0045","46.9519","31.3012","0.4511","0.0000"
"56.5200","47.1016","0.0047","47.1016","31.4010","0.4655","0.0000"
"56.7000","47.2519","0.0047","47.2519","31.5012","0.4687","0.0000"
"56.8800","47.4018","0.0050","47.4018","31.6012","0.4995","0.0000"
"57.0600","47.5520","0.0051","47.5520","31.7013","0.5057","0.0000"
"57.2400","47.7018","0.0049","47.7018","31.8012","0.4867","0.0000"
"57.4200","47.8518","0.0050","47.8518","31.9012","0.4954","0.0000"
"57.6000","48.0020","0.0051","48.0020","32.0013","0.5065","0.0000"
"57.7800","48.1516","0.0051","48.1516","32.1010","0.5125","0.0000"
"57.9600","48.3016","0.0053","48.3016","32.2011","0.5282","0.0000"
"58.1400","48.4518","0.0053","48.4518","32.3012","0.5292","0.0000"
"58.3200","48.6022","0.0053","48.6022","32.4014","0.5284","0.0000"
"58.5000","48.7515","0.0054","48.7515","32.5010","0.5391","0.0000"
"58.6800","48.9016","0.0055","48.9016","32.6010","0.5492","0.0000"
"58.8600","49.0518","0.0056","49.0518","32.7012","0.5580","0.0000"
"59.0400","49.2019","0.0056","49.2019","32.8013","0.5635","0.0000"
"59.2200","49.3517","0.0057","49.3517","32.9011","0.5671","0.0000"
"59.4000","49.5015","0.0057","49.5015","33.0010","0.5663","0.0000"
"59.5800","49.6518","0.0057","49.6518","33.1012","0.5660","0.0000"
"59.7600","49.8019","0.0056","49.8019","33.2012","0.5611","0.0000"
"59.9400","49.9514","0.0057","49.9514","33.3010","0.5687","0.0000"
"60.1200","50.1018","0.0056","50.1018","33.4012","0.5630","0.0000"
"60.3000","50.2520","0.0057","50.2520","33.5013","0.5662","0.0000"
"60.4800","50.4016","0.0058","50.4016","33.6011","0.5842","0.0000"
"60.6600","50.5517","0.0059","50.5517","33.7012","0.5934","0.0000"
"60.8400","50.7018","0.0060","50.7018","33.8012","0.6001","0.0000"
"61.0200","50.8520","0.0061","50.8520","33.9013","0.6087","0.0000"
"61.2000","51.0014","0.0062","51.0014","34.0009","0.6179","0.0000"
"61.3800","51.1517","0.0062","51.1517","34.1011","0.6203","0.0000"
"61.5600","51.3020","0.0060","51.3020","34.2013","0.6017","0.0000"
"61.7400","51.4518","0.0064","51.4518","34.3012","0.6350","0.0000"
"61.9200","51.6016","0.0064","51.6016","34.4011","0.6426","0.0000"
"62.1000","51.7519","0.0071","51.7519","34.5013","0.7130","0.0000"
"62.2800","51.9016","0.0091","51.9016","34.6011","0.9081","0.0000"
"62.4600","52.0519","0.0113","52.0519","34.7013","1.1339","0.0000"
"62.6400","52.2017","0.0139","52.2017","34.8011","1.3895","0.0000"
"62.8200","52.3519","0.0164","52.3519","34.9012","1.6402","0.0000"
"63.0000","52.5018","0.0189","52.5018","35.0012","1.8893","0.0000"
"63.1800","52.6514","0.0213","52.6514","35.1009","2.1293","0.0000"
"63.3600","52.8014","0.0239","52.8014","35.2009","2.3856","0.0000"
"63.5400","52.9520","0.0265","52.9520","35.3014","2.6538","0.0000"
"63.7200","53.1019","0.0292","53.1019","35.4012","2.9154","0.0000"
"63.9000","53.2518","0.0320","53.2518","35.5012","3.1950","0.0000"
"64.0800","53.4018","0.0348","53.4018","35.6012","3.4830","0.0000"
"64.2600","53.5519","0.0378","53.5519","35.7013","3.7766","0.0000"
"64.4400","53.7017","0.0407","53.7017","35.8011","4.0692","0.0000"
"64.6200","53.8516","0.0439","53.8516","35.9011","4.3857","0.0000"
"64.8000","54.0017","0.0471","54.0017","36.0011","4.7140","0.0000"
"64.9800","54.1517","0.0506","54.1517","36.1012","5.0597","0.0000"
"65.1600","54.3019","0.0541","54.3019","36.2013","5.4115","0.0000"
"65.3400","54.4517","0.0558","54.4517","36.3011","5.5791","0.0000"
"65.5200","54.6018","0.0554","54.6018","36.4012","5.5421","0.0000"
"65.7000","54.7519","0.0567","54.7519","36.5013","5.6697","0.0000"
"65.8800","54.9013","0.0585","54.9013","36.6008","5.8470","0.0000"
"66.0600","55.0519","0.0606","55.0519","36.7013","6.0575","0.0000"
"66.2400","55.2018","0.0625","55.2018","36.8012","6.2530","0.0000"
"66.4200","55.3518","0.0644","55.3518","36.9012","6.4394","0.0000"
"66.6000","55.5018","0.0671","55.5018","37.0012","6.7078","0.0000"
"66.7800","55.6516","0.0698","55.6516","37.1011","6.9751","0.0000"
"66.9600","55.8019","0.0731","55.8019","37.2013","7.3067","0.0000"
"67.1400","55.9516","0.0773","55.9516","37.3011","7.7302","0.0000"
"67.3200","56.1015","0.0813","56.1015","37.4010","8.1285","0.0000"
"67.5000","56.2519","0.0849","56.2519","37.5013","8.4915","0.0000"
"67.6800","56.4019","0.0884","56.4019","37.6012","8.8361","0.0000"
"67.8600","56.5514","0.0917","56.5514","37.7010","9.1676","0.0000"
"68.0400","56.7021","0.0954","56.7021","37.8014","9.5355","0.0000"
"68.2200","56.8518","0.0991","56.8518","37.9012","9.9146","0.0000"
"68.4000","57.0021","0.1026","57.0021","38.0014","10.2625","0.0000"
"68.5800","57.1514","0.1060","57.1514","38.1009","10.5988","0.0000"
"68.7600","57.3020","0.1091","57.3020","38.2014","10.9143","0.0000"
"68.9400","57.4521","0.1120","57.4521","38.3014","11.2019","0.0000"
"69.1200","57.6018","0.1152","57.6018","38.4012","11.5161","0.0000"
"69.3000","57.7516","0.1185","57.7516","38.5011","11.8476","0.0000"
"69.4800","57.9019","0.1210","57.9019","38.6013","12.1007","0.0000"
"69.6600","58.0519","0.1226","58.0519","38.7013","12.2596","0.0000"
"69.8400","58.2016","0.1223","58.2016","38.8011","12.2345","0.0000"
"70.0200","58.3519","0.1212","58.3519","38.9013","12.1213","0.0000"
"70.2000","58.5020","0.1239","58.5020","39.0013","12.3876","0.0000"
"70.3800","58.6518","0.1272","58.6518","39.1012","12.7199","0.0000"
"70.5600","58.8016","0.1300","58.8016","39.2011","12.9955","0.0000"
"70.7400","58.9514","0.1332","58.9514","39.3009","13.3186","0.0000"
"70.9200","59.1023","0.1364","59.1023","39.4015","13.6409","0.0000"
"71.1000","59.2516","0.1389","59.2516","39.5011","13.8924","0.0000"
"71.2800","59.4017","0.1412","59.4017","39.6011","14.1245","0.0000"
"71.4600","59.5516","0.1422","59.5516","39.7011","14.2172","0.0000"
"71.6400","59.7021","0.1438","59.7021","39.8014","14.3768","0.0000"
"71.8200","59.8518","0.1458","59.8518","39.9012","14.5755","0.0000"
"72.0000","60.0017","0.1491","60.0017","40.0012","14.9134","0.0000"
"72.1800","60.1517","0.1523","60.1517","40.1011","15.2277","0.0000"
"72.3600","60.3018","0.1538","60.3018","40.2012","15.3835","0.0000"
"72.5400","60.4515","0.1569","60.4515","40.3010","15.6921","0.0000"
"72.7200","60.6017","0.1589","60.6017","40.4011","15.8890","0.0000"
"72.9000","60.7520","0.1616","60.7520","40.5013","16.1597","0.0000"
"73.0800","60.9017","0.1654","60.9017","40.6011","16.5354","0.0000"
"73.2600","61.0516","0.1677","61.0516","40.7011","16.7712","0.0000"
"73.4400","61.2020","0.1688","61.2020","40.8013","16.8809","0.0000"
"73.6200","61.3518","0.1609","61.3518","40.9012","16.0854","0.0000"
"73.8000","61.5016","0.1645","61.5016","41.0011","16.4456","0.0000"
"73.9800","61.6516","0.1678","61.6516","41.1010","16.7835","0.0000"
"74.1600","61.8021","0.1711","61.8021","41.2014","17.1105","0.0000"
"74.3400","61.9519","0.1744","61.9519","41.3013","17.4361","0.0000"
"74.5200","62.1016","0.1779","62.1016","41.4011","17.7876","0.0000"
"74.7000","62.2519","0.1813","62.2519","41.5013","18.1311","0.0000"
"74.8800","62.4019","0.1845","62.4019","41.6013","18.4522","0.0000"
"75.0600","62.5517","0.1849","62.5517","41.7012","18.4881","0.0000"
"75.2400","62.7017","0.1821","62.7017","41.8011","18.2089","0.0000"
"75.4200","62.8520","0.1824","62.8520","41.9013","18.2396","0.0000"
"75.6000","63.0020","0.1842","63.0020","42.0013","18.4151","0.0000"
"75.7800","63.1517","0.1851","63.1517","42.1011","18.5113","0.0000"
"75.9600","63.3017","0.1858","63.3017","42.2012","18.5805","0.0000"
"76.1400","63.4518","0.1866","63.4518","42.3012","18.6635","0.0000"
"76.3200","63.6018","0.1875","63.6018","42.4012","18.7475","0.0000"
"76.5000","63.7519","0.1892","63.7519","42.5013","18.9225","0.0000"
"76.6800","63.9019","0.1909","63.9019","42.6013","19.0937","0.0000"
"76.8600","64.0520","0.1922","64.0520","42.7013","19.2239","0.0000"
"77.0400","64.2017","0.1953","64.2017","42.8011","19.5277","0.0000"
"77.2200","64.3515","0.1985","64.3515","42.9010","19.8463","0.0000"
"77.4000","64.5018","0.2014","64.5018","43.0012","20.1361","0.0000"
"77.5800","64.6518","0.2043","64.6518","43.1012","20.4296","0.0000"
"77.7600","64.8016","0.2062","64.8016","43.2011","20.6217","0.0000"
"77.9400","64.9515","0.2082","64.9515","43.3010","20.8163","0.0000"
"78.1200","65.1017","0.2102","65.1017","43.4012","21.0220","0.0000"
"78.3000","65.2521","0.2115","65.2521","43.5014","21.1520","0.0000"
"78.4800","65.4012","0.2138","65.4012","43.6008","21.3811","0.0000"
"78.6600","65.5516","0.2160","65.5516","43.7011","21.6017","0.0000"
"78.8400","65.7019","0.2177","65.7019","43.8013","21.7710","0.0000"
"79.0200","65.8516","0.2183","65.8516","43.9011","21.8338","0.0000"
"79.2000","66.0016","0.2200","66.0016","44.0010","21.9983","0.0000"
"79.3800","66.1521","0.2221","66.1521","44.1014","22.2080","0.0000"
"79.5600","66.3019","0.2233","66.3019","44.2013","22.3345","0.0000"
"79.7400","66.4515","0.2253","66.4515","44.3010","22.5290","0.0000"
"79.9200","66.6016","0.2264","66.6016","44.4011","22.6450","0.0000"
"80.1000","66.7519","0.2264","66.7519","44.5013","22.6352","0.0000"
"80.2800","66.9017","0.2270","66.9017","44.6012","22.6982","0.0000"
"80.4600","67.0520","0.2281","67.0520","44.7013","22.8087","0.0000"
"80.6400","67.2016","0.2291","67.2016","44.8011","22.9063","0.0000"
"80.8200","67.3519","0.2306","67.3519","44.9012","23.0567","0.0000"
"81.0000","67.5020","0.2314","67.5020","45.0014","23.1435","0.0000"
"81.1800","67.6515","0.2325","67.6515","45.1010","23.2455","0.0000"
"81.3600","67.8016","0.2337","67.8016","45.2010","23.3738","0.0000"
"81.5400","67.9520","0.2351","67.9520","45.3013","23.5069","0.0000"
"81.7200","68.1018","0.2373","68.1018","45.4012","23.7253","0.0000"
"81.9000","68.2517","0.2380","68.2517","45.5011","23.8037","0.0000"
"82.0800","68.4016","0.2390","68.4016","45.6011","23.8986","0.0000"
"82.2600","68.5522","0.2400","68.5522","45.7014","23.9957","0.0000"
"82.4400","68.7017","0.2400","68.7017","45.8011","24.0014","0.0000"
"82.6200","68.8515","0.2407","68.8515","45.9010","24.0682","0.0000"
"82.8000","69.0019","0.2408","69.0019","46.0013","24.0769","0.0000"
"82.9800","69.1517","0.2406","69.1517","46.1012","24.0579","0.0000"
"83.1600","69.3016","0.2412","69.3016","46.2010","24.1248","0.0000"
"83.3400","69.4518","0.2416","69.4518","46.3012","24.1642","0.0000"
"83.5200","69.6017","0.2421","69.6017","46.4011","24.2060","0.0000"
"83.7000","69.7517","0.2422","69.7517","46.5011","24.2245","0.0000"
"83.8800","69.9018","0.2421","69.9018","46.6012","24.2118","0.0000"
"84.0600","70.0519","0.2424","70.0519","46.7013","24.2394","0.0000"
"84.2400","70.2020","0.2430","70.2020","46.8013","24.2975","0.0000"
"84.4200","70.3519","0.2436","70.3519","46.9013","24.3562","0.0000"
"84.6000","70.5015","0.2435","70.5015","47.0010","24.3497","0.0000"
"84.7800","70.6519","0.2434","70.6519","47.1013","24.3387","0.0000"
"84.9600","70.8017","0.2438","70.8017","47.2011","24.3778","0.0000"
"85.1400","70.9516","0.2450","70.9516","47.3011","24.4976","0.0000"
"85.3200","71.1018","0.2464","71.1018","47.4012","24.6442","0.0000"
"85.5000","71.2520","0.2474","71.2520","47.5013","24.7429","0.0000"
"85.6800","71.4019","0.2482","71.4019","47.6013","24.8193","0.0000"
"85.8600","71.5516","0.2492","71.5516","47.7011","24.9187","0.0000"
"86.0400","71.7019","0.2494","71.7019","47.8012","24.9369","0.0000"
"86.2200","71.8520","0.2496","71.8520","47.9014","24.9597","0.0000"
"86.4000","72.0014","0.2501","72.0014","48.0009","25.0118","0.0000"
"86.5800","72.1513","0.2498","72.1513","48.1009","24.9806","0.0000"
"86.7600","72.3022","0.2506","72.3022","48.2015","25.0638","0.0000"
"86.9400","72.4518","0.2507","72.4518","48.3012","25.0723","0.0000"
"87.1200","72.6017","0.2509","72.6017","48.4011","25.0857","0.0000"
"87.3000","72.7519","0.2505","72.7519","48.5012","25.0480","0.0000"
"87.4800","72.9018","0.2514","72.9018","48.6012","25.1411","0.0000"
"87.6600","73.0519","0.2521","73.0519","48.7013","25.2115","0.0000"
"87.8400","73.2015","0.2528","73.2015","48.8010","25.2830","0.0000"
"88.0200","73.3518","0.2542","73.3518","48.9012","25.4212","0.0000"
"88.2000","73.5020","0.2549","73.5020","49.0013","25.4851","0.0000"
"88.3800","73.6517","0.2547","73.6517","49.1011","25.4697","0.0000"
"88.5600","73.8017","0.2543","73.8017","49.2012","25.4327","0.0000"
"88.7400","73.9519","0.2549","73.9519","49.3013","25.4914","0.0000"
"88.9200","74.1017","0.2551","74.1017","49.4011","25.5122","0.0000"
"89.1000","74.2517","0.2558","74.2517","49.5012","25.5757","0.0000"
"89.2800","74.4017","0.2571","74.4017","49.6011","25.7117","0.0000"
"89.4600","74.5520","0.2584","74.5520","49.7013","25.8443","0.0000"
"89.6400","74.7018","0.2601","74.7018","49.8012","26.0130","0.0000"
"89.8200","74.8517","0.2612","74.8517","49.9011","26.1213","0.0000"
"90.0000","75.0019","0.2623","75.0019","50.0013","26.2340","0.0000"
"90.1800","75.1518","0.2635","75.1518","50.1012","26.3457","0.0000"
"90.3600","75.3017","0.2642","75.3017","50.2012","26.4235","0.0000"
"90.5400","75.4516","0.2652","75.4516","50.3010","26.5192","0.0000"
"90.7200","75.6017","0.2661","75.6017","50.4012","26.6064","0.0000"
"90.9000","75.7520","0.2663","75.7520","50.5013","26.6321","0.0000"
"91.0800","75.9016","0.2674","75.9016","50.6010","26.7390","0.0000"
"91.2600","76.0517","0.2683","76.0517","50.7012","26.8254","0.0000"
"91.4400","76.2017","0.2694","76.2017","50.8011","26.9420","0.0000"
"91.6200","76.3517","0.2697","76.3517","50.9012","26.9729","0.0000"
"91.8000","76.5017","0.2699","76.5017","51.0011","26.9870","0.0000"
"91.9800","76.6517","0.2701","76.6517","51.1011","27.0114","0.0000"
"92.1600","76.8021","0.2707","76.8021","51.2014","27.0739","0.0000"
"92.3400","76.9518","0.2720","76.9518","51.3012","27.2006","0.0000"
"92.5200","77.1016","0.2727","77.1016","51.4011","27.2732","0.0000"
"92.7000","77.2520","0.2728","77.2520","51.5013","27.2822","0.0000"
"92.8800","77.4018","0.2727","77.4018","51.6012","27.2737","0.0000"
"93.0600","77.5518","0.2731","77.5518","51.7012","27.3147","0.0000"
"93.2400","77.7017","0.2735","77.7017","51.8011","27.3533","0.0000"
"93.4200","77.8517","0.2738","77.8517","51.9012","27.3772","0.0000"
"93.6000","78.0021","0.2740","78.0021","52.0014","27.3996","0.0000"
"93.7800","78.1514","0.2736","78.1514","52.1009","27.3558","0.0000"
"93.9600","78.3018","0.2727","78.3018","52.2012","27.2668","0.0000"
"94.1400","78.4518","0.2721","78.4518","52.3012","27.2080","0.0000"
"94.3200","78.6019","0.2707","78.6019","52.4012","27.0717","0.0000"
"94.5000","78.7517","0.2693","78.7517","52.5011","26.9326","0.0000"
"94.6800","78.9018","0.2688","78.9018","52.6012","26.8817","0.0000"
"94.8600","79.0520","0.2686","79.0520","52.7013","26.8556","0.0000"
"95.0400","79.2015","0.2682","79.2015","52.8010","26.8229","0.0000"
"95.2200","79.3518","0.2680","79.3518","52.9012","26.8011","0.0000"
"95.4000","79.5017","0.2673","79.5017","53.0011","26.7311","0.0000"
"95.5800","79.6518","0.2668","79.6518","53.1012","26.6779","0.0000"
"95.7600","79.8018","0.2652","79.8018","53.2012","26.5196","0.0000"
"95.9400","79.9515","0.2633","79.9515","53.3010","26.3347","0.0000"
"96.1200","80.1020","0.2621","80.1020","53.4013","26.2118","0.0000"
"96.3000","80.2518","0.2611","80.2518","53.5012","26.1109","0.0000"
"96.4800","80.4017","0.2602","80.4017","53.6012","26.0192","0.0000"
"96.6600","80.5517","0.2576","80.5517","53.7011","25.7627","0.0000"
"96.8400","80.7020","0.2546","80.7020","53.8013","25.4628","0.0000"
"97.0200","80.8519","0.2518","80.8519","53.9013","25.1810","0.0000"
"97.2000","81.0016","0.2498","81.0016","54.0011","24.9773","0.0000"
"97.3800","81.1517","0.2486","81.1517","54.1012","24.8587","0.0000"
"97.5600","81.3022","0.2468","81.3022","54.2014","24.6759","0.0000"
"97.7400","81.4514","0.2441","81.4514","54.3009","24.4139","0.0000"
"97.9200","81.6017","0.2410","81.6017","54.4011","24.0961","0.0000"
"98.1000","81.7522","0.2369","81.7522","54.5015","23.6949","0.0000"
"98.2800","81.9019","0.2324","81.9019","54.6012","23.2384","0.0000"
"98.4600","82.0518","0.2267","82.0518","54.7012","22.6724","0.0000"
"98.6400","82.2017","0.2192","82.2017","54.8012","21.9186","0.0000"
"98.8200","82.3518","0.2123","82.3518","54.9012","21.2336","0.0000"
"99.0000","82.5019","0.2047","82.5019","55.0013","20.4732","0.0000"
"99.1800","82.6515","0.1974","82.6515","55.1010","19.7372","0.0000"
"99.3600","82.8019","0.1881","82.8019","55.2013","18.8094","0.0000"
"99.5400","82.9521","0.1791","82.9521","55.3014","17.9067","0.0000"
"99.7200","83.1017","0.1725","83.1017","55.4011","17.2537","0.0000"
"99.9000","83.2518","0.1676","83.2518","55.5012","16.7569","0.0000"
"100.0800","83.4019","0.1635","83.4019","55.6013","16.3513","0.0000"
"100.2600","83.5519","0.1558","83.5519","55.7013","15.5841","0.0000"
"100.4400","83.7017","0.1491","83.7017","55.8012","14.9064","0.0000"
"100.6200","83.8518","0.1364","83.8518","55.9012","13.6427","0.0000"
"100.8000","84.0021","0.1220","84.0021","56.0014","12.1985","0.0000"
"100.9800","84.1521","0.1097","84.1521","56.1014","10.9685","0.0000"
"101.1600","84.3017","0.1006","84.3017","56.2011","10.0593","0.0000"
"101.3400","84.4516","0.0929","84.4516","56.3011","9.2935","0.0000"
"101.5200","84.6019","0.0846","84.6019","56.4013","8.4571","0.0000"
"101.7000","84.7517","0.0793","84.7517","56.5012","7.9346","0.0000"
"101.8800","84.9018","0.0759","84.9018","56.6012","7.5903","0.0000"
"102.0600","85.0519","0.0720","85.0519","56.7013","7.2035","0.0000"
"102.2400","85.2019","0.0689","85.2019","56.8012","6.8932","0.0000"
"102.4200","85.3517","0.0662","85.3517","56.9011","6.6172","0.0000"
"102.6000","85.5020","0.0638","85.5020","57.0013","6.3794","0.0000"
"102.7800","85.6519","0.0610","85.6519","57.1013","6.1037","0.0000"
"102.9600","85.8021","0.0560","85.8021","57.2014","5.5981","0.0000"
"103.1400","85.9518","0.0524","85.9518","57.3012","5.2416","0.0000"
"103.3200","86.1018","0.0491","86.1018","57.4012","4.9067","0.0000"
"103.5000","86.2521","0.0469","86.2521","57.5014","4.6919","0.0000"
"103.6800","86.4016","0.0438","86.4016","57.6010","4.3815","0.0000"
"103.8600","86.5516","0.0353","86.5516","57.7011","3.5284","0.0000"
"104.0400","86.7019","0.0334","86.7019","57.8013","3.3415","0.0000"
"104.2200","86.8517","0.0345","86.8517","57.9011","3.4501","0.0000"
"104.4000","87.0016","0.0352","87.0016","58.0011","3.5163","0.0000"
"104.5800","87.1516","0.0355","87.1516","58.1010","3.5526","0.0000"
"104.7600","87.3020","0.0366","87.3020","58.2013","3.6648","0.0000"
"104.9400","87.4517","0.0368","87.4517","58.3011","3.6765","0.0000"
"105.1200","87.6016","0.0371","87.6016","58.4011","3.7064","0.0000"
"105.3000","87.7513","0.0368","87.7513","58.5009","3.6838","0.0000"
"105.4800","87.9019","0.0370","87.9019","58.6013","3.6964","0.0000"
"105.6600","88.0520","0.0359","88.0520","58.7013","3.5937","0.0000"
"105.8400","88.2016","0.0348","88.2016","58.8010","3.4815","0.0000"
"106.0200","88.3521","0.0344","88.3521","58.9014","3.4448","0.0000"
"106.2000","88.5019","0.0332","88.5019","59.0013","3.3218","0.0000"
"106.3800","88.6515","0.0330","88.6515","59.1010","3.3040","0.0000"
"106.5600","88.8017","0.0333","88.8017","59.2012","3.3264","0.0000"
"106.7400","88.9518","0.0336","88.9518","59.3012","3.3562","0.0000"
"106.9200","89.1021","0.0326","89.1021","59.4014","3.2608","0.0000"
"107.1000","89.2517","0.0327","89.2517","59.5011","3.2662","0.0000"
"107.2800","89.4018","0.0333","89.4018","59.6012","3.3264","0.0000"
"107.4600","89.5520","0.0344","89.5520","59.7013","3.4356","0.0000"
"107.6400","89.7018","0.0353","89.7018","59.8012","3.5258","0.0000"
"107.8200","89.8516","0.0356","89.8516","59.9011","3.5561","0.0000"
"108.0000","90.0017","0.0360","90.0017","60.0011","3.5954","0.0000"
"108.1800","90.1518","0.0360","90.1518","60.1012","3.5972","0.0000"
"108.3600","90.3016","0.0357","90.3016","60.2011","3.5661","0.0000"
"108.5400","90.4518","0.0353","90.4518","60.3012","3.5297","0.0000"
"108.7200","90.6016","0.0321","90.6016","60.4011","3.2132","0.0000"
"108.9000","90.7519","0.0318","90.7519","60.5013","3.1782","0.0000"
"109.0800","90.9015","0.0324","90.9015","60.6010","3.2417","0.0000"
"109.2600","91.0518","0.0331","91.0518","60.7012","3.3136","0.0000"
"109.4400","91.2018","0.0337","91.2018","60.8012","3.3718","0.0000"
"109.6200","91.3520","0.0361","91.3520","60.9013","3.6090","0.0000"
"109.8000","91.5017","0.0396","91.5017","61.0011","3.9642","0.0000"
"109.9800","91.6517","0.0446","91.6517","61.1012","4.4613","0.0000"
"110.1600","91.8019","0.0524","91.8019","61.2013","5.2368","0.0000"
"110.3400","91.9518","0.0682","91.9518","61.3012","6.8171","0.0000"
"110.5200","92.1013","0.1002","92.1013","61.4008","10.0228","0.0000"
"110.7000","92.2518","0.1498","92.2518","61.5012","14.9794","0.0000"
"110.8800","92.4017","0.2048","92.4017","61.6012","20.4763","0.0000"
"111.0600","92.5518","0.2611","92.5518","61.7012","26.1066","0.0000"
"111.2400","92.7017","0.3202","92.7017","61.8011","32.0167","0.0000"
"111.4200","92.8518","0.3818","92.8518","61.9012","38.1751","0.0000"
"111.6000","93.0017","0.4461","93.0017","62.0011","44.6139","0.0000"
"111.7800","93.1515","0.5117","93.1515","62.1010","51.1672","0.0000"
"111.9600","93.3017","0.5790","93.3017","62.2011","57.8959","0.0000"
"112.1400","93.4518","0.6474","93.4518","62.3012","64.7444","0.0000"
"112.3200","93.6016","0.7150","93.6016","62.4011","71.4988","0.0000"
"112.5000","93.7515","0.7774","93.7515","62.5010","77.7383","0.0000"
"112.6800","93.9016","0.8380","93.9016","62.6011","83.7962","0.0000"
"112.8600","94.0518","0.8959","94.0518","62.7012","89.5929","0.0000"
"113.0400","94.2015","0.9400","94.2015","62.8010","93.9952","0.0000"
"113.2200","94.3517","0.9737","94.3517","62.9011","97.3683","0.0000"
"113.4000","94.5016","1.0062","94.5016","63.0011","100.6190","0.0000"
"113.5800","94.6519","1.0354","94.6519","63.1012","103.5371","0.0000"
"113.7600","94.8014","1.0604","94.8014","63.2010","106.0386","0.0000"
"113.9400","94.9520","1.0897","94.9520","63.3013","108.9658","0.0000"
"114.1200","95.1018","1.1215","95.1018","63.4012","112.1511","0.0000"
"114.3000","95.2519","1.1542","95.2519","63.5013","115.4203","0.0000"
"114.4800","95.4016","1.1866","95.4016","63.6011","118.6573","0.0000"
"114.6600","95.5519","1.2181","95.5519","63.7013","121.8137","0.0000"
"114.8400","95.7019","1.2475","95.7019","63.8012","124.7527","0.0000"
"115.0200","95.8518","1.2740","95.8518","63.9012","127.4026","0.0000"
"115.2000","96.0015","1.2999","96.0015","64.0010","129.9946","0.0000"
"115.3800","96.1515","1.3290","96.1515","64.1010","132.8980","0.0000"
"115.5600","96.3019","1.3599","96.3019","64.2013","135.9862","0.0000"
"115.7400","96.4514","1.3898","96.4514","64.3009","138.9808","0.0000"
"115.9200","96.6017","1.4179","96.6017","64.4011","141.7862","0.0000"
"116.1000","96.7522","1.4457","96.7522","64.5015","144.5723","0.0000"
"116.2800","96.9017","1.4765","96.9017","64.6011","147.6453","0.0000"
"116.4600","97.0515","1.5088","97.0515","64.7010","150.8766","0.0000"
"116.6400","97.2015","1.5436","97.2015","64.8010","154.3551","0.0000"
"116.8200","97.3522","1.5788","97.3522","64.9014","157.8846","0.0000"
"117.0000","97.5017","1.6140","97.5017","65.0012","161.3955","0.0000"
"117.1800","97.6514","1.6519","97.6514","65.1009","165.1909","0.0000"
"117.3600","97.8019","1.6902","97.8019","65.2013","169.0184","0.0000"
"117.5400","97.9517","1.7258","97.9517","65.3012","172.5785","0.0000"
"117.7200","98.1015","1.7583","98.1015","65.4010","175.8301","0.0000"
"117.9000","98.2519","1.7929","98.2519","65.5012","179.2934","0.0000"
"118.0800","98.4017","1.8299","98.4017","65.6011","182.9897","0.0000"
"118.2600","98.5519","1.8678","98.5519","65.7013","186.7817","0.0000"
"118.4400","98.7018","1.9100","98.7018","65.8012","190.9985","0.0000"
"118.6200","98.8517","1.9499","98.8517","65.9011","194.9922","0.0000"
"118.8000","99.0021","1.9875","99.0021","66.0014","198.7538","0.0000"
"118.9800","99.1513","2.0307","99.1513","66.1009","203.0669","0.0000"
"119.1600","99.3016","2.0789","99.3016","66.2011","207.8940","0.0000"
"119.3400","99.4518","2.1284","99.4518","66.3012","212.8398","0.0000"
"119.5200","99.6019","2.1773","99.6019","66.4013","217.7296","0.0000"
"119.7000","99.7517","2.2207","99.7517","66.5012","222.0696","0.0000"
"119.8800","99.9016","2.2642","99.9016","66.6010","226.4231","0.0000"
"120.0600","100.0518","2.3092","100.0518","66.7012","230.9237","0.0000"
"120.2400","100.2018","2.3531","100.2018","66.8012","235.3072","0.0000"
"120.4200","100.3516","2.3946","100.3516","66.9011","239.4614","0.0000"
"120.6000","100.5018","2.4362","100.5018","67.0012","243.6212","0.0000"
"120.7800","100.6516","2.4767","100.6516","67.1010","247.6728","0.0000"
"120.9600","100.8016","2.5166","100.8016","67.2011","251.6554","0.0000"
"121.1400","100.9513","2.5552","100.9513","67.3009","255.5225","0.0000"
"121.3200","101.1021","2.5952","101.1021","67.4014","259.5172","0.0000"
"121.5000","101.2518","2.6324","101.2518","67.5012","263.2402","0.0000"
"121.6800","101.4018","2.6701","101.4018","67.6012","267.0142","0.0000"
"121.8600","101.5515","2.7060","101.5515","67.7010","270.5953","0.0000"
"122.0400","101.7020","2.7409","101.7020","67.8014","274.0884","0.0000"
"122.2200","101.8515","2.7741","101.8515","67.9010","277.4123","0.0000"
"122.4000","102.0019","2.8071","102.0019","68.0013","280.7089","0.0000"
"122.5800","102.1517","2.8381","102.1517","68.1011","283.8115","0.0000"
"122.7600","102.3019","2.8695","102.3019","68.2012","286.9539","0.0000"
"122.9400","102.4516","2.9007","102.4516","68.3010","290.0682","0.0000"
"123.1200","102.6017","2.9349","102.6017","68.4012","293.4942","0.0000"
"123.3000","102.7518","2.9676","102.7518","68.5012","296.7563","0.0000"
"123.4800","102.9018","3.0030","102.9018","68.6012","300.2995","0.0000"
"123.6600","103.0514","3.0378","103.0514","68.7009","303.7770","0.0000"
"123.8400","103.2018","3.0742","103.2018","68.8012","307.4196","0.0000"
"124.0200","103.3516","3.1124","103.3516","68.9011","311.2420","0.0000"
"124.2000","103.5020","3.1518","103.5020","69.0013","315.1756","0.0000"
"124.3800","103.6516","3.1908","103.6516","69.1011","319.0801","0.0000"
"124.5600","103.8018","3.2292","103.8018","69.2012","322.9157","0.0000"
"124.7400","103.9518","3.2697","103.9518","69.3012","326.9736","0.0000"
"124.9200","104.1016","3.3129","104.1016","69.4011","331.2905","0.0000"
"125.1000","104.2517","3.3566","104.2517","69.5011","335.6578","0.0000"
"125.2800","104.4015","3.3997","104.4015","69.6010","339.9705","0.0000"
"125.4600","104.5518","3.4433","104.5518","69.7012","344.3272","0.0000"
"125.6400","104.7015","3.4844","104.7015","69.8010","348.4418","0.0000"
"125.8200","104.8514","3.5224","104.8514","69.9009","352.2415","0.0000"
"126.0000","105.0018","3.5640","105.0018","70.0012","356.4031","0.0000"
"126.1800","105.1517","3.6060","105.1517","70.1011","360.6015","0.0000"
"126.3600","105.3017","3.6500","105.3017","70.2011","364.9987","0.0000"
"126.5400","105.4515","3.6909","105.4515","70.3010","369.0855","0.0000"
"126.7200","105.6015","3.7278","105.6015","70.4010","372.7827","0.0000"
"126.9000","105.7520","3.7636","105.7520","70.5014","376.3633","0.0000"
"127.0800","105.9016","3.7980","105.9016","70.6011","379.7975","0.0000"
"127.2600","106.0517","3.8327","106.0517","70.7011","383.2738","0.0000"
"127.4400","106.2020","3.8716","106.2020","70.8013","387.1588","0.0000"
"127.6200","106.3516","3.9126","106.3516","70.9011","391.2560","0.0000"
"127.8000","106.5017","3.9513","106.5017","71.0011","395.1336","0.0000"
"127.9800","106.6515","3.9915","106.6515","71.1010","399.1510","0.0000"
"128.1600","106.8019","4.0351","106.8019","71.2013","403.5080","0.0000"
"128.3400","106.9515","4.0792","106.9515","71.3010","407.9164","0.0000"
"128.5200","107.1015","4.1224","107.1015","71.4010","412.2363","0.0000"
"128.7000","107.2519","4.1668","107.2519","71.5013","416.6766","0.0000"
"128.8800","107.4016","4.2109","107.4016","71.6011","421.0895","0.0000"
"129.0600","107.5518","4.2535","107.5518","71.7012","425.3515","0.0000"
"129.2400","107.7017","4.2996","107.7017","71.8011","429.9581","0.0000"
"129.4200","107.8517","4.3493","107.8517","71.9011","434.9335","0.0000"
"129.6000","108.0016","4.3949","108.0016","72.0011","439.4911","0.0000"
"129.7800","108.1516","4.4430","108.1516","72.1011","444.2996","0.0000"
"129.9600","108.3017","4.4875","108.3017","72.2011","448.7460","0.0000"
"130.1400","108.4520","4.5308","108.4520","72.3013","453.0780","0.0000"
"130.3200","108.6017","4.5731","108.6017","72.4011","457.3125","0.0000"
"130.5000","108.7517","4.6150","108.7517","72.5011","461.4977","0.0000"
"130.6800","108.9018","4.6551","108.9018","72.6012","465.5116","0.0000"
"130.8600","109.0520","4.6981","109.0520","72.7014","469.8070","0.0000"
"131.0400","109.2013","4.7424","109.2013","72.8008","474.2398","0.0000"
"131.2200","109.3518","4.7877","109.3518","72.9012","478.7704","0.0000"
"131.4000","109.5020","4.8364","109.5020","73.0013","483.6393","0.0000"
"131.5800","109.6515","4.8873","109.6515","73.1010","488.7346","0.0000"
"131.7600","109.8016","4.9367","109.8016","73.2011","493.6742","0.0000"
"131.9400","109.9519","4.9867","109.9519","73.3012","498.6661","0.0000"
"131.9860","109.9902","5.0001","109.9902","73.3268","500.0083","0.0000"