File: Fig6C/211130_Instron/211130/tensile_curtain_3.is_tens_Exports/tensile_curtain_3_2.csv
Results Table 1


Results Table 2


Time,Displacement,Force,Tensile displacement,Tensile strain (Displacement),Tensile stress
(s),(mm),(kN),(mm),(%),(MPa)
"0.0000","0.0532","0.0002","0.0532","0.1087","0.0992"
"0.0200","0.0554","0.0002","0.0554","0.1130","0.0959"
"0.0400","0.0633","0.0003","0.0633","0.1291","0.1233"
"0.0600","0.0797","0.0004","0.0797","0.1626","0.1636"
"0.0800","0.1016","0.0005","0.1016","0.2074","0.2166"
"0.1000","0.1247","0.0007","0.1247","0.2544","0.2763"
"0.1200","0.1459","0.0008","0.1459","0.2978","0.3407"
"0.1400","0.1654","0.0010","0.1654","0.3375","0.4151"
"0.1600","0.1839","0.0012","0.1839","0.3754","0.4831"
"0.1800","0.2018","0.0013","0.2018","0.4117","0.5541"
"0.2000","0.2191","0.0015","0.2191","0.4472","0.6300"
"0.2200","0.2362","0.0017","0.2362","0.4821","0.6880"
"0.2400","0.2531","0.0018","0.2531","0.5166","0.7435"
"0.2600","0.2696","0.0019","0.2696","0.5503","0.7981"
"0.2800","0.2864","0.0020","0.2864","0.5845","0.8523"
"0.3000","0.3032","0.0022","0.3032","0.6187","0.9033"
"0.3200","0.3199","0.0023","0.3199","0.6529","0.9576"
"0.3400","0.3367","0.0024","0.3367","0.6871","0.9943"
"0.3600","0.3535","0.0025","0.3535","0.7213","1.0315"
"0.3800","0.3699","0.0026","0.3699","0.7548","1.0865"
"0.4000","0.3865","0.0027","0.3865","0.7888","1.1315"
"0.4200","0.4030","0.0028","0.4030","0.8225","1.1815"
"0.4400","0.4197","0.0030","0.4197","0.8565","1.2314"
"0.4600","0.4366","0.0031","0.4366","0.8910","1.2911"
"0.4800","0.4535","0.0032","0.4535","0.9254","1.3457"
"0.5000","0.4701","0.0033","0.4701","0.9594","1.3544"
"0.5200","0.4866","0.0034","0.4866","0.9931","1.3961"
"0.5400","0.5033","0.0035","0.5033","1.0271","1.4666"
"0.5600","0.5198","0.0036","0.5198","1.0608","1.5021"
"0.5800","0.5366","0.0037","0.5366","1.0950","1.5401"
"0.6000","0.5534","0.0038","0.5534","1.1295","1.5681"
"0.6200","0.5702","0.0039","0.5702","1.1637","1.6114"
"0.6400","0.5870","0.0040","0.5870","1.1979","1.6480"
"0.6600","0.6035","0.0040","0.6035","1.2316","1.6755"
"0.6800","0.6198","0.0041","0.6198","1.2649","1.7069"
"0.7000","0.6363","0.0042","0.6363","1.2986","1.7331"
"0.7200","0.6528","0.0043","0.6528","1.3323","1.7742"
"0.7400","0.6696","0.0044","0.6696","1.3666","1.8150"
"0.7600","0.6865","0.0044","0.6865","1.4010","1.8529"
"0.7800","0.7034","0.0045","0.7034","1.4355","1.8828"
"0.8000","0.7200","0.0046","0.7200","1.4694","1.9064"
"0.8200","0.7365","0.0047","0.7365","1.5032","1.9481"
"0.8400","0.7531","0.0047","0.7531","1.5369","1.9713"
"0.8600","0.7698","0.0048","0.7698","1.5711","1.9822"
"0.8800","0.7866","0.0048","0.7866","1.6053","2.0120"
"0.9000","0.8034","0.0049","0.8034","1.6395","2.0233"
"0.9200","0.8202","0.0049","0.8202","1.6740","2.0440"
"0.9400","0.8369","0.0050","0.8369","1.7080","2.0850"
"0.9600","0.8533","0.0050","0.8533","1.7414","2.1031"
"0.9800","0.8697","0.0051","0.8697","1.7749","2.1239"
"1.0000","0.8864","0.0052","0.8864","1.8089","2.1484"
"1.0200","0.9032","0.0053","0.9032","1.8434","2.1886"
"1.0400","0.9200","0.0053","0.9200","1.8776","2.1975"
"1.0600","0.9367","0.0053","0.9367","1.9115","2.2182"
"1.0800","0.9533","0.0054","0.9533","1.9455","2.2516"
"1.1000","0.9698","0.0054","0.9698","1.9792","2.2647"
"1.1200","0.9861","0.0055","0.9861","2.0125","2.2769"
"1.1400","1.0029","0.0055","1.0029","2.0467","2.2822"
"1.1600","1.0198","0.0055","1.0198","2.0812","2.3036"
"1.1800","1.0365","0.0056","1.0365","2.1154","2.3247"
"1.2000","1.0533","0.0056","1.0533","2.1496","2.3383"
"1.2200","1.0701","0.0057","1.0701","2.1838","2.3590"
"1.2400","1.0867","0.0057","1.0867","2.2178","2.3785"
"1.2600","1.1031","0.0058","1.1031","2.2512","2.3981"
"1.2800","1.1196","0.0059","1.1196","2.2850","2.4516"
"1.3000","1.1364","0.0059","1.1364","2.3192","2.4710"
"1.3200","1.1534","0.0060","1.1534","2.3539","2.4894"
"1.3400","1.1700","0.0060","1.1700","2.3879","2.5033"
"1.3600","1.1866","0.0060","1.1866","2.4216","2.5170"
"1.3800","1.2033","0.0061","1.2033","2.4558","2.5288"
"1.4000","1.2199","0.0061","1.2199","2.4895","2.5409"
"1.4200","1.2364","0.0062","1.2364","2.5233","2.5660"
"1.4400","1.2532","0.0062","1.2532","2.5575","2.5820"
"1.4600","1.2700","0.0062","1.2700","2.5919","2.5953"
"1.4800","1.2868","0.0063","1.2868","2.6261","2.6222"
"1.5000","1.3033","0.0063","1.3033","2.6599","2.6365"
"1.5200","1.3197","0.0064","1.3197","2.6934","2.6601"
"1.5400","1.3363","0.0064","1.3363","2.7271","2.6853"
"1.5600","1.3530","0.0065","1.3530","2.7613","2.7039"
"1.5800","1.3697","0.0065","1.3697","2.7953","2.7179"
"1.6000","1.3867","0.0066","1.3867","2.8300","2.7325"
"1.6200","1.4036","0.0066","1.4036","2.8644","2.7554"
"1.6400","1.4202","0.0067","1.4202","2.8984","2.7798"
"1.6600","1.4366","0.0067","1.4366","2.9319","2.8073"
"1.6800","1.4531","0.0068","1.4531","2.9656","2.8436"
"1.7000","1.4698","0.0069","1.4698","2.9996","2.8635"
"1.7200","1.4863","0.0069","1.4863","3.0333","2.8768"
"1.7400","1.5030","0.0069","1.5030","3.0673","2.8886"
"1.7600","1.5200","0.0070","1.5200","3.1020","2.9038"
"1.7800","1.5367","0.0070","1.5367","3.1362","2.9375"
"1.8000","1.5531","0.0071","1.5531","3.1697","2.9547"
"1.8200","1.5697","0.0071","1.5697","3.2034","2.9750"
"1.8400","1.5862","0.0072","1.5862","3.2371","2.9991"
"1.8600","1.6030","0.0072","1.6030","3.2713","3.0096"
"1.8800","1.6197","0.0073","1.6197","3.3056","3.0223"
"1.9000","1.6366","0.0073","1.6366","3.3400","3.0294"
"1.9200","1.6535","0.0073","1.6535","3.3745","3.0542"
"1.9400","1.6701","0.0074","1.6701","3.4084","3.0731"
"1.9600","1.6864","0.0074","1.6864","3.4417","3.0707"
"1.9800","1.7030","0.0074","1.7030","3.4754","3.0921"
"2.0000","1.7200","0.0074","1.7200","3.5101","3.1026"
"2.0200","1.7366","0.0075","1.7366","3.5441","3.1112"
"2.0400","1.7531","0.0075","1.7531","3.5778","3.1254"
"2.0600","1.7699","0.0075","1.7699","3.6120","3.1074"
"2.0800","1.7867","0.0075","1.7867","3.6462","3.1098"
"2.1000","1.8029","0.0075","1.8029","3.6795","3.1373"
"2.1200","1.8195","0.0076","1.8195","3.7132","3.1510"
"2.1400","1.8365","0.0076","1.8365","3.7479","3.1596"
"2.1600","1.8532","0.0076","1.8532","3.7821","3.1684"
"2.1800","1.8698","0.0076","1.8698","3.8158","3.1783"
"2.2000","1.8865","0.0076","1.8865","3.8501","3.1753"
"2.2200","1.9033","0.0077","1.9033","3.8843","3.2028"
"2.2400","1.9197","0.0077","1.9197","3.9178","3.2257"
"2.2600","1.9360","0.0078","1.9360","3.9510","3.2485"
"2.2800","1.9530","0.0079","1.9530","3.9857","3.2728"
"2.3000","1.9700","0.0079","1.9700","4.0204","3.2915"
"2.3200","1.9868","0.0079","1.9868","4.0546","3.3021"
"2.3400","2.0030","0.0080","2.0030","4.0879","3.3186"
"2.3600","2.0198","0.0080","2.0198","4.1221","3.3425"
"2.3800","2.0365","0.0081","2.0365","4.1560","3.3745"
"2.4000","2.0527","0.0081","2.0527","4.1893","3.3941"
"2.4200","2.0696","0.0083","2.0696","4.2237","3.4464"
"2.4400","2.0867","0.0083","2.0867","4.2587","3.4629"
"2.4600","2.1036","0.0084","2.1036","4.2931","3.4977"
"2.4800","2.1202","0.0084","2.1202","4.3269","3.4813"
"2.5000","2.1367","0.0084","2.1367","4.3606","3.4820"
"2.5200","2.1535","0.0084","2.1535","4.3948","3.5082"
"2.5400","2.1699","0.0085","2.1699","4.4283","3.5217"
"2.5600","2.1864","0.0085","2.1864","4.4620","3.5413"
"2.5800","2.2033","0.0086","2.2033","4.4965","3.5734"
"2.6000","2.2200","0.0086","2.2200","4.5307","3.6032"
"2.6200","2.2364","0.0087","2.2364","4.5642","3.6303"
"2.6400","2.2531","0.0088","2.2531","4.5981","3.6514"
"2.6600","2.2699","0.0088","2.2699","4.6324","3.6718"
"2.6800","2.2864","0.0089","2.2864","4.6661","3.7023"
"2.7000","2.3029","0.0089","2.3029","4.6998","3.7121"
"2.7200","2.3197","0.0090","2.3197","4.7340","3.7405"
"2.7400","2.3367","0.0090","2.3367","4.7687","3.7675"
"2.7600","2.3534","0.0091","2.3534","4.8029","3.7787"
"2.7800","2.3697","0.0091","2.3697","4.8362","3.7930"
"2.8000","2.3864","0.0091","2.3864","4.8702","3.8019"
"2.8200","2.4030","0.0092","2.4030","4.9041","3.8221"
"2.8400","2.4198","0.0093","2.4198","4.9383","3.8580"
"2.8600","2.4363","0.0093","2.4363","4.9721","3.8953"
"2.8800","2.4532","0.0094","2.4532","5.0065","3.9196"
"2.9000","2.4702","0.0094","2.4702","5.0412","3.9335"
"2.9200","2.4868","0.0095","2.4868","5.0752","3.9511"
"2.9400","2.5034","0.0095","2.5034","5.1089","3.9762"
"2.9600","2.5198","0.0096","2.5198","5.1424","3.9980"
"2.9800","2.5364","0.0096","2.5364","5.1764","4.0108"
"3.0000","2.5531","0.0097","2.5531","5.2103","4.0243"
"3.0200","2.5697","0.0097","2.5697","5.2443","4.0579"
"3.0400","2.5867","0.0098","2.5867","5.2790","4.0824"
"3.0600","2.6035","0.0099","2.6035","5.3132","4.1063"
"3.0800","2.6198","0.0099","2.6198","5.3465","4.1304"
"3.1000","2.6364","0.0099","2.6364","5.3804","4.1338"
"3.1200","2.6532","0.0099","2.6532","5.4147","4.1414"
"3.1400","2.6699","0.0100","2.6699","5.4489","4.1683"
"3.1600","2.6866","0.0101","2.6866","5.4828","4.1974"
"3.1800","2.7032","0.0101","2.7032","5.5168","4.2121"
"3.2000","2.7202","0.0101","2.7202","5.5515","4.2200"
"3.2200","2.7365","0.0102","2.7365","5.5847","4.2467"
"3.2400","2.7528","0.0103","2.7528","5.6180","4.2717"
"3.2600","2.7696","0.0103","2.7696","5.6522","4.2956"
"3.2800","2.7866","0.0103","2.7866","5.6869","4.3055"
"3.3000","2.8033","0.0104","2.8033","5.7211","4.3133"
"3.3200","2.8200","0.0104","2.8200","5.7551","4.3482"
"3.3400","2.8368","0.0105","2.8368","5.7893","4.3866"
"3.3600","2.8534","0.0106","2.8534","5.8233","4.4039"
"3.3800","2.8696","0.0106","2.8696","5.8563","4.4215"
"3.4000","2.8860","0.0107","2.8860","5.8898","4.4476"
"3.4200","2.9031","0.0107","2.9031","5.9247","4.4678"
"3.4400","2.9201","0.0108","2.9201","5.9594","4.4953"
"3.4600","2.9365","0.0109","2.9365","5.9929","4.5295"
"3.4800","2.9535","0.0109","2.9535","6.0276","4.5578"
"3.5000","2.9702","0.0110","2.9702","6.0615","4.5666"
"3.5200","2.9865","0.0110","2.9865","6.0948","4.5912"
"3.5400","3.0029","0.0111","3.0029","6.1283","4.6232"
"3.5600","3.0197","0.0112","3.0197","6.1627","4.6489"
"3.5800","3.0365","0.0112","3.0365","6.1970","4.6521"
"3.6000","3.0530","0.0112","3.0530","6.2307","4.6721"
"3.6200","3.0698","0.0112","3.0698","6.2649","4.6818"
"3.6400","3.0866","0.0113","3.0866","6.2991","4.7194"
"3.6600","3.1032","0.0114","3.1032","6.3331","4.7442"
"3.6800","3.1196","0.0115","3.1196","6.3666","4.7748"
"3.7000","3.1365","0.0115","3.1365","6.4010","4.7923"
"3.7200","3.1535","0.0115","3.1535","6.4357","4.8124"
"3.7400","3.1700","0.0116","3.1700","6.4694","4.8407"
"3.7600","3.1866","0.0117","3.1866","6.5032","4.8600"
"3.7800","3.2033","0.0117","3.2033","6.5374","4.8934"
"3.8000","3.2200","0.0118","3.2200","6.5714","4.9155"
"3.8200","3.2365","0.0119","3.2365","6.6051","4.9516"
"3.8400","3.2531","0.0120","3.2531","6.6391","4.9812"
"3.8600","3.2701","0.0120","3.2701","6.6738","4.9946"
"3.8800","3.2869","0.0121","3.2869","6.7080","5.0274"
"3.9000","3.3033","0.0121","3.3033","6.7415","5.0581"
"3.9200","3.3200","0.0122","3.3200","6.7754","5.0837"
"3.9400","3.3367","0.0123","3.3367","6.8096","5.1047"
"3.9600","3.3532","0.0123","3.3532","6.8434","5.1259"
"3.9800","3.3697","0.0123","3.3697","6.8769","5.1396"
"4.0000","3.3864","0.0125","3.3864","6.9111","5.1984"
"4.0200","3.4034","0.0126","3.4034","6.9458","5.2380"
"4.0400","3.4201","0.0126","3.4201","6.9797","5.2599"
"4.0600","3.4365","0.0126","3.4365","7.0132","5.2483"
"4.0800","3.4532","0.0126","3.4532","7.0474","5.2473"
"4.1000","3.4699","0.0126","3.4699","7.0814","5.2616"
"4.1200","3.4865","0.0127","3.4865","7.1154","5.2882"
"4.1400","3.5033","0.0128","3.5033","7.1496","5.3269"
"4.1600","3.5201","0.0128","3.5201","7.1838","5.3536"
"4.1800","3.5368","0.0129","3.5368","7.2180","5.3769"
"4.2000","3.5532","0.0130","3.5532","7.2515","5.4012"
"4.2200","3.5696","0.0130","3.5696","7.2850","5.4343"
"4.2400","3.5864","0.0131","3.5864","7.3192","5.4557"
"4.2600","3.6031","0.0132","3.6031","7.3532","5.4828"
"4.2800","3.6197","0.0132","3.6197","7.3871","5.5086"
"4.3000","3.6367","0.0133","3.6367","7.4218","5.5466"
"4.3200","3.6536","0.0134","3.6536","7.4563","5.5902"
"4.3400","3.6700","0.0135","3.6700","7.4898","5.6172"
"4.3600","3.6863","0.0135","3.6863","7.5230","5.6317"
"4.3800","3.7029","0.0136","3.7029","7.5570","5.6677"
"4.4000","3.7199","0.0136","3.7199","7.5917","5.6840"
"4.4200","3.7367","0.0138","3.7367","7.6259","5.7352"
"4.4400","3.7533","0.0139","3.7533","7.6599","5.7719"
"4.4600","3.7702","0.0139","3.7702","7.6943","5.7876"
"4.4800","3.7870","0.0139","3.7870","7.7285","5.8077"
"4.5000","3.8033","0.0140","3.8033","7.7618","5.8357"
"4.5200","3.8196","0.0141","3.8196","7.7950","5.8692"
"4.5400","3.8366","0.0142","3.8366","7.8297","5.9051"
"4.5600","3.8533","0.0142","3.8533","7.8639","5.9266"
"4.5800","3.8699","0.0143","3.8699","7.8977","5.9558"
"4.6000","3.8866","0.0144","3.8866","7.9319","5.9851"
"4.6200","3.9035","0.0144","3.9035","7.9663","6.0202"
"4.6400","3.9199","0.0145","3.9199","7.9998","6.0394"
"4.6600","3.9361","0.0146","3.9361","8.0328","6.0698"
"4.6800","3.9529","0.0146","3.9529","8.0670","6.0979"
"4.7000","3.9701","0.0147","3.9701","8.1022","6.1095"
"4.7200","3.9867","0.0147","3.9867","8.1362","6.1383"
"4.7400","4.0033","0.0148","4.0033","8.1699","6.1819"
"4.7600","4.0200","0.0149","4.0200","8.2041","6.2022"
"4.7800","4.0368","0.0150","4.0368","8.2383","6.2310"
"4.8000","4.0530","0.0150","4.0530","8.2714","6.2460"
"4.8200","4.0696","0.0151","4.0696","8.3053","6.2788"
"4.8400","4.0866","0.0151","4.0866","8.3400","6.3033"
"4.8600","4.1034","0.0152","4.1034","8.3742","6.3361"
"4.8800","4.1200","0.0153","4.1200","8.4082","6.3759"
"4.9000","4.1365","0.0154","4.1365","8.4419","6.3970"
"4.9200","4.1534","0.0155","4.1534","8.4764","6.4471"
"4.9400","4.1698","0.0155","4.1698","8.5099","6.4791"
"4.9600","4.1862","0.0156","4.1862","8.5434","6.5089"
"4.9800","4.2031","0.0157","4.2031","8.5778","6.5449"
"5.0000","4.2201","0.0158","4.2201","8.6125","6.5669"
"5.0200","4.2365","0.0158","4.2365","8.6460","6.6020"
"5.0400","4.2531","0.0159","4.2531","8.6797","6.6388"
"5.0600","4.2698","0.0160","4.2698","8.7139","6.6680"
"5.0800","4.2865","0.0161","4.2865","8.7479","6.6922"
"5.1000","4.3029","0.0161","4.3029","8.7814","6.7228"
"5.1200","4.3195","0.0162","4.3195","8.8154","6.7626"
"5.1400","4.3367","0.0163","4.3367","8.8503","6.7907"
"5.1600","4.3535","0.0164","4.3535","8.8848","6.8173"
"5.1800","4.3701","0.0164","4.3701","8.9185","6.8173"
"5.2000","4.3866","0.0165","4.3866","8.9522","6.8714"
"5.2200","4.4031","0.0167","4.4031","8.9860","6.9387"
"5.2400","4.4199","0.0167","4.4199","9.0202","6.9653"
"5.2600","4.4364","0.0168","4.4364","9.0539","6.9821"
"5.2800","4.4532","0.0168","4.4532","9.0881","7.0130"
"5.3000","4.4702","0.0169","4.4702","9.1228","7.0461"
"5.3200","4.4868","0.0170","4.4868","9.1568","7.0800"
"5.3400","4.5032","0.0171","4.5032","9.1903","7.1135"
"5.3600","4.5199","0.0171","4.5199","9.2242","7.1396"
"5.3800","4.5365","0.0172","4.5365","9.2582","7.1625"
"5.4000","4.5532","0.0172","4.5532","9.2922","7.1813"
"5.4200","4.5698","0.0173","4.5698","9.3261","7.2165"
"5.4400","4.5868","0.0174","4.5868","9.3608","7.2404"
"5.4600","4.6036","0.0174","4.6036","9.3951","7.2544"
"5.4800","4.6200","0.0175","4.6200","9.4285","7.2841"
"5.5000","4.6364","0.0175","4.6364","9.4620","7.3017"
"5.5200","4.6532","0.0176","4.6532","9.4962","7.3462"
"5.5400","4.6702","0.0177","4.6702","9.5309","7.3941"
"5.5600","4.6867","0.0179","4.6867","9.5647","7.4386"
"5.5800","4.7033","0.0179","4.7033","9.5986","7.4724"
"5.6000","4.7202","0.0180","4.7202","9.6331","7.4797"
"5.6200","4.7367","0.0180","4.7367","9.6668","7.4953"
"5.6400","4.7530","0.0180","4.7530","9.7001","7.5024"
"5.6600","4.7697","0.0181","4.7697","9.7340","7.5252"
"5.6800","4.7867","0.0181","4.7867","9.7687","7.5581"
"5.7000","4.8032","0.0182","4.8032","9.8025","7.6007"
"5.7200","4.8199","0.0183","4.8199","9.8364","7.6347"
"5.7400","4.8366","0.0184","4.8366","9.8706","7.6644"
"5.7600","4.8533","0.0185","4.8533","9.9046","7.6906"
"5.7800","4.8696","0.0185","4.8696","9.9379","7.7257"
"5.8000","4.8861","0.0186","4.8861","9.9716","7.7610"
"5.8200","4.9031","0.0187","4.9031","10.0063","7.7975"
"5.8400","4.9200","0.0188","4.9200","10.0407","7.8281"
"5.8600","4.9366","0.0188","4.9366","10.0747","7.8498"
"5.8800","4.9534","0.0189","4.9534","10.1089","7.8953"
"5.9000","4.9703","0.0190","4.9703","10.1434","7.9347"
"5.9200","4.9865","0.0192","4.9865","10.1766","7.9811"
"5.9400","5.0028","0.0193","5.0028","10.2099","8.0280"
"5.9600","5.0197","0.0193","5.0197","10.2443","8.0330"
"5.9800","5.0367","0.0194","5.0367","10.2790","8.0821"
"6.0000","5.0532","0.0194","5.0532","10.3128","8.0947"
"6.0200","5.0699","0.0195","5.0699","10.3467","8.1132"
"6.0400","5.0868","0.0195","5.0868","10.3812","8.1346"
"6.0600","5.1033","0.0195","5.1033","10.4149","8.1391"
"6.0800","5.1196","0.0196","5.1196","10.4482","8.1659"
"6.1000","5.1364","0.0196","5.1364","10.4824","8.1792"
"6.1200","5.1534","0.0197","5.1534","10.5171","8.2144"
"6.1400","5.1701","0.0198","5.1701","10.5513","8.2585"
"6.1600","5.1867","0.0199","5.1867","10.5850","8.2884"
"6.1800","5.2034","0.0200","5.2034","10.6192","8.3162"
"6.2000","5.2199","0.0200","5.2199","10.6529","8.3452"
"6.2200","5.2362","0.0202","5.2362","10.6862","8.4005"
"6.2400","5.2528","0.0203","5.2528","10.7199","8.4387"
"6.2600","5.2698","0.0203","5.2698","10.7546","8.4709"
"6.2800","5.2866","0.0204","5.2866","10.7891","8.5073"
"6.3000","5.3033","0.0205","5.3033","10.8230","8.5371"
"6.3200","5.3201","0.0206","5.3201","10.8573","8.5738"
"6.3400","5.3367","0.0207","5.3367","10.8912","8.6061"
"6.3600","5.3532","0.0208","5.3532","10.9250","8.6504"
"6.3800","5.3695","0.0208","5.3695","10.9582","8.6848"
"6.4000","5.3863","0.0209","5.3863","10.9924","8.6941"
"6.4200","5.4033","0.0209","5.4033","11.0271","8.7247"
"6.4400","5.4200","0.0211","5.4200","11.0613","8.7735"
"6.4600","5.4367","0.0212","5.4367","11.0953","8.8158"
"6.4800","5.4533","0.0212","5.4533","11.1293","8.8473"
"6.5000","5.4697","0.0213","5.4697","11.1628","8.8772"
"6.5200","5.4862","0.0214","5.4862","11.1962","8.9167"
"6.5400","5.5028","0.0215","5.5028","11.2302","8.9436"
"6.5600","5.5197","0.0215","5.5197","11.2647","8.9769"
"6.5800","5.5368","0.0216","5.5368","11.2996","9.0099"
"6.6000","5.5533","0.0217","5.5533","11.3333","9.0508"
"6.6200","5.5699","0.0218","5.5699","11.3671","9.0900"
"6.6400","5.5865","0.0219","5.5865","11.4010","9.1266"
"6.6600","5.6033","0.0220","5.6033","11.4352","9.1486"
"6.6800","5.6198","0.0220","5.6198","11.4690","9.1809"
"6.7000","5.6366","0.0221","5.6366","11.5032","9.1960"
"6.7200","5.6537","0.0221","5.6537","11.5381","9.2250"
"6.7400","5.6703","0.0222","5.6703","11.5721","9.2380"
"6.7600","5.6867","0.0222","5.6867","11.6056","9.2693"
"6.7800","5.7030","0.0224","5.7030","11.6388","9.3140"
"6.8000","5.7198","0.0225","5.7198","11.6730","9.3583"
"6.8200","5.7363","0.0225","5.7363","11.7068","9.3930"
"6.8400","5.7530","0.0226","5.7530","11.7407","9.4161"
"6.8600","5.7700","0.0227","5.7700","11.7754","9.4519"
"6.8800","5.7868","0.0228","5.7868","11.8099","9.5043"
"6.9000","5.8033","0.0229","5.8033","11.8434","9.5246"
"6.9200","5.8198","0.0229","5.8198","11.8771","9.5558"
"6.9400","5.8364","0.0231","5.8364","11.9111","9.6085"
"6.9600","5.8532","0.0231","5.8532","11.9453","9.6422"
"6.9800","5.8697","0.0232","5.8697","11.9790","9.6661"
"7.0000","5.8866","0.0233","5.8866","12.0135","9.6888"
"7.0200","5.9035","0.0233","5.9035","12.0479","9.7256"
"7.0400","5.9200","0.0234","5.9200","12.0817","9.7480"
"7.0600","5.9363","0.0234","5.9363","12.1149","9.7584"
"7.0800","5.9530","0.0235","5.9530","12.1489","9.7800"
"7.1000","5.9700","0.0235","5.9700","12.1836","9.7997"
"7.1200","5.9866","0.0235","5.9866","12.2175","9.8009"
"7.1400","6.0032","0.0236","6.0032","12.2515","9.8212"
"7.1600","6.0200","0.0237","6.0200","12.2857","9.8746"
"7.1800","6.0368","0.0239","6.0368","12.3199","9.9430"
"7.2000","6.0531","0.0240","6.0531","12.3532","9.9831"
"7.2200","6.0695","0.0241","6.0695","12.3867","10.0296"
"7.2400","6.0865","0.0242","6.0865","12.4214","10.0695"
"7.2600","6.1034","0.0243","6.1034","12.4558","10.1084"
"7.2800","6.1199","0.0244","6.1199","12.4896","10.1616"
"7.3000","6.1366","0.0244","6.1366","12.5238","10.1870"
"7.3200","6.1536","0.0245","6.1536","12.5585","10.2082"
"7.3400","6.1701","0.0246","6.1701","12.5919","10.2316"
"7.3600","6.1862","0.0246","6.1862","12.6250","10.2561"
"7.3800","6.2030","0.0247","6.2030","12.6592","10.2901"
"7.4000","6.2200","0.0248","6.2200","12.6939","10.3234"
"7.4200","6.2368","0.0249","6.2368","12.7281","10.3639"
"7.4400","6.2533","0.0250","6.2533","12.7618","10.4110"
"7.4600","6.2700","0.0251","6.2700","12.7960","10.4619"
"7.4800","6.2867","0.0252","6.2867","12.8300","10.4908"
"7.5000","6.3030","0.0252","6.3030","12.8632","10.5034"
"7.5200","6.3196","0.0254","6.3196","12.8972","10.5636"
"7.5400","6.3366","0.0254","6.3366","12.9319","10.5764"
"7.5600","6.3536","0.0255","6.3536","12.9666","10.6053"
"7.5800","6.3702","0.0256","6.3702","13.0003","10.6511"
"7.6000","6.3865","0.0257","6.3865","13.0336","10.6918"
"7.6200","6.4031","0.0258","6.4031","13.0675","10.7310"
"7.6400","6.4196","0.0258","6.4196","13.1013","10.7582"
"7.6600","6.4362","0.0259","6.4362","13.1350","10.7945"
"7.6800","6.4530","0.0260","6.4530","13.1695","10.8330"
"7.7000","6.4702","0.0261","6.4702","13.2044","10.8694"
"7.7200","6.4868","0.0262","6.4868","13.2384","10.9013"
"7.7400","6.5033","0.0263","6.5033","13.2721","10.9423"
"7.7600","6.5199","0.0263","6.5199","13.3058","10.9685"
"7.7800","6.5365","0.0264","6.5365","13.3398","10.9950"
"7.8000","6.5530","0.0264","6.5530","13.3735","11.0205"
"7.8200","6.5696","0.0265","6.5696","13.4073","11.0582"
"7.8400","6.5866","0.0266","6.5866","13.4419","11.0925"
"7.8600","6.6036","0.0267","6.6036","13.4766","11.1265"
"7.8800","6.6200","0.0267","6.6200","13.5101","11.1434"
"7.9000","6.6363","0.0268","6.6363","13.5434","11.1678"
"7.9200","6.6530","0.0269","6.6530","13.5776","11.2198"
"7.9400","6.6698","0.0270","6.6698","13.6118","11.2498"
"7.9600","6.6864","0.0270","6.6864","13.6458","11.2680"
"7.9800","6.7032","0.0272","6.7032","13.6800","11.3150"
"8.0000","6.7203","0.0272","6.7203","13.7149","11.3446"
"8.0200","6.7370","0.0273","6.7370","13.7489","11.3843"
"8.0400","6.7531","0.0274","6.7531","13.7819","11.4104"
"8.0600","6.7695","0.0275","6.7695","13.8154","11.4445"
"8.0800","6.7862","0.0275","6.7862","13.8494","11.4728"
"8.1000","6.8028","0.0276","6.8028","13.8833","11.5098"
"8.1200","6.8195","0.0277","6.8195","13.9173","11.5499"
"8.1400","6.8366","0.0278","6.8366","13.9522","11.5822"
"8.1600","6.8534","0.0279","6.8534","13.9864","11.6143"
"8.1800","6.8698","0.0280","6.8698","14.0199","11.6480"
"8.2000","6.8862","0.0280","6.8862","14.0534","11.6790"
"8.2200","6.9031","0.0281","6.9031","14.0879","11.7134"
"8.2400","6.9198","0.0282","6.9198","14.1221","11.7584"
"8.2600","6.9365","0.0283","6.9365","14.1561","11.7903"
"8.2800","6.9534","0.0284","6.9534","14.1905","11.8142"
"8.3000","6.9702","0.0283","6.9702","14.2250","11.8053"
"8.3200","6.9866","0.0284","6.9866","14.2585","11.8179"
"8.3400","7.0029","0.0284","7.0029","14.2917","11.8413"
"8.3600","7.0197","0.0285","7.0197","14.3259","11.8718"
"8.3800","7.0366","0.0286","7.0366","14.3604","11.9050"
"8.4000","7.0531","0.0287","7.0531","14.3941","11.9435"
"8.4200","7.0699","0.0288","7.0699","14.4283","11.9846"
"8.4400","7.0868","0.0288","7.0868","14.4628","12.0172"
"8.4600","7.1033","0.0289","7.1033","14.4965","12.0444"
"8.4800","7.1195","0.0290","7.1195","14.5295","12.0813"
"8.5000","7.1360","0.0290","7.1360","14.5632","12.1014"
"8.5200","7.1530","0.0291","7.1530","14.5979","12.1170"
"8.5400","7.1699","0.0291","7.1699","14.6324","12.1321"
"8.5600","7.1865","0.0292","7.1865","14.6664","12.1693"
"8.5800","7.2033","0.0293","7.2033","14.7006","12.2020"
"8.6000","7.2200","0.0294","7.2200","14.7348","12.2336"
"8.6200","7.2363","0.0294","7.2363","14.7680","12.2574"
"8.6400","7.2529","0.0295","7.2529","14.8018","12.2836"
"8.6600","7.2699","0.0296","7.2699","14.8364","12.3261"
"8.6800","7.2869","0.0297","7.2869","14.8711","12.3755"
"8.7000","7.3036","0.0297","7.3036","14.9054","12.3895"
"8.7200","7.3203","0.0297","7.3203","14.9393","12.3727"
"8.7400","7.3370","0.0297","7.3370","14.9735","12.3946"
"8.7600","7.3533","0.0298","7.3533","15.0068","12.4296"
"8.7800","7.3695","0.0299","7.3695","15.0398","12.4523"
"8.8000","7.3864","0.0299","7.3864","15.0742","12.4788"
"8.8200","7.4034","0.0300","7.4034","15.1089","12.5205"
"8.8400","7.4201","0.0301","7.4201","15.1432","12.5599"
"8.8600","7.4367","0.0302","7.4367","15.1769","12.5972"
"8.8800","7.4533","0.0303","7.4533","15.2109","12.6289"
"8.9000","7.4697","0.0304","7.4697","15.2443","12.6505"
"8.9200","7.4861","0.0304","7.4861","15.2778","12.6793"
"8.9400","7.5030","0.0305","7.5030","15.3123","12.6958"
"8.9600","7.5200","0.0305","7.5200","15.3470","12.7187"
"8.9800","7.5368","0.0306","7.5368","15.3812","12.7645"
"9.0000","7.5534","0.0307","7.5534","15.4152","12.7921"
"9.0200","7.5700","0.0308","7.5700","15.4489","12.8356"
"9.0400","7.5867","0.0309","7.5867","15.4831","12.8659"
"9.0600","7.6031","0.0310","7.6031","15.5166","12.8986"
"9.0800","7.6197","0.0311","7.6197","15.5503","12.9591"
"9.1000","7.6365","0.0311","7.6365","15.5848","12.9723"
"9.1200","7.6535","0.0312","7.6535","15.6195","12.9872"
"9.1400","7.6702","0.0312","7.6702","15.6534","13.0030"
"9.1600","7.6866","0.0313","7.6866","15.6869","13.0379"
"9.1800","7.7031","0.0313","7.7031","15.7207","13.0584"
"9.2000","7.7197","0.0314","7.7197","15.7544","13.0742"
"9.2200","7.7361","0.0314","7.7361","15.7879","13.1028"
"9.2400","7.7529","0.0315","7.7529","15.8223","13.1298"
"9.2600","7.7699","0.0316","7.7699","15.8570","13.1601"
"9.2800","7.7866","0.0317","7.7866","15.8910","13.2018"
"9.3000","7.8031","0.0317","7.8031","15.9247","13.2236"
"9.3200","7.8196","0.0318","7.8196","15.9585","13.2603"
"9.3400","7.8365","0.0319","7.8365","15.9929","13.2714"
"9.3600","7.8532","0.0319","7.8532","16.0269","13.2987"
"9.3800","7.8699","0.0320","7.8699","16.0611","13.3232"
"9.4000","7.8868","0.0320","7.8868","16.0955","13.3452"
"9.4200","7.9038","0.0321","7.9038","16.1302","13.3782"
"9.4400","7.9202","0.0321","7.9202","16.1637","13.3906"
"9.4600","7.9365","0.0321","7.9365","16.1970","13.3861"
"9.4800","7.9530","0.0322","7.9530","16.2307","13.4030"
"9.5000","7.9699","0.0322","7.9699","16.2652","13.4192"
"9.5200","7.9866","0.0322","7.9866","16.2991","13.4323"
"9.5400","8.0031","0.0322","8.0031","16.3329","13.4250"
"9.5600","8.0201","0.0322","8.0201","16.3676","13.4275"
"9.5800","8.0367","0.0323","8.0367","16.4015","13.4493"
"9.6000","8.0530","0.0323","8.0530","16.4348","13.4635"
"9.6200","8.0695","0.0324","8.0695","16.4683","13.4996"
"9.6400","8.0863","0.0325","8.0863","16.5027","13.5274"
"9.6600","8.1032","0.0325","8.1032","16.5372","13.5442"
"9.6800","8.1199","0.0326","8.1199","16.5711","13.5725"
"9.7000","8.1367","0.0327","8.1367","16.6056","13.6147"
"9.7200","8.1537","0.0327","8.1537","16.6403","13.6435"
"9.7400","8.1700","0.0328","8.1700","16.6735","13.6577"
"9.7600","8.1862","0.0328","8.1862","16.7065","13.6771"
"9.7800","8.2030","0.0329","8.2030","16.7408","13.7058"
"9.8000","8.2200","0.0329","8.2200","16.7755","13.7237"
"9.8200","8.2367","0.0330","8.2367","16.8097","13.7701"
"9.8400","8.2531","0.0331","8.2531","16.8432","13.8014"
"9.8600","8.2699","0.0331","8.2699","16.8774","13.7980"
"9.8800","8.2864","0.0332","8.2864","16.9111","13.8349"
"9.9000","8.3026","0.0333","8.3026","16.9441","13.8579"
"9.9200","8.3193","0.0333","8.3193","16.9781","13.8816"
"9.9400","8.3365","0.0334","8.3365","17.0132","13.9023"
"9.9600","8.3533","0.0334","8.3533","17.0475","13.9243"
"9.9800","8.3699","0.0335","8.3699","17.0814","13.9624"
"10.0000","8.3868","0.0336","8.3868","17.1159","13.9899"
"10.0200","8.4035","0.0336","8.4035","17.1501","14.0107"
"10.0400","8.4198","0.0337","8.4198","17.1833","14.0368"
"10.0600","8.4362","0.0337","8.4362","17.2168","14.0621"
"10.0800","8.4532","0.0338","8.4532","17.2515","14.0944"
"10.1000","8.4702","0.0339","8.4702","17.2862","14.1198"
"10.1200","8.4868","0.0339","8.4868","17.3200","14.1456"
"10.1400","8.5034","0.0340","8.5034","17.3539","14.1663"
"10.1600","8.5203","0.0340","8.5203","17.3884","14.1839"
"10.1800","8.5366","0.0341","8.5366","17.4216","14.2086"
"10.2000","8.5529","0.0341","8.5529","17.4549","14.2072"
"10.2200","8.5694","0.0341","8.5694","17.4886","14.2013"
"10.2400","8.5865","0.0341","8.5865","17.5235","14.2285"
"10.2600","8.6034","0.0342","8.6034","17.5580","14.2674"
"10.2800","8.6199","0.0343","8.6199","17.5917","14.2800"
"10.3000","8.6366","0.0343","8.6366","17.6257","14.3100"
"10.3200","8.6532","0.0344","8.6532","17.6597","14.3483"
"10.3400","8.6698","0.0345","8.6698","17.6934","14.3741"
"10.3600","8.6863","0.0346","8.6863","17.7271","14.3983"
"10.3800","8.7032","0.0346","8.7032","17.7616","14.4270"
"10.4000","8.7202","0.0347","8.7202","17.7963","14.4640"
"10.4200","8.7368","0.0347","8.7368","17.8302","14.4763"
"10.4400","8.7533","0.0347","8.7533","17.8640","14.4698"
"10.4600","8.7700","0.0347","8.7700","17.8979","14.4777"
"10.4800","8.7865","0.0348","8.7865","17.9317","14.4939"
"10.5000","8.8032","0.0348","8.8032","17.9656","14.5014"
"10.5200","8.8199","0.0349","8.8199","17.9999","14.5239"
"10.5400","8.8368","0.0349","8.8368","18.0343","14.5570"
"10.5600","8.8535","0.0350","8.8535","18.0683","14.5825"
"10.5800","8.8699","0.0350","8.8699","18.1018","14.6041"
"10.6000","8.8864","0.0351","8.8864","18.1355","14.6164"
"10.6200","8.9032","0.0351","8.9032","18.1697","14.6456"
"10.6400","8.9199","0.0353","8.9199","18.2039","14.6883"
"10.6600","8.9366","0.0353","8.9366","18.2379","14.6958"
"10.6800","8.9533","0.0352","8.9533","18.2721","14.6827"
"10.7000","8.9702","0.0352","8.9702","18.3066","14.6754"
"10.7200","8.9867","0.0353","8.9867","18.3403","14.6924"
"10.7400","9.0032","0.0353","9.0032","18.3738","14.7074"
"10.7600","9.0197","0.0353","9.0197","18.4075","14.7225"
"10.7800","9.0364","0.0354","9.0364","18.4417","14.7485"
"10.8000","9.0532","0.0355","9.0532","18.4759","14.7734"
"10.8200","9.0700","0.0355","9.0700","18.5101","14.7954"
"10.8400","9.0869","0.0356","9.0869","18.5446","14.8219"
"10.8600","9.1034","0.0356","9.1034","18.5783","14.8467"
"10.8800","9.1197","0.0357","9.1197","18.6116","14.8704"
"10.9000","9.1362","0.0357","9.1362","18.6453","14.8854"
"10.9200","9.1533","0.0358","9.1533","18.6802","14.9182"
"10.9400","9.1701","0.0359","9.1701","18.7145","14.9484"
"10.9600","9.1867","0.0359","9.1867","18.7484","14.9643"
"10.9800","9.2036","0.0360","9.2036","18.7829","14.9909"
"11.0000","9.2200","0.0360","9.2200","18.8164","14.9995"
"11.0200","9.2363","0.0361","9.2363","18.8496","15.0232"
"11.0400","9.2527","0.0361","9.2527","18.8831","15.0507"
"11.0600","9.2696","0.0362","9.2696","18.9176","15.0654"
"11.0800","9.2865","0.0362","9.2865","18.9520","15.0852"
"11.1000","9.3032","0.0362","9.3032","18.9862","15.0845"
"11.1200","9.3199","0.0362","9.3199","19.0202","15.0957"
"11.1400","9.3368","0.0363","9.3368","19.0546","15.1136"
"11.1600","9.3532","0.0363","9.3532","19.0881","15.1346"
"11.1800","9.3695","0.0361","9.3695","19.1214","15.0583"
"11.2000","9.3864","0.0355","9.3864","19.1558","14.7736"
"11.2200","9.4032","0.0351","9.4032","19.1903","14.6296"
"11.2400","9.4200","0.0351","9.4200","19.2245","14.6251"
"11.2600","9.4367","0.0352","9.4367","19.2585","14.6639"
"11.2800","9.4534","0.0353","9.4534","19.2927","14.7036"
"11.3000","9.4701","0.0353","9.4701","19.3267","14.7246"
"11.3200","9.4865","0.0354","9.4865","19.3601","14.7514"
"11.3400","9.5030","0.0354","9.5030","19.3939","14.7609"
"11.3600","9.5200","0.0354","9.5200","19.4286","14.7649"
"11.3800","9.5368","0.0355","9.5368","19.4628","14.7958"
"11.4000","9.5533","0.0355","9.5533","19.4965","14.8110"
"11.4200","9.5699","0.0356","9.5699","19.5305","14.8534"
"11.4400","9.5866","0.0357","9.5866","19.5645","14.8576"
"11.4600","9.6030","0.0357","9.6030","19.5979","14.8652"
"11.4800","9.6195","0.0357","9.6195","19.6317","14.8752"
"11.5000","9.6364","0.0357","9.6364","19.6661","14.8918"
"11.5200","9.6534","0.0358","9.6534","19.7008","14.9173"
"11.5400","9.6702","0.0358","9.6702","19.7350","14.9285"
"11.5600","9.6867","0.0359","9.6867","19.7688","14.9576"
"11.5800","9.7033","0.0360","9.7033","19.8027","14.9922"
"11.6000","9.7200","0.0360","9.7200","19.8367","14.9884"
"11.6200","9.7364","0.0360","9.7364","19.8702","15.0049"
"11.6400","9.7530","0.0361","9.7530","19.9042","15.0251"
"11.6600","9.7700","0.0361","9.7700","19.9389","15.0396"
"11.6800","9.7869","0.0361","9.7869","19.9733","15.0563"
"11.7000","9.8033","0.0362","9.8033","20.0068","15.0794"
"11.7200","9.8200","0.0363","9.8200","20.0408","15.1079"
"11.7400","9.8366","0.0363","9.8366","20.0747","15.1306"
"11.7600","9.8530","0.0363","9.8530","20.1082","15.1454"
"11.7800","9.8696","0.0364","9.8696","20.1420","15.1787"
"11.8000","9.8866","0.0364","9.8866","20.1767","15.1581"
"11.8200","9.9036","0.0363","9.9036","20.2114","15.1452"
"11.8400","9.9201","0.0365","9.9201","20.2451","15.2069"
"11.8600","9.9365","0.0366","9.9365","20.2786","15.2523"
"11.8800","9.9530","0.0366","9.9530","20.3123","15.2695"
"11.9000","9.9697","0.0367","9.9697","20.3463","15.2793"
"11.9200","9.9863","0.0367","9.9863","20.3802","15.2958"
"11.9400","10.0032","0.0368","10.0032","20.4147","15.3137"
"11.9600","10.0202","0.0368","10.0202","20.4494","15.3350"
"11.9800","10.0370","0.0369","10.0370","20.4836","15.3613"
"12.0000","10.0534","0.0369","10.0534","20.5171","15.3722"
"12.0200","10.0698","0.0369","10.0698","20.5506","15.3891"
"12.0400","10.0864","0.0370","10.0864","20.5846","15.4010"
"12.0600","10.1033","0.0370","10.1033","20.6190","15.4139"
"12.0800","10.1200","0.0370","10.1200","20.6530","15.4319"
"12.1000","10.1367","0.0370","10.1367","20.6872","15.4317"
"12.1200","10.1535","0.0371","10.1535","20.7214","15.4517"
"12.1400","10.1700","0.0371","10.1700","20.7551","15.4752"
"12.1600","10.1864","0.0372","10.1864","20.7886","15.5204"
"12.1800","10.2029","0.0373","10.2029","20.8223","15.5375"
"12.2000","10.2199","0.0373","10.2199","20.8570","15.5385"
"12.2200","10.2366","0.0374","10.2366","20.8910","15.5678"
"12.2400","10.2532","0.0374","10.2532","20.9250","15.5929"
"12.2600","10.2701","0.0374","10.2701","20.9594","15.6007"
"12.2800","10.2869","0.0375","10.2869","20.9936","15.6107"
"12.3000","10.3031","0.0375","10.3031","21.0267","15.6153"
"12.3200","10.3195","0.0375","10.3195","21.0601","15.6325"
"12.3400","10.3365","0.0376","10.3365","21.0948","15.6528"
"12.3600","10.3536","0.0376","10.3536","21.1298","15.6621"
"12.3800","10.3701","0.0376","10.3701","21.1635","15.6842"
"12.4000","10.3868","0.0376","10.3868","21.1975","15.6860"
"12.4200","10.4035","0.0377","10.4035","21.2317","15.7006"
"12.4400","10.4199","0.0377","10.4199","21.2652","15.7115"
"12.4600","10.4361","0.0377","10.4361","21.2982","15.7281"
"12.4800","10.4529","0.0378","10.4529","21.3324","15.7414"
"12.5000","10.4699","0.0378","10.4699","21.3671","15.7452"
"12.5200","10.4866","0.0378","10.4866","21.4013","15.7604"
"12.5400","10.5032","0.0379","10.5032","21.4350","15.7889"
"12.5600","10.5197","0.0379","10.5197","21.4688","15.8008"
"12.5800","10.5363","0.0379","10.5363","21.5027","15.8025"
"12.6000","10.5526","0.0379","10.5526","21.5360","15.8067"
"12.6200","10.5694","0.0380","10.5694","21.5702","15.8153"
"12.6400","10.5865","0.0380","10.5865","21.6051","15.8338"
"12.6600","10.6034","0.0380","10.6034","21.6396","15.8510"
"12.6800","10.6199","0.0381","10.6199","21.6733","15.8712"
"12.7000","10.6366","0.0382","10.6366","21.7073","15.9004"
"12.7200","10.6532","0.0382","10.6532","21.7413","15.9243"
"12.7400","10.6696","0.0382","10.6696","21.7747","15.9346"
"12.7600","10.6860","0.0382","10.6860","21.8082","15.9372"
"12.7800","10.7029","0.0381","10.7029","21.8427","15.8936"
"12.8000","10.7199","0.0375","10.7199","21.8774","15.6141"
"12.8200","10.7366","0.0371","10.7366","21.9113","15.4517"
"12.8400","10.7531","0.0370","10.7531","21.9451","15.4244"
"12.8600","10.7697","0.0370","10.7697","21.9791","15.4368"
"12.8800","10.7863","0.0371","10.7863","22.0128","15.4627"
"12.9000","10.8029","0.0372","10.8029","22.0468","15.4879"
"12.9200","10.8198","0.0372","10.8198","22.0812","15.5129"
"12.9400","10.8368","0.0371","10.8368","22.1159","15.4723"
"12.9600","10.8536","0.0366","10.8536","22.1501","15.2521"
"12.9800","10.8701","0.0363","10.8701","22.1838","15.1043"
"13.0000","10.8866","0.0362","10.8866","22.2176","15.0893"
"13.0200","10.9033","0.0363","10.9033","22.2515","15.1320"
"13.0400","10.9200","0.0364","10.9200","22.2858","15.1479"
"13.0600","10.9367","0.0364","10.9367","22.3197","15.1581"
"13.0800","10.9533","0.0364","10.9533","22.3537","15.1748"
"13.1000","10.9702","0.0364","10.9702","22.3881","15.1756"
"13.1200","10.9868","0.0365","10.9868","22.4221","15.1968"
"13.1400","11.0032","0.0365","11.0032","22.4556","15.2074"
"13.1600","11.0197","0.0365","11.0197","22.4891","15.2207"
"13.1800","11.0364","0.0366","11.0364","22.5233","15.2361"
"13.2000","11.0531","0.0366","11.0531","22.5573","15.2478"
"13.2200","11.0698","0.0366","11.0698","22.5915","15.2665"
"13.2400","11.0868","0.0367","11.0868","22.6262","15.2738"
"13.2600","11.1036","0.0367","11.1036","22.6604","15.2913"
"13.2800","11.1200","0.0368","11.1200","22.6939","15.3165"
"13.3000","11.1365","0.0368","11.1365","22.7276","15.3213"
"13.3200","11.1532","0.0366","11.1532","22.7616","15.2448"
"13.3400","11.1699","0.0359","11.1699","22.7958","14.9591"
"13.3600","11.1867","0.0356","11.1867","22.8300","14.8212"
"13.3800","11.2036","0.0356","11.2036","22.8645","14.8245"
"13.4000","11.2202","0.0350","11.2202","22.8984","14.5775"
"13.4200","11.2368","0.0344","11.2368","22.9322","14.3434"
"13.4400","11.2529","0.0342","11.2529","22.9652","14.2613"
"13.4600","11.2695","0.0342","11.2695","22.9989","14.2642"
"13.4800","11.2863","0.0343","11.2863","23.0334","14.3081"
"13.5000","11.3030","0.0344","11.3030","23.0673","14.3234"
"13.5200","11.3198","0.0344","11.3198","23.1015","14.3404"
"13.5400","11.3365","0.0344","11.3365","23.1358","14.3512"
"13.5600","11.3532","0.0345","11.3532","23.1697","14.3651"
"13.5800","11.3697","0.0345","11.3697","23.2035","14.3706"
"13.6000","11.3863","0.0345","11.3863","23.2374","14.3663"
"13.6200","11.4032","0.0339","11.4032","23.2719","14.1389"
"13.6400","11.4200","0.0334","11.4200","23.3061","13.8986"
"13.6600","11.4366","0.0331","11.4366","23.3401","13.8033"
"13.6800","11.4533","0.0332","11.4533","23.3740","13.8172"
"13.7000","11.4700","0.0332","11.4700","23.4082","13.8334"
"13.7200","11.4864","0.0332","11.4864","23.4417","13.8427"
"13.7400","11.5030","0.0333","11.5030","23.4755","13.8597"
"13.7600","11.5197","0.0334","11.5197","23.5097","13.9032"
"13.7800","11.5366","0.0334","11.5366","23.5441","13.8958"
"13.8000","11.5533","0.0333","11.5533","23.5781","13.8907"
"13.8200","11.5700","0.0334","11.5700","23.6123","13.9033"
"13.8400","11.5867","0.0334","11.5867","23.6463","13.9137"
"13.8600","11.6031","0.0334","11.6031","23.6798","13.9170"
"13.8800","11.6195","0.0334","11.6195","23.7133","13.9256"
"13.9000","11.6364","0.0335","11.6364","23.7477","13.9397"
"13.9200","11.6533","0.0335","11.6533","23.7822","13.9515"
"13.9400","11.6701","0.0335","11.6701","23.8166","13.9751"
"13.9600","11.6867","0.0336","11.6867","23.8504","13.9833"
"13.9800","11.7033","0.0336","11.7033","23.8843","13.9990"
"14.0000","11.7198","0.0336","11.7198","23.9181","14.0089"
"14.0200","11.7363","0.0337","11.7363","23.9515","14.0367"
"14.0400","11.7529","0.0337","11.7529","23.9855","14.0554"
"14.0600","11.7699","0.0338","11.7699","24.0202","14.0723"
"14.0800","11.7868","0.0332","11.7868","24.0547","13.8383"
"14.1000","11.8033","0.0326","11.8033","24.0884","13.5634"
"14.1200","11.8200","0.0323","11.8200","24.1224","13.4736"
"14.1400","11.8366","0.0324","11.8366","24.1563","13.4897"
"14.1600","11.8531","0.0325","11.8531","24.1901","13.5255"
"14.1800","11.8695","0.0325","11.8695","24.2235","13.5300"
"14.2000","11.8863","0.0324","11.8863","24.2578","13.5047"
"14.2200","11.9033","0.0324","11.9033","24.2925","13.5059"
"14.2400","11.9201","0.0325","11.9201","24.3267","13.5287"
"14.2600","11.9365","0.0325","11.9365","24.3602","13.5415"
"14.2800","11.9530","0.0325","11.9530","24.3939","13.5577"
"14.3000","11.9695","0.0326","11.9695","24.4276","13.5632"
"14.3200","11.9864","0.0326","11.9864","24.4621","13.5670"
"14.3400","12.0031","0.0326","12.0031","24.4960","13.5735"
"14.3600","12.0201","0.0326","12.0201","24.5307","13.5944"
"14.3800","12.0369","0.0327","12.0369","24.5652","13.6215"
"14.4000","12.0534","0.0327","12.0534","24.5987","13.6261"
"14.4200","12.0699","0.0327","12.0699","24.6324","13.6431"
"14.4400","12.0865","0.0323","12.0865","24.6664","13.4604"
"14.4600","12.1034","0.0318","12.1034","24.7008","13.2300"
"14.4800","12.1201","0.0315","12.1201","24.7348","13.1281"
"14.5000","12.1368","0.0314","12.1368","24.7690","13.0921"
"14.5200","12.1536","0.0314","12.1536","24.8032","13.0985"
"14.5400","12.1701","0.0306","12.1701","24.8370","12.7570"
"14.5600","12.1864","0.0288","12.1864","24.8702","12.0021"
"14.5800","12.2029","0.0276","12.2029","24.9039","11.4961"
"14.6000","12.2198","0.0267","12.2198","24.9384","11.1358"
"14.6200","12.2366","0.0265","12.2366","24.9726","11.0300"
"14.6400","12.2533","0.0265","12.2533","25.0068","11.0240"
"14.6600","12.2702","0.0265","12.2702","25.0413","11.0541"
"14.6800","12.2869","0.0266","12.2869","25.0752","11.0813"
"14.7000","12.3033","0.0266","12.3033","25.1087","11.0942"
"14.7200","12.3197","0.0267","12.3197","25.1422","11.1105"
"14.7400","12.3364","0.0267","12.3364","25.1764","11.1165"
"14.7600","12.3533","0.0267","12.3533","25.2109","11.1212"
"14.7800","12.3699","0.0267","12.3699","25.2446","11.1143"
"14.8000","12.3865","0.0259","12.3865","25.2786","10.7774"
"14.8200","12.4034","0.0253","12.4034","25.3130","10.5327"
"14.8400","12.4199","0.0251","12.4199","25.3468","10.4596"
"14.8600","12.4360","0.0251","12.4360","25.3795","10.4568"
"14.8800","12.4527","0.0245","12.4527","25.4137","10.2094"
"14.9000","12.4696","0.0234","12.4696","25.4482","9.7360"
"14.9100","12.4780","0.0229","12.4780","25.4653","9.5519"